Workbook

Sheet README
B2: Fund of Funds Model, with Annual Forecast
B4: Copyright & Contact | C4: This was created by Taylor Davidson (@tdavidson) of Foresight. © 2023, Unstructured Ventures, LLC. Questions, contact taylor@foresight.is or @tdavidson
B5: License | C5: tl:dr; You can modify, edit, use, and share within your company (and with third-parties as needed to operate your business). You may not redistribute, resell, give away to others. Full license.
B6: Goal | C6: Simplified model for forecasting a fund investing in venture funds (fund-of-fund, or FoF), to help understand overall fund assumptions and how portfolio construction impacts returns. I've worked with countless founders building complicated models for fund construction - see Venture Investor Model for one - but want to create a model for fund of funds.
B7: Copy to Google Sheets or Download to Excel | C7: File > Make a Copy to copy it to your own Google Drive, or File > Download to download this to use in Excel or other spreadsheet programs. See License for warranties and liabilities.
B8: Support | C8: Questions, happy to assist, contact anytime. More details on how I provide support: https://foresight.is/learn/support
B9: Missing a feature you need? | C9: Check out the Resources for other resources for modeling venture funds, and check out Foresight's Venture Investor Model for a more detailed fund model with financial statements, management company budgeting, and more.
B10: Quickstart | C10: Input fund structural assumptions on Get Started sheet, then review the Key Reports and Forecast sheet to see the key outputs.
B11: Video Overview | C11: https://www.loom.com/share/abc1eec8e3dc4066bd8ab59ab69886b3
B13: Outline
B15: README | C15: Contact into, overview on model. Safe to delete or hide.
B16: Formatting and Colors Overview | C16: Details on what the colors and formatting in the model mean. https://foresight.is/learn/colors-and-formatting
B17: License | C17: Terms of use of the model. Safe to delete or hide. https://foresight.is/license
B18: Get Started | C18: Core assumptions for the fund. Do not delete, safe to hide.
B19: Capital and Fund Assumptions | C19: Video overview at https://www.loom.com/share/d73a5dca6f1c47df9cfdb048aa147f9d
B20: Portfolio Construction | C20: Assumptions related to the funds being invested in, their cost structure, and return profile.
B21: Fund Performance | C21: Overall performance returns for the fund of funds.
B22: Key Reports | C22: Key charts to summarize the model. Safe to delete or hide.
B23: Forecast | C23: The core calculations to forecast the operations of the fund. The core of the model.
B24: Resources | C24: Links to other models and resources for modeling venture capital funds and investments, from around the web. Safe to delete or hide.
B25: Model Comparison | C25: Detailed feature comparison of the range of Foresight models for venture investors
B26: Glossary | C26: Glossary of key terminology in the model. Safe to delete or hide.
B27: Changelog | C27: List of what has been changed in model versions. Safe to delete or hide, although I'd advise to hide (instead of delete) so can always check to see what model version you are using to compare to future changes.

Sheet License
B1: License Agreement
B2: Available on website
B4: This License Agreement (“the Agreement”) between you, the licensee, and Unstructured Ventures, LLC (the “Company”) a limited liability corporation headquartered and registered in the Commonwealth of Pennsylvania and organized under the laws of the state of Delaware. The Company owns the financial model (the “Product”) and any edits, additions, or customizations (the "Service") delivered under this Agreement. This Agreement grants you a non-exclusive, non-transferable right to use and incorporate the Product and Service in personal and corporate projects for the organization that purchased the Product and/or Service.
B6: You agree as follows:
B8: 1. Scope of use
B9: * Use and incorporate the Product and/or Service in personal and commercial projects for your company including financial models, business plans, pitch decks, etc.
B10: * You may modify the Product and/or Service to better serve your project.
B11: * You are granted unlimited usage of the Product and/or Service purchased in your organization.
B12: * If an organization is the licensee, all employees of the organization may use the same license.
B14: 2. Limitations and non-use
B15: * You may not redistribute, sublicense or resell the Product and/or Service.
B16: * You may not distribute, license or sell derivative, recompiled, reverse engineered, or modified versions of the Product and/or Service.
... B29: This Agreement is governed by the laws of the Commonwealth of Pennsylvania and the applicable laws of the United States of America. Legal proceedings related to this Agreement may only be brought in the courts of Pennsylvania. You agree to service of process at the e-mail address on your original order. Notices may be sent to Unstructured Ventures, LLC by email to hello@unstructuredventures.com or by post to Unstructured Ventures, LLC, 6360 Broad St, #5226, Pittsburgh, PA, 15206, USA.

Sheet Get Started
B2: Get Started
B3: Key model assumptions.
B5: Capital and Fund Assumptions
B6: Capital, Management Fees, base Fund Assumptions
B8: Detail | C8: Unit | D8: Assumption | E8: Forecast | J8: Notes
B9: Total Commited Capital (Fund Size) | C9: $ | D9: 100000000 | E9: =D9 -> 100000000 | J9: Fund size. By default, assumes all committed capital is closed at the start. Can adjust that by modifying the committed capital on Forecast sheet.
B10: GP Commit, as % of committed capital | C10: % | D10: 0.02 | E10: =D10*E$9 -> 2000000 | J10: GP commit is treated as an LP interest for purposes of calculating mangement fees and carried interest. see glossary for additional details
B11: Organizational Expenses (one time) | C11: =C$9 -> $ | D11: 150000 | E11: =D11 -> 150000 | J11: paid by fund, in addition to management fees
B12: Operational Expenses (annual) | C12: =C$9 -> $ | D12: 100000 | E12: =D12*D18 -> 1400000 | J12: paid by fund, in addition to management fees
B13: Management Fees, per year, as % of committed capital | C13: % | D13: 0.02 | E13: =Forecast!E35 -> 23520000 | J13: model works for management fees based on called and committed capital (can be edited for fee structures based on assets under management). if you have a management fee structure that steps down over time, you can edit the management fees directly on the Forecast sheet.
B14: Management Fees Recycled | C14: % | D14: 1 | E14: =D14*E13 -> 23520000 | J14: recycling proceeds, as a % of management fees
B15: Carry | C15: % | D15: 0.2 | E15: =Forecast!E40 -> 35689168 | J15: carry is the % of gains that are paid to the managers of the fund. part of the commonly cited "2 and 20" fees structure for funds
B16: Number of years making commitments to funds (years) | C16: # | D16: 3 | J16: time period to make new commitments to funds
B17: Fund of Fund Management Fees time period (years) | C17: # | D17: 12 | J17: time period used for assuming management fees, tied to the fund duration and not including the fund extension period, if applicable
B18: Fund of Fund Operations time period (years) | C18: # | D18: =max(G43:G46)+D37+D16-1 -> 14 | J18: time period used for assuming operational expenses, which is calculated from the new invesetment and exit timeframes, to cover the periods the fund incurrs operational expenses. you can override the calculated period if desired.
B21: Portfolio Construction
B22: Baseline assumptions for the average investment into a fund, and the baseline expectations for a fund
B24: Fund Expenses | C24: Unit | D24: LP Investment | E24: Total Fund
B25: Total Commited Capital (Fund Size) | C25: =C$9 -> $ | D25: 5000000 | E25: 25000000 | J25: Input the average fund size investing into, and the LP position taken in the fund
B26: GP Commit, as % of committed capital | C26: % | D26: 0 | E26: 0 | J26: Assume zero, as we are modeling the performance of the underlying fund, but only for the capital invested by the LP, of which there is no GP commit per the LP's investment
B27: Organizational Expenses (one time) | C27: =C$9 -> $ | D27: =D25/E25*E27 -> 30000 | E27: 150000 | J27: Assume the total fund, then the model calculates the prorata - based on portion of the fund invested in - to use across the fund
B28: Operational Expenses (annual) | C28: =C$9 -> $ | D28: =D25/E25*E28 -> 20000 | E28: 100000 | J28: Assume the total fund, then the model calculates the prorata - based on portion of the fund invested in - to use across the fund
B29: Management Fees, per year, as % of committed capital | C29: % | D29: 0.02 | E29: =Forecast!E305/Forecast!E158*E25 -> 5000000 | J29: Structurally assumes the LP's stake modeled here has the same terms as all other LPs. Possible to adjust to reflect different terms, if needed, contact taylor@foresight.is
B30: Management Fees Recycled | C30: % | D30: 1 | E30: =D30*E29 -> 5000000 | J30: Structurally assumes the LP's stake modeled here has the same terms as all other LPs. Possible to adjust to reflect different terms, if needed, contact taylor@foresight.is
B31: Carry | C31: % | D31: 0.2 | J31: Structurally assumes the LP's stake modeled here has the same terms as all other LPs. Possible to adjust to reflect different terms, if needed, contact taylor@foresight.is
B34: Investment Allocation Detail | C34: Unit | D34: New | E34: Follow
B35: % Allocation of Invested Capital | C35: % | D35: 0.6 | E35: =1-D35 -> 0.4 | J35: Allocation of overall invested capital to new and follow, for this example fund
B36: Average Check Size | C36: =C$9 -> $ | D36: 250000 | E36: 125000 | J36: Follow ons are assumed to be on average 1-2 years after the new investment. If more detailed required, consider the Venture Investor Model (see Model Comparison sheet)
B37: Investment time period (years) | C37: # | D37: 4 | J37: time period for new investments (follow ons by default assumed to come over time)
B38: Management Fees time period (years) | C38: # | D38: 10 | J38: time period used for assuming management fees, tied to the fund duration and not including the fund extension period, if applicable
B39: Fund Operations time period (years) | C39: # | D39: =max(G43:G46)+D37 -> 12 | J39: time period used for assuming operational expenses, which is calculated from the new invesetment and exit timeframes, to cover the periods the fund incurrs operational expenses. you can override the calculated period if desired.
B40: Invested Capital | C40: =C$9 -> $ | D40: =if( sumproduct(--(Forecast!G135:Z135<>"committed"),--(Forecast!G9:Z9=1)) = 0 , E25-E27-E28*D39-E29+E30 , E25-E27-E28*D39-E25*Forecast!E134*(1-D30) ) -> 23650000 | J40: total for the average fund being modeled
B42: Type of Exit | C42: Unit | D42: % of Investments | E42: # of Investments | F42: Average Gross Exit Multiple | G42: Average Hold Period (years) | H42: % of Total Proceeds | J42: Type of Exit can be defined in a few ways: by returns (writeoffs, small, medium, large), by strategy (Seed, A, B, etc.), by investment strategy (early, late, growth), or industry strategy (tech, energy, etc.)
B43: Writeoff | C43: #, % | D43: 0.6 | E43: =D43*E$47 -> 34.056 | F43: 0 | G43: 2 | H43: =iferror(F43*D43/F$47,0) -> 0 | J43: Average Hold Period is the average time from initial investment to exit, per # of investments
B44: Small | C44: #, % | D44: 0.2 | E44: =D44*E$47 -> 11.352 | F44: 1.5 | G44: 3 | H44: =iferror(F44*D44/F$47,0) -> 0.075 | J44: Ownership at initial investment is assumed to be same across all types of investments
B45: Medium | C45: #, % | D45: 0.1 | E45: =D45*E$47 -> 5.676 | F45: 5 | G45: 5 | H45: =iferror(F45*D45/F$47,0) -> 0.125 | J45: % of Total Follow on is an assumption to help assume how your total follow on capital is allocated across types of invesetments. You could make it equal across all types, or weight your follow ons differently to show larger investments into certain types of investments.
B46: Large | C46: #, % | D46: =max(0,1-sum(D43:D45)) -> 0.1 | E46: =D46*E$47 -> 5.676 | F46: 32 | G46: 8 | H46: =iferror(F46*D46/F$47,0) -> 0.8 | J46: Ownership % at exit an assumption, which you will need to make based on your investment strategy and expectation of how many rounds of capital a company will need to raise. This is a simplified way to do what can be a complicated thing, to do this in more detail consider the Venture Investor Model (see link in Model Comparison sheet), which has a full detailed Portfolio Construction option.
B47: Average | D47: =sum(D43:D46) -> 1 | E47: =iferror(D40*D35/D36,0) -> 56.76 | F47: =sumproduct(F43:F46,$D43:$D46) -> 4 | G47: =sumproduct(G43:G46,$D43:$D46) -> 3.1 | H47: =sum(H43:H46) -> 1 | J47: Can adjust this structure to add additional lines, just note will need to make a few edits on Forecast sheet.
B50: Fund of Funds Performance
B51: Performance summary
...

Sheet Key Reports

Sheet Forecast
B2: Annual Forecast
B4: Relative Year | G4: =1 -> 1 | H4: =G4+1 -> 2 | I4: =H4+1 -> 3 | J4: =I4+1 -> 4 | K4: =J4+1 -> 5 | L4: =K4+1 -> 6 | M4: =L4+1 -> 7 | N4: =M4+1 -> 8 | O4: =N4+1 -> 9 | ... Z4: =Y4+1 -> 20
B5: Date at end of period | G5: 44926 | H5: =edate(G5,12) -> 45291 | I5: =edate(H5,12) -> 45657 | J5: =edate(I5,12) -> 46022 | K5: =edate(J5,12) -> 46387 | L5: =edate(K5,12) -> 46752 | M5: =edate(L5,12) -> 47118 | N5: =edate(M5,12) -> 47483 | O5: =edate(N5,12) -> 47848 | ... Z5: =edate(Y5,12) -> 51866
B7: Triggers
B8: FoF Investment time period (years) | C8: period for making new investments only | D8: sum | E8: =if(D8="sum",sum(G8:Z8),if(D8="final",Z8,if(D8="initial",G8,if(D8="average",average(G8:Z8),0)))) -> 3 | G8: =if(G$4<='Get Started'!$D16,1,0) -> 1 | H8: =if(H$4<='Get Started'!$D16,1,0) -> 1 | I8: =if(I$4<='Get Started'!$D16,1,0) -> 1 | J8: =if(J$4<='Get Started'!$D16,1,0) -> 0 | K8: =if(K$4<='Get Started'!$D16,1,0) -> 0 | L8: =if(L$4<='Get Started'!$D16,1,0) -> 0 | M8: =if(M$4<='Get Started'!$D16,1,0) -> 0 | N8: =if(N$4<='Get Started'!$D16,1,0) -> 0 | ... Z8: =if(Z$4<='Get Started'!$D16,1,0) -> 0
B9: FoF Management Fees time period (years) | C9: see FAST Standard for how to use triggers: https://foresight.is/learn/fast-standard | D9: sum | E9: =if(D9="sum",sum(G9:Z9),if(D9="final",Z9,if(D9="initial",G9,if(D9="average",average(G9:Z9),0)))) -> 12 | G9: =if(G$4<='Get Started'!$D17,1,0) -> 1 | H9: =if(H$4<='Get Started'!$D17,1,0) -> 1 | I9: =if(I$4<='Get Started'!$D17,1,0) -> 1 | J9: =if(J$4<='Get Started'!$D17,1,0) -> 1 | K9: =if(K$4<='Get Started'!$D17,1,0) -> 1 | L9: =if(L$4<='Get Started'!$D17,1,0) -> 1 | M9: =if(M$4<='Get Started'!$D17,1,0) -> 1 | N9: =if(N$4<='Get Started'!$D17,1,0) -> 1 | ... Z9: =if(Z$4<='Get Started'!$D17,1,0) -> 0
B10: FoF Operations time period (years) | D10: sum | E10: =if(D10="sum",sum(G10:Z10),if(D10="final",Z10,if(D10="initial",G10,if(D10="average",average(G10:Z10),0)))) -> 14 | G10: =if(G$4<='Get Started'!$D18,1,0) -> 1 | H10: =if(H$4<='Get Started'!$D18,1,0) -> 1 | I10: =if(I$4<='Get Started'!$D18,1,0) -> 1 | J10: =if(J$4<='Get Started'!$D18,1,0) -> 1 | K10: =if(K$4<='Get Started'!$D18,1,0) -> 1 | L10: =if(L$4<='Get Started'!$D18,1,0) -> 1 | M10: =if(M$4<='Get Started'!$D18,1,0) -> 1 | N10: =if(N$4<='Get Started'!$D18,1,0) -> 1 | ... Z10: =if(Z$4<='Get Started'!$D18,1,0) -> 0
B12: Inputs
B13: Management Fees | D13: sum | E13: =if(D13="sum",sum(G13:Z13),if(D13="final",Z13,if(D13="initial",G13,if(D13="average",average(G13:Z13),0)))) -> 0.24 | G13: =if(G9=1,'Get Started'!$D13,0) -> 0.02 | H13: =if(H9=1,'Get Started'!$D13,0) -> 0.02 | I13: =if(I9=1,'Get Started'!$D13,0) -> 0.02 | J13: =if(J9=1,'Get Started'!$D13,0) -> 0.02 | K13: =if(K9=1,'Get Started'!$D13,0) -> 0.02 | L13: =if(L9=1,'Get Started'!$D13,0) -> 0.02 | M13: =if(M9=1,'Get Started'!$D13,0) -> 0.02 | N13: =if(N9=1,'Get Started'!$D13,0) -> 0.02 | ... Z13: =if(Z9=1,'Get Started'!$D13,0) -> 0
B14: ="Management Fees based on "&G14&" capital. Can change per period if method for calc changes." -> Management Fees based on committed capital. Can change per period if method for calc changes. | D14: sum | E14: =if(D14="sum",sum(G14:Z14),if(D14="final",Z14,if(D14="initial",G14,if(D14="average",average(G14:Z14),0)))) -> 0 | G14: committed | H14: =G14 -> committed | I14: =H14 -> committed | J14: =I14 -> committed | K14: =J14 -> committed | L14: =K14 -> committed | M14: =L14 -> committed | N14: =M14 -> committed | O14: =N14 -> committed | ... Z14: =Y14 -> committed
B15: GP Commit, excluded from LP capital. By default, GP commit is treated as an LP interest. Check the box to have the GP commit not treated as an LP investment. This will affect management fees (management fees will not be charged on the GP commit if it's not an LP interest, and it will change the waterfall so that GPs only get carried interest, and not carried interest + their share of distributions as an LP) | C15: FALSE | D15: sum | E15: =if(D15="sum",sum(G15:Z15),if(D15="final",Z15,if(D15="initial",G15,if(D15="average",average(G15:Z15),0)))) -> 0 | G15: =if($C15=true,G27*'Get Started'!$D10,0) -> 0 | H15: =if($C15=true,H27*'Get Started'!$D10,0) -> 0 | I15: =if($C15=true,I27*'Get Started'!$D10,0) -> 0 | J15: =if($C15=true,J27*'Get Started'!$D10,0) -> 0 | K15: =if($C15=true,K27*'Get Started'!$D10,0) -> 0 | L15: =if($C15=true,L27*'Get Started'!$D10,0) -> 0 | M15: =if($C15=true,M27*'Get Started'!$D10,0) -> 0 | N15: =if($C15=true,N27*'Get Started'!$D10,0) -> 0 | ... Z15: =if($C15=true,Z27*'Get Started'!$D10,0) -> 0
B16: GP Commit, excluded from management fees. Check the box to have the GP commit - capital contributed by the GP as LP capital and an ownership in the fund - excluded from calculation of management fees | C16: TRUE | D16: sum | E16: =if(D16="sum",sum(G16:Z16),if(D16="final",Z16,if(D16="initial",G16,if(D16="average",average(G16:Z16),0)))) -> 2000000 | G16: =if($C16=true,G27*'Get Started'!$D10,0) -> 157023.7 | H16: =if($C16=true,H27*'Get Started'!$D10,0) -> 324998.53 | I16: =if($C16=true,I27*'Get Started'!$D10,0) -> 495973.37 | J16: =if($C16=true,J27*'Get Started'!$D10,0) -> 514744.5 | K16: =if($C16=true,K27*'Get Started'!$D10,0) -> 375043.95 | L16: =if($C16=true,L27*'Get Started'!$D10,0) -> 132215.95 | M16: =if($C16=true,M27*'Get Started'!$D10,0) -> 0 | N16: =if($C16=true,N27*'Get Started'!$D10,0) -> 0 | ... Z16: =if($C16=true,Z27*'Get Started'!$D10,0) -> 0
B18: Capital, beginning of period | D18: initial | E18: =if(D18="sum",sum(G18:Z18),if(D18="final",Z18,if(D18="initial",G18,if(D18="average",average(G18:Z18),0)))) | G18: =F24 | H18: =G24 -> 0 | I18: =H24 -> 0 | J18: =I24 -> 0 | K18: =J24 -> 0 | L18: =K24 -> -1.8626451e-09 | M18: =L24 -> 0 | N18: =M24 -> -4.6566129e-10 | ... Z18: =Y24 -> 0
B19: Called Capital | D19: sum | E19: =if(D19="sum",sum(G19:Z19),if(D19="final",Z19,if(D19="initial",G19,if(D19="average",average(G19:Z19),0)))) -> 100000000 | G19: =G27 -> 7851185 | H19: =H27 -> 16249927 | I19: =I27 -> 24798668 | J19: =J27 -> 25737225 | K19: =K27 -> 18752198 | L19: =L27 -> 6610797.5 | M19: =M27 -> 0 | N19: =N27 -> 0 | ... Z19: =Z27 -> 0
B20: Proceeds | D20: sum | E20: =if(D20="sum",sum(G20:Z20),if(D20="final",Z20,if(D20="initial",G20,if(D20="average",average(G20:Z20),0)))) -> 301965840 | G20: =G37 -> 0 | H20: =H37 -> 0 | I20: =I37 -> 0 | J20: =J37 -> 359342.5 | K20: =K37 -> 359342.5 | L20: =L37 -> 4302265 | M20: =M37 -> 10151836 | N20: =N37 -> 14032407 | ... Z20: =Z37 -> 0
B21: Distributions + Carried Interest | D21: sum | E21: =if(D21="sum",sum(G21:Z21),if(D21="final",Z21,if(D21="initial",G21,if(D21="average",average(G21:Z21),0)))) -> -278445840 | G21: =sum(G41,G40,G39)*-1 -> 0 | H21: =sum(H41,H40,H39)*-1 -> 0 | I21: =sum(I41,I40,I39)*-1 -> 0 | J21: =sum(J41,J40,J39)*-1 -> -359342.5 | K21: =sum(K41,K40,K39)*-1 -> -359342.5 | L21: =sum(L41,L40,L39)*-1 -> -709606.67 | M21: =sum(M41,M40,M39)*-1 -> -5740521.7 | N21: =sum(N41,N40,N39)*-1 -> -10397207 | ... Z21: =sum(Z41,Z40,Z39)*-1 -> 0
B22: Fees | D22: sum | E22: =if(D22="sum",sum(G22:Z22),if(D22="final",Z22,if(D22="initial",G22,if(D22="average",average(G22:Z22),0)))) -> -25070000 | G22: =sum(G33,G34,G35)*-1 -> -2210000 | H22: =sum(H33,H34,H35)*-1 -> -2060000 | I22: =sum(I33,I34,I35)*-1 -> -2060000 | J22: =sum(J33,J34,J35)*-1 -> -2060000 | K22: =sum(K33,K34,K35)*-1 -> -2060000 | L22: =sum(L33,L34,L35)*-1 -> -2060000 | M22: =sum(M33,M34,M35)*-1 -> -2060000 | N22: =sum(N33,N34,N35)*-1 -> -2060000 | ... Z22: =sum(Z33,Z34,Z35)*-1 -> 0
B23: Investments | D23: sum | E23: =if(D23="sum",sum(G23:Z23),if(D23="final",Z23,if(D23="initial",G23,if(D23="average",average(G23:Z23),0)))) -> -98450000 | G23: =G32*-1 -> -5641185 | H23: =H32*-1 -> -14189927 | I23: =I32*-1 -> -22738668 | J23: =J32*-1 -> -23677225 | K23: =K32*-1 -> -16692198 | L23: =L32*-1 -> -8143455.8 | M23: =M32*-1 -> -2351314.2 | N23: =N32*-1 -> -1575200 | ... Z23: =Z32*-1 -> 0
B24: Capital, end of period | D24: final | E24: =if(D24="sum",sum(G24:Z24),if(D24="final",Z24,if(D24="initial",G24,if(D24="average",average(G24:Z24),0)))) -> 0 | G24: =sum(G18:G23) -> 0 | H24: =sum(H18:H23) -> 0 | I24: =sum(I18:I23) -> 0 | J24: =sum(J18:J23) -> 0 | K24: =sum(K18:K23) -> -1.8626451e-09 | L24: =sum(L18:L23) -> 0 | M24: =sum(M18:M23) -> -4.6566129e-10 | N24: =sum(N18:N23) -> 0 | ... Z24: =sum(Z18:Z23) -> 0
B26: Committed Capital | D26: sum | E26: =if(D26="sum",sum(G26:Z26),if(D26="final",Z26,if(D26="initial",G26,if(D26="average",average(G26:Z26),0)))) -> 100000000 | G26: =if(G4=1,'Get Started'!$D9,0) -> 100000000 | H26: =if(H4=1,'Get Started'!$D9,0) -> 0 | I26: =if(I4=1,'Get Started'!$D9,0) -> 0 | J26: =if(J4=1,'Get Started'!$D9,0) -> 0 | K26: =if(K4=1,'Get Started'!$D9,0) -> 0 | L26: =if(L4=1,'Get Started'!$D9,0) -> 0 | M26: =if(M4=1,'Get Started'!$D9,0) -> 0 | N26: =if(N4=1,'Get Started'!$D9,0) -> 0 | ... Z26: =if(Z4=1,'Get Started'!$D9,0) -> 0
B27: Called Capital | D27: sum | E27: =if(D27="sum",sum(G27:Z27),if(D27="final",Z27,if(D27="initial",G27,if(D27="average",average(G27:Z27),0)))) -> 100000000 | G27: =min($E26-F53, max(0,G32+G33+G34+G35)) -> 7851185 | H27: =min($E26-G53, max(0,H32+H33+H34+H35)) -> 16249927 | I27: =min($E26-H53, max(0,I32+I33+I34+I35)) -> 24798668 | J27: =min($E26-I53, max(0,J32+J33+J34+J35)) -> 25737225 | K27: =min($E26-J53, max(0,K32+K33+K34+K35)) -> 18752198 | L27: =min($E26-K53, max(0,L32+L33+L34+L35)) -> 6610797.5 | M27: =min($E26-L53, max(0,M32+M33+M34+M35)) -> 0 | N27: =min($E26-M53, max(0,N32+N33+N34+N35)) -> 0 | ... Z27: =min($E26-Y53, max(0,Z32+Z33+Z34+Z35)) -> 0
B28: New Investments | D28: sum | E28: =if(D28="sum",sum(G28:Z28),if(D28="final",Z28,if(D28="initial",G28,if(D28="average",average(G28:Z28),0)))) -> 98450000 | G28: =G158 -> 5641185 | H28: =H158 -> 14189927 | I28: =I158 -> 22738668 | J28: =J158 -> 23677225 | K28: =K158 -> 16692198 | L28: =L158 -> 8143455.8 | M28: =M158 -> 2351314.2 | N28: =N158 -> 1575200 | ... Z28: =Z158 -> 0
B29: Prorata Opportunities | D29: sum | E29: =if(D29="sum",sum(G29:Z29),if(D29="final",Z29,if(D29="initial",G29,if(D29="average",average(G29:Z29),0)))) -> 0 | G29: 0 | H29: 0 | I29: 0 | J29: 0 | K29: 0 | L29: 0 | M29: 0 | N29: 0 | O29: 0 | P29: 0 | Q29: 0 | R29: 0 | S29: 0 | T29: 0 | U29: 0 | V29: 0 | W29: 0 | X29: 0 | Y29: 0 | Z29: 0
B30: Follow on Investments | D30: sum | E30: =if(D30="sum",sum(G30:Z30),if(D30="final",Z30,if(D30="initial",G30,if(D30="average",average(G30:Z30),0)))) -> 0 | G30: 0 | H30: 0 | I30: 0 | J30: 0 | K30: 0 | L30: 0 | M30: 0 | N30: 0 | O30: 0 | P30: 0 | Q30: 0 | R30: 0 | S30: 0 | T30: 0 | U30: 0 | V30: 0 | W30: 0 | X30: 0 | Y30: 0 | Z30: 0
B31: Total Investments, by cohort of New Investments | D31: sum | E31: =if(D31="sum",sum(G31:Z31),if(D31="final",Z31,if(D31="initial",G31,if(D31="average",average(G31:Z31),0)))) -> 0 | G31: 0 | H31: 0 | I31: 0 | J31: 0 | K31: 0 | L31: 0 | M31: 0 | N31: 0 | O31: 0 | P31: 0 | Q31: 0 | R31: 0 | S31: 0 | T31: 0 | U31: 0 | V31: 0 | W31: 0 | X31: 0 | Y31: 0 | Z31: 0
B32: Total Investments | C32: 0 | D32: sum | E32: =if(D32="sum",sum(G32:Z32),if(D32="final",Z32,if(D32="initial",G32,if(D32="average",average(G32:Z32),0)))) -> 98450000 | G32: =sum(G28,G30) -> 5641185 | H32: =sum(H28,H30) -> 14189927 | I32: =sum(I28,I30) -> 22738668 | J32: =sum(J28,J30) -> 23677225 | K32: =sum(K28,K30) -> 16692198 | L32: =sum(L28,L30) -> 8143455.8 | M32: =sum(M28,M30) -> 2351314.2 | N32: =sum(N28,N30) -> 1575200 | ... Z32: =sum(Z28,Z30) -> 0
B33: Organizational Expenses | D33: sum | E33: =if(D33="sum",sum(G33:Z33),if(D33="final",Z33,if(D33="initial",G33,if(D33="average",average(G33:Z33),0)))) -> 150000 | G33: =if(G4=1,'Get Started'!$D11,0) -> 150000 | H33: =if(H4=1,'Get Started'!$D11,0) -> 0 | I33: =if(I4=1,'Get Started'!$D11,0) -> 0 | J33: =if(J4=1,'Get Started'!$D11,0) -> 0 | K33: =if(K4=1,'Get Started'!$D11,0) -> 0 | L33: =if(L4=1,'Get Started'!$D11,0) -> 0 | M33: =if(M4=1,'Get Started'!$D11,0) -> 0 | N33: =if(N4=1,'Get Started'!$D11,0) -> 0 | ... Z33: =if(Z4=1,'Get Started'!$D11,0) -> 0
B34: Operational Expenses | D34: sum | E34: =if(D34="sum",sum(G34:Z34),if(D34="final",Z34,if(D34="initial",G34,if(D34="average",average(G34:Z34),0)))) -> 1400000 | G34: ='Get Started'!$D12*G10 -> 100000 | H34: ='Get Started'!$D12*H10 -> 100000 | I34: ='Get Started'!$D12*I10 -> 100000 | J34: ='Get Started'!$D12*J10 -> 100000 | K34: ='Get Started'!$D12*K10 -> 100000 | L34: ='Get Started'!$D12*L10 -> 100000 | M34: ='Get Started'!$D12*M10 -> 100000 | N34: ='Get Started'!$D12*N10 -> 100000 | ... Z34: ='Get Started'!$D12*Z10 -> 0
B35: Management Fees | D35: sum | E35: =if(D35="sum",sum(G35:Z35),if(D35="final",Z35,if(D35="initial",G35,if(D35="average",average(G35:Z35),0)))) -> 23520000 | G35: =iferror(if(G14="committed",G73*if($C16=true,1-'Get Started'!$D10,1)*G13+if(and(G4<>1,G47*if($C16=true,1-'Get Started'!$D10,1)<>0,sum($G47:G47)*if($C16=true,1-'Get Started'!$D10,1)<>E47*if($C16=true,1-'Get Started'!$D10,1)),G47*if($C16=true,1-'Get Started'!$D10,1)*(G4-1)*G13,0),if(G14="called",G13*(G53+F53)/2*if($C16=true,1-'Get Started'!$D10,1),G13*(G75+F75)/2*if($C16=true,1-'Get Started'!$D10,1))),0) -> 1960000 | H35: =iferror(if(H14="committed",H73*if($C16=true,1-'Get Started'!$D10,1)*H13+if(and(H4<>1,H47*if($C16=true,1-'Get Started'!$D10,1)<>0,sum($G47:H47)*if($C16=true,1-'Get Started'!$D10,1)<>F47*if($C16=true,1-'Get Started'!$D10,1)),H47*if($C16=true,1-'Get Started'!$D10,1)*(H4-1)*H13,0),if(H14="called",H13*(H53+G53)/2*if($C16=true,1-'Get Started'!$D10,1),H13*(H75+G75)/2*if($C16=true,1-'Get Started'!$D10,1))),0) -> 1960000 | I35: =iferror(if(I14="committed",I73*if($C16=true,1-'Get Started'!$D10,1)*I13+if(and(I4<>1,I47*if($C16=true,1-'Get Started'!$D10,1)<>0,sum($G47:I47)*if($C16=true,1-'Get Started'!$D10,1)<>G47*if($C16=true,1-'Get Started'!$D10,1)),I47*if($C16=true,1-'Get Started'!$D10,1)*(I4-1)*I13,0),if(I14="called",I13*(I53+H53)/2*if($C16=true,1-'Get Started'!$D10,1),I13*(I75+H75)/2*if($C16=true,1-'Get Started'!$D10,1))),0) -> 1960000 | J35: =iferror(if(J14="committed",J73*if($C16=true,1-'Get Started'!$D10,1)*J13+if(and(J4<>1,J47*if($C16=true,1-'Get Started'!$D10,1)<>0,sum($G47:J47)*if($C16=true,1-'Get Started'!$D10,1)<>H47*if($C16=true,1-'Get Started'!$D10,1)),J47*if($C16=true,1-'Get Started'!$D10,1)*(J4-1)*J13,0),if(J14="called",J13*(J53+I53)/2*if($C16=true,1-'Get Started'!$D10,1),J13*(J75+I75)/2*if($C16=true,1-'Get Started'!$D10,1))),0) -> 1960000 | K35: =iferror(if(K14="committed",K73*if($C16=true,1-'Get Started'!$D10,1)*K13+if(and(K4<>1,K47*if($C16=true,1-'Get Started'!$D10,1)<>0,sum($G47:K47)*if($C16=true,1-'Get Started'!$D10,1)<>I47*if($C16=true,1-'Get Started'!$D10,1)),K47*if($C16=true,1-'Get Started'!$D10,1)*(K4-1)*K13,0),if(K14="called",K13*(K53+J53)/2*if($C16=true,1-'Get Started'!$D10,1),K13*(K75+J75)/2*if($C16=true,1-'Get Started'!$D10,1))),0) -> 1960000 | L35: =iferror(if(L14="committed",L73*if($C16=true,1-'Get Started'!$D10,1)*L13+if(and(L4<>1,L47*if($C16=true,1-'Get Started'!$D10,1)<>0,sum($G47:L47)*if($C16=true,1-'Get Started'!$D10,1)<>J47*if($C16=true,1-'Get Started'!$D10,1)),L47*if($C16=true,1-'Get Started'!$D10,1)*(L4-1)*L13,0),if(L14="called",L13*(L53+K53)/2*if($C16=true,1-'Get Started'!$D10,1),L13*(L75+K75)/2*if($C16=true,1-'Get Started'!$D10,1))),0) -> 1960000 | M35: =iferror(if(M14="committed",M73*if($C16=true,1-'Get Started'!$D10,1)*M13+if(and(M4<>1,M47*if($C16=true,1-'Get Started'!$D10,1)<>0,sum($G47:M47)*if($C16=true,1-'Get Started'!$D10,1)<>K47*if($C16=true,1-'Get Started'!$D10,1)),M47*if($C16=true,1-'Get Started'!$D10,1)*(M4-1)*M13,0),if(M14="called",M13*(M53+L53)/2*if($C16=true,1-'Get Started'!$D10,1),M13*(M75+L75)/2*if($C16=true,1-'Get Started'!$D10,1))),0) -> 1960000 | N35: =iferror(if(N14="committed",N73*if($C16=true,1-'Get Started'!$D10,1)*N13+if(and(N4<>1,N47*if($C16=true,1-'Get Started'!$D10,1)<>0,sum($G47:N47)*if($C16=true,1-'Get Started'!$D10,1)<>L47*if($C16=true,1-'Get Started'!$D10,1)),N47*if($C16=true,1-'Get Started'!$D10,1)*(N4-1)*N13,0),if(N14="called",N13*(N53+M53)/2*if($C16=true,1-'Get Started'!$D10,1),N13*(N75+M75)/2*if($C16=true,1-'Get Started'!$D10,1))),0) -> 1960000 | ... Z35: =iferror(if(Z14="committed",Z73*if($C16=true,1-'Get Started'!$D10,1)*Z13+if(and(Z4<>1,Z47*if($C16=true,1-'Get Started'!$D10,1)<>0,sum($G47:Z47)*if($C16=true,1-'Get Started'!$D10,1)<>X47*if($C16=true,1-'Get Started'!$D10,1)),Z47*if($C16=true,1-'Get Started'!$D10,1)*(Z4-1)*Z13,0),if(Z14="called",Z13*(Z53+Y53)/2*if($C16=true,1-'Get Started'!$D10,1),Z13*(Z75+Y75)/2*if($C16=true,1-'Get Started'!$D10,1))),0) -> 0
B36: Management Fees Recycled | D36: sum | E36: =if(D36="sum",sum(G36:Z36),if(D36="final",Z36,if(D36="initial",G36,if(D36="average",average(G36:Z36),0)))) -> 23520000 | G36: =MIN(sum(G33,G34,G35,G28,G30),min(G37,$E61*'Get Started'!$D14-F62,F61*'Get Started'!$D14)) -> 0 | H36: =MIN(sum(H33,H34,H35,H28,H30),min(H37,$E61*'Get Started'!$D14-G62,G61*'Get Started'!$D14)) -> 0 | I36: =MIN(sum(I33,I34,I35,I28,I30),min(I37,$E61*'Get Started'!$D14-H62,H61*'Get Started'!$D14)) -> 0 | J36: =MIN(sum(J33,J34,J35,J28,J30),min(J37,$E61*'Get Started'!$D14-I62,I61*'Get Started'!$D14)) -> 359342.5 | K36: =MIN(sum(K33,K34,K35,K28,K30),min(K37,$E61*'Get Started'!$D14-J62,J61*'Get Started'!$D14)) -> 359342.5 | L36: =MIN(sum(L33,L34,L35,L28,L30),min(L37,$E61*'Get Started'!$D14-K62,K61*'Get Started'!$D14)) -> 4302265 | M36: =MIN(sum(M33,M34,M35,M28,M30),min(M37,$E61*'Get Started'!$D14-L62,L61*'Get Started'!$D14)) -> 4411314.2 | N36: =MIN(sum(N33,N34,N35,N28,N30),min(N37,$E61*'Get Started'!$D14-M62,M61*'Get Started'!$D14)) -> 3635200 | ... Z36: =MIN(sum(Z33,Z34,Z35,Z28,Z30),min(Z37,$E61*'Get Started'!$D14-Y62,Y61*'Get Started'!$D14)) -> 0
B37: Proceeds | D37: sum | E37: =if(D37="sum",sum(G37:Z37),if(D37="final",Z37,if(D37="initial",G37,if(D37="average",average(G37:Z37),0)))) -> 301965840 | G37: =G539 -> 0 | H37: =H539 -> 0 | I37: =I539 -> 0 | J37: =J539 -> 359342.5 | K37: =K539 -> 359342.5 | L37: =L539 -> 4302265 | M37: =M539 -> 10151836 | N37: =N539 -> 14032407 | ... Z37: =Z539 -> 0
B38: Preferred Return | D38: sum | E38: =if(D38="sum",sum(G38:Z38),if(D38="final",Z38,if(D38="initial",G38,if(D38="average",average(G38:Z38),0)))) -> 0 | G38: 0 | H38: 0 | I38: 0 | J38: 0 | K38: 0 | L38: 0 | M38: 0 | N38: 0 | O38: 0 | P38: 0 | Q38: 0 | R38: 0 | S38: 0 | T38: 0 | U38: 0 | V38: 0 | W38: 0 | X38: 0 | Y38: 0 | Z38: 0
B39: GP Catchup | D39: sum | E39: =if(D39="sum",sum(G39:Z39),if(D39="final",Z39,if(D39="initial",G39,if(D39="average",average(G39:Z39),0)))) -> 0 | G39: 0 | H39: 0 | I39: 0 | J39: 0 | K39: 0 | L39: 0 | M39: 0 | N39: 0 | O39: 0 | P39: 0 | Q39: 0 | R39: 0 | S39: 0 | T39: 0 | U39: 0 | V39: 0 | W39: 0 | X39: 0 | Y39: 0 | Z39: 0
B40: Carried Interest | D40: sum | E40: =if(D40="sum",sum(G40:Z40),if(D40="final",Z40,if(D40="initial",G40,if(D40="average",average(G40:Z40),0)))) -> 35689168 | G40: =G121 -> 0 | H40: =H121 -> 0 | I40: =I121 -> 0 | J40: =J121 -> 0 | K40: =K121 -> 0 | L40: =L121 -> 0 | M40: =M121 -> 0 | N40: =N121 -> 0 | ... Z40: =Z121 -> 0
B41: Distributions | D41: sum | E41: =if(D41="sum",sum(G41:Z41),if(D41="final",Z41,if(D41="initial",G41,if(D41="average",average(G41:Z41),0)))) -> 242756672 | G41: =G117+G120-G121 -> 0 | H41: =H117+H120-H121 -> 0 | I41: =I117+I120-I121 -> 0 | J41: =J117+J120-J121 -> 359342.5 | K41: =K117+K120-K121 -> 359342.5 | L41: =L117+L120-L121 -> 709606.67 | M41: =M117+M120-M121 -> 5740521.7 | N41: =N117+N120-N121 -> 10397207 | ... Z41: =Z117+Z120-Z121 -> 0
B42: Writeoffs | D42: sum | E42: =if(D42="sum",sum(G42:Z42),if(D42="final",Z42,if(D42="initial",G42,if(D42="average",average(G42:Z42),0)))) -> 0 | G42: 0 | H42: 0 | I42: 0 | J42: 0 | K42: 0 | L42: 0 | M42: 0 | N42: 0 | O42: 0 | P42: 0 | Q42: 0 | R42: 0 | S42: 0 | T42: 0 | U42: 0 | V42: 0 | W42: 0 | X42: 0 | Y42: 0 | Z42: 0
B43: Invested Capital Exited | C43: value of the original capital invested, that exits (proceeds > 0) | D43: sum | E43: =if(D43="sum",sum(G43:Z43),if(D43="final",Z43,if(D43="initial",G43,if(D43="average",average(G43:Z43),0)))) -> 0 | G43: 0 | H43: 0 | I43: 0 | J43: 0 | K43: 0 | L43: 0 | M43: 0 | N43: 0 | O43: 0 | P43: 0 | Q43: 0 | R43: 0 | S43: 0 | T43: 0 | U43: 0 | V43: 0 | W43: 0 | X43: 0 | Y43: 0 | Z43: 0
B44: Change in Invested Capital | C44: value of the original capital invested. goes up when investments are made, down when investments are written off, and down when investments exit. using the net return from the funds in the calcs to estimate. | D44: sum | E44: =if(D44="sum",sum(G44:Z44),if(D44="final",Z44,if(D44="initial",G44,if(D44="average",average(G44:Z44),0)))) -> -8.3819032e-09 | G44: =G32+abs(G42)*-1+G37/$C791*-1 -> 5641185 | H44: =H32+abs(H42)*-1+H37/$C791*-1 -> 14189927 | I44: =I32+abs(I42)*-1+I37/$C791*-1 -> 22738668 | J44: =J32+abs(J42)*-1+J37/$C791*-1 -> 23560068 | K44: =K32+abs(K42)*-1+K37/$C791*-1 -> 16575041 | L44: =L32+abs(L42)*-1+L37/$C791*-1 -> 6740787.3 | M44: =M32+abs(M42)*-1+M37/$C791*-1 -> -958491.46 | N44: =N32+abs(N42)*-1+N37/$C791*-1 -> -2999789.1 | ... Z44: =Z32+abs(Z42)*-1+Z37/$C791*-1 -> 0
B45: Change in Unrealized Gain (Loss) | C45: using the udnerlying unrealized gains from the funds, and adjusting it by subtracting out carry. an estimate, likely a little low. | D45: sum | E45: =if(D45="sum",sum(G45:Z45),if(D45="final",Z45,if(D45="initial",G45,if(D45="average",average(G45:Z45),0)))) -> 0 | G45: =-G263-G284-G305+G326+if(G67=$E67,sum(F45:$G45)*-1+G32,if(G4<>1,G44*'Get Started'!$D63,0)) -> -984500 | H45: =-H263-H284-H305+H326+if(H67=$E67,sum(G45:$G45)*-1+H32,if(H4<>1,H44*'Get Started'!$D63,0)) -> 737089.03 | I45: =-I263-I284-I305+I326+if(I67=$E67,sum($G45:H45)*-1+I32,if(I4<>1,I44*'Get Started'!$D63,0)) -> 1461153.6 | J45: =-J263-J284-J305+J326+if(J67=$E67,sum($G45:I45)*-1+J32,if(J4<>1,J44*'Get Started'!$D63,0)) -> 3772300.8 | K45: =-K263-K284-K305+K326+if(K67=$E67,sum($G45:J45)*-1+K32,if(K4<>1,K44*'Get Started'!$D63,0)) -> 4865488.7 | L45: =-L263-L284-L305+L326+if(L67=$E67,sum($G45:K45)*-1+L32,if(L4<>1,L44*'Get Started'!$D63,0)) -> 5392499.3 | M45: =-M263-M284-M305+M326+if(M67=$E67,sum($G45:L45)*-1+M32,if(M4<>1,M44*'Get Started'!$D63,0)) -> 2062044.3 | N45: =-N263-N284-N305+N326+if(N67=$E67,sum($G45:M45)*-1+N32,if(N4<>1,N44*'Get Started'!$D63,0)) -> -627258.56 | O45: =-O263-O284-O305+O326+if(O67=$E67,sum($G45:N45)*-1+O32,if(O4<>1,O44*'Get Started'!$D63,0)) -> -4139265 | P45: =-P263-P284-P305+P326+if(P67=$E67,sum($G45:O45)*-1+P32,if(P4<>1,P44*'Get Started'!$D63,0)) -> -5066033.3 | ... Z45: =-Z263-Z284-Z305+Z326+if(Z67=$E67,sum($G45:Y45)*-1+Z32,if(Z4<>1,Z44*'Get Started'!$D63,0)) -> 0
B46: Change in Residual Value | C46: change in invested capital + change in residual value | D46: sum | E46: =if(D46="sum",sum(G46:Z46),if(D46="final",Z46,if(D46="initial",G46,if(D46="average",average(G46:Z46),0)))) -> 1.3969839e-08 | G46: =G45+G44 -> 4656685 | H46: =H45+H44 -> 14927016 | I46: =I45+I44 -> 24199822 | J46: =J45+J44 -> 27332369 | K46: =K45+K44 -> 21440530 | L46: =L45+L44 -> 12133287 | M46: =M45+M44 -> 1103552.9 | N46: =N45+N44 -> -3627047.7 | ... Z46: =Z45+Z44 -> 0
...

Sheet Resources
B2: Resources and Templates
B3: Every tool and template has its own rationale and goals, almost all share the same goal, to help emerging managers and entrepreneurs understand how the economics for venture funds work.
B5: Name | C5: Key Attributes | D5: Link
B7: How to Model a Venture Capital Fund | C7: Post detailing how to model a venture capital fund, detailing all the components, methods, considerations, and links to template models to review | D7: https://openvc.app/blog/how-to-model-a-venture-capital-fund
B8: Portfolio Construction for Dummies, by Hadley Harris (Eniac Ventures) | C8: Free Excel and Google Sheets Model and explanations on how to model a venture fund | D8: https://eniacvc.medium.com/seed-fund-portfolio-construction-for-dummies-9ec5b4d152dc
B9: Tactyc Venture Manager | C9: Web app to build, manage and strategize venture portfolio models | D9: https://vc.tactyc.io/
B10: Venture Fund Model, by Craig Thomas | C10: Free model in Causal for modeling portfolio construction | D10: https://my.causal.app/models/7140
B11: Open Source Venture Model (V1), by Sam Gerstenzang | C11: Google Sheet, open source, helpful for understanding how follow-on dynamics work in modeling and planning for reserves. | D11: https://medium.com/@gerstenzang/open-source-venture-model-osvm-v1-55bebf3eda9
B12: Airstream Alpha | C12: Fund budget template from a fund CFO firm (submit email to access) | D12: https://airstreamalpha.com/financial-model/
B13: Venture Capital Starter Model, by Foresight | C13: Free Google Sheet (can download to Excel) for forecasting a venture fund, including basic fund performance metrics. Calculates at an overall portfolio level (does not model cashflows over time) | D13: https://foresight.is/vc
B14: Venture Capital Starter Model, by Foresight | C14: Simple, free model in Causal to show overall returns based on fund size, follow-on reserves, and fees. | D14: https://foresight.is/vc
B15: Venture Capital Model, Annual Forecast, by Foresight | C15: Free Google Sheet (can download to Excel) for forecasting a venture fund, including all fund performance metrics, showing annual cashflows over time. | D15: https://foresight.is/vc
B16: Venture Capital Model, Annual Forecast, by Foresight (Causal) | C16: Free Causal model for forecasting a venture fund, including all fund performance metrics, showing annual cashflows over time. | D16: https://foresight.is/vc
B17: Venture Fund Model, Quarterly Forecast, by Foresight | C17: $$ Excel and Google Sheets model to use in detailing cash flows and presenting to LPs in fundraising. Used by hundreds of emerging managers to raise funds. Includes financial statements for the fund, full forecast and statements for the management company, done on a quarterly timescale. | D17: https://foresight.is/venture-fund-model
... B26: Venture Capital Method (Valuation) | C26: Examples of how to use the Venture Capital Method for valuation, free Google Sheets | D26: https://vcmethod.com/

Sheet Model Comparison
B2: Foresight Template Comparison
B3: I offer a range of templates for venture funds and angels. Here's a breakdown of the models and how they compare.
B5: Template | C5: Link | D5: Software | E5: Price | F5: Overall Portfolio Forecast | G5: Annual Portfolio Forecast | H5: Quarterly Portfolio Forecast | I5: Fund Performance Metrics | J5: Portfolio Construction | K5: Financial Statements | L5: Track Actual Investments | M5: Budget v. Actuals, and rolling Forecast | N5: Multi-tiered Carried Interest | O5: Preferred Return (and GP Catchup) | P5: Rolling Funds | Q5: Individual Investment Evaluation | R5: Management Company Budgeting | T5: Fund-of-Funds
B7: Venture Capital Model, Overall Portfolio, by Foresight | C7: https://foresight.is/venture-fund-model-overall/ | D7: Google Sheets, download to Excel, Causal | E7: Free | F7: TRUE | G7: FALSE | H7: FALSE | I7: TRUE | J7: FALSE | K7: FALSE | L7: FALSE | M7: FALSE | N7: FALSE | O7: FALSE | P7: FALSE | Q7: FALSE | R7: FALSE | T7: FALSE
B8: Venture Capital Model, Annual Forecast, by Foresight | C8: https://foresight.is/venture-fund-model-annual/ | D8: Google Sheets, download to Excel, Causal | E8: Free | F8: TRUE | G8: TRUE | H8: FALSE | I8: TRUE | J8: FALSE | K8: FALSE | L8: FALSE | M8: FALSE | N8: FALSE | O8: FALSE | P8: FALSE | Q8: FALSE | R8: FALSE | T8: FALSE
B9: Venture Capital Model, Annual forecast using Portfolio Model, by Foresight | C9: https://foresight.is/venture-fund-model-portfolio/ | D9: Google Sheets, download to Excel | E9: Free | F9: TRUE | G9: TRUE | H9: FALSE | I9: TRUE | J9: TRUE | K9: FALSE | L9: FALSE | M9: FALSE | N9: FALSE | O9: FALSE | P9: FALSE | Q9: FALSE | R9: FALSE | T9: FALSE
B10: Venture Capital Model, Annual Forecast, Intermediate Portfolio Construction | C10: https://foresight.is/venture-fund-model-detailed/ | D10: Google Sheets, download to Excel | E10: $74 USD | F10: TRUE | G10: TRUE | H10: FALSE | I10: TRUE | J10: TRUE | K10: FALSE | L10: FALSE | M10: FALSE | N10: FALSE | O10: FALSE | P10: FALSE | Q10: FALSE | R10: TRUE | T10: FALSE
B11: Venture Fund Model, Quarterly, by Foresight | C11: https://foresight.is/venture-fund-model | D11: Google Sheets, download to Excel | E11: $349 USD | F11: TRUE | G11: TRUE | H11: TRUE | I11: TRUE | J11: TRUE | K11: TRUE | L11: FALSE | M11: FALSE | N11: TRUE | O11: TRUE | P11: FALSE | Q11: FALSE | R11: TRUE | T11: FALSE
B12: Venture Fund Model, Quarterly, with Tracking by Foresight | C12: https://foresight.is/venture-fund-model-tracking/ | D12: Google Sheets, download to Excel | E12: $479 USD | F12: TRUE | G12: TRUE | H12: TRUE | I12: TRUE | J12: TRUE | K12: TRUE | L12: TRUE | M12: TRUE | N12: TRUE | O12: TRUE | P12: FALSE | Q12: FALSE | R12: TRUE | T12: FALSE
B13: Angel and Venture Fund Portfolio Tracking, by Foresight | C13: https://foresight.is/venture-portfolio-model/ | D13: Google Sheets, download to Excel | E13: Free | F13: TRUE | G13: FALSE | H13: FALSE | I13: TRUE | J13: FALSE | K13: FALSE | L13: TRUE | M13: FALSE | N13: FALSE | O13: FALSE | P13: FALSE | Q13: FALSE | R13: FALSE | T13: FALSE
B14: Rolling Fund Template, by Foresight | C14: https://foresight.is/rolling-fund-template/ | D14: Google Sheets, download to Excel | E14: Free | F14: TRUE | G14: TRUE | H14: FALSE | I14: FALSE | J14: FALSE | K14: FALSE | L14: FALSE | M14: FALSE | N14: FALSE | O14: FALSE | P14: TRUE | Q14: FALSE | R14: FALSE | T14: TRUE
B15: Cap Table and Exit Waterfall Tool, by Foresight | C15: https://foresight.is/cap-table | D15: Excel, upload to Google Sheets | E15: Free | F15: FALSE | G15: FALSE | H15: FALSE | I15: FALSE | J15: FALSE | K15: FALSE | L15: FALSE | M15: FALSE | N15: FALSE | O15: FALSE | P15: FALSE | Q15: TRUE | R15: FALSE | T15: FALSE
B16: Venture Valuation Tool, by Foresight | C16: https://foresight.is/venture-valuation-tool/ | D16: Excel, upload to Google Sheets | E16: Free | F16: FALSE | G16: FALSE | H16: FALSE | I16: FALSE | J16: FALSE | K16: FALSE | L16: FALSE | M16: FALSE | N16: FALSE | O16: FALSE | P16: FALSE | Q16: TRUE | R16: FALSE | T16: FALSE
B17: Runway and Cash Budget Tool | C17: https://foresight.is/runway-cash-forecasting | D17: Excel, upload to Google Sheets | E17: Free | F17: FALSE | G17: FALSE | H17: FALSE | I17: FALSE | J17: FALSE | K17: FALSE | L17: FALSE | M17: FALSE | N17: FALSE | O17: FALSE | P17: FALSE | Q17: FALSE | R17: TRUE | T17: FALSE
B18: Custom Services | C18: Contact taylor@foresight.is | D18: Customization, edits to models, and custom services in Excel, Google Sheets, Causal | E18: Quote | F18: FALSE | G18: FALSE | H18: FALSE | I18: FALSE | J18: FALSE | K18: FALSE | L18: FALSE | M18: FALSE | N18: FALSE | O18: FALSE | P18: FALSE | Q18: FALSE | R18: FALSE | T18: FALSE

Sheet Glossary
B2: Glossary
B3: Key venture terms and metrics used in this model. For more, http://www.allenlatta.com/glossary-of-private-equity-terms.html is a good resource
B5: Term | C5: Definition
B7: Limited Partner | C7: Part-owner of a company whose liability for the firm's debts cannot exceed the amount that an individual invested in the company. In VC, the investors in the fund. https://www.investopedia.com/terms/l/limited-partner.asp
B8: General Partner | C8: A general partner is one of two or more investors who jointly own a business that is structured as a partnership, and who assumes a day-to-day role in managing it. In venture capital, often the management company or the owners and managers of the management company. https://www.investopedia.com/terms/g/generalpartner.asp
B9: Rolling Fund | C9: A newer fund structure created where each quarter is its own "fund" for reporting purposes, so that new limited partners can be accepted into the fund at every quarter. See https://www.angellist.com/blog/rolling-fund-budget for budgeting for rolling funds and more details on the structure
B10: Evergreen Fund | C10: Fund structure where proceeds are continually recycled, and typically limited partners can invest and divest regularly throughout the fund's life. (This model does not fit an evergreen structure.)
B11: Committed Capital | C11: Also known as total fund size. Total capital committed to the fund. May vary over a fund's lifetime if the fund is holding multiple closes.
B12: Called Capital | C12: Capital called from limited partners. Used to pay fund expenses and invest in companies. Once all capital is called, total called capital will equal committed capital.
B13: GP Commit | C13: % of total called capital that is required to be contributed by the general partners of the fund. May be funded through management fees if limited partners allow in fund operating agreements.
B14: Organizational Expenses | C14: Expenses occured in creating a fund entity, which can often be charged to the fund (in addition to management fees)
B15: Operational Expenses | C15: Expenses occured in operating a fund, which can often be charged to the fund (in addition to management fees). Can include fund administration, fund tax reporting, legal costs in working on investment opportunities, and more.
B16: Management Fees | C16: Fees charged by the management company operating the fund to the fund. They are revenues to the management company, and used to pay expenses such as salaries, insurance, marketing, operating costs, and more.
B17: Management Fees Recycled | C17: Many funds will recycle their management fees, meaning they reinvest early proceeds back into new investments. The rationale is that it allows the management company to invest more capital from the same fund size and improve returns. Recycling all fees into new investments can be difficult to do, based on the timeframe for new investments and the timing of when proceeds happen. Budgeting a schedule of invested capital for management fee recycling can be difficult. Many funds will target higher recycling earlier (>100%) knowing they will not be able to recycle all management fees into new investments later in period, or to be more aggressive in redeploying capital/.
... B42: Pro rata | C42: Potential investment amount in a new investment round offered to an pre-existing investor, often an amount that allows them to maintain their ownership position. Managers should have a strategy about how to handle pro rata investment opportunities, as well as a point of view on pro rata investment rights and their desire and ability to secure pro rata rights in investments.

Sheet Changelog
B2: Changelog
B3: Here's what has changed.
B5: Version | C5: Date | D5: Definition
B7: v4.1.7 | C7: 45268 | D7: Edited Get Started and Forecast to apply the edit from v4.1.6 to the underlying funds. Edited Get Started and Forecast to build new way to forecast operational expenses. Previously model assumed operational fees were not charged to the fund in the extension period, after the initial fund operations period, if the fund was not yet exited out of all investments. Now by default it does estimate that period and use that for budgeting for operational expenses.
B8: v4.1.6 | C8: 45266 | D8: Edited Get Started to create new calculation of invested capital if using assets under management as the base for any period in calculating management fees. Previously the model relied on circular references to calculate fees and create a schedule of called capital, but that method sometimes failed to work reliably because of how iterative calculations work to resolve circulars (context on circulars, https://foresight.is/circulars ). Now, if the model observes any option other than committed capital used, it will alter the estimate of invested capital so that it does not create a circular. The trade-off is that the model will not result in called capital = committed capital if you are not recycling 100% of management fees, due to the difficulty in estimating the budget for management fees.
B9: v4.1.5 | C9: 45238 | D9: Edited Forecast sheet, calculation of RVPI, to estimate the value of carried interest. Previously RVPI was reported on a gross basis, while DPI was reported on a net basis, creating a TVPI that reflected a net DPI and gross RVPI, slightly overestimating TVPI because it did not estimate carried interest to net from the residual value. A small edit that removed the slight change in TVPI on the last period where RVPI goes to zero.
B10: v4.1.4 | C10: 45237 | D10: Edited Forecast sheet to change calc for Change in Unrealized Value in the per-fund buildup. The timing was off in the rows leading to it recognizing changes in unrealized value for the year 1 cohort of funds after the funds were completely exited. No change to total change, but does change the timing of the unrealized gains across all cohorts.
B11: v4.1.3 | C11: 44707 | D11: Edited organizational and operational expenses for component funds to correctly account for the number of funds invested in. (Thanks Forrest.) Now, the model calculates the number of new fund commitments per period, and uses that in the calculation of the expenses.
B12: v4.1.2 | C12: 44669 | D12: Edited Forecast sheet to add one more performance metric to the model Edited logic behind the change in unrealized gains calculation on Forecast, based on conversation with a user. I think the numbers calculated previously were directionally correct, although the logic behind the formula didn't make sense. So, I revisted the logic and created a new formula that uses a different logic to calculate this estimate, by accounting for all capital to date. The end result isn't that different, but I do think the logic makes more sense.
B13: v4.1.1 | C13: 44624 | D13: Edited the Interim IRR calculation for the first period in the model, so that it would capture the change in value during the first year and record a negative IRR. No change to any other calculations, no change in cash flows, just to change the reporting of the IRR in the first year
B14: v4.1.0 | C14: 44470 | D14: New Fund of Funds Model, based on the Venture Capital Model, Annual Forecast, to model out a fund investing in funds.
