Workbook
Name misc: #REF!
Name total_shareholders_equity: #REF!
Name uniforms: #REF!
Name insurance: #REF!
Name start_up_cost_amortization: #REF!
Name Salary: #REF!
Name aircraft_subscriptions: #REF!
Name offices: #REF!
Name net_working_capital: #REF!
Name accrued_IT_expenses: #REF!
Name net_working_capital_t_minus_1: #REF!
Name crew_salary: #REF!
Name management_salary: #REF!
Name accrued_manag_salary: #REF!
Name EBIT: #REF!
Name debt: #REF!
Name maintenance: #REF!
Name net_income: #REF!
Name accrued_employee_and_crew_salary: #REF!
Name required_capital: #REF!
Name Postholder_salary: #REF!
Name operating_cash_flow: #REF!
Name subscriptions: #REF!
Name current_liabilities: #REF!
Name EBITDA: #REF!
Name Cost_of_Goods_Sold: #REF!
Name other_operating_cost: #REF!
Name revenues: #REF!
Name uniform_writeoff_expense: #REF!
Name initial_training: #REF!
Name interest_on_debts: #REF!
Name total_dep_and_amort: #REF!
Name total_startup_asset_funds: #REF!
Name furn_soft_equip_depreciation: #REF!
Name total_revised_startup_costs: #REF!
Name aircraft_lease: #REF!
Name furn_soft_equip: #REF!
Name employee_salary: #REF!
Name accrued_postholder_salary: #REF!
Name travel: #REF!
Name tax: #REF!
Name change_in_NWC: #REF!
Name aircraft_lease_deposit: #REF!
Name contingency: #REF!
Name cash_and_cash_equiv: #REF!
Name interest_on_debt: #REF!
Name recurrent_training: #REF!
Name total_operating_expenses: #REF!
Name current_assets: #REF!
Name IT: #REF!

Sheet README
B2: Runway Budgeting Tool, by Foresight
B3: aka Pre-seed and Seed Budget Tool, Runway and Cash Budget Tool, Runway and Cash Forecasting Tool
B5: Copyright & Contact | C5: This was created by Taylor Davidson (@tdavidson) of Foresight. © 2023, Unstructured Ventures, LLC. Questions, contact taylor@foresight.is or @tdavidson
B6: License | C6: tl:dr; You can modify, edit, use, and share within your company (and with third-parties as needed to operate your business). You may not redistribute, resell, give away to others. Full license.
B7: Goal | C7: Goal of this model is to create an easy way for anyone to model a startup business. The model uses external market data where applicable and estimates when necessary. You should adjust all metrics and inputs to fit your business.
B8: Copy to Google Sheets or Download to Excel | C8: File > Make a Copy to copy it to your own Google Drive, or File > Download to download this to use in Excel or other spreadsheet programs. See License for warranties and liabilities.
B9: Support | C9: Questions, happy to assist, contact anytime. More details on how I provide support: https://foresight.is/learn/support
B10: Missing a feature you need? | C10: Check out Alternatives to Foresight for more modeling tools, and check out Foresight's Standard Financial Model for a more comprehensive model with extensive prebuilt options for different revenue models, MRR and ARR, historical financials, budget variances, and more.
B11: Quickstart | C11: 1) Any number in blue with grey shaded background is an input (i.e. an assumption or data point that can be changed), anything in black is the result of a formula. Change blue at will, change anything in black with caution. 2) All cells and formulas are unlocked - as in all Foresight models - so that you can make edits as needed and completely understand what is going on. 3) All assumptions are illustrative ONLY, do not assume they are market data or standard. 4) As with all templates, feel free to create your own model from scratch, using this as a guide. 5) The model is constructed to fit a wide variety of businesses, and therefore, some sections may or may not be relevant to yours. I have grouped together sections on all sheets so that you can review different sections and see all the possibilities, but also easily hide the sections not relevant for you. Simply click on the "+" button on the left-hand side to unhide a section, and click on the "-" button to hide it.
B13: Outline
B15: README | C15: Contact into, overview on model. Safe to delete or hide.
B16: Formatting and Colors Overview | C16: Details on what the colors and formatting in the model mean. https://foresight.is/learn/colors-and-formatting
B17: License | C17: Terms of use of the model. Safe to delete or hide. https://foresight.is/license
B18: Get Started | C18: Core assumptions for the fund. Do not delete, safe to hide. Overall model summary: https://www.loom.com/share/938d2d52ead548beb0d3608b73d44408
B19: Model Structure | C19: Overall model summary: https://www.loom.com/share/938d2d52ead548beb0d3608b73d44408
B20: Balance Sheet | C20: https://www.loom.com/share/39ead41b345547cdac1461ee493e151f
B21: Seasonality | C21: https://www.loom.com/share/86297c4ba4584ec791e08ab49b280240
B22: Model Checks | C22: https://www.loom.com/share/e0ceaab1ec284905af5afeff41cdbe7a
B23: Forecast
B24: Revenues, Expenses, and Cash Flows | C24: https://www.loom.com/share/86f2d7320cf64d2fab27488f7ee5eae1
B25: Categories | C25: https://www.loom.com/share/86f2d7320cf64d2fab27488f7ee5eae1
B26: Detailed Calculations | C26: https://www.loom.com/share/39ead41b345547cdac1461ee493e151f
B27: Key Reports | C27: https://www.loom.com/share/0ff526ed8ae54efcaa230e7b28b4752a
B28: Sources & Uses | C28: https://www.loom.com/share/2a2a1ffd603646b4ba781fa193c9d6b4
B29: Statements | C29: https://www.loom.com/share/bfe33b507a424b31aab02b9f579f1b1b
B30: Model Comparison | C30: Informational sheet with links to other models available to use. Safe to delete or hide.
B31: Glossary | C31: Informational sheet on common financial terms used in the model. Safe to delete or hide.
B32: Changelog | C32: List of what has been changed in model versions. Safe to delete or hide, although I'd advise to hide (instead of delete) so can always check to see what model version you are using to compare to future changes.

Sheet License
B1: License Agreement
B2: Available on website
B4: This License Agreement (“the Agreement”) between you, the licensee, and Unstructured Ventures, LLC (the “Company”) a limited liability corporation headquartered and registered in the Commonwealth of Pennsylvania and organized under the laws of the state of Delaware. The Company owns the financial model (the “Product”) and any edits, additions, or customizations (the "Service") delivered under this Agreement. This Agreement grants you a non-exclusive, non-transferable right to use and incorporate the Product and Service in personal and corporate projects for the organization that purchased the Product and/or Service.
B6: You agree as follows:
B8: 1. Scope of use
B9: * Use and incorporate the Product and/or Service in personal and commercial projects for your company including financial models, business plans, pitch decks, etc.
B10: * You may modify the Product and/or Service to better serve your project.
B11: * You are granted unlimited usage of the Product and/or Service purchased in your organization.
B12: * If an organization is the licensee, all employees of the organization may use the same license.
B14: 2. Limitations and non-use
B15: * You may not redistribute, sublicense or resell the Product and/or Service.
B16: * You may not distribute, license or sell derivative, recompiled, reverse engineered, or modified versions of the Product and/or Service.
... B29: This Agreement is governed by the laws of the Commonwealth of Pennsylvania and the applicable laws of the United States of America. Legal proceedings related to this Agreement may only be brought in the courts of Pennsylvania. You agree to service of process at the e-mail address on your original order. Notices may be sent to Unstructured Ventures, LLC by email to hello@unstructuredventures.com or by post to Unstructured Ventures, LLC, 6360 Broad St, #5226, Pittsburgh, PA, 15206, USA.

Sheet Disclaimer
B2: Disclaimer
B4: ="This Investor Presentation is provided for informational purposes only and does not constitute an offer to buy or a solicitation of an offer to invest, or to procure an investment in "&'Get Started'!D9&" (the “Company”)." -> This Investor Presentation is provided for informational purposes only and does not constitute an offer to buy or a solicitation of an offer to invest, or to procure an investment in Company (the “Company”).
B5: Investments in the Company, if offered, will only be offered to a selected number of accredited investors, and only on the basis of a private offering memorandum for the Company. There are significant risks that are not presented and disclosed in this Investor Presentation. These risks could have a significant negative impact on the performance of the Company.
B6: This Investor Presentation contains forward-looking statements regarding our business plans and prospects and financial conditions, all statements, other than statements of historical fact, in this Investor Presentation, and the attached exhibits, including, among other things, statements regarding our competitive strengths, business strategy, financial projections and plans and objectives of management are forward-looking statements. Although we believe that the expectations reflected in such forward-looking statements are reasonable, there can be no assurance that such expectations will prove to be correct. Forward-looking statements are inherently subject to risks and uncertainties, many of which cannot be predicted with accuracy and some of which might not even be anticipated. Future events and actual results, financial or otherwise, could differ materially from those set forth in, or contemplated by, the forward-looking statements in this Investor Presentation, and, as such, the forward-looking statements contained herein should not be relied upon when making your investment decision. We undertake no obligation to update or revise any forward-looking statements.
B7: The financial projections in this Investor Presentation present, to the best of management’s knowledge and belief, the Company’s expected financial position, results of operations, and cash flows for the forecast period. Accordingly, the financial projections reflect its judgment, as of the date of these financial projections, of the expected conditions and its expected course of action following the sale of securities by the Company. The assumptions disclosed herein are those that management believes are significant to the financial projections. There will usually be differences between the projected and actual results, because events and circumstances frequently do not occur as expected, and those differences may be material. Since the projections are based upon assumptions about circumstances and events that have not yet taken place regarding costs, income, expenses and federal tax matters, which are subject to variations and economic events as future operations actually occur, they do not necessarily reflect the results that will be achieved and should not be relied upon. In all cases, the targeted returns are not predictions or projections that the results in the pro forma financials will be achieved nor of the performance of any investment, and are expressly subject to all assumptions embedded in the pro forma financials and the risk factors disclosed herein. This investment has a high degree of risk, and there can be no assurances that all or any of the assumptions will be true or that an investment’s actual performance will bear any relation to these hypothetical illustrations.
B8: This information contained in this Investor Presentation includes proprietary information, is strictly confidential, and is not to be used or distributed to others without the express written consent of the Company.
B9: This document has been prepared solely for information purposes and is being furnished solely for use by prospective purchasers in considering their interest in obtaining additional information and making their own evaluation of the Company and does not contain all of the information that a prospective purchaser may desire. This information reflects various assumptions by the Company concerning anticipated results, which assumptions may or may not prove to be correct, and the Company has no obligation to update such information. The only information that will have any legal effect will be that specifically contained in definitive documentation. This Investor Presentation has been submitted confidentially to a limited number of investors so that they can consider their interest in obtaining additional information and making their own evaluation of the Company. No offers to purchase the securities of the Company will be accepted prior to (1) the receipt by recipient of a complete private offering memorandum and (2) determination by the Company that the recipient is an appropriate purchaser in light of standards contained in U.S. Securities laws after a full evaluation of recipient by the Company. The Company has not authorized its use for any other purpose. This Investor Presentation may not be copied or reproduced in whole or in part. By accepting a copy of this Investor Presentation, the recipient agrees that neither it nor any of its representatives, agents or employees shall use it for any other purpose or divulge to any party any confidential information about the Company.

Sheet Get Started
B2: Get Started
B3: Key model assumptions and summaries. Detailed inputs on Forecast sheet.
B6: Model Structure
B7: Capital, Management Fees, base Fund-level assumptions
B9: Company Name | D9: Company | F9: This is used in the Legal Disclaimer sheet, which is purely optional, but something many people choose to include in their projections when they provide them to potential investors
B10: Base Timescale | D10: monthly | F10: You can use the model to forecast monthly, quarterly, or annually, and then the model will use that as it's base timescale.
B11: ="# of "&if(D10="monthly","months",if(D10="quarterly","quarters","years"))&" in model" -> # of months in model | D11: 36 | F11: This sets the # of periods in the model. (1 period = 1 month, or 1 quarter, or 1 year, as set in assumption above.) Max 36 periods in prebuilt model, can be extended if needed.
B12: Date of first period in model | D12: 44927 | F12: Define the end date that is the last date of the period used in the model
B13: Fiscal year end | D13: =DATE(YEAR(D12),12,31) -> 45291 | F13: Defines the end of the fiscal year used in the model
B14: Do you want to use relative or absolute dates? | D14: relative | F14: The dates above set the start date and fiscal year end used in the timescales, but you can also set whether you want the primary timescale used for reports and charts to be absolute (for example, Jan 2021 or 2021) or relative (month 1 or year 1)
B17: Balance Sheet
B18: Optional assumptions for automatic revenue recognition and cash collection calculations, depreciation, corporate taxes, and VAT
B20: Cash on hand, beginning of model | C20: $ | D20: 0 | F20: sets the currency symbol used in the model, and the opening cash balance for the financial statements
B22: Optional: Revenue Recognition
B23: Use automatic revenue recognition? | D23: yes | F23: by default this is turned on (select "yes"), you can turn off (select "no") to enter in your revenue recognition and billings schedules manually
B24: ="Optional: Recognize pre-existing deferred revenues over "&MAX(1,D24)&" month"&IF(D24>1,"s","") -> Optional: Recognize pre-existing deferred revenues over 1 month | C24: # | D24: 1 | F24: If select "yes" in the cell above, if applicable, and only if you feed billings into model and not revenues. do not use if you are calculating revenue recognition with the default revenue structure in the Standard Model or other themes (i.e. leave as "0"). If you have a business where you are taking upfront payments as revenues, they need to be recognized over the length of the period over which you are obligated to provide the services for which the payments cover. This assumption is used to calculated deferred revenues
B26: Optional: Accounts Receivable
B27: Use automatic cash collection calculations? | D27: yes | F27: by default this is turned on (select "yes"), you can turn off (select "no") to enter in your cash collection schedule manually
B28: Optional: Days Accounts Receivable | C28: # | D28: 0 | F28: days. If select "yes" in the assumption above, the model allows you to assume the Days Accounts Receivable so that you can collect the cash later than recognizing the revenenues, if applicable for your business. Any period assumed <= 30 days means it's collected in same month as revenues.
B30: Optional: Accrued Liabilities and Prepaid Expenses | F30: by default model uses a simpler method for estimating balances of these accounts. Can be edited on Statements sheet, or can create different methods more similar to Accounts Receivable method if desired
B31: Balance of Prepaid Expenses, as % of SG&A | C31: % | D31: 0
B32: Balance of Accounts Payable, as % of SG&A | C32: % | D32: 0
B33: Balance of Accrued Liabilities, as % of SG&A | C33: % | D33: 0
B35: Optional: Depreciation
B36: ="Depreciation, straight line for "&D36&" "&if(D10="monthly","months",if(D10="quarterly","quarters","years")) -> Depreciation, straight line for 36 months | C36: # | D36: 36 | F36: months. The model assumes straight-line depreciation for all capital expenditures, all depreciated by the # of months in this input. If you need different depreciation schedules for different assets, it's not difficult to build that in, create that and link into the expense section.
B38: Optional: Corporate Income Taxes and VAT
B39: Corporate Income Taxes | C39: % | D39: 0.21 | F39: used for calculating corporate taxes, only if any net loss carry-forwards are extinguished
B40: ="Schedule for paying "&B39 -> Schedule for paying Corporate Income Taxes | C40: - | D40: quarterly | F40: By default, this has options for paying monthly, quarterly, or annually. Select your option in the dropdown.
B41: VAT (Value-Added Taxes) | C41: % | D41: 0 | F41: assumption for VAT collected, as % of revenues. Assumption for VAT deductions is directly on Forecast sheet
B42: ="Schedule for paying "&B41 -> Schedule for paying VAT (Value-Added Taxes) | C42: - | D42: quarterly | F42: By default, this has options for paying monthly, quarterly, or annually. Select your option in the dropdown.
B44: Optional: Inventory | F44: this section forecasts inventory purchases based on a schedule of sales. Inventory purchases flow through cash, and are expensed through cost of sales to match the costs to revenues. Default assumption is that all purchases are paid in the month forecasted in the model, to create deferrals or inventory payable, create a custom schedule and feed into hooks.
B45: # Months lead time from purchase to in inventory | C45: # | D45: 0 | F45: if applicable, enter in positive numbers only. this takes the forecasted COGS and applies a lead time from when purchases are made to when they are added to inventory. This takes the forecasted purchases and creates a lag to when they are added to inventory.Work in progress and finished goods are considered a subset of the inventory and are not split out specifically.
B46: Safety Stock - Ending Inventory as % of COGS | C46: % | D46: 0 | F46: if applicable, a % of current month's COGS can be kept in inventory, as "safety stock". This can be used in addition to the lead time assumptions if desired.
B47: Minimum Order Quantity (MOQ) | C47: $ | D47: 0 | F47: if applicable, the dollar value of the minimum order quantity. For example, if the inventory calcs say you need to purchase $500 of inventory, and your minimum order from your supplier is $1500, the model will buy $1500 of inventory and then run it down until next time it needs inventory.
B48: Optional: % of Inventory Purchase paid at time of purchase | C48: % | D48: 1 | F48: optional. This lets you determine when the inventory purchases are paid, and set how much is paid at time of purchase.
B49: Optional: Remaining Inventory Purchases, paid 0 days post-purchase | C49: # | D49: 0 | F49: days. The model allows you to assume the Inventory Accounts Payable so that you can pay for inventory after purchase. The model calculates the payables based on the other two options above first, then assumes the remaining flows through this timing.
B52: Seasonality
B53: Per Calendar Month, % change, from baseline | F53: Optional section. This section allows you to set + and - % impacts on a recurring monthly basis that is separate from the growth rates above. The two layer on each other, creating cyclical, seasonal effect on forecasted metrics.
B55: =TEXT(EDATE('Get Started'!D$12,-12),"mmmm") -> January | C55: % | D55: 0 | F55: change in baseline, per calendar month
B56: =TEXT(EDATE('Get Started'!D$12,-11),"mmmm") -> February | C56: % | D56: 0 | F56: The inputs here start with the first month in the model, and are reused for this month in every year throughout the forecast period in the model
...

Sheet Summary
B2: Annual Summary
B4: Year | C4: =if('Get Started'!D14="relative",1,year('Get Started'!D12)) -> 1 | D4: =if(C4<max(Forecast!$T7:$BA7),C4+1,"") -> 2 | E4: =if(D4<max(Forecast!$T7:$BA7),D4+1,"") -> 3
C5: =if('Get Started'!D14="absolute",IF(ROUNDUP(DAYS360('Get Started'!D12,'Get Started'!D13)/30,0)<11," ("&ROUNDUP(DAYS360('Get Started'!D12,'Get Started'!D13)/30,0)&" months)",""),"")
B6: Revenues | C6: =if(C4="","",sumifs(Statements!$S12:$BB12,Statements!$S$7:$BB$7,C$4)) -> 12300 | D6: =if(D4="","",sumifs(Statements!$S12:$BB12,Statements!$S$7:$BB$7,D$4)) -> 13560.75 | E6: =if(E4="","",sumifs(Statements!$S12:$BB12,Statements!$S$7:$BB$7,E$4)) -> 14950.727
B7: Y/Y % Growth | C7: =if(C4="","",IFERROR(C6/B6-1,0)) -> 0 | D7: =if(D4="","",IFERROR(D6/C6-1,0)) -> 0.1025 | E7: =if(E4="","",IFERROR(E6/D6-1,0)) -> 0.1025
B8: Growth Multiple | C8: =if(C4="","",IFERROR(C6/B6,"na")) -> na | D8: =if(D4="","",IFERROR(D6/C6,"na")) -> 1.1025 | E8: =if(E4="","",IFERROR(E6/D6,"na")) -> 1.1025
B10: COGS | C10: =if(C4="","",sumifs(Statements!$S15:$BB15,Statements!$S$7:$BB$7,C$4)) -> 0 | D10: =if(D4="","",sumifs(Statements!$S15:$BB15,Statements!$S$7:$BB$7,D$4)) -> 0 | E10: =if(E4="","",sumifs(Statements!$S15:$BB15,Statements!$S$7:$BB$7,E$4)) -> 0
B11: Gross Margin | C11: =if(C4="","",C6-C10) -> 12300 | D11: =if(D4="","",D6-D10) -> 13560.75 | E11: =if(E4="","",E6-E10) -> 14950.727
B12: % of Revenue | C12: =if(C4="","",IFERROR(C11/C$6,0)) -> 1 | D12: =if(D4="","",IFERROR(D11/D$6,0)) -> 1 | E12: =if(E4="","",IFERROR(E11/E$6,0)) -> 1
B13: Y/Y % Growth | C13: =if(C4="","",IFERROR(C11/B11-1,0)) -> 0 | D13: =if(D4="","",IFERROR(D11/C11-1,0)) -> 0.1025 | E13: =if(E4="","",IFERROR(E11/D11-1,0)) -> 0.1025
B15: SG&A | C15: =if(C4="","",sumifs(Statements!$S20:$BB20,Statements!$S$7:$BB$7,C$4)) -> 0 | D15: =if(D4="","",sumifs(Statements!$S20:$BB20,Statements!$S$7:$BB$7,D$4)) -> 0 | E15: =if(E4="","",sumifs(Statements!$S20:$BB20,Statements!$S$7:$BB$7,E$4)) -> 0
B16: % of Revenue | C16: =if(C8="","",IFERROR(C15/C$6,0)) -> 0 | D16: =if(D8="","",IFERROR(D15/D$6,0)) -> 0 | E16: =if(E8="","",IFERROR(E15/E$6,0)) -> 0
B18: EBITDA | C18: =if(C4="","",C11-C15) -> 12300 | D18: =if(D4="","",D11-D15) -> 13560.75 | E18: =if(E4="","",E11-E15) -> 14950.727
B19: % of Revenue | C19: =if(C11="","",IFERROR(C18/C$6,0)) -> 1 | D19: =if(D11="","",IFERROR(D18/D$6,0)) -> 1 | E19: =if(E11="","",IFERROR(E18/E$6,0)) -> 1
B21: Depreciation and Amortization | C21: =if(C4="","",sumifs(Statements!$S26:$BB26,Statements!$S$7:$BB$7,C$4)+sumifs(Statements!$S27:$BB27,Statements!$S$7:$BB$7,C$4)) -> 0 | D21: =if(D4="","",sumifs(Statements!$S26:$BB26,Statements!$S$7:$BB$7,D$4)+sumifs(Statements!$S27:$BB27,Statements!$S$7:$BB$7,D$4)) -> 0 | E21: =if(E4="","",sumifs(Statements!$S26:$BB26,Statements!$S$7:$BB$7,E$4)+sumifs(Statements!$S27:$BB27,Statements!$S$7:$BB$7,E$4)) -> 0
B22: Interest Expense | C22: =if(C4="","",sumifs(Statements!$S28:$BB28,Statements!$S$7:$BB$7,C$4)) -> 0 | D22: =if(D4="","",sumifs(Statements!$S28:$BB28,Statements!$S$7:$BB$7,D$4)) -> 0 | E22: =if(E4="","",sumifs(Statements!$S28:$BB28,Statements!$S$7:$BB$7,E$4)) -> 0
B23: Other (Income) Expense | C23: =if(C4="","",sumifs(Statements!$S29:$BB29,Statements!$S$7:$BB$7,C$4)*-1+sumifs(Statements!$S30:$BB30,Statements!$S$7:$BB$7,C$4)) -> 0 | D23: =if(D4="","",sumifs(Statements!$S29:$BB29,Statements!$S$7:$BB$7,D$4)*-1+sumifs(Statements!$S30:$BB30,Statements!$S$7:$BB$7,D$4)) -> 0 | E23: =if(E4="","",sumifs(Statements!$S29:$BB29,Statements!$S$7:$BB$7,E$4)*-1+sumifs(Statements!$S30:$BB30,Statements!$S$7:$BB$7,E$4)) -> 0
B24: Taxes | C24: =if(C4="","",sumifs(Statements!$S34:$BB34,Statements!$S$7:$BB$7,C$4)) -> 2583 | D24: =if(D4="","",sumifs(Statements!$S34:$BB34,Statements!$S$7:$BB$7,D$4)) -> 2847.7575 | E24: =if(E4="","",sumifs(Statements!$S34:$BB34,Statements!$S$7:$BB$7,E$4)) -> 3139.6526
B26: Net Income | C26: =if(C4="","",C18-C21-C22-C23-C24) -> 9717 | D26: =if(D4="","",D18-D21-D22-D23-D24) -> 10712.993 | E26: =if(E4="","",E18-E21-E22-E23-E24) -> 11811.074
B27: % of Revenue | C27: =if(C19="","",IFERROR(C26/C$6,0)) -> 0.79 | D27: =if(D19="","",IFERROR(D26/D$6,0)) -> 0.79 | E27: =if(E19="","",IFERROR(E26/E$6,0)) -> 0.79
B28: Y/Y % Growth | C28: =if(C4="","",IFERROR(ABS(C26-B26)/ABS(B26),0)) -> 0 | D28: =if(D4="","",IFERROR(ABS(D26-C26)/ABS(C26),0)) -> 0.1025 | E28: =if(E4="","",IFERROR(ABS(E26-D26)/ABS(D26),0)) -> 0.1025
B31: Statement of Cash Flows
B33: Year | C33: =C$4 -> 1 | D33: =D$4 -> 2 | E33: =E$4 -> 3
C34: =C5
B35: Cash, Beginning of Period | C35: =Statements!R44 -> 0 | D35: =if(D4="","",C41) -> 510158 | E35: =if(E4="","",D41) -> 520916.2
B37: Cash Flow from Operations | C37: =if(C4="","",sumifs(Statements!$S98:$BB98,Statements!$S$7:$BB$7,C$4)) -> 10158 | D37: =if(D4="","",sumifs(Statements!$S98:$BB98,Statements!$S$7:$BB$7,D$4)) -> 10758.195 | E37: =if(E4="","",sumifs(Statements!$S98:$BB98,Statements!$S$7:$BB$7,E$4)) -> 11860.91
B38: Cash Flow from Investing | C38: =if(C4="","",sumifs(Statements!$S103:$BB103,Statements!$S$7:$BB$7,C$4)) -> 0 | D38: =if(D4="","",sumifs(Statements!$S103:$BB103,Statements!$S$7:$BB$7,D$4)) -> 0 | E38: =if(E4="","",sumifs(Statements!$S103:$BB103,Statements!$S$7:$BB$7,E$4)) -> 0
B39: Cash Flow from Financing | C39: =if(C4="","",sumifs(Statements!$S113:$BB113,Statements!$S$7:$BB$7,C$4)) -> 500000 | D39: =if(D4="","",sumifs(Statements!$S113:$BB113,Statements!$S$7:$BB$7,D$4)) -> 0 | E39: =if(E4="","",sumifs(Statements!$S113:$BB113,Statements!$S$7:$BB$7,E$4)) -> 0
B41: Cash, End of Period | C41: =if(C4="","",sum(C35,C37:C39)) -> 510158 | D41: =if(D4="","",sum(D35,D37:D39)) -> 520916.2 | E41: =if(E4="","",sum(E35,E37:E39)) -> 532777.1
B44: Balance Sheet
B46: Year | C46: =C$4 -> 1 | D46: =D$4 -> 2 | E46: =E$4 -> 3
B48: Assets | C48: {=if(C4="","",index(Statements!$S57:$BB57,,match(C$4,Statements!$S$7:$BB$7,0)))} -> 500790 | D48: {=if(D4="","",index(Statements!$S57:$BB57,,match(D$4,Statements!$S$7:$BB$7,0)))} -> 510587.97 | E48: {=if(E4="","",index(Statements!$S57:$BB57,,match(E$4,Statements!$S$7:$BB$7,0)))} -> 521390.24
B49: Liabilities | C49: {=if(C4="","",index(Statements!$S68:$BB68,,match(C$4,Statements!$S$7:$BB$7,0)))} -> 0 | D49: {=if(D4="","",index(Statements!$S68:$BB68,,match(D$4,Statements!$S$7:$BB$7,0)))} -> 0 | E49: {=if(E4="","",index(Statements!$S68:$BB68,,match(E$4,Statements!$S$7:$BB$7,0)))} -> 0
B50: Shareholder's Equity | C50: {=if(C4="","",index(Statements!$S83:$BB83,,match(C$4,Statements!$S$7:$BB$7,0)))} -> 500790 | D50: {=if(D4="","",index(Statements!$S83:$BB83,,match(D$4,Statements!$S$7:$BB$7,0)))} -> 510587.97 | E50: {=if(E4="","",index(Statements!$S83:$BB83,,match(E$4,Statements!$S$7:$BB$7,0)))} -> 521390.24

Sheet Key Reports

Sheet Forecast
B2: Forecast
B4: =if('Get Started'!$D10="monthly","Month ",if('Get Started'!$D10="quarterly","Quarter ","Year ")) -> Month | S4: =if('Get Started'!$D14="relative",$B4&S5,text(S6,"mmm yyy")) -> Month 0 | T4: =if('Get Started'!$D14="relative",$B4&T5,text(T6,"mmm yyy")) -> Month 1 | U4: =if('Get Started'!$D14="relative",$B4&U5,text(U6,"mmm yyy")) -> Month 2 | V4: =if('Get Started'!$D14="relative",$B4&V5,text(V6,"mmm yyy")) -> Month 3 | W4: =if('Get Started'!$D14="relative",$B4&W5,text(W6,"mmm yyy")) -> Month 4 | X4: =if('Get Started'!$D14="relative",$B4&X5,text(X6,"mmm yyy")) -> Month 5 | Y4: =if('Get Started'!$D14="relative",$B4&Y5,text(Y6,"mmm yyy")) -> Month 6 | Z4: =if('Get Started'!$D14="relative",$B4&Z5,text(Z6,"mmm yyy")) -> Month 7 | ... BC4: =if('Get Started'!$D14="relative",$B4&BC5,text(BC6,"mmm yyy")) -> Month 36
B5: Period in model | C5: # | D5: period in the model, base timescale | H5: final | I5: =if(H5="sum",sum(T5:BC5),if(H5="final",index(T5:BC5,match(99^99,T5:BC5,1)),if(H5="initial",T5,if(H5="average",average(T5:BC5),0)))) -> 36 | S5: 0 | T5: =1 -> 1 | U5: =if(T5<'Get Started'!$D11,T5+1,"") -> 2 | V5: =if(U5<'Get Started'!$D11,U5+1,"") -> 3 | W5: =if(V5<'Get Started'!$D11,V5+1,"") -> 4 | X5: =if(W5<'Get Started'!$D11,W5+1,"") -> 5 | Y5: =if(X5<'Get Started'!$D11,X5+1,"") -> 6 | Z5: =if(Y5<'Get Started'!$D11,Y5+1,"") -> 7 | AA5: =if(Z5<'Get Started'!$D11,Z5+1,"") -> 8 | AB5: =if(AA5<'Get Started'!$D11,AA5+1,"") -> 9 | ... BC5: =if(BB5<'Get Started'!$D11,BB5+1,"") -> 36
B6: Date at end of period | C6: - | D6: date at end of period | H6: final | I6: =if(H6="sum",sum(T6:BC6),if(H6="final",index(T6:BC6,match(99^99,T6:BC6,1)),if(H6="initial",T6,if(H6="average",average(T6:BC6),0)))) -> 46022 | S6: =eomonth(edate(T6,if('Get Started'!$D10="monthly",-1,if('Get Started'!$D10="quarterly",-3,-12))),0) -> 44926 | T6: =eomonth('Get Started'!D12,0) -> 44957 | U6: =if(T5<'Get Started'!$D11,eomonth(edate(T6,if('Get Started'!$D10="monthly",1,if('Get Started'!$D10="quarterly",3,12))),0),"") -> 44985 | V6: =if(U5<'Get Started'!$D11,eomonth(edate(U6,if('Get Started'!$D10="monthly",1,if('Get Started'!$D10="quarterly",3,12))),0),"") -> 45016 | W6: =if(V5<'Get Started'!$D11,eomonth(edate(V6,if('Get Started'!$D10="monthly",1,if('Get Started'!$D10="quarterly",3,12))),0),"") -> 45046 | X6: =if(W5<'Get Started'!$D11,eomonth(edate(W6,if('Get Started'!$D10="monthly",1,if('Get Started'!$D10="quarterly",3,12))),0),"") -> 45077 | Y6: =if(X5<'Get Started'!$D11,eomonth(edate(X6,if('Get Started'!$D10="monthly",1,if('Get Started'!$D10="quarterly",3,12))),0),"") -> 45107 | Z6: =if(Y5<'Get Started'!$D11,eomonth(edate(Y6,if('Get Started'!$D10="monthly",1,if('Get Started'!$D10="quarterly",3,12))),0),"") -> 45138 | AA6: =if(Z5<'Get Started'!$D11,eomonth(edate(Z6,if('Get Started'!$D10="monthly",1,if('Get Started'!$D10="quarterly",3,12))),0),"") -> 45169 | AB6: =if(AA5<'Get Started'!$D11,eomonth(edate(AA6,if('Get Started'!$D10="monthly",1,if('Get Started'!$D10="quarterly",3,12))),0),"") -> 45199 | ... BC6: =if(BB5<'Get Started'!$D11,eomonth(edate(BB6,if('Get Started'!$D10="monthly",1,if('Get Started'!$D10="quarterly",3,12))),0),"") -> 46022
B7: Fiscal Year | C7: # | D7: fiscal year, expressed as either a relative # or an absolute date | H7: final | I7: =if(H7="sum",sum(T7:BC7),if(H7="final",index(T7:BC7,match(99^99,T7:BC7,1)),if(H7="initial",T7,if(H7="average",average(T7:BC7),0)))) -> 3 | T7: =if(T$5="","",if('Get Started'!$D14="relative",ROUNDUP(T5/if('Get Started'!$D10="monthly",12,if('Get Started'!$D10="quarterly",4,1)),0),year(T6))) -> 1 | U7: =if(U$5="","",if('Get Started'!$D14="relative",ROUNDUP(U5/if('Get Started'!$D10="monthly",12,if('Get Started'!$D10="quarterly",4,1)),0),year(U6))) -> 1 | V7: =if(V$5="","",if('Get Started'!$D14="relative",ROUNDUP(V5/if('Get Started'!$D10="monthly",12,if('Get Started'!$D10="quarterly",4,1)),0),year(V6))) -> 1 | W7: =if(W$5="","",if('Get Started'!$D14="relative",ROUNDUP(W5/if('Get Started'!$D10="monthly",12,if('Get Started'!$D10="quarterly",4,1)),0),year(W6))) -> 1 | X7: =if(X$5="","",if('Get Started'!$D14="relative",ROUNDUP(X5/if('Get Started'!$D10="monthly",12,if('Get Started'!$D10="quarterly",4,1)),0),year(X6))) -> 1 | Y7: =if(Y$5="","",if('Get Started'!$D14="relative",ROUNDUP(Y5/if('Get Started'!$D10="monthly",12,if('Get Started'!$D10="quarterly",4,1)),0),year(Y6))) -> 1 | Z7: =if(Z$5="","",if('Get Started'!$D14="relative",ROUNDUP(Z5/if('Get Started'!$D10="monthly",12,if('Get Started'!$D10="quarterly",4,1)),0),year(Z6))) -> 1 | AA7: =if(AA$5="","",if('Get Started'!$D14="relative",ROUNDUP(AA5/if('Get Started'!$D10="monthly",12,if('Get Started'!$D10="quarterly",4,1)),0),year(AA6))) -> 1 | ... BC7: =if(BC$5="","",if('Get Started'!$D14="relative",ROUNDUP(BC5/if('Get Started'!$D10="monthly",12,if('Get Started'!$D10="quarterly",4,1)),0),year(BC6))) -> 3
B8: Timestep | C8: # | D8: period - 1, used in a couple calculations | H8: final | I8: =if(H8="sum",sum(T8:BC8),if(H8="final",index(T8:BC8,match(99^99,T8:BC8,1)),if(H8="initial",T8,if(H8="average",average(T8:BC8),0)))) -> 35 | T8: 0 | U8: =if(T5<'Get Started'!$D11,T8+1,"") -> 1 | V8: =if(U5<'Get Started'!$D11,U8+1,"") -> 2 | W8: =if(V5<'Get Started'!$D11,V8+1,"") -> 3 | X8: =if(W5<'Get Started'!$D11,W8+1,"") -> 4 | Y8: =if(X5<'Get Started'!$D11,X8+1,"") -> 5 | Z8: =if(Y5<'Get Started'!$D11,Y8+1,"") -> 6 | AA8: =if(Z5<'Get Started'!$D11,Z8+1,"") -> 7 | AB8: =if(AA5<'Get Started'!$D11,AA8+1,"") -> 8 | ... BC8: =if(BB5<'Get Started'!$D11,BB8+1,"") -> 35
B9: Month # in Fiscal Year | C9: # | D9: tracks the month in the fiscal year, 1 through 12 | H9: final | I9: =if(H9="sum",sum(T9:BC9),if(H9="final",index(T9:BC9,match(99^99,T9:BC9,1)),if(H9="initial",T9,if(H9="average",average(T9:BC9),0)))) -> 12 | T9: =if(T$5="","",IF(MOD(MONTH(T6)+12-MONTH('Get Started'!$D13),12)=0,12,MOD(MONTH(T6)+12-MONTH('Get Started'!$D13),12))) -> 1 | U9: =if(U$5="","",IF(MOD(MONTH(U6)+12-MONTH('Get Started'!$D13),12)=0,12,MOD(MONTH(U6)+12-MONTH('Get Started'!$D13),12))) -> 2 | V9: =if(V$5="","",IF(MOD(MONTH(V6)+12-MONTH('Get Started'!$D13),12)=0,12,MOD(MONTH(V6)+12-MONTH('Get Started'!$D13),12))) -> 3 | W9: =if(W$5="","",IF(MOD(MONTH(W6)+12-MONTH('Get Started'!$D13),12)=0,12,MOD(MONTH(W6)+12-MONTH('Get Started'!$D13),12))) -> 4 | X9: =if(X$5="","",IF(MOD(MONTH(X6)+12-MONTH('Get Started'!$D13),12)=0,12,MOD(MONTH(X6)+12-MONTH('Get Started'!$D13),12))) -> 5 | Y9: =if(Y$5="","",IF(MOD(MONTH(Y6)+12-MONTH('Get Started'!$D13),12)=0,12,MOD(MONTH(Y6)+12-MONTH('Get Started'!$D13),12))) -> 6 | Z9: =if(Z$5="","",IF(MOD(MONTH(Z6)+12-MONTH('Get Started'!$D13),12)=0,12,MOD(MONTH(Z6)+12-MONTH('Get Started'!$D13),12))) -> 7 | AA9: =if(AA$5="","",IF(MOD(MONTH(AA6)+12-MONTH('Get Started'!$D13),12)=0,12,MOD(MONTH(AA6)+12-MONTH('Get Started'!$D13),12))) -> 8 | ... BC9: =if(BC$5="","",IF(MOD(MONTH(BC6)+12-MONTH('Get Started'!$D13),12)=0,12,MOD(MONTH(BC6)+12-MONTH('Get Started'!$D13),12))) -> 12
B10: Seasonality | C10: % | D10: optional, used for any driver that selects "use seasonality" | H10: sum | I10: =if(H10="sum",sum(T10:BC10),if(H10="final",index(T10:BC10,match(99^99,T10:BC10,1)),if(H10="initial",T10,if(H10="average",average(T10:BC10),0)))) -> 0 | T10: {=if(T$5="","",index('Get Started'!$D55:$D66,match(text(T6,"mmmm"),'Get Started'!$B55:$B66,0)))} -> 0 | U10: {=if(U$5="","",index('Get Started'!$D55:$D66,match(text(U6,"mmmm"),'Get Started'!$B55:$B66,0)))} -> 0 | V10: {=if(V$5="","",index('Get Started'!$D55:$D66,match(text(V6,"mmmm"),'Get Started'!$B55:$B66,0)))} -> 0 | W10: {=if(W$5="","",index('Get Started'!$D55:$D66,match(text(W6,"mmmm"),'Get Started'!$B55:$B66,0)))} -> 0 | X10: {=if(X$5="","",index('Get Started'!$D55:$D66,match(text(X6,"mmmm"),'Get Started'!$B55:$B66,0)))} -> 0 | Y10: {=if(Y$5="","",index('Get Started'!$D55:$D66,match(text(Y6,"mmmm"),'Get Started'!$B55:$B66,0)))} -> 0 | Z10: {=if(Z$5="","",index('Get Started'!$D55:$D66,match(text(Z6,"mmmm"),'Get Started'!$B55:$B66,0)))} -> 0 | AA10: {=if(AA$5="","",index('Get Started'!$D55:$D66,match(text(AA6,"mmmm"),'Get Started'!$B55:$B66,0)))} -> 0 | ... BC10: {=if(BC$5="","",index('Get Started'!$D55:$D66,match(text(BC6,"mmmm"),'Get Started'!$B55:$B66,0)))} -> 0
B11: Note: Deferred revenues start month | C11: # | D11: optional start month for recognizing deferred revenues, used in one calculation in model | H11: initial | I11: =if(H11="sum",sum(T11:BC11),if(H11="final",index(T11:BC11,match(99^99,T11:BC11,1)),if(H11="initial",T11,if(H11="average",average(T11:BC11),0)))) -> 1 | T11: =if(T$5="","",T5+MIN(T$5,'Get Started'!$D$24)-1) -> 1 | U11: =if(U$5="","",U5+MIN(U$5,'Get Started'!$D$24)-1) -> 2 | V11: =if(V$5="","",V5+MIN(V$5,'Get Started'!$D$24)-1) -> 3 | W11: =if(W$5="","",W5+MIN(W$5,'Get Started'!$D$24)-1) -> 4 | X11: =if(X$5="","",X5+MIN(X$5,'Get Started'!$D$24)-1) -> 5 | Y11: =if(Y$5="","",Y5+MIN(Y$5,'Get Started'!$D$24)-1) -> 6 | Z11: =if(Z$5="","",Z5+MIN(Z$5,'Get Started'!$D$24)-1) -> 7 | AA11: =if(AA$5="","",AA5+MIN(AA$5,'Get Started'!$D$24)-1) -> 8 | ... BC11: =if(BC$5="","",BC5+MIN(BC$5,'Get Started'!$D$24)-1) -> 36
B14: Forecasted Revenues, Expenses, and Cash Flows
B15: Used to forecast operating metrics, revenues, and expenses. Use the forecasting drivers *or* directly overwrite the formulas in the appropriate months to directly input your assumptions or create your own logic.
B16: Detail | D16: Category | K16: Initial Value | L16: Starts in period # | M16: ="Repeats every N "&lower($B4) -> Repeats every N month | N16: Changing based on | O16: ="Changes every N "&lower($B4) -> Changes every N month | P16: Changing by % or # | Q16: Using Driver | R16: Use Seasonality | T16: Use the prebuilt formulas *or* directly type in your inputs over the formulas, either way is valid.
B18: Revenues | C18: ='Get Started'!$C$20 -> $ | D18: First Revenue Description | H18: sum | I18: =if(H18="sum",sum(T18:BC18),if(H18="final",index(T18:BC18,match(99^99,T18:BC18,1)),if(H18="initial",T18,if(H18="average",average(T18:BC18),0)))) -> 0 | K18: 0 | L18: 0 | M18: 0 | N18: ... | O18: 0 | P18: 0 | Q18: ... | R18: FALSE | T18: =if(T$5="","",iferror(if($R18=true,if((T$5-$L18)>=1,(1+T$10)/(1+S$10),(1+T$10)),1) * if(or($N18="# per",$N18="% of"),if(T$5<$L18,0,IF(AND(T$5<>1,MOD(T$5-1-$L18+1,$M18)),0,$K18*index(T$53:T$92,match($Q18,$B$53:$B$92,0)))),if(T$5=$L18,$K18,if($N18="% change",if(T$5<$M18,0,offset(S18,,-1*$M18+1))*if(AND(T$5<>1,MOD(T$5-1-$L18+1,$O18)),1,(1+$P18)),if(and($N18="# change",T$5>=$L18),if(T$5<$M18,0,offset(S18,,-1*$M18+1))+if(AND(T$5<>1,MOD(T$5-1-$L18+1,$O18)),0,$P18),if($N18="log change",$K18*IF(T$5<=$O18,1,ROUND((T$5-$L18)/$O18+1,0))^$P18,if($M18=0,0,if(T$5<$M18,0,offset(S18,,-1*$M18+1)))))))),0)) -> 0 | U18: =if(U$5="","",iferror(if($R18=true,if((U$5-$L18)>=1,(1+U$10)/(1+T$10),(1+U$10)),1) * if(or($N18="# per",$N18="% of"),if(U$5<$L18,0,IF(AND(U$5<>1,MOD(U$5-1-$L18+1,$M18)),0,$K18*index(U$53:U$92,match($Q18,$B$53:$B$92,0)))),if(U$5=$L18,$K18,if($N18="% change",if(U$5<$M18,0,offset(T18,,-1*$M18+1))*if(AND(U$5<>1,MOD(U$5-1-$L18+1,$O18)),1,(1+$P18)),if(and($N18="# change",U$5>=$L18),if(U$5<$M18,0,offset(T18,,-1*$M18+1))+if(AND(U$5<>1,MOD(U$5-1-$L18+1,$O18)),0,$P18),if($N18="log change",$K18*IF(U$5<=$O18,1,ROUND((U$5-$L18)/$O18+1,0))^$P18,if($M18=0,0,if(U$5<$M18,0,offset(T18,,-1*$M18+1)))))))),0)) -> 0 | V18: =if(V$5="","",iferror(if($R18=true,if((V$5-$L18)>=1,(1+V$10)/(1+U$10),(1+V$10)),1) * if(or($N18="# per",$N18="% of"),if(V$5<$L18,0,IF(AND(V$5<>1,MOD(V$5-1-$L18+1,$M18)),0,$K18*index(V$53:V$92,match($Q18,$B$53:$B$92,0)))),if(V$5=$L18,$K18,if($N18="% change",if(V$5<$M18,0,offset(U18,,-1*$M18+1))*if(AND(V$5<>1,MOD(V$5-1-$L18+1,$O18)),1,(1+$P18)),if(and($N18="# change",V$5>=$L18),if(V$5<$M18,0,offset(U18,,-1*$M18+1))+if(AND(V$5<>1,MOD(V$5-1-$L18+1,$O18)),0,$P18),if($N18="log change",$K18*IF(V$5<=$O18,1,ROUND((V$5-$L18)/$O18+1,0))^$P18,if($M18=0,0,if(V$5<$M18,0,offset(U18,,-1*$M18+1)))))))),0)) -> 0 | W18: =if(W$5="","",iferror(if($R18=true,if((W$5-$L18)>=1,(1+W$10)/(1+V$10),(1+W$10)),1) * if(or($N18="# per",$N18="% of"),if(W$5<$L18,0,IF(AND(W$5<>1,MOD(W$5-1-$L18+1,$M18)),0,$K18*index(W$53:W$92,match($Q18,$B$53:$B$92,0)))),if(W$5=$L18,$K18,if($N18="% change",if(W$5<$M18,0,offset(V18,,-1*$M18+1))*if(AND(W$5<>1,MOD(W$5-1-$L18+1,$O18)),1,(1+$P18)),if(and($N18="# change",W$5>=$L18),if(W$5<$M18,0,offset(V18,,-1*$M18+1))+if(AND(W$5<>1,MOD(W$5-1-$L18+1,$O18)),0,$P18),if($N18="log change",$K18*IF(W$5<=$O18,1,ROUND((W$5-$L18)/$O18+1,0))^$P18,if($M18=0,0,if(W$5<$M18,0,offset(V18,,-1*$M18+1)))))))),0)) -> 0 | X18: =if(X$5="","",iferror(if($R18=true,if((X$5-$L18)>=1,(1+X$10)/(1+W$10),(1+X$10)),1) * if(or($N18="# per",$N18="% of"),if(X$5<$L18,0,IF(AND(X$5<>1,MOD(X$5-1-$L18+1,$M18)),0,$K18*index(X$53:X$92,match($Q18,$B$53:$B$92,0)))),if(X$5=$L18,$K18,if($N18="% change",if(X$5<$M18,0,offset(W18,,-1*$M18+1))*if(AND(X$5<>1,MOD(X$5-1-$L18+1,$O18)),1,(1+$P18)),if(and($N18="# change",X$5>=$L18),if(X$5<$M18,0,offset(W18,,-1*$M18+1))+if(AND(X$5<>1,MOD(X$5-1-$L18+1,$O18)),0,$P18),if($N18="log change",$K18*IF(X$5<=$O18,1,ROUND((X$5-$L18)/$O18+1,0))^$P18,if($M18=0,0,if(X$5<$M18,0,offset(W18,,-1*$M18+1)))))))),0)) -> 0 | Y18: =if(Y$5="","",iferror(if($R18=true,if((Y$5-$L18)>=1,(1+Y$10)/(1+X$10),(1+Y$10)),1) * if(or($N18="# per",$N18="% of"),if(Y$5<$L18,0,IF(AND(Y$5<>1,MOD(Y$5-1-$L18+1,$M18)),0,$K18*index(Y$53:Y$92,match($Q18,$B$53:$B$92,0)))),if(Y$5=$L18,$K18,if($N18="% change",if(Y$5<$M18,0,offset(X18,,-1*$M18+1))*if(AND(Y$5<>1,MOD(Y$5-1-$L18+1,$O18)),1,(1+$P18)),if(and($N18="# change",Y$5>=$L18),if(Y$5<$M18,0,offset(X18,,-1*$M18+1))+if(AND(Y$5<>1,MOD(Y$5-1-$L18+1,$O18)),0,$P18),if($N18="log change",$K18*IF(Y$5<=$O18,1,ROUND((Y$5-$L18)/$O18+1,0))^$P18,if($M18=0,0,if(Y$5<$M18,0,offset(X18,,-1*$M18+1)))))))),0)) -> 0 | Z18: =if(Z$5="","",iferror(if($R18=true,if((Z$5-$L18)>=1,(1+Z$10)/(1+Y$10),(1+Z$10)),1) * if(or($N18="# per",$N18="% of"),if(Z$5<$L18,0,IF(AND(Z$5<>1,MOD(Z$5-1-$L18+1,$M18)),0,$K18*index(Z$53:Z$92,match($Q18,$B$53:$B$92,0)))),if(Z$5=$L18,$K18,if($N18="% change",if(Z$5<$M18,0,offset(Y18,,-1*$M18+1))*if(AND(Z$5<>1,MOD(Z$5-1-$L18+1,$O18)),1,(1+$P18)),if(and($N18="# change",Z$5>=$L18),if(Z$5<$M18,0,offset(Y18,,-1*$M18+1))+if(AND(Z$5<>1,MOD(Z$5-1-$L18+1,$O18)),0,$P18),if($N18="log change",$K18*IF(Z$5<=$O18,1,ROUND((Z$5-$L18)/$O18+1,0))^$P18,if($M18=0,0,if(Z$5<$M18,0,offset(Y18,,-1*$M18+1)))))))),0)) -> 0 | AA18: =if(AA$5="","",iferror(if($R18=true,if((AA$5-$L18)>=1,(1+AA$10)/(1+Z$10),(1+AA$10)),1) * if(or($N18="# per",$N18="% of"),if(AA$5<$L18,0,IF(AND(AA$5<>1,MOD(AA$5-1-$L18+1,$M18)),0,$K18*index(AA$53:AA$92,match($Q18,$B$53:$B$92,0)))),if(AA$5=$L18,$K18,if($N18="% change",if(AA$5<$M18,0,offset(Z18,,-1*$M18+1))*if(AND(AA$5<>1,MOD(AA$5-1-$L18+1,$O18)),1,(1+$P18)),if(and($N18="# change",AA$5>=$L18),if(AA$5<$M18,0,offset(Z18,,-1*$M18+1))+if(AND(AA$5<>1,MOD(AA$5-1-$L18+1,$O18)),0,$P18),if($N18="log change",$K18*IF(AA$5<=$O18,1,ROUND((AA$5-$L18)/$O18+1,0))^$P18,if($M18=0,0,if(AA$5<$M18,0,offset(Z18,,-1*$M18+1)))))))),0)) -> 0 | ... BC18: =if(BC$5="","",iferror(if($R18=true,if((BC$5-$L18)>=1,(1+BC$10)/(1+BB$10),(1+BC$10)),1) * if(or($N18="# per",$N18="% of"),if(BC$5<$L18,0,IF(AND(BC$5<>1,MOD(BC$5-1-$L18+1,$M18)),0,$K18*index(BC$53:BC$92,match($Q18,$B$53:$B$92,0)))),if(BC$5=$L18,$K18,if($N18="% change",if(BC$5<$M18,0,offset(BB18,,-1*$M18+1))*if(AND(BC$5<>1,MOD(BC$5-1-$L18+1,$O18)),1,(1+$P18)),if(and($N18="# change",BC$5>=$L18),if(BC$5<$M18,0,offset(BB18,,-1*$M18+1))+if(AND(BC$5<>1,MOD(BC$5-1-$L18+1,$O18)),0,$P18),if($N18="log change",$K18*IF(BC$5<=$O18,1,ROUND((BC$5-$L18)/$O18+1,0))^$P18,if($M18=0,0,if(BC$5<$M18,0,offset(BB18,,-1*$M18+1)))))))),0)) -> 0
B19: Subscribers | C19: ='Get Started'!$C$20 -> $ | D19: Subscribers | H19: sum | I19: =if(H19="sum",sum(T19:BC19),if(H19="final",index(T19:BC19,match(99^99,T19:BC19,1)),if(H19="initial",T19,if(H19="average",average(T19:BC19),0)))) -> 4081.1477 | K19: 100 | L19: 1 | M19: 1 | N19: % change | O19: 6 | P19: 0.05 | Q19: ... | R19: FALSE | T19: =if(T$5="","",iferror(if($R19=true,if((T$5-$L19)>=1,(1+T$10)/(1+S$10),(1+T$10)),1) * if(or($N19="# per",$N19="% of"),if(T$5<$L19,0,IF(AND(T$5<>1,MOD(T$5-1-$L19+1,$M19)),0,$K19*index(T$53:T$92,match($Q19,$B$53:$B$92,0)))),if(T$5=$L19,$K19,if($N19="% change",if(T$5<$M19,0,offset(S19,,-1*$M19+1))*if(AND(T$5<>1,MOD(T$5-1-$L19+1,$O19)),1,(1+$P19)),if(and($N19="# change",T$5>=$L19),if(T$5<$M19,0,offset(S19,,-1*$M19+1))+if(AND(T$5<>1,MOD(T$5-1-$L19+1,$O19)),0,$P19),if($N19="log change",$K19*IF(T$5<=$O19,1,ROUND((T$5-$L19)/$O19+1,0))^$P19,if($M19=0,0,if(T$5<$M19,0,offset(S19,,-1*$M19+1)))))))),0)) -> 100 | U19: =if(U$5="","",iferror(if($R19=true,if((U$5-$L19)>=1,(1+U$10)/(1+T$10),(1+U$10)),1) * if(or($N19="# per",$N19="% of"),if(U$5<$L19,0,IF(AND(U$5<>1,MOD(U$5-1-$L19+1,$M19)),0,$K19*index(U$53:U$92,match($Q19,$B$53:$B$92,0)))),if(U$5=$L19,$K19,if($N19="% change",if(U$5<$M19,0,offset(T19,,-1*$M19+1))*if(AND(U$5<>1,MOD(U$5-1-$L19+1,$O19)),1,(1+$P19)),if(and($N19="# change",U$5>=$L19),if(U$5<$M19,0,offset(T19,,-1*$M19+1))+if(AND(U$5<>1,MOD(U$5-1-$L19+1,$O19)),0,$P19),if($N19="log change",$K19*IF(U$5<=$O19,1,ROUND((U$5-$L19)/$O19+1,0))^$P19,if($M19=0,0,if(U$5<$M19,0,offset(T19,,-1*$M19+1)))))))),0)) -> 100 | V19: =if(V$5="","",iferror(if($R19=true,if((V$5-$L19)>=1,(1+V$10)/(1+U$10),(1+V$10)),1) * if(or($N19="# per",$N19="% of"),if(V$5<$L19,0,IF(AND(V$5<>1,MOD(V$5-1-$L19+1,$M19)),0,$K19*index(V$53:V$92,match($Q19,$B$53:$B$92,0)))),if(V$5=$L19,$K19,if($N19="% change",if(V$5<$M19,0,offset(U19,,-1*$M19+1))*if(AND(V$5<>1,MOD(V$5-1-$L19+1,$O19)),1,(1+$P19)),if(and($N19="# change",V$5>=$L19),if(V$5<$M19,0,offset(U19,,-1*$M19+1))+if(AND(V$5<>1,MOD(V$5-1-$L19+1,$O19)),0,$P19),if($N19="log change",$K19*IF(V$5<=$O19,1,ROUND((V$5-$L19)/$O19+1,0))^$P19,if($M19=0,0,if(V$5<$M19,0,offset(U19,,-1*$M19+1)))))))),0)) -> 100 | W19: =if(W$5="","",iferror(if($R19=true,if((W$5-$L19)>=1,(1+W$10)/(1+V$10),(1+W$10)),1) * if(or($N19="# per",$N19="% of"),if(W$5<$L19,0,IF(AND(W$5<>1,MOD(W$5-1-$L19+1,$M19)),0,$K19*index(W$53:W$92,match($Q19,$B$53:$B$92,0)))),if(W$5=$L19,$K19,if($N19="% change",if(W$5<$M19,0,offset(V19,,-1*$M19+1))*if(AND(W$5<>1,MOD(W$5-1-$L19+1,$O19)),1,(1+$P19)),if(and($N19="# change",W$5>=$L19),if(W$5<$M19,0,offset(V19,,-1*$M19+1))+if(AND(W$5<>1,MOD(W$5-1-$L19+1,$O19)),0,$P19),if($N19="log change",$K19*IF(W$5<=$O19,1,ROUND((W$5-$L19)/$O19+1,0))^$P19,if($M19=0,0,if(W$5<$M19,0,offset(V19,,-1*$M19+1)))))))),0)) -> 100 | X19: =if(X$5="","",iferror(if($R19=true,if((X$5-$L19)>=1,(1+X$10)/(1+W$10),(1+X$10)),1) * if(or($N19="# per",$N19="% of"),if(X$5<$L19,0,IF(AND(X$5<>1,MOD(X$5-1-$L19+1,$M19)),0,$K19*index(X$53:X$92,match($Q19,$B$53:$B$92,0)))),if(X$5=$L19,$K19,if($N19="% change",if(X$5<$M19,0,offset(W19,,-1*$M19+1))*if(AND(X$5<>1,MOD(X$5-1-$L19+1,$O19)),1,(1+$P19)),if(and($N19="# change",X$5>=$L19),if(X$5<$M19,0,offset(W19,,-1*$M19+1))+if(AND(X$5<>1,MOD(X$5-1-$L19+1,$O19)),0,$P19),if($N19="log change",$K19*IF(X$5<=$O19,1,ROUND((X$5-$L19)/$O19+1,0))^$P19,if($M19=0,0,if(X$5<$M19,0,offset(W19,,-1*$M19+1)))))))),0)) -> 100 | Y19: =if(Y$5="","",iferror(if($R19=true,if((Y$5-$L19)>=1,(1+Y$10)/(1+X$10),(1+Y$10)),1) * if(or($N19="# per",$N19="% of"),if(Y$5<$L19,0,IF(AND(Y$5<>1,MOD(Y$5-1-$L19+1,$M19)),0,$K19*index(Y$53:Y$92,match($Q19,$B$53:$B$92,0)))),if(Y$5=$L19,$K19,if($N19="% change",if(Y$5<$M19,0,offset(X19,,-1*$M19+1))*if(AND(Y$5<>1,MOD(Y$5-1-$L19+1,$O19)),1,(1+$P19)),if(and($N19="# change",Y$5>=$L19),if(Y$5<$M19,0,offset(X19,,-1*$M19+1))+if(AND(Y$5<>1,MOD(Y$5-1-$L19+1,$O19)),0,$P19),if($N19="log change",$K19*IF(Y$5<=$O19,1,ROUND((Y$5-$L19)/$O19+1,0))^$P19,if($M19=0,0,if(Y$5<$M19,0,offset(X19,,-1*$M19+1)))))))),0)) -> 100 | Z19: =if(Z$5="","",iferror(if($R19=true,if((Z$5-$L19)>=1,(1+Z$10)/(1+Y$10),(1+Z$10)),1) * if(or($N19="# per",$N19="% of"),if(Z$5<$L19,0,IF(AND(Z$5<>1,MOD(Z$5-1-$L19+1,$M19)),0,$K19*index(Z$53:Z$92,match($Q19,$B$53:$B$92,0)))),if(Z$5=$L19,$K19,if($N19="% change",if(Z$5<$M19,0,offset(Y19,,-1*$M19+1))*if(AND(Z$5<>1,MOD(Z$5-1-$L19+1,$O19)),1,(1+$P19)),if(and($N19="# change",Z$5>=$L19),if(Z$5<$M19,0,offset(Y19,,-1*$M19+1))+if(AND(Z$5<>1,MOD(Z$5-1-$L19+1,$O19)),0,$P19),if($N19="log change",$K19*IF(Z$5<=$O19,1,ROUND((Z$5-$L19)/$O19+1,0))^$P19,if($M19=0,0,if(Z$5<$M19,0,offset(Y19,,-1*$M19+1)))))))),0)) -> 105 | AA19: =if(AA$5="","",iferror(if($R19=true,if((AA$5-$L19)>=1,(1+AA$10)/(1+Z$10),(1+AA$10)),1) * if(or($N19="# per",$N19="% of"),if(AA$5<$L19,0,IF(AND(AA$5<>1,MOD(AA$5-1-$L19+1,$M19)),0,$K19*index(AA$53:AA$92,match($Q19,$B$53:$B$92,0)))),if(AA$5=$L19,$K19,if($N19="% change",if(AA$5<$M19,0,offset(Z19,,-1*$M19+1))*if(AND(AA$5<>1,MOD(AA$5-1-$L19+1,$O19)),1,(1+$P19)),if(and($N19="# change",AA$5>=$L19),if(AA$5<$M19,0,offset(Z19,,-1*$M19+1))+if(AND(AA$5<>1,MOD(AA$5-1-$L19+1,$O19)),0,$P19),if($N19="log change",$K19*IF(AA$5<=$O19,1,ROUND((AA$5-$L19)/$O19+1,0))^$P19,if($M19=0,0,if(AA$5<$M19,0,offset(Z19,,-1*$M19+1)))))))),0)) -> 105 | ... BC19: =if(BC$5="","",iferror(if($R19=true,if((BC$5-$L19)>=1,(1+BC$10)/(1+BB$10),(1+BC$10)),1) * if(or($N19="# per",$N19="% of"),if(BC$5<$L19,0,IF(AND(BC$5<>1,MOD(BC$5-1-$L19+1,$M19)),0,$K19*index(BC$53:BC$92,match($Q19,$B$53:$B$92,0)))),if(BC$5=$L19,$K19,if($N19="% change",if(BC$5<$M19,0,offset(BB19,,-1*$M19+1))*if(AND(BC$5<>1,MOD(BC$5-1-$L19+1,$O19)),1,(1+$P19)),if(and($N19="# change",BC$5>=$L19),if(BC$5<$M19,0,offset(BB19,,-1*$M19+1))+if(AND(BC$5<>1,MOD(BC$5-1-$L19+1,$O19)),0,$P19),if($N19="log change",$K19*IF(BC$5<=$O19,1,ROUND((BC$5-$L19)/$O19+1,0))^$P19,if($M19=0,0,if(BC$5<$M19,0,offset(BB19,,-1*$M19+1)))))))),0)) -> 127.62816
B20: Revenues | C20: ='Get Started'!$C$20 -> $ | D20: Second Revenue Description | H20: sum | I20: =if(H20="sum",sum(T20:BC20),if(H20="final",index(T20:BC20,match(99^99,T20:BC20,1)),if(H20="initial",T20,if(H20="average",average(T20:BC20),0)))) -> 40811.477 | K20: 10 | L20: 1 | M20: 1 | N20: # per | O20: 0 | P20: 0 | Q20: Subscribers | R20: FALSE | T20: =if(T$5="","",iferror(if($R20=true,if((T$5-$L20)>=1,(1+T$10)/(1+S$10),(1+T$10)),1) * if(or($N20="# per",$N20="% of"),if(T$5<$L20,0,IF(AND(T$5<>1,MOD(T$5-1-$L20+1,$M20)),0,$K20*index(T$53:T$92,match($Q20,$B$53:$B$92,0)))),if(T$5=$L20,$K20,if($N20="% change",if(T$5<$M20,0,offset(S20,,-1*$M20+1))*if(AND(T$5<>1,MOD(T$5-1-$L20+1,$O20)),1,(1+$P20)),if(and($N20="# change",T$5>=$L20),if(T$5<$M20,0,offset(S20,,-1*$M20+1))+if(AND(T$5<>1,MOD(T$5-1-$L20+1,$O20)),0,$P20),if($N20="log change",$K20*IF(T$5<=$O20,1,ROUND((T$5-$L20)/$O20+1,0))^$P20,if($M20=0,0,if(T$5<$M20,0,offset(S20,,-1*$M20+1)))))))),0)) -> 1000 | U20: =if(U$5="","",iferror(if($R20=true,if((U$5-$L20)>=1,(1+U$10)/(1+T$10),(1+U$10)),1) * if(or($N20="# per",$N20="% of"),if(U$5<$L20,0,IF(AND(U$5<>1,MOD(U$5-1-$L20+1,$M20)),0,$K20*index(U$53:U$92,match($Q20,$B$53:$B$92,0)))),if(U$5=$L20,$K20,if($N20="% change",if(U$5<$M20,0,offset(T20,,-1*$M20+1))*if(AND(U$5<>1,MOD(U$5-1-$L20+1,$O20)),1,(1+$P20)),if(and($N20="# change",U$5>=$L20),if(U$5<$M20,0,offset(T20,,-1*$M20+1))+if(AND(U$5<>1,MOD(U$5-1-$L20+1,$O20)),0,$P20),if($N20="log change",$K20*IF(U$5<=$O20,1,ROUND((U$5-$L20)/$O20+1,0))^$P20,if($M20=0,0,if(U$5<$M20,0,offset(T20,,-1*$M20+1)))))))),0)) -> 1000 | V20: =if(V$5="","",iferror(if($R20=true,if((V$5-$L20)>=1,(1+V$10)/(1+U$10),(1+V$10)),1) * if(or($N20="# per",$N20="% of"),if(V$5<$L20,0,IF(AND(V$5<>1,MOD(V$5-1-$L20+1,$M20)),0,$K20*index(V$53:V$92,match($Q20,$B$53:$B$92,0)))),if(V$5=$L20,$K20,if($N20="% change",if(V$5<$M20,0,offset(U20,,-1*$M20+1))*if(AND(V$5<>1,MOD(V$5-1-$L20+1,$O20)),1,(1+$P20)),if(and($N20="# change",V$5>=$L20),if(V$5<$M20,0,offset(U20,,-1*$M20+1))+if(AND(V$5<>1,MOD(V$5-1-$L20+1,$O20)),0,$P20),if($N20="log change",$K20*IF(V$5<=$O20,1,ROUND((V$5-$L20)/$O20+1,0))^$P20,if($M20=0,0,if(V$5<$M20,0,offset(U20,,-1*$M20+1)))))))),0)) -> 1000 | W20: =if(W$5="","",iferror(if($R20=true,if((W$5-$L20)>=1,(1+W$10)/(1+V$10),(1+W$10)),1) * if(or($N20="# per",$N20="% of"),if(W$5<$L20,0,IF(AND(W$5<>1,MOD(W$5-1-$L20+1,$M20)),0,$K20*index(W$53:W$92,match($Q20,$B$53:$B$92,0)))),if(W$5=$L20,$K20,if($N20="% change",if(W$5<$M20,0,offset(V20,,-1*$M20+1))*if(AND(W$5<>1,MOD(W$5-1-$L20+1,$O20)),1,(1+$P20)),if(and($N20="# change",W$5>=$L20),if(W$5<$M20,0,offset(V20,,-1*$M20+1))+if(AND(W$5<>1,MOD(W$5-1-$L20+1,$O20)),0,$P20),if($N20="log change",$K20*IF(W$5<=$O20,1,ROUND((W$5-$L20)/$O20+1,0))^$P20,if($M20=0,0,if(W$5<$M20,0,offset(V20,,-1*$M20+1)))))))),0)) -> 1000 | X20: =if(X$5="","",iferror(if($R20=true,if((X$5-$L20)>=1,(1+X$10)/(1+W$10),(1+X$10)),1) * if(or($N20="# per",$N20="% of"),if(X$5<$L20,0,IF(AND(X$5<>1,MOD(X$5-1-$L20+1,$M20)),0,$K20*index(X$53:X$92,match($Q20,$B$53:$B$92,0)))),if(X$5=$L20,$K20,if($N20="% change",if(X$5<$M20,0,offset(W20,,-1*$M20+1))*if(AND(X$5<>1,MOD(X$5-1-$L20+1,$O20)),1,(1+$P20)),if(and($N20="# change",X$5>=$L20),if(X$5<$M20,0,offset(W20,,-1*$M20+1))+if(AND(X$5<>1,MOD(X$5-1-$L20+1,$O20)),0,$P20),if($N20="log change",$K20*IF(X$5<=$O20,1,ROUND((X$5-$L20)/$O20+1,0))^$P20,if($M20=0,0,if(X$5<$M20,0,offset(W20,,-1*$M20+1)))))))),0)) -> 1000 | Y20: =if(Y$5="","",iferror(if($R20=true,if((Y$5-$L20)>=1,(1+Y$10)/(1+X$10),(1+Y$10)),1) * if(or($N20="# per",$N20="% of"),if(Y$5<$L20,0,IF(AND(Y$5<>1,MOD(Y$5-1-$L20+1,$M20)),0,$K20*index(Y$53:Y$92,match($Q20,$B$53:$B$92,0)))),if(Y$5=$L20,$K20,if($N20="% change",if(Y$5<$M20,0,offset(X20,,-1*$M20+1))*if(AND(Y$5<>1,MOD(Y$5-1-$L20+1,$O20)),1,(1+$P20)),if(and($N20="# change",Y$5>=$L20),if(Y$5<$M20,0,offset(X20,,-1*$M20+1))+if(AND(Y$5<>1,MOD(Y$5-1-$L20+1,$O20)),0,$P20),if($N20="log change",$K20*IF(Y$5<=$O20,1,ROUND((Y$5-$L20)/$O20+1,0))^$P20,if($M20=0,0,if(Y$5<$M20,0,offset(X20,,-1*$M20+1)))))))),0)) -> 1000 | Z20: =if(Z$5="","",iferror(if($R20=true,if((Z$5-$L20)>=1,(1+Z$10)/(1+Y$10),(1+Z$10)),1) * if(or($N20="# per",$N20="% of"),if(Z$5<$L20,0,IF(AND(Z$5<>1,MOD(Z$5-1-$L20+1,$M20)),0,$K20*index(Z$53:Z$92,match($Q20,$B$53:$B$92,0)))),if(Z$5=$L20,$K20,if($N20="% change",if(Z$5<$M20,0,offset(Y20,,-1*$M20+1))*if(AND(Z$5<>1,MOD(Z$5-1-$L20+1,$O20)),1,(1+$P20)),if(and($N20="# change",Z$5>=$L20),if(Z$5<$M20,0,offset(Y20,,-1*$M20+1))+if(AND(Z$5<>1,MOD(Z$5-1-$L20+1,$O20)),0,$P20),if($N20="log change",$K20*IF(Z$5<=$O20,1,ROUND((Z$5-$L20)/$O20+1,0))^$P20,if($M20=0,0,if(Z$5<$M20,0,offset(Y20,,-1*$M20+1)))))))),0)) -> 1050 | AA20: =if(AA$5="","",iferror(if($R20=true,if((AA$5-$L20)>=1,(1+AA$10)/(1+Z$10),(1+AA$10)),1) * if(or($N20="# per",$N20="% of"),if(AA$5<$L20,0,IF(AND(AA$5<>1,MOD(AA$5-1-$L20+1,$M20)),0,$K20*index(AA$53:AA$92,match($Q20,$B$53:$B$92,0)))),if(AA$5=$L20,$K20,if($N20="% change",if(AA$5<$M20,0,offset(Z20,,-1*$M20+1))*if(AND(AA$5<>1,MOD(AA$5-1-$L20+1,$O20)),1,(1+$P20)),if(and($N20="# change",AA$5>=$L20),if(AA$5<$M20,0,offset(Z20,,-1*$M20+1))+if(AND(AA$5<>1,MOD(AA$5-1-$L20+1,$O20)),0,$P20),if($N20="log change",$K20*IF(AA$5<=$O20,1,ROUND((AA$5-$L20)/$O20+1,0))^$P20,if($M20=0,0,if(AA$5<$M20,0,offset(Z20,,-1*$M20+1)))))))),0)) -> 1050 | ... BC20: =if(BC$5="","",iferror(if($R20=true,if((BC$5-$L20)>=1,(1+BC$10)/(1+BB$10),(1+BC$10)),1) * if(or($N20="# per",$N20="% of"),if(BC$5<$L20,0,IF(AND(BC$5<>1,MOD(BC$5-1-$L20+1,$M20)),0,$K20*index(BC$53:BC$92,match($Q20,$B$53:$B$92,0)))),if(BC$5=$L20,$K20,if($N20="% change",if(BC$5<$M20,0,offset(BB20,,-1*$M20+1))*if(AND(BC$5<>1,MOD(BC$5-1-$L20+1,$O20)),1,(1+$P20)),if(and($N20="# change",BC$5>=$L20),if(BC$5<$M20,0,offset(BB20,,-1*$M20+1))+if(AND(BC$5<>1,MOD(BC$5-1-$L20+1,$O20)),0,$P20),if($N20="log change",$K20*IF(BC$5<=$O20,1,ROUND((BC$5-$L20)/$O20+1,0))^$P20,if($M20=0,0,if(BC$5<$M20,0,offset(BB20,,-1*$M20+1)))))))),0)) -> 1276.2816
