Workbook

Sheet README
B2: Venture Capital Model, with Annual Forecast
B4: Copyright & Contact | C4: This was created by Taylor Davidson (@tdavidson) of Foresight. © 2025, Unstructured Ventures, LLC. Questions, contact taylor@foresight.is or @tdavidson
B5: License | C5: tl:dr; You can modify, edit, use, and share within your company (and with third-parties as needed to operate your business). You may not redistribute, resell, give away to others. Full license.
B6: Goal | C6: Simplified model for forecasting a venture fund, to help understand overall fund assumptions and how portfolio construction impacts returns. I've worked with countless founders building complicated models for fund construction - see Venture Investor Model for one - but want to create a simpler, more accessible model that removes some of the lesser-used edge cases and covers the basics for most emerging managers.
B7: Copy to Google Sheets or Download to Excel | C7: File > Make a Copy to copy it to your own Google Drive, or File > Download to download this to use in Excel or other spreadsheet programs. See License for warranties and liabilities.
B8: Support | C8: Questions, happy to assist, contact anytime. More details on how I provide support: https://foresight.is/help
B9: Missing a feature you need? | C9: Check out the Resources for other resources for modeling venture funds, and check out Foresight's Venture Investor Model for a more detailed fund model with financial statements, management company budgeting, and more.
B10: Quickstart | C10: Input fund structural assumptions on Get Started sheet, then review the Key Reports and Forecast sheet to see the key outputs. More details at https://foresight.is/docs/
B12: Outline
B14: README | C14: Contact into, overview on model. Safe to delete or hide.
B15: Formatting and Colors Overview | C15: Details on what the colors and formatting in the model mean. https://foresight.is/learn/colors-and-formatting
B16: License | C16: Terms of use of the model. Safe to delete or hide. https://foresight.is/license
B17: Get Started | C17: Core assumptions for the fund. Do not delete, safe to hide.
B18: Capital and Fund Assumptions | C18: Assumptions for fund economics
B19: Recycling | C19: Optional section for assuming fund recycling policy
B20: Portfolio Construction Assumptions | C20: Core portfolio construction assumptions
B21: Return Assumptions | C21: Investment performance assumptions
B22: Fund Performance | C22: Summary of fund performance. Details and more metrics on Forecast sheet
B23: Key Reports | C23: Key charts to summarize the model. Safe to delete or hide.
B24: Forecast | C24: The core calculations to forecast the operations of the fund. The core of the model.
B25: Resources | C25: Links to other models and resources for modeling venture capital funds and investments, from around the web. Safe to delete or hide.
... B28: Changelog | C28: List of what has been changed in model versions. Safe to delete or hide, although I'd advise to hide (instead of delete) so can always check to see what model version you are using to compare to future changes.

Sheet License
B1: License Agreement
B2: Available on website
B4: This License Agreement (“the Agreement”) between you, the licensee, and Unstructured Ventures, LLC (the “Company”) a limited liability corporation headquartered and registered in the Commonwealth of Pennsylvania and organized under the laws of the state of Delaware. The Company owns the financial model (the “Product”) and any edits, additions, or customizations (the "Service") delivered under this Agreement. This Agreement grants you a non-exclusive, non-transferable right to use and incorporate the Product and Service in personal and corporate projects for the organization that purchased the Product and/or Service.
B6: You agree as follows:
B8: 1. Scope of use
B9: * Use and incorporate the Product and/or Service in personal and commercial projects for your company including financial models, business plans, pitch decks, etc.
B10: * You may modify the Product and/or Service to better serve your project.
B11: * You are granted unlimited usage of the Product and/or Service purchased in your organization.
B12: * If an organization is the licensee, all employees of the organization may use the same license.
B14: 2. Limitations and non-use
B15: * You may not redistribute, sublicense or resell the Product and/or Service.
B16: * You may not distribute, license or sell derivative, recompiled, reverse engineered, or modified versions of the Product and/or Service.
... B29: This Agreement is governed by the laws of the Commonwealth of Pennsylvania and the applicable laws of the United States of America. Legal proceedings related to this Agreement may only be brought in the courts of Pennsylvania. You agree to service of process at the e-mail address on your original order. Notices may be sent to Unstructured Ventures, LLC by email to hello@unstructuredventures.com or by post to Unstructured Ventures, LLC, 6360 Broad St, #5226, Pittsburgh, PA, 15206, USA.

Sheet Get Started
B2: Get Started
B3: Key model assumptions and performance metrics
B5: Capital and Fund Assumptions
B6: Capital, Management Fees, base Fund-level assumptions
B8: Detail | C8: Unit | E8: Assumption | F8: Forecast | K8: Notes
B9: Total Commited Capital (Fund Size) | C9: $ | E9: 25000000 | F9: =Forecast!E30 -> 25000000 | K9: Fund size. By default, assumes all committed capital is closed at the start. Can adjust that by modifying the committed capital on Forecast sheet.
B10: GP Commit, as % of committed capital | C10: % | E10: 0.02 | F10: =E10*F$9 -> 500000 | K10: GP commit is treated as an LP interest for purposes of calculating mangement fees and carried interest. see glossary for additional details
B11: Organizational Expenses (one time) | C11: =C$9 -> $ | E11: 100000 | F11: =Forecast!E39 -> 100000 | K11: paid by fund, in addition to management fees. one time costs associated with forming the fund, primarily legal fees
B12: Operational Expenses (annual) | C12: =C$9 -> $ | E12: 75000 | F12: =Forecast!E40 -> 750000 | K12: paid by fund, in addition to management fees. see https://foresight.is/docs/management-company/ for more context. calculated based on the fund operations period for operating expenses
B13: Management Fees, per year, as % of committed capital | C13: % | E13: 0.02 | F13: =Forecast!E41 -> 4900000 | K13: model works for management fees based on called and committed capital (can be edited for fee structures based on assets under management). if you have a management fee structure that steps down over time, you can edit the management fees directly on the Forecast sheet.
B14: Carry | C14: % | E14: 0.2 | F14: =E59 -> 10977500 | K14: carry is the % of gains that are paid to the managers of the fund. part of the commonly cited "2 and 20" fees structure for funds
B15: New Investment time period (years) | C15: # | E15: 4 | K15: time period for new investments (follow ons by default assumed to come over time)
B16: Fund Duration (Management Fees time period) (quarters) | C16: # | E16: 10 | K16: time period used for assuming management fees, tied to the fund duration and not including the fund extension period, if applicable
B17: Fund Operations time period (years) | C17: # | E17: =E15+MAX(H45:H48) -> 10 | K17: time period used for assuming operational expenses, which is calculated from the new invesetment and exit timeframes, to cover the periods the fund incurrs operational expenses. you can override the calculated period if desired.
B18: Fund Duration Extension Period (years) | C18: # | E18: =MAX(0,E17-E16) -> 0 | K18: extra time period calculated from your deployment and holding period assumptions. purely for informational purposes, the model uses the fund duration for calculating management fees, this just shows how long of an extension you will need based on your assumptions
B21: Recycling
B22: Details on recycling provisions for closed end and evergreen funds | K22: more at https://foresight.is/docs/management-fee-recycling/
B24: Detail | C24: Unit | E24: Assumption | F24: Forecast | K24: Notes
B25: ="Target recycling %, and max achievable" -> Target recycling %, and max achievable | C25: % | E25: 0.25 | F25: =IFERROR(F29/F26,0) -> 0.0385 | K25: input is for the target % to recycle, and the forecast shows the % that is achievable given the parameters in the assumptions below. It is very common for the max acheivable to be less than the target. Note that LPAs may set the number differently; for example, some LPAs may note that recycling is 125% of committed capital (meaning that the total can be 25% higher than the amount of committed capital), or it may say that recycling is 25% of committed capital. They mean the same thing, but the number may be expressed differently. The model uses an assumption of 25% of recycling + 100% of committed capital = 125% of total committed capital plus recycling
B26: ="... based on "&E26 -> ... based on committed capital | C26: - | E26: committed capital | F26: =IF(E26="management fees",F13,F9) -> 25000000 | K26: can be set to management fees or committed capital, and the forecast outputs the amount of it forecasted in the model
B27: ="... from exits "&E27&" years or less post-investment" -> ... from exits 6 years or less post-investment | C27: # | E27: 6 | F27: =Forecast!E145 -> 80850000 | K27: can set the time limit from original investment to time to proceeds (exit), and only allow exits within that timeframe to recycle their proceeds. if there is no limit, simply input a number greater thant the fund operations period or the max holding period in the return assumptions
B28: ="... up to the amount of "&E28&" per investment exited" -> ... up to the amount of invested capital per investment exited | C28: - | E28: invested capital | F28: =IF(E28="invested capital",Forecast!E147,IF(E28="invested capital plus cost basis",Forecast!E146,Forecast!E145)) -> 8085000 | K28: can set to recycle the amount originally invested in the company (meaning any profits would be distributed), the amount invested in the company plus the cost basis (allocating expenses to the invested capital, so that it reflects paid in capital related to the investent), or all proceeds, meaning all proceeds from the exit
B29: ="... able to invest in "&E29 -> ... able to invest in new investments | C29: - | E29: new investments | F29: =Forecast!E42 -> 962500 | K29: can set to new investments only, or new and follow on investments. this will set the proceeds recycling timeframe on the forecast sheet, meaning the period when recycling can be done
B32: Portfolio Construction
B33: Capital Allocation and Investment Timeframe Assumptions
B35: Detail | C35: Unit | E35: New | F35: Follow
B36: % Allocation of Invested Capital | C36: % | E36: 1 | F36: =1-E36 -> 0 | K36: Allocation of overall invested capital to new and follow
B37: Average Check Size | C37: =C$9 -> $ | E37: 500000 | F37: 0 | K37: Follow ons are assumed to be on average 1-2 years after the new investment. If more detailed required, consider the Venture Investor Model (see Model Comparison sheet)
B38: # of Checks | C38: # | E38: =F49 -> 40.425 | F38: =IFERROR(F36*E57/F37,0) -> 0 | K38: # of new checks = # of unique companies invested into. # of follow checks = # of rounds participated in, can consist of multiple follow checks into a single company
B41: Return Assumptions
B42: Used to create estimates of average investment outcome by gross exit multiple and hold period
B44: Type of Exit | C44: Unit | E44: % of Investments | F44: # of Investments | G44: Average Gross Exit Multiple | H44: Average Hold Period (years) | I44: % of Total Proceeds | K44: Type of Exit can be defined in a few ways: by returns (writeoffs, small, medium, large), by strategy (Seed, A, B, etc.), by investment strategy (early, late, growth), or industry strategy (tech, energy, etc.)
B45: Writeoff | C45: #, % | E45: 0.6 | F45: =E45*F$49 -> 24.255 | G45: 0 | H45: 2 | I45: =IFERROR(G45*E45*E$57/E$58,0) -> 0 | K45: Average Hold Period is the average time from initial investment to exit, per # of investments, used to calculate the timing of proceeds and writeoffs
B46: Small | C46: #, % | E46: 0.2 | F46: =E46*F$49 -> 8.085 | G46: 1.5 | H46: 3 | I46: =IFERROR(G46*E46*E$57/E$58,0) -> 0.075 | K46: The % of total proceeds is calculated from the gross exit multiple and the % of investments for each exit type, to estimate where the fund returns come from. More complicated methods for estimated proceeds are in the paid venture models at https://foresight.is/vc
B47: Medium | C47: #, % | E47: 0.1 | F47: =E47*F$49 -> 4.0425 | G47: 5 | H47: 4 | I47: =IFERROR(G47*E47*E$57/E$58,0) -> 0.125
B48: Large | C48: #, % | E48: =MAX(0,1-SUM(E45:E47)) -> 0.1 | F48: =E48*F$49 -> 4.0425 | G48: 32 | H48: 6 | I48: =IFERROR(G48*E48*E$57/E$58,0) -> 0.8
E49: =SUM(E45:E48) -> 1 | F49: =IFERROR(E57*E36/E37,0) -> 40.425 | G49: =SUMPRODUCT(G45:G48,$E45:$E48) -> 4 | H49: =SUMPRODUCT(H45:H48,$E45:$E48) -> 2.8 | I49: =SUM(I45:I48) -> 1 | K49: Can adjust this structure to add additional lines for types of exits, just note will need to make a few edits on Forecast sheet to pull those into the calculations of proceeds and changes in invested capital.
B51: Fund Performance
B52: Fund performance summary
B54: Called Capital (also called Paid in Capital) | C54: =C$9 -> $ | E54: =Forecast!E31 -> 25000000 | K54: should equal committed capital. in some cases this will not, e.g. when using assets under management to calculate management fees, or when selecting "new and follow investments" as a recycling method. the natural circularity in those calculations and the slight deviation from committed capital using the algebra in the model aligns with the difficulty in planning (in real life) for investments and expenses with those methods
...

Sheet Key Reports

Sheet Forecast
B2: Annual Forecast
B4: Relative Year | G4: =1 -> 1 | H4: =G4+1 -> 2 | I4: =H4+1 -> 3 | J4: =I4+1 -> 4 | K4: =J4+1 -> 5 | L4: =K4+1 -> 6 | M4: =L4+1 -> 7 | N4: =M4+1 -> 8 | O4: =N4+1 -> 9 | ... Z4: =Y4+1 -> 20
B5: Date at end of period | G5: =DATE(YEAR(TODAY()),12,31) -> 46022 | H5: =EDATE(G5,12) -> 46387 | I5: =EDATE(H5,12) -> 46752 | J5: =EDATE(I5,12) -> 47118 | K5: =EDATE(J5,12) -> 47483 | L5: =EDATE(K5,12) -> 47848 | M5: =EDATE(L5,12) -> 48213 | N5: =EDATE(M5,12) -> 48579 | O5: =EDATE(N5,12) -> 48944 | ... Z5: =EDATE(Y5,12) -> 52962
B7: Triggers
B8: ='Get Started'!B15 -> New Investment time period (years) | C8: period for making new investments only | D8: sum | E8: =IF(D8="sum",SUM(G8:Z8),IF(D8="final",Z8,IF(D8="initial",G8,IF(D8="average",AVERAGE(G8:Z8),0)))) -> 4 | G8: =IF(G$4<='Get Started'!$E15,1,0) -> 1 | H8: =IF(H$4<='Get Started'!$E15,1,0) -> 1 | I8: =IF(I$4<='Get Started'!$E15,1,0) -> 1 | J8: =IF(J$4<='Get Started'!$E15,1,0) -> 1 | K8: =IF(K$4<='Get Started'!$E15,1,0) -> 0 | L8: =IF(L$4<='Get Started'!$E15,1,0) -> 0 | M8: =IF(M$4<='Get Started'!$E15,1,0) -> 0 | N8: =IF(N$4<='Get Started'!$E15,1,0) -> 0 | ... Z8: =IF(Z$4<='Get Started'!$E15,1,0) -> 0
B9: ='Get Started'!B16 -> Fund Duration (Management Fees time period) (quarters) | C9: see FAST Standard for how to use triggers: https://foresight.is/learn/fast-standard | D9: sum | E9: =IF(D9="sum",SUM(G9:Z9),IF(D9="final",Z9,IF(D9="initial",G9,IF(D9="average",AVERAGE(G9:Z9),0)))) -> 10 | G9: =IF(G$4<='Get Started'!$E16,1,0)*G10 -> 1 | H9: =IF(H$4<='Get Started'!$E16,1,0)*H10 -> 1 | I9: =IF(I$4<='Get Started'!$E16,1,0)*I10 -> 1 | J9: =IF(J$4<='Get Started'!$E16,1,0)*J10 -> 1 | K9: =IF(K$4<='Get Started'!$E16,1,0)*K10 -> 1 | L9: =IF(L$4<='Get Started'!$E16,1,0)*L10 -> 1 | M9: =IF(M$4<='Get Started'!$E16,1,0)*M10 -> 1 | N9: =IF(N$4<='Get Started'!$E16,1,0)*N10 -> 1 | ... Z9: =IF(Z$4<='Get Started'!$E16,1,0)*Z10 -> 0
B10: ='Get Started'!B17 -> Fund Operations time period (years) | D10: sum | E10: =IF(D10="sum",SUM(G10:Z10),IF(D10="final",Z10,IF(D10="initial",G10,IF(D10="average",AVERAGE(G10:Z10),0)))) -> 10 | G10: =IF(G$4<='Get Started'!$E17,1,0) -> 1 | H10: =IF(H$4<='Get Started'!$E17,1,0) -> 1 | I10: =IF(I$4<='Get Started'!$E17,1,0) -> 1 | J10: =IF(J$4<='Get Started'!$E17,1,0) -> 1 | K10: =IF(K$4<='Get Started'!$E17,1,0) -> 1 | L10: =IF(L$4<='Get Started'!$E17,1,0) -> 1 | M10: =IF(M$4<='Get Started'!$E17,1,0) -> 1 | N10: =IF(N$4<='Get Started'!$E17,1,0) -> 1 | ... Z10: =IF(Z$4<='Get Started'!$E17,1,0) -> 0
B11: Proceeds Recycling period (years) | D11: sum | E11: =IF(D11="sum",SUM(G11:CH11),IF(D11="final",CH11,IF(D11="initial",G11,IF(D11="average",AVERAGE(G11:CH11),0)))) -> 4 | G11: =IF('Get Started'!$E29="new investments",G8,IF(G$4<='Get Started'!$E15,1,IF(AND(G$4<='Get Started'!$E15+2,'Get Started'!$F36<>0),1,0))) -> 1 | H11: =IF('Get Started'!$E29="new investments",H8,IF(H$4<='Get Started'!$E15,1,IF(AND(H$4<='Get Started'!$E15+1,'Get Started'!$F36<>0),1,0))) -> 1 | I11: =IF('Get Started'!$E29="new investments",I8,IF(I$4<='Get Started'!$E15,1,IF(AND(I$4<='Get Started'!$E15+1,'Get Started'!$F36<>0),1,0))) -> 1 | J11: =IF('Get Started'!$E29="new investments",J8,IF(J$4<='Get Started'!$E15,1,IF(AND(J$4<='Get Started'!$E15+1,'Get Started'!$F36<>0),1,0))) -> 1 | K11: =IF('Get Started'!$E29="new investments",K8,IF(K$4<='Get Started'!$E15,1,IF(AND(K$4<='Get Started'!$E15+1,'Get Started'!$F36<>0),1,0))) -> 0 | L11: =IF('Get Started'!$E29="new investments",L8,IF(L$4<='Get Started'!$E15,1,IF(AND(L$4<='Get Started'!$E15+1,'Get Started'!$F36<>0),1,0))) -> 0 | M11: =IF('Get Started'!$E29="new investments",M8,IF(M$4<='Get Started'!$E15,1,IF(AND(M$4<='Get Started'!$E15+1,'Get Started'!$F36<>0),1,0))) -> 0 | N11: =IF('Get Started'!$E29="new investments",N8,IF(N$4<='Get Started'!$E15,1,IF(AND(N$4<='Get Started'!$E15+1,'Get Started'!$F36<>0),1,0))) -> 0 | O11: =IF('Get Started'!$E29="new investments",O8,IF(O$4<='Get Started'!$E15,1,IF(AND(O$4<='Get Started'!$E15+1,'Get Started'!$F36<>0),1,0))) -> 0 | ... Z11: =IF('Get Started'!$E29="new investments",Z8,IF(Z$4<='Get Started'!$E15,1,IF(AND(Z$4<='Get Started'!$E15+1,'Get Started'!$F36<>0),1,0))) -> 0
B13: Inputs
B14: Management Fees | D14: sum | E14: =IF(D14="sum",SUM(G14:Z14),IF(D14="final",Z14,IF(D14="initial",G14,IF(D14="average",AVERAGE(G14:Z14),0)))) -> 0.2 | G14: =IF(G9=1,'Get Started'!$E13,0) -> 0.02 | H14: =IF(H9=1,'Get Started'!$E13,0) -> 0.02 | I14: =IF(I9=1,'Get Started'!$E13,0) -> 0.02 | J14: =IF(J9=1,'Get Started'!$E13,0) -> 0.02 | K14: =IF(K9=1,'Get Started'!$E13,0) -> 0.02 | L14: =IF(L9=1,'Get Started'!$E13,0) -> 0.02 | M14: =IF(M9=1,'Get Started'!$E13,0) -> 0.02 | N14: =IF(N9=1,'Get Started'!$E13,0) -> 0.02 | ... Z14: =IF(Z9=1,'Get Started'!$E13,0) -> 0
B15: ="Management Fees based on "&G15&" capital. Can change per period if method for calc changes." -> Management Fees based on committed capital. Can change per period if method for calc changes. | D15: sum | E15: =IF(D15="sum",SUM(G15:Z15),IF(D15="final",Z15,IF(D15="initial",G15,IF(D15="average",AVERAGE(G15:Z15),0)))) -> 0 | G15: committed | H15: =G15 -> committed | I15: =H15 -> committed | J15: =I15 -> committed | K15: =J15 -> committed | L15: =K15 -> committed | M15: =L15 -> committed | N15: =M15 -> committed | O15: =N15 -> committed | ... Z15: =Y15 -> committed
B16: GP Commit, excluded from LP capital. By default, GP commit is treated as an LP interest. Check the box to have the GP commit not treated as an LP investment. This will affect management fees (management fees will not be charged on the GP commit if it's not an LP interest, and it will change the waterfall so that GPs only get carried interest, and not carried interest + their share of distributions as an LP) | C16: FALSE | D16: sum | E16: =IF(D16="sum",SUM(G16:Z16),IF(D16="final",Z16,IF(D16="initial",G16,IF(D16="average",AVERAGE(G16:Z16),0)))) -> 0 | G16: =IF($C16=TRUE,G31*'Get Started'!$E10,0) -> 0 | H16: =IF($C16=TRUE,H31*'Get Started'!$E10,0) -> 0 | I16: =IF($C16=TRUE,I31*'Get Started'!$E10,0) -> 0 | J16: =IF($C16=TRUE,J31*'Get Started'!$E10,0) -> 0 | K16: =IF($C16=TRUE,K31*'Get Started'!$E10,0) -> 0 | L16: =IF($C16=TRUE,L31*'Get Started'!$E10,0) -> 0 | M16: =IF($C16=TRUE,M31*'Get Started'!$E10,0) -> 0 | N16: =IF($C16=TRUE,N31*'Get Started'!$E10,0) -> 0 | ... Z16: =IF($C16=TRUE,Z31*'Get Started'!$E10,0) -> 0
B17: GP Commit, excluded from management fees. Check the box to have the GP commit - capital contributed by the GP as LP capital and an ownership in the fund - excluded from calculation of management fees | C17: TRUE | D17: sum | E17: =IF(D17="sum",SUM(G17:Z17),IF(D17="final",Z17,IF(D17="initial",G17,IF(D17="average",AVERAGE(G17:Z17),0)))) -> 500000 | G17: =IF($C17=TRUE,G31*'Get Started'!$E10,0) -> 109550 | H17: =IF($C17=TRUE,H31*'Get Started'!$E10,0) -> 107550 | I17: =IF($C17=TRUE,I31*'Get Started'!$E10,0) -> 107550 | J17: =IF($C17=TRUE,J31*'Get Started'!$E10,0) -> 107550 | K17: =IF($C17=TRUE,K31*'Get Started'!$E10,0) -> 11300 | L17: =IF($C17=TRUE,L31*'Get Started'!$E10,0) -> 11300 | M17: =IF($C17=TRUE,M31*'Get Started'!$E10,0) -> 11300 | N17: =IF($C17=TRUE,N31*'Get Started'!$E10,0) -> 11300 | ... Z17: =IF($C17=TRUE,Z31*'Get Started'!$E10,0) -> 0
B18: GP Commit, covered via cashless contributions from management fees | C18: if management fees are used to cover for a GP Commit. Please discuss the implications of this with your tax advisor and fund admin if you choose this option | D18: final | E18: =IF(D18="sum",SUM(G18:CH18),IF(D18="final",CH18,IF(D18="initial",G18,IF(D18="average",AVERAGE(G18:CH18),0)))) -> 0 | G18: 0 | H18: =G18 -> 0 | I18: =H18 -> 0 | J18: =I18 -> 0 | K18: =J18 -> 0 | L18: =K18 -> 0 | M18: =L18 -> 0 | N18: =M18 -> 0 | O18: =N18 -> 0 | ... Z18: =Y18 -> 0
B19: Commited Capital, % of total fund committed per year | D19: sum | E19: =IF(D19="sum",SUM(G19:CH19),IF(D19="final",CH19,IF(D19="initial",G19,IF(D19="average",AVERAGE(G19:CH19),0)))) -> 1 | G19: 1 | H19: 0 | I19: 0 | J19: 0 | K19: 0 | L19: 0 | M19: 0 | N19: 0 | O19: 0 | P19: 0 | Q19: 0 | R19: 0 | S19: 0 | T19: 0 | U19: 0 | V19: 0 | W19: 0 | X19: 0 | Y19: 0 | Z19: 0
B20: Called Capital, % of total fund committed | C20: optional manual override to the automatically calculated called capital schedule, if you do not want to use the calculated schedule. this will not change your investment deployment, only your called capital and cash balances | D20: sum | E20: =IF(D20="sum",SUM(G20:EP20),IF(D20="final",EP20,IF(D20="initial",G20,IF(D20="average",AVERAGE(G20:EP20),0)))) -> 0 | G20: 0 | H20: 0 | I20: 0 | J20: 0 | K20: 0 | L20: 0 | M20: 0 | N20: 0 | O20: 0 | P20: 0 | Q20: 0 | R20: 0 | S20: 0 | T20: 0 | U20: 0 | V20: 0 | W20: 0 | X20: 0 | Y20: 0 | Z20: 0
B22: Capital, beginning of period | D22: initial | E22: =IF(D22="sum",SUM(G22:Z22),IF(D22="final",Z22,IF(D22="initial",G22,IF(D22="average",AVERAGE(G22:Z22),0)))) -> 0 | G22: =F28 -> 0 | H22: =G28 -> 0 | I22: =H28 -> 0 | J22: =I28 -> 0 | K22: =J28 -> 0 | L22: =K28 -> 0 | M22: =L28 -> 0 | N22: =M28 -> 0 | ... Z22: =Y28 -> 0
B23: Called Capital | D23: sum | E23: =IF(D23="sum",SUM(G23:Z23),IF(D23="final",Z23,IF(D23="initial",G23,IF(D23="average",AVERAGE(G23:Z23),0)))) -> 25000000 | G23: =G31 -> 5477500 | H23: =H31 -> 5377500 | I23: =I31 -> 5377500 | J23: =J31 -> 5377500 | K23: =K31 -> 565000 | L23: =L31 -> 565000 | M23: =M31 -> 565000 | N23: =N31 -> 565000 | ... Z23: =Z31 -> 0
B24: Proceeds | D24: sum | E24: =IF(D24="sum",SUM(G24:Z24),IF(D24="final",Z24,IF(D24="initial",G24,IF(D24="average",AVERAGE(G24:Z24),0)))) -> 80850000 | G24: =G43 -> 0 | H24: =H43 -> 0 | I24: =I43 -> 0 | J24: =J43 -> 1443750 | K24: =K43 -> 3850000 | L24: =L43 -> 3850000 | M24: =M43 -> 19538750 | N24: =N43 -> 18287500 | ... Z24: =Z43 -> 0
B25: Distributions + Carried Interest | D25: sum | E25: =IF(D25="sum",SUM(G25:Z25),IF(D25="final",Z25,IF(D25="initial",G25,IF(D25="average",AVERAGE(G25:Z25),0)))) -> -79887500 | G25: =SUM(G47,G46,G45)*-1 -> 0 | H25: =SUM(H47,H46,H45)*-1 -> 0 | I25: =SUM(I47,I46,I45)*-1 -> 0 | J25: =SUM(J47,J46,J45)*-1 -> -481250 | K25: =SUM(K47,K46,K45)*-1 -> -3850000 | L25: =SUM(L47,L46,L45)*-1 -> -3850000 | M25: =SUM(M47,M46,M45)*-1 -> -19538750 | N25: =SUM(N47,N46,N45)*-1 -> -18287500 | ... Z25: =SUM(Z47,Z46,Z45)*-1 -> 0
B26: Fees | D26: sum | E26: =IF(D26="sum",SUM(G26:Z26),IF(D26="final",Z26,IF(D26="initial",G26,IF(D26="average",AVERAGE(G26:Z26),0)))) -> -5750000 | G26: =SUM(G39,G40,G41)*-1 -> -665000 | H26: =SUM(H39,H40,H41)*-1 -> -565000 | I26: =SUM(I39,I40,I41)*-1 -> -565000 | J26: =SUM(J39,J40,J41)*-1 -> -565000 | K26: =SUM(K39,K40,K41)*-1 -> -565000 | L26: =SUM(L39,L40,L41)*-1 -> -565000 | M26: =SUM(M39,M40,M41)*-1 -> -565000 | N26: =SUM(N39,N40,N41)*-1 -> -565000 | ... Z26: =SUM(Z39,Z40,Z41)*-1 -> 0
B27: Investments | D27: sum | E27: =IF(D27="sum",SUM(G27:Z27),IF(D27="final",Z27,IF(D27="initial",G27,IF(D27="average",AVERAGE(G27:Z27),0)))) -> -20212500 | G27: =G38*-1 -> -4812500 | H27: =H38*-1 -> -4812500 | I27: =I38*-1 -> -4812500 | J27: =J38*-1 -> -5775000 | K27: =K38*-1 -> 0 | L27: =L38*-1 -> 0 | M27: =M38*-1 -> 0 | N27: =N38*-1 -> 0 | ... Z27: =Z38*-1 -> 0
B28: Capital, end of period | D28: final | E28: =IF(D28="sum",SUM(G28:Z28),IF(D28="final",Z28,IF(D28="initial",G28,IF(D28="average",AVERAGE(G28:Z28),0)))) -> 0 | G28: =SUM(G22:G27) -> 0 | H28: =SUM(H22:H27) -> 0 | I28: =SUM(I22:I27) -> 0 | J28: =SUM(J22:J27) -> 0 | K28: =SUM(K22:K27) -> 0 | L28: =SUM(L22:L27) -> 0 | M28: =SUM(M22:M27) -> 0 | N28: =SUM(N22:N27) -> 0 | ... Z28: =SUM(Z22:Z27) -> 0
B30: Committed Capital | D30: sum | E30: =IF(D30="sum",SUM(G30:Z30),IF(D30="final",Z30,IF(D30="initial",G30,IF(D30="average",AVERAGE(G30:Z30),0)))) -> 25000000 | G30: ='Get Started'!$E9*G19 -> 25000000 | H30: ='Get Started'!$E9*H19 -> 0 | I30: ='Get Started'!$E9*I19 -> 0 | J30: ='Get Started'!$E9*J19 -> 0 | K30: ='Get Started'!$E9*K19 -> 0 | L30: ='Get Started'!$E9*L19 -> 0 | M30: ='Get Started'!$E9*M19 -> 0 | N30: ='Get Started'!$E9*N19 -> 0 | ... Z30: ='Get Started'!$E9*Z19 -> 0
B31: Called Capital | D31: sum | E31: =IF(D31="sum",SUM(G31:CH31),IF(D31="final",CH31,IF(D31="initial",G31,IF(D31="average",AVERAGE(G31:CH31),0)))) -> 25000000 | G31: =IF($E20<>0,G20*$E30, MIN($E30-F60, MAX(0,G38+G39+G40+G41-G42))) -> 5477500 | H31: =IF($E20<>0,H20*$E30, MIN($E30-G60, MAX(0,H38+H39+H40+H41-H42))) -> 5377500 | I31: =IF($E20<>0,I20*$E30, MIN($E30-H60, MAX(0,I38+I39+I40+I41-I42))) -> 5377500 | J31: =IF($E20<>0,J20*$E30, MIN($E30-I60, MAX(0,J38+J39+J40+J41-J42))) -> 5377500 | K31: =IF($E20<>0,K20*$E30, MIN($E30-J60, MAX(0,K38+K39+K40+K41-K42))) -> 565000 | L31: =IF($E20<>0,L20*$E30, MIN($E30-K60, MAX(0,L38+L39+L40+L41-L42))) -> 565000 | M31: =IF($E20<>0,M20*$E30, MIN($E30-L60, MAX(0,M38+M39+M40+M41-M42))) -> 565000 | N31: =IF($E20<>0,N20*$E30, MIN($E30-M60, MAX(0,N38+N39+N40+N41-N42))) -> 565000 | ... Z31: =IF($E20<>0,Z20*$E30, MIN($E30-Y60, MAX(0,Z38+Z39+Z40+Z41-Z42))) -> 0
B32: Manual Investments | D32: sum | E32: =IF(D32="sum",SUM(G32:Z32),IF(D32="final",Z32,IF(D32="initial",G32,IF(D32="average",AVERAGE(G32:Z32),0)))) -> 0 | G32: 0 | H32: 0 | I32: 0 | J32: 0 | K32: 0 | L32: 0 | M32: 0 | N32: 0 | O32: 0 | P32: 0 | Q32: 0 | R32: 0 | S32: 0 | T32: 0 | U32: 0 | V32: 0 | W32: 0 | X32: 0 | Y32: 0 | Z32: 0
B33: New Investments | C33: if(G8=1,'Get Started'!$E56/'Get Started'!$E15*'Get Started'!$E36+G149*'Get Started'!$E36,0) | D33: sum | E33: =IF(D33="sum",SUM(G33:Z33),IF(D33="final",Z33,IF(D33="initial",G33,IF(D33="average",AVERAGE(G33:Z33),0)))) -> 20212500 | G33: =$E30*G161 -> 4812500 | H33: =$E30*H161 -> 4812500 | I33: =$E30*I161 -> 4812500 | J33: =$E30*J161 -> 5775000 | K33: =$E30*K161 -> 0 | L33: =$E30*L161 -> 0 | M33: =$E30*M161 -> 0 | N33: =$E30*N161 -> 0 | ... Z33: =$E30*Z161 -> 0
B34: Prorata Opportunities | D34: sum | E34: =IF(D34="sum",SUM(G34:Z34),IF(D34="final",Z34,IF(D34="initial",G34,IF(D34="average",AVERAGE(G34:Z34),0)))) -> 0 | G34: 0 | H34: 0 | I34: 0 | J34: 0 | K34: 0 | L34: 0 | M34: 0 | N34: 0 | O34: 0 | P34: 0 | Q34: 0 | R34: 0 | S34: 0 | T34: 0 | U34: 0 | V34: 0 | W34: 0 | X34: 0 | Y34: 0 | Z34: 0
B35: Reserves for Follow on | C35: change in reserves per period, increase in reserves when new investments are made, decrease when follow on are made or investments are written off | D35: sum | E35: =IF(D35="sum",SUM(G35:CH35),IF(D35="final",CH35,IF(D35="initial",G35,IF(D35="average",AVERAGE(G35:CH35),0)))) -> 0 | G35: 0 | H35: 0 | I35: 0 | J35: 0 | K35: 0 | L35: 0 | M35: 0 | N35: 0 | O35: 0 | P35: 0 | Q35: 0 | R35: 0 | S35: 0 | T35: 0 | U35: 0 | V35: 0 | W35: 0 | X35: 0 | Y35: 0 | Z35: 0
B36: Follow on Investments | C36: offset(G33,0,-1)*'Get Started'!$F36/'Get Started'!$E36 | D36: sum | E36: =IF(D36="sum",SUM(G36:Z36),IF(D36="final",Z36,IF(D36="initial",G36,IF(D36="average",AVERAGE(G36:Z36),0)))) -> 0 | G36: =$E30*G162 -> 0 | H36: =$E30*H162 -> 0 | I36: =$E30*I162 -> 0 | J36: =$E30*J162 -> 0 | K36: =$E30*K162 -> 0 | L36: =$E30*L162 -> 0 | M36: =$E30*M162 -> 0 | N36: =$E30*N162 -> 0 | ... Z36: =$E30*Z162 -> 0
B37: Total Investments, by cohort of New Investments | D37: sum | E37: =IF(D37="sum",SUM(G37:Z37),IF(D37="final",Z37,IF(D37="initial",G37,IF(D37="average",AVERAGE(G37:Z37),0)))) -> 20212500 | G37: =G33*'Get Started'!$F36/'Get Started'!$E36+G33+G32 -> 4812500 | H37: =H33*'Get Started'!$F36/'Get Started'!$E36+H33+H32 -> 4812500 | I37: =I33*'Get Started'!$F36/'Get Started'!$E36+I33+I32 -> 4812500 | J37: =J33*'Get Started'!$F36/'Get Started'!$E36+J33+J32 -> 5775000 | K37: =K33*'Get Started'!$F36/'Get Started'!$E36+K33+K32 -> 0 | L37: =L33*'Get Started'!$F36/'Get Started'!$E36+L33+L32 -> 0 | M37: =M33*'Get Started'!$F36/'Get Started'!$E36+M33+M32 -> 0 | N37: =N33*'Get Started'!$F36/'Get Started'!$E36+N33+N32 -> 0 | ... Z37: =Z33*'Get Started'!$F36/'Get Started'!$E36+Z33+Z32 -> 0
B38: Total Investments | D38: sum | E38: =IF(D38="sum",SUM(G38:Z38),IF(D38="final",Z38,IF(D38="initial",G38,IF(D38="average",AVERAGE(G38:Z38),0)))) -> 20212500 | G38: =SUM(G33,G36,G32) -> 4812500 | H38: =SUM(H33,H36,H32) -> 4812500 | I38: =SUM(I33,I36,I32) -> 4812500 | J38: =SUM(J33,J36,J32) -> 5775000 | K38: =SUM(K33,K36,K32) -> 0 | L38: =SUM(L33,L36,L32) -> 0 | M38: =SUM(M33,M36,M32) -> 0 | N38: =SUM(N33,N36,N32) -> 0 | ... Z38: =SUM(Z33,Z36,Z32) -> 0
B39: Organizational Expenses | D39: sum | E39: =IF(D39="sum",SUM(G39:Z39),IF(D39="final",Z39,IF(D39="initial",G39,IF(D39="average",AVERAGE(G39:Z39),0)))) -> 100000 | G39: =IF(G4=1,'Get Started'!$E11,0) -> 100000 | H39: =IF(H4=1,'Get Started'!$E11,0) -> 0 | I39: =IF(I4=1,'Get Started'!$E11,0) -> 0 | J39: =IF(J4=1,'Get Started'!$E11,0) -> 0 | K39: =IF(K4=1,'Get Started'!$E11,0) -> 0 | L39: =IF(L4=1,'Get Started'!$E11,0) -> 0 | M39: =IF(M4=1,'Get Started'!$E11,0) -> 0 | N39: =IF(N4=1,'Get Started'!$E11,0) -> 0 | ... Z39: =IF(Z4=1,'Get Started'!$E11,0) -> 0
B40: Operational Expenses | D40: sum | E40: =IF(D40="sum",SUM(G40:Z40),IF(D40="final",Z40,IF(D40="initial",G40,IF(D40="average",AVERAGE(G40:Z40),0)))) -> 750000 | G40: ='Get Started'!$E12*G10 -> 75000 | H40: ='Get Started'!$E12*H10 -> 75000 | I40: ='Get Started'!$E12*I10 -> 75000 | J40: ='Get Started'!$E12*J10 -> 75000 | K40: ='Get Started'!$E12*K10 -> 75000 | L40: ='Get Started'!$E12*L10 -> 75000 | M40: ='Get Started'!$E12*M10 -> 75000 | N40: ='Get Started'!$E12*N10 -> 75000 | ... Z40: ='Get Started'!$E12*Z10 -> 0
B41: Management Fees | C41: if(H15="called",$E30*H159,H14*(H85+G85)/2*if($C17=true,1-'Get Started'!$E10,1)) | D41: sum | E41: =IF(D41="sum",SUM(G41:Z41),IF(D41="final",Z41,IF(D41="initial",G41,IF(D41="average",AVERAGE(G41:Z41),0)))) -> 4900000 | G41: =IFERROR(IF(G15="committed",G83*IF($C17=TRUE,1-'Get Started'!$E10,1)*G14+IF(AND(G4<>1,G54*IF($C17=TRUE,1-'Get Started'!$E10,1)<>0,SUM($G54:G54)*IF($C17=TRUE,1-'Get Started'!$E10,1)=$E54*IF($C17=TRUE,1-'Get Started'!$E10,1)),G54*IF($C17=TRUE,1-'Get Started'!$E10,1)*(G4-1)*G14,0),IF(G15="called",G59*G159 + IF(AND(G4<>1,G54*IF($C17=TRUE,1-'Get Started'!$E10,1)<>0, SUM($G54:G54)*IF($C17=TRUE,1-'Get Started'!$E10,1)<>$E54*IF($C17=TRUE,1-'Get Started'!$E10,1) ),G59*SUM(F159:G159)-G59*G159-SUM(F41:$G41),0),G59*G159 + IF(AND(G4<>1,G54*IF($C17=TRUE,1-'Get Started'!$E10,1)<>0, SUM($G54:G54)*IF($C17=TRUE,1-'Get Started'!$E10,1)=$E54*IF($C17=TRUE,1-'Get Started'!$E10,1) ),G59*SUM(F159:G159)-G59*G159-SUM(F41:$G41),0))),0) -> 490000 | H41: =IFERROR(IF(H15="committed",H83*IF($C17=TRUE,1-'Get Started'!$E10,1)*H14+IF(AND(H4<>1,H54*IF($C17=TRUE,1-'Get Started'!$E10,1)<>0,SUM($G54:H54)*IF($C17=TRUE,1-'Get Started'!$E10,1)=$E54*IF($C17=TRUE,1-'Get Started'!$E10,1)),H54*IF($C17=TRUE,1-'Get Started'!$E10,1)*(H4-1)*H14,0),IF(H15="called",H59*H159 + IF(AND(H4<>1,H54*IF($C17=TRUE,1-'Get Started'!$E10,1)<>0, SUM($G54:H54)*IF($C17=TRUE,1-'Get Started'!$E10,1)<>$E54*IF($C17=TRUE,1-'Get Started'!$E10,1) ),H59*SUM(G159:H159)-H59*H159-SUM(G41:$G41),0),H59*H159 + IF(AND(H4<>1,H54*IF($C17=TRUE,1-'Get Started'!$E10,1)<>0, SUM($G54:H54)*IF($C17=TRUE,1-'Get Started'!$E10,1)=$E54*IF($C17=TRUE,1-'Get Started'!$E10,1) ),H59*SUM(G159:H159)-H59*H159-SUM(G41:$G41),0))),0) -> 490000 | I41: =IFERROR(IF(I15="committed",I83*IF($C17=TRUE,1-'Get Started'!$E10,1)*I14+IF(AND(I4<>1,I54*IF($C17=TRUE,1-'Get Started'!$E10,1)<>0,SUM($G54:I54)*IF($C17=TRUE,1-'Get Started'!$E10,1)=$E54*IF($C17=TRUE,1-'Get Started'!$E10,1)),I54*IF($C17=TRUE,1-'Get Started'!$E10,1)*(I4-1)*I14,0),IF(I15="called",I59*I159 + IF(AND(I4<>1,I54*IF($C17=TRUE,1-'Get Started'!$E10,1)<>0, SUM($G54:I54)*IF($C17=TRUE,1-'Get Started'!$E10,1)<>$E54*IF($C17=TRUE,1-'Get Started'!$E10,1) ),I59*SUM(H159:I159)-I59*I159-SUM($G41:H41),0),I59*I159 + IF(AND(I4<>1,I54*IF($C17=TRUE,1-'Get Started'!$E10,1)<>0, SUM($G54:I54)*IF($C17=TRUE,1-'Get Started'!$E10,1)=$E54*IF($C17=TRUE,1-'Get Started'!$E10,1) ),I59*SUM(H159:I159)-I59*I159-SUM($G41:H41),0))),0) -> 490000 | J41: =IFERROR(IF(J15="committed",J83*IF($C17=TRUE,1-'Get Started'!$E10,1)*J14+IF(AND(J4<>1,J54*IF($C17=TRUE,1-'Get Started'!$E10,1)<>0,SUM($G54:J54)*IF($C17=TRUE,1-'Get Started'!$E10,1)=$E54*IF($C17=TRUE,1-'Get Started'!$E10,1)),J54*IF($C17=TRUE,1-'Get Started'!$E10,1)*(J4-1)*J14,0),IF(J15="called",J59*J159 + IF(AND(J4<>1,J54*IF($C17=TRUE,1-'Get Started'!$E10,1)<>0, SUM($G54:J54)*IF($C17=TRUE,1-'Get Started'!$E10,1)<>$E54*IF($C17=TRUE,1-'Get Started'!$E10,1) ),J59*SUM(I159:J159)-J59*J159-SUM($G41:I41),0),J59*J159 + IF(AND(J4<>1,J54*IF($C17=TRUE,1-'Get Started'!$E10,1)<>0, SUM($G54:J54)*IF($C17=TRUE,1-'Get Started'!$E10,1)=$E54*IF($C17=TRUE,1-'Get Started'!$E10,1) ),J59*SUM(I159:J159)-J59*J159-SUM($G41:I41),0))),0) -> 490000 | K41: =IFERROR(IF(K15="committed",K83*IF($C17=TRUE,1-'Get Started'!$E10,1)*K14+IF(AND(K4<>1,K54*IF($C17=TRUE,1-'Get Started'!$E10,1)<>0,SUM($G54:K54)*IF($C17=TRUE,1-'Get Started'!$E10,1)=$E54*IF($C17=TRUE,1-'Get Started'!$E10,1)),K54*IF($C17=TRUE,1-'Get Started'!$E10,1)*(K4-1)*K14,0),IF(K15="called",K59*K159 + IF(AND(K4<>1,K54*IF($C17=TRUE,1-'Get Started'!$E10,1)<>0, SUM($G54:K54)*IF($C17=TRUE,1-'Get Started'!$E10,1)<>$E54*IF($C17=TRUE,1-'Get Started'!$E10,1) ),K59*SUM(J159:K159)-K59*K159-SUM($G41:J41),0),K59*K159 + IF(AND(K4<>1,K54*IF($C17=TRUE,1-'Get Started'!$E10,1)<>0, SUM($G54:K54)*IF($C17=TRUE,1-'Get Started'!$E10,1)=$E54*IF($C17=TRUE,1-'Get Started'!$E10,1) ),K59*SUM(J159:K159)-K59*K159-SUM($G41:J41),0))),0) -> 490000 | L41: =IFERROR(IF(L15="committed",L83*IF($C17=TRUE,1-'Get Started'!$E10,1)*L14+IF(AND(L4<>1,L54*IF($C17=TRUE,1-'Get Started'!$E10,1)<>0,SUM($G54:L54)*IF($C17=TRUE,1-'Get Started'!$E10,1)=$E54*IF($C17=TRUE,1-'Get Started'!$E10,1)),L54*IF($C17=TRUE,1-'Get Started'!$E10,1)*(L4-1)*L14,0),IF(L15="called",L59*L159 + IF(AND(L4<>1,L54*IF($C17=TRUE,1-'Get Started'!$E10,1)<>0, SUM($G54:L54)*IF($C17=TRUE,1-'Get Started'!$E10,1)<>$E54*IF($C17=TRUE,1-'Get Started'!$E10,1) ),L59*SUM(K159:L159)-L59*L159-SUM($G41:K41),0),L59*L159 + IF(AND(L4<>1,L54*IF($C17=TRUE,1-'Get Started'!$E10,1)<>0, SUM($G54:L54)*IF($C17=TRUE,1-'Get Started'!$E10,1)=$E54*IF($C17=TRUE,1-'Get Started'!$E10,1) ),L59*SUM(K159:L159)-L59*L159-SUM($G41:K41),0))),0) -> 490000 | M41: =IFERROR(IF(M15="committed",M83*IF($C17=TRUE,1-'Get Started'!$E10,1)*M14+IF(AND(M4<>1,M54*IF($C17=TRUE,1-'Get Started'!$E10,1)<>0,SUM($G54:M54)*IF($C17=TRUE,1-'Get Started'!$E10,1)=$E54*IF($C17=TRUE,1-'Get Started'!$E10,1)),M54*IF($C17=TRUE,1-'Get Started'!$E10,1)*(M4-1)*M14,0),IF(M15="called",M59*M159 + IF(AND(M4<>1,M54*IF($C17=TRUE,1-'Get Started'!$E10,1)<>0, SUM($G54:M54)*IF($C17=TRUE,1-'Get Started'!$E10,1)<>$E54*IF($C17=TRUE,1-'Get Started'!$E10,1) ),M59*SUM(L159:M159)-M59*M159-SUM($G41:L41),0),M59*M159 + IF(AND(M4<>1,M54*IF($C17=TRUE,1-'Get Started'!$E10,1)<>0, SUM($G54:M54)*IF($C17=TRUE,1-'Get Started'!$E10,1)=$E54*IF($C17=TRUE,1-'Get Started'!$E10,1) ),M59*SUM(L159:M159)-M59*M159-SUM($G41:L41),0))),0) -> 490000 | N41: =IFERROR(IF(N15="committed",N83*IF($C17=TRUE,1-'Get Started'!$E10,1)*N14+IF(AND(N4<>1,N54*IF($C17=TRUE,1-'Get Started'!$E10,1)<>0,SUM($G54:N54)*IF($C17=TRUE,1-'Get Started'!$E10,1)=$E54*IF($C17=TRUE,1-'Get Started'!$E10,1)),N54*IF($C17=TRUE,1-'Get Started'!$E10,1)*(N4-1)*N14,0),IF(N15="called",N59*N159 + IF(AND(N4<>1,N54*IF($C17=TRUE,1-'Get Started'!$E10,1)<>0, SUM($G54:N54)*IF($C17=TRUE,1-'Get Started'!$E10,1)<>$E54*IF($C17=TRUE,1-'Get Started'!$E10,1) ),N59*SUM(M159:N159)-N59*N159-SUM($G41:M41),0),N59*N159 + IF(AND(N4<>1,N54*IF($C17=TRUE,1-'Get Started'!$E10,1)<>0, SUM($G54:N54)*IF($C17=TRUE,1-'Get Started'!$E10,1)=$E54*IF($C17=TRUE,1-'Get Started'!$E10,1) ),N59*SUM(M159:N159)-N59*N159-SUM($G41:M41),0))),0) -> 490000 | O41: =IFERROR(IF(O15="committed",O83*IF($C17=TRUE,1-'Get Started'!$E10,1)*O14+IF(AND(O4<>1,O54*IF($C17=TRUE,1-'Get Started'!$E10,1)<>0,SUM($G54:O54)*IF($C17=TRUE,1-'Get Started'!$E10,1)=$E54*IF($C17=TRUE,1-'Get Started'!$E10,1)),O54*IF($C17=TRUE,1-'Get Started'!$E10,1)*(O4-1)*O14,0),IF(O15="called",O59*O159 + IF(AND(O4<>1,O54*IF($C17=TRUE,1-'Get Started'!$E10,1)<>0, SUM($G54:O54)*IF($C17=TRUE,1-'Get Started'!$E10,1)<>$E54*IF($C17=TRUE,1-'Get Started'!$E10,1) ),O59*SUM(N159:O159)-O59*O159-SUM($G41:N41),0),O59*O159 + IF(AND(O4<>1,O54*IF($C17=TRUE,1-'Get Started'!$E10,1)<>0, SUM($G54:O54)*IF($C17=TRUE,1-'Get Started'!$E10,1)=$E54*IF($C17=TRUE,1-'Get Started'!$E10,1) ),O59*SUM(N159:O159)-O59*O159-SUM($G41:N41),0))),0) -> 490000 | P41: =IFERROR(IF(P15="committed",P83*IF($C17=TRUE,1-'Get Started'!$E10,1)*P14+IF(AND(P4<>1,P54*IF($C17=TRUE,1-'Get Started'!$E10,1)<>0,SUM($G54:P54)*IF($C17=TRUE,1-'Get Started'!$E10,1)=$E54*IF($C17=TRUE,1-'Get Started'!$E10,1)),P54*IF($C17=TRUE,1-'Get Started'!$E10,1)*(P4-1)*P14,0),IF(P15="called",P59*P159 + IF(AND(P4<>1,P54*IF($C17=TRUE,1-'Get Started'!$E10,1)<>0, SUM($G54:P54)*IF($C17=TRUE,1-'Get Started'!$E10,1)<>$E54*IF($C17=TRUE,1-'Get Started'!$E10,1) ),P59*SUM(O159:P159)-P59*P159-SUM($G41:O41),0),P59*P159 + IF(AND(P4<>1,P54*IF($C17=TRUE,1-'Get Started'!$E10,1)<>0, SUM($G54:P54)*IF($C17=TRUE,1-'Get Started'!$E10,1)=$E54*IF($C17=TRUE,1-'Get Started'!$E10,1) ),P59*SUM(O159:P159)-P59*P159-SUM($G41:O41),0))),0) -> 490000 | ... Z41: =IFERROR(IF(Z15="committed",Z83*IF($C17=TRUE,1-'Get Started'!$E10,1)*Z14+IF(AND(Z4<>1,Z54*IF($C17=TRUE,1-'Get Started'!$E10,1)<>0,SUM($G54:Z54)*IF($C17=TRUE,1-'Get Started'!$E10,1)=$E54*IF($C17=TRUE,1-'Get Started'!$E10,1)),Z54*IF($C17=TRUE,1-'Get Started'!$E10,1)*(Z4-1)*Z14,0),IF(Z15="called",Z59*Z159 + IF(AND(Z4<>1,Z54*IF($C17=TRUE,1-'Get Started'!$E10,1)<>0, SUM($G54:Z54)*IF($C17=TRUE,1-'Get Started'!$E10,1)<>$E54*IF($C17=TRUE,1-'Get Started'!$E10,1) ),Z59*SUM(Y159:Z159)-Z59*Z159-SUM($G41:Y41),0),Z59*Z159 + IF(AND(Z4<>1,Z54*IF($C17=TRUE,1-'Get Started'!$E10,1)<>0, SUM($G54:Z54)*IF($C17=TRUE,1-'Get Started'!$E10,1)=$E54*IF($C17=TRUE,1-'Get Started'!$E10,1) ),Z59*SUM(Y159:Z159)-Z59*Z159-SUM($G41:Y41),0))),0) -> 0
B42: Recycled Capital | D42: sum | E42: =IF(D42="sum",SUM(G42:Z42),IF(D42="final",Z42,IF(D42="initial",G42,IF(D42="average",AVERAGE(G42:Z42),0)))) -> 962500 | G42: =G149 -> 0 | H42: =H149 -> 0 | I42: =I149 -> 0 | J42: =J149 -> 962500 | K42: =K149 -> 0 | L42: =L149 -> 0 | M42: =M149 -> 0 | N42: =N149 -> 0 | ... Z42: =Z149 -> 0
B43: Proceeds | D43: sum | E43: =IF(D43="sum",SUM(G43:Z43),IF(D43="final",Z43,IF(D43="initial",G43,IF(D43="average",AVERAGE(G43:Z43),0)))) -> 80850000 | G43: =IF(G4<'Get Started'!$H48,0,OFFSET(G37,0,-1*'Get Started'!$H48)*'Get Started'!$E48*'Get Started'!$G48)+IF(G4<'Get Started'!$H47,0,OFFSET(G37,0,-1*'Get Started'!$H47)*'Get Started'!$E47*'Get Started'!$G47)+IF(G4<'Get Started'!$H46,0,OFFSET(G37,0,-1*'Get Started'!$H46)*'Get Started'!$E46*'Get Started'!$G46)+IF(G4<'Get Started'!$H45,0,OFFSET(G37,0,-1*'Get Started'!$H45)*'Get Started'!$E45*'Get Started'!$G45) -> 0 | H43: =IF(H4<'Get Started'!$H48,0,OFFSET(H37,0,-1*'Get Started'!$H48)*'Get Started'!$E48*'Get Started'!$G48)+IF(H4<'Get Started'!$H47,0,OFFSET(H37,0,-1*'Get Started'!$H47)*'Get Started'!$E47*'Get Started'!$G47)+IF(H4<'Get Started'!$H46,0,OFFSET(H37,0,-1*'Get Started'!$H46)*'Get Started'!$E46*'Get Started'!$G46)+IF(H4<'Get Started'!$H45,0,OFFSET(H37,0,-1*'Get Started'!$H45)*'Get Started'!$E45*'Get Started'!$G45) -> 0 | I43: =IF(I4<'Get Started'!$H48,0,OFFSET(I37,0,-1*'Get Started'!$H48)*'Get Started'!$E48*'Get Started'!$G48)+IF(I4<'Get Started'!$H47,0,OFFSET(I37,0,-1*'Get Started'!$H47)*'Get Started'!$E47*'Get Started'!$G47)+IF(I4<'Get Started'!$H46,0,OFFSET(I37,0,-1*'Get Started'!$H46)*'Get Started'!$E46*'Get Started'!$G46)+IF(I4<'Get Started'!$H45,0,OFFSET(I37,0,-1*'Get Started'!$H45)*'Get Started'!$E45*'Get Started'!$G45) -> 0 | J43: =IF(J4<'Get Started'!$H48,0,OFFSET(J37,0,-1*'Get Started'!$H48)*'Get Started'!$E48*'Get Started'!$G48)+IF(J4<'Get Started'!$H47,0,OFFSET(J37,0,-1*'Get Started'!$H47)*'Get Started'!$E47*'Get Started'!$G47)+IF(J4<'Get Started'!$H46,0,OFFSET(J37,0,-1*'Get Started'!$H46)*'Get Started'!$E46*'Get Started'!$G46)+IF(J4<'Get Started'!$H45,0,OFFSET(J37,0,-1*'Get Started'!$H45)*'Get Started'!$E45*'Get Started'!$G45) -> 1443750 | K43: =IF(K4<'Get Started'!$H48,0,OFFSET(K37,0,-1*'Get Started'!$H48)*'Get Started'!$E48*'Get Started'!$G48)+IF(K4<'Get Started'!$H47,0,OFFSET(K37,0,-1*'Get Started'!$H47)*'Get Started'!$E47*'Get Started'!$G47)+IF(K4<'Get Started'!$H46,0,OFFSET(K37,0,-1*'Get Started'!$H46)*'Get Started'!$E46*'Get Started'!$G46)+IF(K4<'Get Started'!$H45,0,OFFSET(K37,0,-1*'Get Started'!$H45)*'Get Started'!$E45*'Get Started'!$G45) -> 3850000 | L43: =IF(L4<'Get Started'!$H48,0,OFFSET(L37,0,-1*'Get Started'!$H48)*'Get Started'!$E48*'Get Started'!$G48)+IF(L4<'Get Started'!$H47,0,OFFSET(L37,0,-1*'Get Started'!$H47)*'Get Started'!$E47*'Get Started'!$G47)+IF(L4<'Get Started'!$H46,0,OFFSET(L37,0,-1*'Get Started'!$H46)*'Get Started'!$E46*'Get Started'!$G46)+IF(L4<'Get Started'!$H45,0,OFFSET(L37,0,-1*'Get Started'!$H45)*'Get Started'!$E45*'Get Started'!$G45) -> 3850000 | M43: =IF(M4<'Get Started'!$H48,0,OFFSET(M37,0,-1*'Get Started'!$H48)*'Get Started'!$E48*'Get Started'!$G48)+IF(M4<'Get Started'!$H47,0,OFFSET(M37,0,-1*'Get Started'!$H47)*'Get Started'!$E47*'Get Started'!$G47)+IF(M4<'Get Started'!$H46,0,OFFSET(M37,0,-1*'Get Started'!$H46)*'Get Started'!$E46*'Get Started'!$G46)+IF(M4<'Get Started'!$H45,0,OFFSET(M37,0,-1*'Get Started'!$H45)*'Get Started'!$E45*'Get Started'!$G45) -> 19538750 | N43: =IF(N4<'Get Started'!$H48,0,OFFSET(N37,0,-1*'Get Started'!$H48)*'Get Started'!$E48*'Get Started'!$G48)+IF(N4<'Get Started'!$H47,0,OFFSET(N37,0,-1*'Get Started'!$H47)*'Get Started'!$E47*'Get Started'!$G47)+IF(N4<'Get Started'!$H46,0,OFFSET(N37,0,-1*'Get Started'!$H46)*'Get Started'!$E46*'Get Started'!$G46)+IF(N4<'Get Started'!$H45,0,OFFSET(N37,0,-1*'Get Started'!$H45)*'Get Started'!$E45*'Get Started'!$G45) -> 18287500 | ... Z43: =IF(Z4<'Get Started'!$H48,0,OFFSET(Z37,0,-1*'Get Started'!$H48)*'Get Started'!$E48*'Get Started'!$G48)+IF(Z4<'Get Started'!$H47,0,OFFSET(Z37,0,-1*'Get Started'!$H47)*'Get Started'!$E47*'Get Started'!$G47)+IF(Z4<'Get Started'!$H46,0,OFFSET(Z37,0,-1*'Get Started'!$H46)*'Get Started'!$E46*'Get Started'!$G46)+IF(Z4<'Get Started'!$H45,0,OFFSET(Z37,0,-1*'Get Started'!$H45)*'Get Started'!$E45*'Get Started'!$G45) -> 0
B44: Preferred Return | D44: sum | E44: =IF(D44="sum",SUM(G44:Z44),IF(D44="final",Z44,IF(D44="initial",G44,IF(D44="average",AVERAGE(G44:Z44),0)))) -> 0 | G44: 0 | H44: 0 | I44: 0 | J44: 0 | K44: 0 | L44: 0 | M44: 0 | N44: 0 | O44: 0 | P44: 0 | Q44: 0 | R44: 0 | S44: 0 | T44: 0 | U44: 0 | V44: 0 | W44: 0 | X44: 0 | Y44: 0 | Z44: 0
B45: GP Catchup | D45: sum | E45: =IF(D45="sum",SUM(G45:Z45),IF(D45="final",Z45,IF(D45="initial",G45,IF(D45="average",AVERAGE(G45:Z45),0)))) -> 0 | G45: 0 | H45: 0 | I45: 0 | J45: 0 | K45: 0 | L45: 0 | M45: 0 | N45: 0 | O45: 0 | P45: 0 | Q45: 0 | R45: 0 | S45: 0 | T45: 0 | U45: 0 | V45: 0 | W45: 0 | X45: 0 | Y45: 0 | Z45: 0
B46: Carried Interest | D46: sum | E46: =IF(D46="sum",SUM(G46:Z46),IF(D46="final",Z46,IF(D46="initial",G46,IF(D46="average",AVERAGE(G46:Z46),0)))) -> 10977500 | G46: =G135 -> 0 | H46: =H135 -> 0 | I46: =I135 -> 0 | J46: =J135 -> 0 | K46: =K135 -> 0 | L46: =L135 -> 0 | M46: =M135 -> 1067809.5 | N46: =N135 -> 3395595.2 | ... Z46: =Z135 -> 0
...

Sheet Resources
B2: Resources and Templates
B3: Every tool and template has its own rationale and goals, almost all share the same goal, to help emerging managers and entrepreneurs understand how the economics for venture funds work.
B5: Name | C5: Key Attributes | D5: Link
B7: How to Model a Venture Capital Fund | C7: Post detailing how to model a venture capital fund, detailing all the components, methods, considerations, and links to template models to review | D7: https://openvc.app/blog/how-to-model-a-venture-capital-fund
B8: Portfolio Construction for Dummies, by Hadley Harris (Eniac Ventures) | C8: Free Excel and Google Sheets Model and explanations on how to model a venture fund | D8: https://eniacvc.medium.com/seed-fund-portfolio-construction-for-dummies-9ec5b4d152dc
B9: Tactyc Venture Manager | C9: Web app to build, manage and strategize venture portfolio models | D9: https://vc.tactyc.io/
B10: Venture Fund Model, by Craig Thomas | C10: Free model in Causal for modeling portfolio construction | D10: https://my.causal.app/models/7140
B11: Open Source Venture Model (V1), by Sam Gerstenzang | C11: Google Sheet, open source, helpful for understanding how follow-on dynamics work in modeling and planning for reserves. | D11: https://medium.com/@gerstenzang/open-source-venture-model-osvm-v1-55bebf3eda9
B12: Airstream Alpha | C12: Fund budget template from a fund CFO firm (submit email to access) | D12: https://airstreamalpha.com/financial-model/
B13: Venture Capital Starter Model, by Foresight | C13: Free Google Sheet (can download to Excel) for forecasting a venture fund, including basic fund performance metrics. Calculates at an overall portfolio level (does not model cashflows over time) | D13: https://foresight.is/vc
B14: Venture Capital Starter Model, by Foresight | C14: Simple, free model in Causal to show overall returns based on fund size, follow-on reserves, and fees. | D14: https://foresight.is/vc
B15: Venture Capital Model, Annual Forecast, by Foresight | C15: Free Google Sheet (can download to Excel) for forecasting a venture fund, including all fund performance metrics, showing annual cashflows over time. | D15: https://foresight.is/vc
B16: Venture Capital Model, Annual Forecast, by Foresight (Causal) | C16: Free Causal model for forecasting a venture fund, including all fund performance metrics, showing annual cashflows over time. | D16: https://foresight.is/vc
B17: Venture Fund Model, Quarterly Forecast, by Foresight | C17: $$ Excel and Google Sheets model to use in detailing cash flows and presenting to LPs in fundraising. Used by hundreds of emerging managers to raise funds. Includes financial statements for the fund, full forecast and statements for the management company, done on a quarterly timescale. | D17: https://foresight.is/venture-fund-model
... B26: Venture Capital Method (Valuation) | C26: Examples of how to use the Venture Capital Method for valuation, free Google Sheets | D26: https://vcmethod.com/

Sheet Model Comparison
B2: Foresight Template Comparison
B3: I offer a range of templates for venture funds and angels. Here's a breakdown of the models and how they compare.
B5: Template | C5: Link | D5: Software | E5: Price | F5: Overall Portfolio Forecast | G5: Annual Portfolio Forecast | H5: Quarterly Portfolio Forecast | I5: Fund Performance Metrics | J5: Portfolio Construction | K5: Scenarios | L5: Financial Statements | M5: Track Actual Investments | N5: Budget v. Actuals, and rolling Forecast | O5: Multi-tiered Carried Interest | P5: Preferred Return (and GP Catchup) | Q5: Rolling Funds | R5: Individual Investment Evaluation | S5: Venture Studios | T5: Management Company Budgeting | U5: Fund-of-Funds
B7: Venture Capital Model, Overall Portfolio, by Foresight | C7: https://foresight.is/venture-fund-model-overall/ | D7: Google Sheets, download to Excel, Causal | E7: Free | F7: TRUE | G7: FALSE | H7: FALSE | I7: TRUE | J7: FALSE | K7: FALSE | L7: FALSE | M7: FALSE | N7: FALSE | O7: FALSE | P7: FALSE | Q7: FALSE | R7: FALSE | S7: FALSE | T7: FALSE | U7: FALSE
B8: Venture Capital Model, Annual Forecast, by Foresight | C8: https://foresight.is/venture-fund-model-annual/ | D8: Google Sheets, download to Excel, Causal | E8: Free, Suggested Donation | F8: TRUE | G8: TRUE | H8: FALSE | I8: TRUE | J8: FALSE | K8: FALSE | L8: FALSE | M8: FALSE | N8: FALSE | O8: FALSE | P8: FALSE | Q8: FALSE | R8: FALSE | S8: FALSE | T8: FALSE | U8: FALSE
B9: Venture Capital Model, Quarterly Forecast, by Foresight | C9: https://foresight.is/venture-fund-model-quarterly/ | D9: Google Sheets, download to Excel, Causal | E9: Free, Suggested Donation | F9: TRUE | G9: TRUE | H9: FALSE | I9: TRUE | J9: TRUE | K9: TRUE | L9: FALSE | M9: FALSE | N9: FALSE | O9: FALSE | P9: FALSE | Q9: FALSE | R9: FALSE | S9: FALSE | T9: FALSE | U9: FALSE
B10: Venture Capital Model, Manual Investment Input, by Foresight | C10: https://foresight.is/venture-fund-model-portfolio/ | D10: Google Sheets, download to Excel | E10: Free, Suggested Donation | F10: TRUE | G10: TRUE | H10: FALSE | I10: TRUE | J10: TRUE | K10: FALSE | L10: FALSE | M10: FALSE | N10: FALSE | O10: FALSE | P10: FALSE | Q10: FALSE | R10: FALSE | S10: FALSE | T10: FALSE | U10: FALSE
B11: Venture Studio Model, Annual Forecast, by Foresight | C11: https://foresight.is/venture-studio-model | D11: Google Sheets, download to Excel | E11: Free, Suggested Donation | F11: TRUE | G11: TRUE | H11: FALSE | I11: TRUE | J11: TRUE | K11: FALSE | L11: FALSE | M11: FALSE | N11: FALSE | O11: FALSE | P11: FALSE | Q11: FALSE | R11: FALSE | S11: TRUE | T11: TRUE | U11: FALSE
B12: Venture Capital Model, Average Cap Table | C12: https://foresight.is/venture-fund-model-detailed/ | D12: Google Sheets, download to Excel | E12: $74 USD | F12: TRUE | G12: TRUE | H12: FALSE | I12: TRUE | J12: TRUE | K12: TRUE | L12: FALSE | M12: FALSE | N12: FALSE | O12: FALSE | P12: FALSE | Q12: FALSE | R12: FALSE | S12: FALSE | T12: TRUE | U12: FALSE
B13: Venture Investor Model, by Foresight | C13: https://foresight.is/venture-fund-model | D13: Google Sheets, download to Excel | E13: $349 USD | F13: TRUE | G13: TRUE | H13: TRUE | I13: TRUE | J13: TRUE | K13: FALSE | L13: TRUE | M13: FALSE | N13: FALSE | O13: TRUE | P13: TRUE | Q13: FALSE | R13: FALSE | S13: FALSE | T13: TRUE | U13: FALSE
B14: Angel and Venture Fund Portfolio Tracking, by Foresight | C14: https://foresight.is/venture-portfolio-model/ | D14: Google Sheets, download to Excel | E14: Free, Suggested Donation | F14: TRUE | G14: FALSE | H14: FALSE | I14: TRUE | J14: FALSE | K14: FALSE | L14: FALSE | M14: TRUE | N14: FALSE | O14: FALSE | P14: FALSE | Q14: FALSE | R14: FALSE | S14: FALSE | T14: FALSE | U14: FALSE
B15: Fund of Venture Funds | C15: https://foresight.is/fund-of-funds/ | D15: Google Sheets, download to Excel | E15: Free, Suggested Donation | F15: TRUE | G15: TRUE | H15: FALSE | I15: TRUE | J15: TRUE | K15: FALSE | L15: FALSE | M15: FALSE | N15: FALSE | O15: FALSE | P15: FALSE | Q15: FALSE | R15: FALSE | S15: FALSE | T15: FALSE | U15: TRUE
B16: Rolling Fund Template, by Foresight | C16: https://foresight.is/rolling-fund-template/ | D16: Google Sheets, download to Excel | E16: Free, Suggested Donation | F16: TRUE | G16: TRUE | H16: FALSE | I16: FALSE | J16: FALSE | K16: FALSE | L16: FALSE | M16: FALSE | N16: FALSE | O16: FALSE | P16: FALSE | Q16: TRUE | R16: FALSE | S16: FALSE | T16: FALSE | U16: FALSE
B17: Cap Table and Exit Waterfall Tool, by Foresight | C17: https://foresight.is/cap-table | D17: Excel, upload to Google Sheets | E17: Free, Suggested Donation | F17: FALSE | G17: FALSE | H17: FALSE | I17: FALSE | J17: FALSE | K17: FALSE | L17: FALSE | M17: FALSE | N17: FALSE | O17: FALSE | P17: FALSE | Q17: FALSE | R17: TRUE | S17: FALSE | T17: FALSE | U17: FALSE
B18: Venture Valuation Tool, by Foresight | C18: https://foresight.is/venture-valuation-tool/ | D18: Excel, upload to Google Sheets | E18: Free, Suggested Donation | F18: FALSE | G18: FALSE | H18: FALSE | I18: FALSE | J18: FALSE | K18: FALSE | L18: FALSE | M18: FALSE | N18: FALSE | O18: FALSE | P18: FALSE | Q18: FALSE | R18: TRUE | S18: FALSE | T18: FALSE | U18: FALSE
... B20: Custom Services | C20: Contact taylor@foresight.is | D20: Customization, edits to models, and custom services in Excel, Google Sheets, Causal | E20: Quote | F20: FALSE | G20: FALSE | H20: FALSE | I20: FALSE | J20: FALSE | K20: FALSE | L20: FALSE | M20: FALSE | N20: FALSE | O20: FALSE | P20: FALSE | Q20: FALSE | R20: FALSE | S20: FALSE | T20: FALSE | U20: FALSE

Sheet Glossary
B2: Glossary
B3: Key venture terms and metrics used in this model. For more, http://www.allenlatta.com/glossary-of-private-equity-terms.html is a good resource
B5: Term | C5: Definition
B7: Limited Partner | C7: Part-owner of a company whose liability for the firm's debts cannot exceed the amount that an individual invested in the company. In VC, the investors in the fund. https://www.investopedia.com/terms/l/limited-partner.asp
B8: General Partner | C8: A general partner is one of two or more investors who jointly own a business that is structured as a partnership, and who assumes a day-to-day role in managing it. In venture capital, often the management company or the owners and managers of the management company. https://www.investopedia.com/terms/g/generalpartner.asp
B9: Rolling Fund | C9: A newer fund structure created where each quarter is its own "fund" for reporting purposes, so that new limited partners can be accepted into the fund at every quarter. See https://www.angellist.com/blog/rolling-fund-budget for budgeting for rolling funds and more details on the structure
B10: Evergreen Fund | C10: Fund structure where proceeds are continually recycled, and typically limited partners can invest and divest regularly throughout the fund's life. (This model does not fit an evergreen structure.)
B11: Committed Capital | C11: Also known as total fund size. Total capital committed to the fund. May vary over a fund's lifetime if the fund is holding multiple closes.
B12: Called Capital | C12: Capital called from limited partners. Used to pay fund expenses and invest in companies. Once all capital is called, total called capital will equal committed capital.
B13: GP Commit | C13: % of total called capital that is required to be contributed by the general partners of the fund. May be funded through management fees if limited partners allow in fund operating agreements.
B14: Organizational Expenses | C14: Expenses occured in creating a fund entity, which can often be charged to the fund (in addition to management fees)
B15: Operational Expenses | C15: Expenses occured in operating a fund, which can often be charged to the fund (in addition to management fees). Can include fund administration, fund tax reporting, legal costs in working on investment opportunities, and more.
B16: Management Fees | C16: Fees charged by the management company operating the fund to the fund. They are revenues to the management company, and used to pay expenses such as salaries, insurance, marketing, operating costs, and more.
B17: Management Fees Recycled | C17: Many funds will recycle their management fees, meaning they reinvest early proceeds back into new investments. The rationale is that it allows the management company to invest more capital from the same fund size and improve returns. Recycling all fees into new investments can be difficult to do, based on the timeframe for new investments and the timing of when proceeds happen. Budgeting a schedule of invested capital for management fee recycling can be difficult. Many funds will target higher recycling earlier (>100%) knowing they will not be able to recycle all management fees into new investments later in period, or to be more aggressive in redeploying capital/.
... B42: Pro rata | C42: Potential investment amount in a new investment round offered to an pre-existing investor, often an amount that allows them to maintain their ownership position. Managers should have a strategy about how to handle pro rata investment opportunities, as well as a point of view on pro rata investment rights and their desire and ability to secure pro rata rights in investments.

Sheet Changelog
B2: Changelog
B3: Here's what has changed.
B5: Version | C5: Date | D5: Definition
B7: v4.3.6 | C7: 45715 | D7: Edited the Forecast sheet to bring back called capital as a base for calculating management fees. This is similarly tricky to assets under management to use for forecast for fund deployment, so the method currently approximates it "pretty close", similar to the description for assets under management below. Additionally, added a catchup on management fees for multiple closes of committted capital to both called capital and assets under management methods. Unlikley that this would happen for a fund, but included for completeness.
B8: v4.3.5 | C8: 45714 | D8: Edited the calculations around calculation of invested capital budgeting when using assets under management and updating the approach when recycling is using "new and follow investments". The details are complicated, but essentially changing the approach to use the calculated deployment schedule based on $1 of capital to drive the forecast of total invested capital instead of the previous approach of calculating the total to invest and then deploying it over time. The algebra is complicated, but the usage of the model should be straightfoward. In some cases of recycling, follow ons, and base for management fee calculations called capital will not exactly equal committed capital, but I think this accurately reflects the fact that budgeting for full deployment when the fees and recycling in the later periods are highly unknown is an intrinsically difficult real-world problem to solve for. The deviation of called capital from committed capital should be < 5%, and since the performance metrics are based on called capital (not committed), any deviation will not impact performance ratios and metrics.
B9: v4.3.4 | C9: 45713 | D9: Edited the calculations around recycling when using "new and follow investments". Basically, this option presents a special problem in trying to forecast the total amount to invest, because the recycling of proceeds allocated for follow investments (during the period when there are follow investments but no new investments) depends on the new investments originally made, and that must be adjusted to account for recycling in later periods. The current algebra-based calc is close, not exact, but is significantly better than the previous method.
B10: v4.3.3 | C10: 45712 | D10: Edited recycling calcs on Forecast sheet to adjust for the "invested capital" and "invested capital plus cost basis" calculation to remove the potential for invested capital that returns less than 1x to lead to recycling more capital than possible.
