Workbook

Sheet README
B2: Venture Capital Model, with Quarterly Forecast
B4: Copyright & Contact | C4: This was created by Taylor Davidson (@tdavidson) of Foresight. © 2025, Unstructured Ventures, LLC. Questions, contact taylor@foresight.is or @tdavidson
B5: License | C5: tl:dr; You can modify, edit, use, and share within your company (and with third-parties as needed to operate your business). You may not redistribute, resell, give away to others. Full license.
B6: Goal | C6: Simplified model for forecasting a venture fund, to help understand overall fund assumptions and how portfolio construction impacts returns. I've worked with countless founders building complicated models for fund construction - see Venture Investor Model for one - but want to create a simpler, more accessible model that removes some of the lesser-used edge cases and covers the basics for most emerging managers.
B7: Copy to Google Sheets or Download to Excel | C7: File > Make a Copy to copy it to your own Google Drive, or File > Download to download this to use in Excel or other spreadsheet programs. See License for warranties and liabilities.
B8: Support | C8: Questions, happy to assist, contact anytime. More details on how I provide support: https://foresight.is/help
B9: Missing a feature you need? | C9: Check out the Resources for other resources for modeling venture funds, and check out Foresight's Venture Investor Model for a more detailed fund model with financial statements, management company budgeting, and more.
B10: Quickstart | C10: Input fund structural assumptions on Get Started sheet, then review the Key Reports and Forecast sheet to see the key outputs. More details at https://foresight.is/docs/
B12: Outline
B14: README | C14: Contact into, overview on model. Safe to delete or hide.
B15: Formatting and Colors Overview | C15: Details on what the colors and formatting in the model mean. https://foresight.is/learn/colors-and-formatting
B16: License | C16: Terms of use of the model. Safe to delete or hide. https://foresight.is/license
B17: Get Started | C17: Core assumptions for the fund. Do not delete, safe to hide.
B18: Capital and Fund Assumptions | C18: Assumptions for fund economics
B19: Recycling | C19: Optional section for assuming fund recycling policy
B20: Portfolio Construction Assumptions | C20: Core portfolio construction assumptions
B21: Return Assumptions | C21: Investment performance assumptions
B22: Fund Performance | C22: Summary of fund performance. Details and more metrics on Forecast sheet
B23: Key Reports | C23: Key charts to summarize the model. Safe to delete or hide.
B24: Scenarios | C24: Output of the Scenarios, allowing you to set two alternate fund outcomes by changing assumptions for the number of value of high exits. The sheets powering the scenarios are hidden, and can be unhidden and changed if desired.
B25: Forecast | C25: The core calculations to forecast the operations of the fund. The core of the model.
... B29: Changelog | C29: List of what has been changed in model versions. Safe to delete or hide, although I'd advise to hide (instead of delete) so can always check to see what model version you are using to compare to future changes.

Sheet License
B1: License Agreement
B2: Available on website
B4: This License Agreement (“the Agreement”) between you, the licensee, and Unstructured Ventures, LLC (the “Company”) a limited liability corporation headquartered and registered in the Commonwealth of Pennsylvania and organized under the laws of the state of Delaware. The Company owns the financial model (the “Product”) and any edits, additions, or customizations (the "Service") delivered under this Agreement. This Agreement grants you a non-exclusive, non-transferable right to use and incorporate the Product and Service in personal and corporate projects for the organization that purchased the Product and/or Service.
B6: You agree as follows:
B8: 1. Scope of use
B9: * Use and incorporate the Product and/or Service in personal and commercial projects for your company including financial models, business plans, pitch decks, etc.
B10: * You may modify the Product and/or Service to better serve your project.
B11: * You are granted unlimited usage of the Product and/or Service purchased in your organization.
B12: * If an organization is the licensee, all employees of the organization may use the same license.
B14: 2. Limitations and non-use
B15: * You may not redistribute, sublicense or resell the Product and/or Service.
B16: * You may not distribute, license or sell derivative, recompiled, reverse engineered, or modified versions of the Product and/or Service.
... B29: This Agreement is governed by the laws of the Commonwealth of Pennsylvania and the applicable laws of the United States of America. Legal proceedings related to this Agreement may only be brought in the courts of Pennsylvania. You agree to service of process at the e-mail address on your original order. Notices may be sent to Unstructured Ventures, LLC by email to hello@unstructuredventures.com or by post to Unstructured Ventures, LLC, 6360 Broad St, #5226, Pittsburgh, PA, 15206, USA.

Sheet Get Started
B2: Get Started
B3: Key model assumptions and performance metrics
B5: Capital and Fund Assumptions
B6: Capital, Management Fees, base Fund-level assumptions
B8: Detail | C8: Unit | E8: Assumption | F8: Forecast | K8: Notes
B9: Total Commited Capital (Fund Size) | C9: $ | E9: 25000000 | F9: =E9 -> 25000000 | K9: Fund size. By default, assumes all committed capital is closed at the start. Can adjust that by modifying the committed capital on Forecast sheet.
B10: GP Commit, as % of committed capital | C10: % | E10: 0.02 | F10: =E10*F$9 -> 500000 | K10: GP commit is treated as an LP interest for purposes of calculating mangement fees and carried interest. see glossary for additional details
B11: Organizational Expenses (one time) | C11: =C$9 -> $ | E11: 100000 | F11: =Forecast!E39 -> 100000 | K11: paid by fund, in addition to management fees. one time costs associated with forming the fund, primarily legal fees
B12: Operational Expenses (annual) | C12: =C$9 -> $ | E12: 75000 | F12: =Forecast!E40 -> 750000 | K12: paid by fund, in addition to management fees. see https://foresight.is/docs/management-company/ for more context. calculated based on the fund operations period for operating expenses
B13: Management Fees, per year, as % of committed capital | C13: % | E13: 0.02 | F13: =Forecast!E41 -> 4900000 | K13: model works for management fees based on called and committed capital (can be edited for fee structures based on assets under management). if you have a management fee structure that steps down over time, you can edit the management fees directly on the Forecast sheet.
B14: Carry | C14: % | E14: 0.2 | F14: =E124 -> 21803315 | K14: carry is the % of gains that are paid to the managers of the fund. part of the commonly cited "2 and 20" fees structure for funds
B15: Active Investment time period (quarters) | C15: # | E15: 16 | K15: time period for new investments (follow ons by default assumed to come over time)
B16: Fund Duration (Management Fees time period) (quarters) | C16: # | E16: 40 | K16: time period used for assuming management fees, tied to the fund duration and not including the fund extension period, if applicable
B17: Fund Operations time period (quarters) | C17: # | E17: =E15+MAX(H109:H112) -> 40 | K17: time period used for assuming operational expenses, which is calculated from the new invesetment and exit timeframes, to cover the periods the fund incurrs operational expenses. you can override the calculated period if desired.
B18: Fund Duration Extension Period (quarters) | C18: # | E18: =MAX(0,E17-E16) -> 0 | K18: extra time period calculated from your deployment and holding period assumptions. purely for informational purposes, the model uses the fund duration for calculating management fees, this just shows how long of an extension you will need based on your assumptions
B21: Recycling
B22: Details on recycling provisions for closed end and evergreen funds | K22: more at https://foresight.is/docs/management-fee-recycling/
B24: Detail | C24: Unit | E24: Assumption | F24: Forecast | K24: Notes
B25: ="Target recycling %, and max achievable" -> Target recycling %, and max achievable | C25: % | E25: 0.25 | F25: =IFERROR(F29/F26,0) -> 0.0385 | K25: input is for the target % to recycle, and the forecast shows the % that is achievable given the parameters in the assumptions below. It is very common for the max acheivable to be less than the target. Note that LPAs may set the number differently; for example, some LPAs may note that recycling is 125% of committed capital (meaning that the total can be 25% higher than the amount of committed capital), or it may say that recycling is 25% of committed capital. They mean the same thing, but the number may be expressed differently. The model uses an assumption of 25% of recycling + 100% of committed capital = 125% of total committed capital plus recycling
B26: ="... based on "&E26 -> ... based on committed capital | C26: - | E26: committed capital | F26: =IF(E26="management fees",F13,F9) -> 25000000 | K26: can be set to management fees or committed capital, and the forecast outputs the amount of it forecasted in the model
B27: ="... from exits "&E27&" quarters or less post-investment" -> ... from exits 24 quarters or less post-investment | C27: # | E27: =6*4 -> 24 | F27: =Forecast!E204 -> 134979075 | K27: can set the time limit from original investment to time to proceeds (exit), and only allow exits within that timeframe to recycle their proceeds. if there is no limit, simply input a number greater thant the fund operations period or the max holding period in the return assumptions
B28: ="... up to the amount of "&E28&" per investment exited" -> ... up to the amount of invested capital per investment exited | C28: - | E28: invested capital | F28: =IF(E28="invested capital",Forecast!E206,IF(E28="invested capital plus cost basis",Forecast!E205,Forecast!E204)) -> 8085000 | K28: can set to recycle the amount originally invested in the company (meaning any profits would be distributed), the amount invested in the company plus the cost basis (allocating expenses to the invested capital, so that it reflects paid in capital related to the investent), or all proceeds, meaning all proceeds from the exit
B29: ="... able to invest in "&E29 -> ... able to invest in new investments | C29: - | E29: new investments | F29: =Forecast!E42 -> 962500 | K29: can set to new investments only, or new and follow on investments. this will set the proceeds recycling timeframe on the forecast sheet, meaning the period when recycling can be done
B32: Investment Strategy and Expectations
B33: Use to detail an investment strategy, new and follow to forecast returns
B35: Exit Outcome | E35: Fail | F35: Low | G35: Medium | H35: High | K35: change the terms to fit what you want to call the different exit outcomes, used to generate the returns expectations on get started.
B37: Investment Performance and Capital Allocation
B38: % of Investments per Exit Outcome | C38: % | E38: 0.6 | F38: 0.2 | G38: 0.1 | H38: =1-SUM(E38:G38) -> 0.1 | K38: % of the number of companies invested in; sum should equal 0%
B39: # of Companies that achieve each Exit Outcome | C39: # | E39: =E42*$E122/E78 -> 24.255 | F39: =F42*$E122/F78 -> 8.085 | G39: =G42*$E122/G78 -> 4.0425 | H39: =H42*$E122/H78 -> 4.0425 | K39: # of companies invested in, per exit outcome
B40: Index of average investment per overall average | C40: % | E40: =$E101/E78 -> 1 | F40: =$E101/F78 -> 1 | G40: =$E101/G78 -> 1 | H40: =$E101/H78 -> 1 | K40: intermediate calculation to calculation % of invested capital
B41: Adjustment to % of Investments to % of Invested Capital | C41: % | E41: =E38/E40 -> 0.6 | F41: =F38/F40 -> 0.2 | G41: =G38/G40 -> 0.1 | H41: =H38/H40 -> 0.1 | K41: intermediate calculation to calculation % of invested capital
B42: % of Invested Capital per Exit Outcome | C42: % | E42: =E41/SUM($E41:$H41) -> 0.6 | F42: =F41/SUM($E41:$H41) -> 0.2 | G42: =G41/SUM($E41:$H41) -> 0.1 | H42: =H41/SUM($E41:$H41) -> 0.1 | K42: % of overall invested capital; sum should equal 0%. this will not be equal to the % of investments (companies) if you have different investment strategies between the companies
B43: % of Initial Capital per Exit Outcome | C43: % | E43: =1/(1+E53*E54/E48+E63*E64/E48)*E42 -> 0.6 | F43: =1/(1+F53*F54/F48+F63*F64/F48)*F42 -> 0.2 | G43: =1/(1+G53*G54/G48+G63*G64/G48)*G42 -> 0.1 | H43: =1/(1+H53*H54/H48+H63*H64/H48)*H42 -> 0.1
B44: % of First Follow per Exit Outcome | C44: % | E44: =IFERROR(E53*E54/E48*E43,0) -> 0 | F44: =IFERROR(F53*F54/F48*F43,0) -> 0 | G44: =IFERROR(G53*G54/G48*G43,0) -> 0 | H44: =IFERROR(H53*H54/H48*H43,0) -> 0
B45: % of Second Follow per Exit Outcome | C45: % | E45: =IFERROR(E63*E64/E48*E43,0) -> 0 | F45: =IFERROR(F63*F64/F48*F43,0) -> 0 | G45: =IFERROR(G63*G64/G48*G43,0) -> 0 | H45: =IFERROR(H63*H64/H48*H43,0) -> 0
B47: Initial Investment
B48: Average Initial Investment | C48: =C$9 -> $ | E48: =E49*E50 -> 500000 | F48: =F49*F50 -> 500000 | G48: =G49*G50 -> 500000 | H48: =H49*H50 -> 500000 | K48: your check into the company, not including other investors in the round. calculated from your ownership % and average postmoney valuation at initial investment
B49: Postmoney Valuation | C49: =C$9 -> $ | E49: 5000000 | F49: 5000000 | G49: 5000000 | H49: 5000000 | K49: assumption, average per type of exit. note, this is an assumption becuase the model is best used to evaluate the impact of ownership % on overall returns, and to do that, it is best to hold the valuation constant and see the impact on ownership % on the size of the portfolio
B50: Ownership %, at initial investment | C50: =C$9 -> $ | E50: 0.1 | F50: 0.1 | G50: 0.1 | H50: 0.1 | K50: your assumed ownership %, not including other investors in the round. for convertibles, assume the post-conversion to equity ownership %
B52: Follow on Investments (First Follow on round)
...

Sheet Get Started  2
B2: Get Started
B3: Key model assumptions and performance metrics
B5: Capital and Fund Assumptions
B6: Capital, Management Fees, base Fund-level assumptions
B8: Detail | C8: Unit | E8: Assumption | F8: Forecast | K8: Notes
B9: Total Commited Capital (Fund Size) | C9: ='Get Started'!C9 -> $ | E9: ='Get Started'!E9 -> 25000000 | F9: =E9 -> 25000000 | K9: Fund size. By default, assumes all committed capital is closed at the start. Can adjust that by modifying the committed capital on Forecast sheet.
B10: GP Commit, as % of committed capital | C10: % | E10: ='Get Started'!E10 -> 0.02 | F10: =E10*F$9 -> 500000 | K10: GP commit is treated as an LP interest for purposes of calculating mangement fees and carried interest. see glossary for additional details
B11: Organizational Expenses (one time) | C11: =C$9 -> $ | E11: ='Get Started'!E11 -> 100000 | F11: ='Forecast 2'!E39 -> 100000 | K11: paid by fund, in addition to management fees. one time costs associated with forming the fund, primarily legal fees
B12: Operational Expenses (annual) | C12: =C$9 -> $ | E12: ='Get Started'!E12 -> 75000 | F12: ='Forecast 2'!E40 -> 750000 | K12: paid by fund, in addition to management fees. see https://foresight.is/docs/management-company/ for more context. calculated based on the fund operations period for operating expenses
B13: Management Fees, per year, as % of committed capital | C13: % | E13: ='Get Started'!E13 -> 0.02 | F13: ='Forecast 2'!E41 -> 4900000 | K13: model works for management fees based on called and committed capital (can be edited for fee structures based on assets under management). if you have a management fee structure that steps down over time, you can edit the management fees directly on the Forecast sheet.
B14: Carry | C14: % | E14: ='Get Started'!E14 -> 0.2 | F14: =E124 -> 13925453 | K14: carry is the % of gains that are paid to the managers of the fund. part of the commonly cited "2 and 20" fees structure for funds
B15: Active Investment time period (quarters) | C15: # | E15: ='Get Started'!E15 -> 16 | K15: time period for new investments (follow ons by default assumed to come over time)
B16: Fund Duration (Management Fees time period) (quarters) | C16: # | E16: ='Get Started'!E16 -> 40 | K16: time period used for assuming management fees, tied to the fund duration and not including the fund extension period, if applicable
B17: Fund Operations time period (quarters) | C17: # | E17: ='Get Started'!E17 -> 40 | K17: time period used for assuming operational expenses, which is calculated from the new invesetment and exit timeframes, to cover the periods the fund incurrs operational expenses. you can override the calculated period if desired.
B18: Fund Duration Extension Period (quarters) | C18: # | E18: =MAX(0,E17-E16) -> 0 | K18: extra time period calculated from your deployment and holding period assumptions. purely for informational purposes, the model uses the fund duration for calculating management fees, this just shows how long of an extension you will need based on your assumptions
B21: Recycling
B22: Details on recycling provisions for closed end and evergreen funds | K22: more at https://foresight.is/docs/management-fee-recycling/
B24: Detail | C24: Unit | E24: Assumption | F24: Forecast | K24: Notes
B25: ="Target recycling %, and max achievable" -> Target recycling %, and max achievable | C25: % | E25: ='Get Started'!E25 -> 0.25 | F25: =IFERROR(F29/F26,0) -> 0.041708333 | K25: input is for the target % to recycle, and the forecast shows the % that is achievable given the parameters in the assumptions below. It is very common for the max acheivable to be less than the target. Note that LPAs may set the number differently; for example, some LPAs may note that recycling is 125% of committed capital (meaning that the total can be 25% higher than the amount of committed capital), or it may say that recycling is 25% of committed capital. They mean the same thing, but the number may be expressed differently. The model uses an assumption of 25% of recycling + 100% of committed capital = 125% of total committed capital plus recycling
B26: ="... based on "&E26 -> ... based on committed capital | C26: - | E26: ='Get Started'!E26 -> committed capital | F26: =IF(E26="management fees",F13,F9) -> 25000000 | K26: can be set to management fees or committed capital, and the forecast outputs the amount of it forecasted in the model
B27: ="... from exits "&E27&" quarters or less post-investment" -> ... from exits 24 quarters or less post-investment | C27: # | E27: ='Get Started'!E27 -> 24 | F27: ='Forecast 2'!E204 -> 95669973 | K27: can set the time limit from original investment to time to proceeds (exit), and only allow exits within that timeframe to recycle their proceeds. if there is no limit, simply input a number greater thant the fund operations period or the max holding period in the return assumptions
B28: ="... up to the amount of "&E28&" per investment exited" -> ... up to the amount of invested capital per investment exited | C28: - | E28: ='Get Started'!E28 -> invested capital | F28: =IF(E28="invested capital",'Forecast 2'!E206,IF(E28="invested capital plus cost basis",'Forecast 2'!E205,'Forecast 2'!E204)) -> 7778871.5 | K28: can set to recycle the amount originally invested in the company (meaning any profits would be distributed), the amount invested in the company plus the cost basis (allocating expenses to the invested capital, so that it reflects paid in capital related to the investent), or all proceeds, meaning all proceeds from the exit
B29: ="... able to invest in "&E29 -> ... able to invest in new investments | C29: - | E29: ='Get Started'!E29 -> new investments | F29: ='Forecast 2'!E42 -> 1042708.3 | K29: can set to new investments only, or new and follow on investments. this will set the proceeds recycling timeframe on the forecast sheet, meaning the period when recycling can be done
B32: Investment Strategy and Expectations
B33: Use to detail an investment strategy, new and follow to forecast returns
B35: Exit Outcome | E35: ='Get Started'!E35 -> Fail | F35: ='Get Started'!F35 -> Low | G35: ='Get Started'!G35 -> Medium | H35: ='Get Started'!H35 -> High | J35: change the terms to fit what you want to call the different exit outcomes, used to generate the returns expectations on get started.
B37: Investment Performance and Capital Allocation
B38: % of Investments per Exit Outcome | C38: % | E38: =1-SUM(F38:H38) -> 0.61666667 | F38: =MAX(0,'Get Started'!F38-($H38-'Get Started'!$H38)/3) -> 0.21666667 | G38: =MAX(0,'Get Started'!G38-($H38-'Get Started'!$H38)/3) -> 0.11666667 | H38: ='Get Started'!H38*(1+Scenarios!D28) -> 0.05 | J38: % of the number of companies invested in; sum should equal 0%
B39: # of Companies that achieve each Exit Outcome | C39: # | E39: =E42*$E122/E78 -> 25.027674 | F39: =F42*$E122/F78 -> 8.7935069 | G39: =G42*$E122/G78 -> 4.7349653 | H39: =H42*$E122/H78 -> 2.0292708 | J39: # of companies invested in, per exit outcome
B40: Index of average investment per overall average | C40: % | E40: =$E101/E78 -> 1 | F40: =$E101/F78 -> 1 | G40: =$E101/G78 -> 1 | H40: =$E101/H78 -> 1 | J40: intermediate calculation to calculation % of invested capital
B41: Adjustment to % of Investments to % of Invested Capital | C41: % | E41: =E38/E40 -> 0.61666667 | F41: =F38/F40 -> 0.21666667 | G41: =G38/G40 -> 0.11666667 | H41: =H38/H40 -> 0.05 | J41: intermediate calculation to calculation % of invested capital
B42: % of Invested Capital per Exit Outcome | C42: % | E42: =E41/SUM($E41:$H41) -> 0.61666667 | F42: =F41/SUM($E41:$H41) -> 0.21666667 | G42: =G41/SUM($E41:$H41) -> 0.11666667 | H42: =H41/SUM($E41:$H41) -> 0.05 | J42: % of overall invested capital; sum should equal 0%. this will not be equal to the % of investments (companies) if you have different investment strategies between the companies
B43: % of Initial Capital per Exit Outcome | C43: % | E43: =1/(1+E53*E54/E48+E63*E64/E48)*E42 -> 0.61666667 | F43: =1/(1+F53*F54/F48+F63*F64/F48)*F42 -> 0.21666667 | G43: =1/(1+G53*G54/G48+G63*G64/G48)*G42 -> 0.11666667 | H43: =1/(1+H53*H54/H48+H63*H64/H48)*H42 -> 0.05
B44: % of First Follow per Exit Outcome | C44: % | E44: =IFERROR(E53*E54/E48*E43,0) -> 0 | F44: =IFERROR(F53*F54/F48*F43,0) -> 0 | G44: =IFERROR(G53*G54/G48*G43,0) -> 0 | H44: =IFERROR(H53*H54/H48*H43,0) -> 0
B45: % of Second Follow per Exit Outcome | C45: % | E45: =IFERROR(E63*E64/E48*E43,0) -> 0 | F45: =IFERROR(F63*F64/F48*F43,0) -> 0 | G45: =IFERROR(G63*G64/G48*G43,0) -> 0 | H45: =IFERROR(H63*H64/H48*H43,0) -> 0
B47: Initial Investment
B48: Average Initial Investment | C48: =C$9 -> $ | E48: =E49*E50 -> 500000 | F48: =F49*F50 -> 500000 | G48: =G49*G50 -> 500000 | H48: =H49*H50 -> 500000 | J48: your check into the company, not including other investors in the round. calculated from your ownership % and average postmoney valuation at initial investment
B49: Postmoney Valuation | C49: =C$9 -> $ | E49: ='Get Started'!E49 -> 5000000 | F49: ='Get Started'!F49 -> 5000000 | G49: ='Get Started'!G49 -> 5000000 | H49: ='Get Started'!H49 -> 5000000 | J49: assumption, average per type of exit. note, this is an assumption becuase the model is best used to evaluate the impact of ownership % on overall returns, and to do that, it is best to hold the valuation constant and see the impact on ownership % on the size of the portfolio
B50: Ownership %, at initial investment | C50: =C$9 -> $ | E50: ='Get Started'!E50 -> 0.1 | F50: ='Get Started'!F50 -> 0.1 | G50: ='Get Started'!G50 -> 0.1 | H50: ='Get Started'!H50 -> 0.1 | J50: your assumed ownership %, not including other investors in the round. for convertibles, assume the post-conversion to equity ownership %
B52: Follow on Investments (First Follow on round)
...

Sheet Forecast  2
B2: Quarterly Forecast
B4: Relative Quarter | G4: =1 -> 1 | H4: =G4+1 -> 2 | I4: =H4+1 -> 3 | J4: =I4+1 -> 4 | K4: =J4+1 -> 5 | L4: =K4+1 -> 6 | M4: =L4+1 -> 7 | N4: =M4+1 -> 8 | O4: =N4+1 -> 9 | ... CH4: =CG4+1 -> 80
B5: Date at end of period | G5: =Forecast!G5 -> 46022 | H5: =EOMONTH(EDATE(G5,3),0) -> 46112 | I5: =EOMONTH(EDATE(H5,3),0) -> 46203 | J5: =EOMONTH(EDATE(I5,3),0) -> 46295 | K5: =EOMONTH(EDATE(J5,3),0) -> 46387 | L5: =EOMONTH(EDATE(K5,3),0) -> 46477 | M5: =EOMONTH(EDATE(L5,3),0) -> 46568 | N5: =EOMONTH(EDATE(M5,3),0) -> 46660 | O5: =EOMONTH(EDATE(N5,3),0) -> 46752 | ... CH5: =EOMONTH(EDATE(CG5,3),0) -> 53235
B7: Triggers
B8: ='Get Started 2'!B15 -> Active Investment time period (quarters) | C8: period for making new investments only | D8: sum | E8: =IF(D8="sum",SUM(G8:CH8),IF(D8="final",CH8,IF(D8="initial",G8,IF(D8="average",AVERAGE(G8:CH8),0)))) -> 16 | G8: =IF(G$4<='Get Started 2'!$E15,1,0) -> 1 | H8: =IF(H$4<='Get Started 2'!$E15,1,0) -> 1 | I8: =IF(I$4<='Get Started 2'!$E15,1,0) -> 1 | J8: =IF(J$4<='Get Started 2'!$E15,1,0) -> 1 | K8: =IF(K$4<='Get Started 2'!$E15,1,0) -> 1 | L8: =IF(L$4<='Get Started 2'!$E15,1,0) -> 1 | M8: =IF(M$4<='Get Started 2'!$E15,1,0) -> 1 | N8: =IF(N$4<='Get Started 2'!$E15,1,0) -> 1 | ... CH8: =IF(CH$4<='Get Started 2'!$E15,1,0) -> 0
B9: ='Get Started 2'!B16 -> Fund Duration (Management Fees time period) (quarters) | C9: see FAST Standard for how to use triggers: https://foresight.is/learn/fast-standard | D9: sum | E9: =IF(D9="sum",SUM(G9:CH9),IF(D9="final",CH9,IF(D9="initial",G9,IF(D9="average",AVERAGE(G9:CH9),0)))) -> 40 | G9: =IF(G$4<='Get Started 2'!$E16,1,0)*G10 -> 1 | H9: =IF(H$4<='Get Started 2'!$E16,1,0)*H10 -> 1 | I9: =IF(I$4<='Get Started 2'!$E16,1,0)*I10 -> 1 | J9: =IF(J$4<='Get Started 2'!$E16,1,0)*J10 -> 1 | K9: =IF(K$4<='Get Started 2'!$E16,1,0)*K10 -> 1 | L9: =IF(L$4<='Get Started 2'!$E16,1,0)*L10 -> 1 | M9: =IF(M$4<='Get Started 2'!$E16,1,0)*M10 -> 1 | N9: =IF(N$4<='Get Started 2'!$E16,1,0)*N10 -> 1 | ... CH9: =IF(CH$4<='Get Started 2'!$E16,1,0)*CH10 -> 0
B10: ='Get Started 2'!B17 -> Fund Operations time period (quarters) | D10: sum | E10: =IF(D10="sum",SUM(G10:CH10),IF(D10="final",CH10,IF(D10="initial",G10,IF(D10="average",AVERAGE(G10:CH10),0)))) -> 40 | G10: =IF(G$4<='Get Started 2'!$E17,1,0) -> 1 | H10: =IF(H$4<='Get Started 2'!$E17,1,0) -> 1 | I10: =IF(I$4<='Get Started 2'!$E17,1,0) -> 1 | J10: =IF(J$4<='Get Started 2'!$E17,1,0) -> 1 | K10: =IF(K$4<='Get Started 2'!$E17,1,0) -> 1 | L10: =IF(L$4<='Get Started 2'!$E17,1,0) -> 1 | M10: =IF(M$4<='Get Started 2'!$E17,1,0) -> 1 | N10: =IF(N$4<='Get Started 2'!$E17,1,0) -> 1 | ... CH10: =IF(CH$4<='Get Started 2'!$E17,1,0) -> 0
B11: Proceeds Recycling period (quarters) | D11: sum | E11: =IF(D11="sum",SUM(G11:EP11),IF(D11="final",EP11,IF(D11="initial",G11,IF(D11="average",AVERAGE(G11:EP11),0)))) -> 16 | G11: =IF('Get Started 2'!$E29="new investments",G8,IF(G$4<='Get Started 2'!$E15+MAX('Get Started 2'!$E55:$H55,'Get Started 2'!$E65:$H65),1,0)) -> 1 | H11: =IF('Get Started 2'!$E29="new investments",H8,IF(H$4<='Get Started 2'!$E15+MAX('Get Started 2'!$E55:$H55,'Get Started 2'!$E65:$H65),1,0)) -> 1 | I11: =IF('Get Started 2'!$E29="new investments",I8,IF(I$4<='Get Started 2'!$E15+MAX('Get Started 2'!$E55:$H55,'Get Started 2'!$E65:$H65),1,0)) -> 1 | J11: =IF('Get Started 2'!$E29="new investments",J8,IF(J$4<='Get Started 2'!$E15+MAX('Get Started 2'!$E55:$H55,'Get Started 2'!$E65:$H65),1,0)) -> 1 | K11: =IF('Get Started 2'!$E29="new investments",K8,IF(K$4<='Get Started 2'!$E15+MAX('Get Started 2'!$E55:$H55,'Get Started 2'!$E65:$H65),1,0)) -> 1 | L11: =IF('Get Started 2'!$E29="new investments",L8,IF(L$4<='Get Started 2'!$E15+MAX('Get Started 2'!$E55:$H55,'Get Started 2'!$E65:$H65),1,0)) -> 1 | M11: =IF('Get Started 2'!$E29="new investments",M8,IF(M$4<='Get Started 2'!$E15+MAX('Get Started 2'!$E55:$H55,'Get Started 2'!$E65:$H65),1,0)) -> 1 | N11: =IF('Get Started 2'!$E29="new investments",N8,IF(N$4<='Get Started 2'!$E15+MAX('Get Started 2'!$E55:$H55,'Get Started 2'!$E65:$H65),1,0)) -> 1 | ... CH11: =IF('Get Started 2'!$E29="new investments",CH8,IF(CH$4<='Get Started 2'!$E15+MAX('Get Started 2'!$E55:$H55,'Get Started 2'!$E65:$H65),1,0)) -> 0
B13: Inputs
B14: Management Fees | D14: sum | E14: =IF(D14="sum",SUM(G14:CH14),IF(D14="final",CH14,IF(D14="initial",G14,IF(D14="average",AVERAGE(G14:CH14),0)))) -> 0.2 | G14: =Forecast!G14 -> 0.005 | H14: =IF(H9=1,'Get Started 2'!$E13/4,0) -> 0.005 | I14: =IF(I9=1,'Get Started 2'!$E13/4,0) -> 0.005 | J14: =IF(J9=1,'Get Started 2'!$E13/4,0) -> 0.005 | K14: =IF(K9=1,'Get Started 2'!$E13/4,0) -> 0.005 | L14: =IF(L9=1,'Get Started 2'!$E13/4,0) -> 0.005 | M14: =IF(M9=1,'Get Started 2'!$E13/4,0) -> 0.005 | N14: =IF(N9=1,'Get Started 2'!$E13/4,0) -> 0.005 | O14: =IF(O9=1,'Get Started 2'!$E13/4,0) -> 0.005 | ... CH14: =IF(CH9=1,'Get Started 2'!$E13/4,0) -> 0
B15: ="Management Fees based on "&G15&" capital. Can change per period if method for calc changes." -> Management Fees based on committed capital. Can change per period if method for calc changes. | D15: sum | E15: =IF(D15="sum",SUM(G15:CH15),IF(D15="final",CH15,IF(D15="initial",G15,IF(D15="average",AVERAGE(G15:CH15),0)))) -> 0 | G15: =Forecast!G15 -> committed | H15: =Forecast!H15 -> committed | I15: =Forecast!I15 -> committed | J15: =Forecast!J15 -> committed | K15: =Forecast!K15 -> committed | L15: =Forecast!L15 -> committed | M15: =Forecast!M15 -> committed | N15: =Forecast!N15 -> committed | ... CH15: =Forecast!CH15 -> committed
B16: GP Commit, excluded from LP capital. By default, GP commit is treated as an LP interest. Check the box to have the GP commit not treated as an LP investment. This will affect management fees (management fees will not be charged on the GP commit if it's not an LP interest, and it will change the waterfall so that GPs only get carried interest, and not carried interest + their share of distributions as an LP) | C16: =Forecast!C16 -> FALSE | D16: sum | E16: =IF(D16="sum",SUM(G16:CH16),IF(D16="final",CH16,IF(D16="initial",G16,IF(D16="average",AVERAGE(G16:CH16),0)))) -> 0 | G16: =IF($C16=TRUE,G31*'Get Started 2'!$E10,0) -> 0 | H16: =IF($C16=TRUE,H31*'Get Started 2'!$E10,0) -> 0 | I16: =IF($C16=TRUE,I31*'Get Started 2'!$E10,0) -> 0 | J16: =IF($C16=TRUE,J31*'Get Started 2'!$E10,0) -> 0 | K16: =IF($C16=TRUE,K31*'Get Started 2'!$E10,0) -> 0 | L16: =IF($C16=TRUE,L31*'Get Started 2'!$E10,0) -> 0 | M16: =IF($C16=TRUE,M31*'Get Started 2'!$E10,0) -> 0 | N16: =IF($C16=TRUE,N31*'Get Started 2'!$E10,0) -> 0 | ... CH16: =IF($C16=TRUE,CH31*'Get Started 2'!$E10,0) -> 0
B17: GP Commit, excluded from management fees. Check the box to have the GP commit - capital contributed by the GP as LP capital and an ownership in the fund - excluded from calculation of management fees | C17: =Forecast!C17 -> TRUE | D17: sum | E17: =IF(D17="sum",SUM(G17:CH17),IF(D17="final",CH17,IF(D17="initial",G17,IF(D17="average",AVERAGE(G17:CH17),0)))) -> 500000 | G17: =IF($C17=TRUE,G31*'Get Started 2'!$E10,0) -> 28887.5 | H17: =IF($C17=TRUE,H31*'Get Started 2'!$E10,0) -> 26887.5 | I17: =IF($C17=TRUE,I31*'Get Started 2'!$E10,0) -> 26887.5 | J17: =IF($C17=TRUE,J31*'Get Started 2'!$E10,0) -> 26887.5 | K17: =IF($C17=TRUE,K31*'Get Started 2'!$E10,0) -> 26887.5 | L17: =IF($C17=TRUE,L31*'Get Started 2'!$E10,0) -> 26887.5 | M17: =IF($C17=TRUE,M31*'Get Started 2'!$E10,0) -> 26887.5 | N17: =IF($C17=TRUE,N31*'Get Started 2'!$E10,0) -> 26887.5 | ... CH17: =IF($C17=TRUE,CH31*'Get Started 2'!$E10,0) -> 0
B18: GP Commit, covered via cashless contributions from management fees | C18: if management fees are used to cover for a GP Commit. Please discuss the implications of this with your tax advisor and fund admin if you choose this option | D18: final | E18: =IF(D18="sum",SUM(G18:EP18),IF(D18="final",EP18,IF(D18="initial",G18,IF(D18="average",AVERAGE(G18:EP18),0)))) -> 0 | G18: =Forecast!G18 -> 0 | H18: =Forecast!H18 -> 0 | I18: =Forecast!I18 -> 0 | J18: =Forecast!J18 -> 0 | K18: =Forecast!K18 -> 0 | L18: =Forecast!L18 -> 0 | M18: =Forecast!M18 -> 0 | N18: =Forecast!N18 -> 0 | ... CH18: =Forecast!CH18 -> 0
B19: Commited Capital, % of total fund committed per year | D19: sum | E19: =IF(D19="sum",SUM(G19:EP19),IF(D19="final",EP19,IF(D19="initial",G19,IF(D19="average",AVERAGE(G19:EP19),0)))) -> 1 | G19: =Forecast!G19 -> 1 | H19: =Forecast!H19 -> 0 | I19: =Forecast!I19 -> 0 | J19: =Forecast!J19 -> 0 | K19: =Forecast!K19 -> 0 | L19: =Forecast!L19 -> 0 | M19: =Forecast!M19 -> 0 | N19: =Forecast!N19 -> 0 | ... CH19: =Forecast!CH19 -> 0
B20: Called Capital, % of total fund committed | C20: optional manual override to the automatically calculated called capital schedule, if you do not want to use the calculated schedule. this will not change your investment deployment, only your called capital and cash balances | D20: sum | E20: =IF(D20="sum",SUM(G20:EP20),IF(D20="final",EP20,IF(D20="initial",G20,IF(D20="average",AVERAGE(G20:EP20),0)))) -> 0 | G20: =Forecast!G20 -> 0 | H20: =Forecast!H20 -> 0 | I20: =Forecast!I20 -> 0 | J20: =Forecast!J20 -> 0 | K20: =Forecast!K20 -> 0 | L20: =Forecast!L20 -> 0 | M20: =Forecast!M20 -> 0 | N20: =Forecast!N20 -> 0 | ... CH20: =Forecast!CH20 -> 0
B22: Capital, beginning of period | D22: initial | E22: =IF(D22="sum",SUM(G22:CH22),IF(D22="final",CH22,IF(D22="initial",G22,IF(D22="average",AVERAGE(G22:CH22),0)))) -> 0 | G22: =F28 -> 0 | H22: =G28 -> 0 | I22: =H28 -> 0 | J22: =I28 -> 0 | K22: =J28 -> 0 | L22: =K28 -> 0 | M22: =L28 -> 0 | N22: =M28 -> 0 | ... CH22: =CG28 -> 0
B23: Called Capital | D23: sum | E23: =IF(D23="sum",SUM(G23:CH23),IF(D23="final",CH23,IF(D23="initial",G23,IF(D23="average",AVERAGE(G23:CH23),0)))) -> 25000000 | G23: =G31 -> 1444375 | H23: =H31 -> 1344375 | I23: =I31 -> 1344375 | J23: =J31 -> 1344375 | K23: =K31 -> 1344375 | L23: =L31 -> 1344375 | M23: =M31 -> 1344375 | N23: =N31 -> 1344375 | ... CH23: =CH31 -> 0
B24: Proceeds | D24: sum | E24: =IF(D24="sum",SUM(G24:CH24),IF(D24="final",CH24,IF(D24="initial",G24,IF(D24="average",AVERAGE(G24:CH24),0)))) -> 95669973 | G24: =G43 -> 0 | H24: =H43 -> 0 | I24: =I43 -> 0 | J24: =J43 -> 0 | K24: =K43 -> 0 | L24: =L43 -> 0 | M24: =M43 -> 0 | N24: =N43 -> 0 | ... CH24: =CH43 -> 0
B25: Distributions + Carried Interest | D25: sum | E25: =IF(D25="sum",SUM(G25:CH25),IF(D25="final",CH25,IF(D25="initial",G25,IF(D25="average",AVERAGE(G25:CH25),0)))) -> -94627265 | G25: =SUM(G47,G46,G45)*-1 -> 0 | H25: =SUM(H47,H46,H45)*-1 -> 0 | I25: =SUM(I47,I46,I45)*-1 -> 0 | J25: =SUM(J47,J46,J45)*-1 -> 0 | K25: =SUM(K47,K46,K45)*-1 -> 0 | L25: =SUM(L47,L46,L45)*-1 -> 0 | M25: =SUM(M47,M46,M45)*-1 -> 0 | N25: =SUM(N47,N46,N45)*-1 -> 0 | ... CH25: =SUM(CH47,CH46,CH45)*-1 -> 0
B26: Fees | D26: sum | E26: =IF(D26="sum",SUM(G26:CH26),IF(D26="final",CH26,IF(D26="initial",G26,IF(D26="average",AVERAGE(G26:CH26),0)))) -> -5750000 | G26: =SUM(G39,G40,G41)*-1 -> -241250 | H26: =SUM(H39,H40,H41)*-1 -> -141250 | I26: =SUM(I39,I40,I41)*-1 -> -141250 | J26: =SUM(J39,J40,J41)*-1 -> -141250 | K26: =SUM(K39,K40,K41)*-1 -> -141250 | L26: =SUM(L39,L40,L41)*-1 -> -141250 | M26: =SUM(M39,M40,M41)*-1 -> -141250 | N26: =SUM(N39,N40,N41)*-1 -> -141250 | ... CH26: =SUM(CH39,CH40,CH41)*-1 -> 0
B27: Investments | D27: sum | E27: =IF(D27="sum",SUM(G27:CH27),IF(D27="final",CH27,IF(D27="initial",G27,IF(D27="average",AVERAGE(G27:CH27),0)))) -> -20292708 | G27: =G38*-1 -> -1203125 | H27: =H38*-1 -> -1203125 | I27: =I38*-1 -> -1203125 | J27: =J38*-1 -> -1203125 | K27: =K38*-1 -> -1203125 | L27: =L38*-1 -> -1203125 | M27: =M38*-1 -> -1203125 | N27: =N38*-1 -> -1203125 | ... CH27: =CH38*-1 -> 0
B28: Capital, end of period | D28: final | E28: =IF(D28="sum",SUM(G28:CH28),IF(D28="final",CH28,IF(D28="initial",G28,IF(D28="average",AVERAGE(G28:CH28),0)))) -> 0 | G28: =SUM(G22:G27) -> 0 | H28: =SUM(H22:H27) -> 0 | I28: =SUM(I22:I27) -> 0 | J28: =SUM(J22:J27) -> 0 | K28: =SUM(K22:K27) -> 0 | L28: =SUM(L22:L27) -> 0 | M28: =SUM(M22:M27) -> 0 | N28: =SUM(N22:N27) -> 0 | ... CH28: =SUM(CH22:CH27) -> 0
B30: Committed Capital | D30: sum | E30: =IF(D30="sum",SUM(G30:CH30),IF(D30="final",CH30,IF(D30="initial",G30,IF(D30="average",AVERAGE(G30:CH30),0)))) -> 25000000 | G30: ='Get Started 2'!$E9*G19 -> 25000000 | H30: ='Get Started 2'!$E9*H19 -> 0 | I30: ='Get Started 2'!$E9*I19 -> 0 | J30: ='Get Started 2'!$E9*J19 -> 0 | K30: ='Get Started 2'!$E9*K19 -> 0 | L30: ='Get Started 2'!$E9*L19 -> 0 | M30: ='Get Started 2'!$E9*M19 -> 0 | N30: ='Get Started 2'!$E9*N19 -> 0 | ... CH30: ='Get Started 2'!$E9*CH19 -> 0
B31: Called Capital | D31: sum | E31: =IF(D31="sum",SUM(G31:CH31),IF(D31="final",CH31,IF(D31="initial",G31,IF(D31="average",AVERAGE(G31:CH31),0)))) -> 25000000 | G31: =IF($E20<>0,G20*$E30, MIN($E30-F60, MAX(0,G38+G39+G40+G41-G42))) -> 1444375 | H31: =IF($E20<>0,H20*$E30, MIN($E30-G60, MAX(0,H38+H39+H40+H41-H42))) -> 1344375 | I31: =IF($E20<>0,I20*$E30, MIN($E30-H60, MAX(0,I38+I39+I40+I41-I42))) -> 1344375 | J31: =IF($E20<>0,J20*$E30, MIN($E30-I60, MAX(0,J38+J39+J40+J41-J42))) -> 1344375 | K31: =IF($E20<>0,K20*$E30, MIN($E30-J60, MAX(0,K38+K39+K40+K41-K42))) -> 1344375 | L31: =IF($E20<>0,L20*$E30, MIN($E30-K60, MAX(0,L38+L39+L40+L41-L42))) -> 1344375 | M31: =IF($E20<>0,M20*$E30, MIN($E30-L60, MAX(0,M38+M39+M40+M41-M42))) -> 1344375 | N31: =IF($E20<>0,N20*$E30, MIN($E30-M60, MAX(0,N38+N39+N40+N41-N42))) -> 1344375 | ... CH31: =IF($E20<>0,CH20*$E30, MIN($E30-CG60, MAX(0,CH38+CH39+CH40+CH41-CH42))) -> 0
B32: Manual Investments | D32: sum | E32: =IF(D32="sum",SUM(G32:CH32),IF(D32="final",CH32,IF(D32="initial",G32,IF(D32="average",AVERAGE(G32:CH32),0)))) -> 0 | G32: 0 | H32: 0 | I32: 0 | J32: 0 | K32: 0 | L32: 0 | M32: 0 | N32: 0 | O32: 0 | P32: 0 | Q32: 0 | R32: 0 | S32: 0 | T32: 0 | U32: 0 | V32: 0 | W32: 0 | X32: 0 | Y32: 0 | Z32: 0 | AA32: 0 | AB32: 0 | AC32: 0 | AD32: 0 | AE32: 0 | AF32: 0 | AG32: 0 | AH32: 0 | AI32: 0 | AJ32: 0 | AK32: 0 | AL32: 0 | AM32: 0 | AN32: 0 | AO32: 0 | AP32: 0 | AQ32: 0 | AR32: 0 | AS32: 0 | AT32: 0 | AU32: 0 | AV32: 0 | AW32: 0 | AX32: 0 | AY32: 0 | AZ32: 0 | BA32: 0 | BB32: 0 | BC32: 0 | BD32: 0 | BE32: 0 | BF32: 0 | BG32: 0 | BH32: 0 | BI32: 0 | BJ32: 0 | BK32: 0 | BL32: 0 | BM32: 0 | BN32: 0 | BO32: 0 | BP32: 0 | BQ32: 0 | BR32: 0 | BS32: 0 | BT32: 0 | BU32: 0 | BV32: 0 | BW32: 0 | BX32: 0 | BY32: 0 | BZ32: 0 | CA32: 0 | CB32: 0 | CC32: 0 | CD32: 0 | CE32: 0 | CF32: 0 | CG32: 0 | CH32: 0
B33: New Investments | D33: sum | E33: =IF(D33="sum",SUM(G33:CH33),IF(D33="final",CH33,IF(D33="initial",G33,IF(D33="average",AVERAGE(G33:CH33),0)))) -> 20292708 | G33: =IF(G8=1,'Get Started 2'!$E120/'Get Started 2'!$E15*'Get Started 2'!$E100+G208*'Get Started 2'!$E100,0) -> 1203125 | H33: =IF(H8=1,'Get Started 2'!$E120/'Get Started 2'!$E15*'Get Started 2'!$E100+H208*'Get Started 2'!$E100,0) -> 1203125 | I33: =IF(I8=1,'Get Started 2'!$E120/'Get Started 2'!$E15*'Get Started 2'!$E100+I208*'Get Started 2'!$E100,0) -> 1203125 | J33: =IF(J8=1,'Get Started 2'!$E120/'Get Started 2'!$E15*'Get Started 2'!$E100+J208*'Get Started 2'!$E100,0) -> 1203125 | K33: =IF(K8=1,'Get Started 2'!$E120/'Get Started 2'!$E15*'Get Started 2'!$E100+K208*'Get Started 2'!$E100,0) -> 1203125 | L33: =IF(L8=1,'Get Started 2'!$E120/'Get Started 2'!$E15*'Get Started 2'!$E100+L208*'Get Started 2'!$E100,0) -> 1203125 | M33: =IF(M8=1,'Get Started 2'!$E120/'Get Started 2'!$E15*'Get Started 2'!$E100+M208*'Get Started 2'!$E100,0) -> 1203125 | N33: =IF(N8=1,'Get Started 2'!$E120/'Get Started 2'!$E15*'Get Started 2'!$E100+N208*'Get Started 2'!$E100,0) -> 1203125 | ... CH33: =IF(CH8=1,'Get Started 2'!$E120/'Get Started 2'!$E15*'Get Started 2'!$E100+CH208*'Get Started 2'!$E100,0) -> 0
B34: Prorata Opportunities | D34: sum | E34: =IF(D34="sum",SUM(G34:CH34),IF(D34="final",CH34,IF(D34="initial",G34,IF(D34="average",AVERAGE(G34:CH34),0)))) -> 0 | G34: 0 | H34: 0 | I34: 0 | J34: 0 | K34: 0 | L34: 0 | M34: 0 | N34: 0 | O34: 0 | P34: 0 | Q34: 0 | R34: 0 | S34: 0 | T34: 0 | U34: 0 | V34: 0 | W34: 0 | X34: 0 | Y34: 0 | Z34: 0 | AA34: 0 | AB34: 0 | AC34: 0 | AD34: 0 | AE34: 0 | AF34: 0 | AG34: 0 | AH34: 0 | AI34: 0 | AJ34: 0 | AK34: 0 | AL34: 0 | AM34: 0 | AN34: 0 | AO34: 0 | AP34: 0 | AQ34: 0 | AR34: 0 | AS34: 0 | AT34: 0 | AU34: 0 | AV34: 0 | AW34: 0 | AX34: 0 | AY34: 0 | AZ34: 0 | BA34: 0 | BB34: 0 | BC34: 0 | BD34: 0 | BE34: 0 | BF34: 0 | BG34: 0 | BH34: 0 | BI34: 0 | BJ34: 0 | BK34: 0 | BL34: 0 | BM34: 0 | BN34: 0 | BO34: 0 | BP34: 0 | BQ34: 0 | BR34: 0 | BS34: 0 | BT34: 0 | BU34: 0 | BV34: 0 | BW34: 0 | BX34: 0 | BY34: 0 | BZ34: 0 | CA34: 0 | CB34: 0 | CC34: 0 | CD34: 0 | CE34: 0 | CF34: 0 | CG34: 0 | CH34: 0
B35: Reserves for Follow on | C35: change in reserves per period, increase in reserves when new investments are made, decrease when follow on are made or investments are written off | D35: sum | E35: =IF(D35="sum",SUM(G35:CH35),IF(D35="final",CH35,IF(D35="initial",G35,IF(D35="average",AVERAGE(G35:CH35),0)))) -> 0 | G35: 0 | H35: 0 | I35: 0 | J35: 0 | K35: 0 | L35: 0 | M35: 0 | N35: 0 | O35: 0 | P35: 0 | Q35: 0 | R35: 0 | S35: 0 | T35: 0 | U35: 0 | V35: 0 | W35: 0 | X35: 0 | Y35: 0 | Z35: 0 | AA35: 0 | AB35: 0 | AC35: 0 | AD35: 0 | AE35: 0 | AF35: 0 | AG35: 0 | AH35: 0 | AI35: 0 | AJ35: 0 | AK35: 0 | AL35: 0 | AM35: 0 | AN35: 0 | AO35: 0 | AP35: 0 | AQ35: 0 | AR35: 0 | AS35: 0 | AT35: 0 | AU35: 0 | AV35: 0 | AW35: 0 | AX35: 0 | AY35: 0 | AZ35: 0 | BA35: 0 | BB35: 0 | BC35: 0 | BD35: 0 | BE35: 0 | BF35: 0 | BG35: 0 | BH35: 0 | BI35: 0 | BJ35: 0 | BK35: 0 | BL35: 0 | BM35: 0 | BN35: 0 | BO35: 0 | BP35: 0 | BQ35: 0 | BR35: 0 | BS35: 0 | BT35: 0 | BU35: 0 | BV35: 0 | BW35: 0 | BX35: 0 | BY35: 0 | BZ35: 0 | CA35: 0 | CB35: 0 | CC35: 0 | CD35: 0 | CE35: 0 | CF35: 0 | CG35: 0 | CH35: 0
B36: Follow on Investments | D36: sum | E36: =IF(D36="sum",SUM(G36:CH36),IF(D36="final",CH36,IF(D36="initial",G36,IF(D36="average",AVERAGE(G36:CH36),0)))) -> 0 | G36: ='Get Started 2'!$E122*G255 -> 0 | H36: ='Get Started 2'!$E122*H255 -> 0 | I36: ='Get Started 2'!$E122*I255 -> 0 | J36: ='Get Started 2'!$E122*J255 -> 0 | K36: ='Get Started 2'!$E122*K255 -> 0 | L36: ='Get Started 2'!$E122*L255 -> 0 | M36: ='Get Started 2'!$E122*M255 -> 0 | N36: ='Get Started 2'!$E122*N255 -> 0 | ... CH36: ='Get Started 2'!$E122*CH255 -> 0
B37: Total Investments, by cohort of New Investments | D37: sum | E37: =IF(D37="sum",SUM(G37:CH37),IF(D37="final",CH37,IF(D37="initial",G37,IF(D37="average",AVERAGE(G37:CH37),0)))) -> 20292708 | G37: =G33*'Get Started 2'!$F100/'Get Started 2'!$E100+G33+G32 -> 1203125 | H37: =H33*'Get Started 2'!$F100/'Get Started 2'!$E100+H33+H32 -> 1203125 | I37: =I33*'Get Started 2'!$F100/'Get Started 2'!$E100+I33+I32 -> 1203125 | J37: =J33*'Get Started 2'!$F100/'Get Started 2'!$E100+J33+J32 -> 1203125 | K37: =K33*'Get Started 2'!$F100/'Get Started 2'!$E100+K33+K32 -> 1203125 | L37: =L33*'Get Started 2'!$F100/'Get Started 2'!$E100+L33+L32 -> 1203125 | M37: =M33*'Get Started 2'!$F100/'Get Started 2'!$E100+M33+M32 -> 1203125 | N37: =N33*'Get Started 2'!$F100/'Get Started 2'!$E100+N33+N32 -> 1203125 | ... CH37: =CH33*'Get Started 2'!$F100/'Get Started 2'!$E100+CH33+CH32 -> 0
B38: Total Investments | D38: sum | E38: =IF(D38="sum",SUM(G38:CH38),IF(D38="final",CH38,IF(D38="initial",G38,IF(D38="average",AVERAGE(G38:CH38),0)))) -> 20292708 | G38: =SUM(G33,G36,G32) -> 1203125 | H38: =SUM(H33,H36,H32) -> 1203125 | I38: =SUM(I33,I36,I32) -> 1203125 | J38: =SUM(J33,J36,J32) -> 1203125 | K38: =SUM(K33,K36,K32) -> 1203125 | L38: =SUM(L33,L36,L32) -> 1203125 | M38: =SUM(M33,M36,M32) -> 1203125 | N38: =SUM(N33,N36,N32) -> 1203125 | ... CH38: =SUM(CH33,CH36,CH32) -> 0
B39: Organizational Expenses | D39: sum | E39: =IF(D39="sum",SUM(G39:CH39),IF(D39="final",CH39,IF(D39="initial",G39,IF(D39="average",AVERAGE(G39:CH39),0)))) -> 100000 | G39: =IF(G4=1,'Get Started 2'!$E11,0) -> 100000 | H39: =IF(H4=1,'Get Started 2'!$E11,0) -> 0 | I39: =IF(I4=1,'Get Started 2'!$E11,0) -> 0 | J39: =IF(J4=1,'Get Started 2'!$E11,0) -> 0 | K39: =IF(K4=1,'Get Started 2'!$E11,0) -> 0 | L39: =IF(L4=1,'Get Started 2'!$E11,0) -> 0 | M39: =IF(M4=1,'Get Started 2'!$E11,0) -> 0 | N39: =IF(N4=1,'Get Started 2'!$E11,0) -> 0 | ... CH39: =IF(CH4=1,'Get Started 2'!$E11,0) -> 0
B40: Operational Expenses | D40: sum | E40: =IF(D40="sum",SUM(G40:CH40),IF(D40="final",CH40,IF(D40="initial",G40,IF(D40="average",AVERAGE(G40:CH40),0)))) -> 750000 | G40: ='Get Started 2'!$E12*G10/4 -> 18750 | H40: ='Get Started 2'!$E12*H10/4 -> 18750 | I40: ='Get Started 2'!$E12*I10/4 -> 18750 | J40: ='Get Started 2'!$E12*J10/4 -> 18750 | K40: ='Get Started 2'!$E12*K10/4 -> 18750 | L40: ='Get Started 2'!$E12*L10/4 -> 18750 | M40: ='Get Started 2'!$E12*M10/4 -> 18750 | N40: ='Get Started 2'!$E12*N10/4 -> 18750 | ... CH40: ='Get Started 2'!$E12*CH10/4 -> 0
B41: Management Fees | D41: sum | E41: =IF(D41="sum",SUM(G41:CH41),IF(D41="final",CH41,IF(D41="initial",G41,IF(D41="average",AVERAGE(G41:CH41),0)))) -> 4900000 | G41: =IFERROR(IF(G15="committed",G83*IF($C17=TRUE,1-'Get Started 2'!$E10,1)*G14+IF(AND(G4<>1,G54*IF($C17=TRUE,1-'Get Started 2'!$E10,1)<>0,SUM($G54:G54)*IF($C17=TRUE,1-'Get Started 2'!$E10,1)<>E54*IF($C17=TRUE,1-'Get Started 2'!$E10,1)),G54*IF($C17=TRUE,1-'Get Started 2'!$E10,1)*(G4-1)*G14,0),IF(G15="called",G14*(G60+F60)/2*IF($C17=TRUE,1-'Get Started 2'!$E10,1),G14*(G85+F85)/2*IF($C17=TRUE,1-'Get Started 2'!$E10,1))),0) -> 122500 | H41: =IFERROR(IF(H15="committed",H83*IF($C17=TRUE,1-'Get Started 2'!$E10,1)*H14+IF(AND(H4<>1,H54*IF($C17=TRUE,1-'Get Started 2'!$E10,1)<>0,SUM($G54:H54)*IF($C17=TRUE,1-'Get Started 2'!$E10,1)<>F54*IF($C17=TRUE,1-'Get Started 2'!$E10,1)),H54*IF($C17=TRUE,1-'Get Started 2'!$E10,1)*(H4-1)*H14,0),IF(H15="called",H14*(H60+G60)/2*IF($C17=TRUE,1-'Get Started 2'!$E10,1),H14*(H85+G85)/2*IF($C17=TRUE,1-'Get Started 2'!$E10,1))),0) -> 122500 | I41: =IFERROR(IF(I15="committed",I83*IF($C17=TRUE,1-'Get Started 2'!$E10,1)*I14+IF(AND(I4<>1,I54*IF($C17=TRUE,1-'Get Started 2'!$E10,1)<>0,SUM($G54:I54)*IF($C17=TRUE,1-'Get Started 2'!$E10,1)<>G54*IF($C17=TRUE,1-'Get Started 2'!$E10,1)),I54*IF($C17=TRUE,1-'Get Started 2'!$E10,1)*(I4-1)*I14,0),IF(I15="called",I14*(I60+H60)/2*IF($C17=TRUE,1-'Get Started 2'!$E10,1),I14*(I85+H85)/2*IF($C17=TRUE,1-'Get Started 2'!$E10,1))),0) -> 122500 | J41: =IFERROR(IF(J15="committed",J83*IF($C17=TRUE,1-'Get Started 2'!$E10,1)*J14+IF(AND(J4<>1,J54*IF($C17=TRUE,1-'Get Started 2'!$E10,1)<>0,SUM($G54:J54)*IF($C17=TRUE,1-'Get Started 2'!$E10,1)<>H54*IF($C17=TRUE,1-'Get Started 2'!$E10,1)),J54*IF($C17=TRUE,1-'Get Started 2'!$E10,1)*(J4-1)*J14,0),IF(J15="called",J14*(J60+I60)/2*IF($C17=TRUE,1-'Get Started 2'!$E10,1),J14*(J85+I85)/2*IF($C17=TRUE,1-'Get Started 2'!$E10,1))),0) -> 122500 | K41: =IFERROR(IF(K15="committed",K83*IF($C17=TRUE,1-'Get Started 2'!$E10,1)*K14+IF(AND(K4<>1,K54*IF($C17=TRUE,1-'Get Started 2'!$E10,1)<>0,SUM($G54:K54)*IF($C17=TRUE,1-'Get Started 2'!$E10,1)<>I54*IF($C17=TRUE,1-'Get Started 2'!$E10,1)),K54*IF($C17=TRUE,1-'Get Started 2'!$E10,1)*(K4-1)*K14,0),IF(K15="called",K14*(K60+J60)/2*IF($C17=TRUE,1-'Get Started 2'!$E10,1),K14*(K85+J85)/2*IF($C17=TRUE,1-'Get Started 2'!$E10,1))),0) -> 122500 | L41: =IFERROR(IF(L15="committed",L83*IF($C17=TRUE,1-'Get Started 2'!$E10,1)*L14+IF(AND(L4<>1,L54*IF($C17=TRUE,1-'Get Started 2'!$E10,1)<>0,SUM($G54:L54)*IF($C17=TRUE,1-'Get Started 2'!$E10,1)<>J54*IF($C17=TRUE,1-'Get Started 2'!$E10,1)),L54*IF($C17=TRUE,1-'Get Started 2'!$E10,1)*(L4-1)*L14,0),IF(L15="called",L14*(L60+K60)/2*IF($C17=TRUE,1-'Get Started 2'!$E10,1),L14*(L85+K85)/2*IF($C17=TRUE,1-'Get Started 2'!$E10,1))),0) -> 122500 | M41: =IFERROR(IF(M15="committed",M83*IF($C17=TRUE,1-'Get Started 2'!$E10,1)*M14+IF(AND(M4<>1,M54*IF($C17=TRUE,1-'Get Started 2'!$E10,1)<>0,SUM($G54:M54)*IF($C17=TRUE,1-'Get Started 2'!$E10,1)<>K54*IF($C17=TRUE,1-'Get Started 2'!$E10,1)),M54*IF($C17=TRUE,1-'Get Started 2'!$E10,1)*(M4-1)*M14,0),IF(M15="called",M14*(M60+L60)/2*IF($C17=TRUE,1-'Get Started 2'!$E10,1),M14*(M85+L85)/2*IF($C17=TRUE,1-'Get Started 2'!$E10,1))),0) -> 122500 | N41: =IFERROR(IF(N15="committed",N83*IF($C17=TRUE,1-'Get Started 2'!$E10,1)*N14+IF(AND(N4<>1,N54*IF($C17=TRUE,1-'Get Started 2'!$E10,1)<>0,SUM($G54:N54)*IF($C17=TRUE,1-'Get Started 2'!$E10,1)<>L54*IF($C17=TRUE,1-'Get Started 2'!$E10,1)),N54*IF($C17=TRUE,1-'Get Started 2'!$E10,1)*(N4-1)*N14,0),IF(N15="called",N14*(N60+M60)/2*IF($C17=TRUE,1-'Get Started 2'!$E10,1),N14*(N85+M85)/2*IF($C17=TRUE,1-'Get Started 2'!$E10,1))),0) -> 122500 | ... CH41: =IFERROR(IF(CH15="committed",CH83*IF($C17=TRUE,1-'Get Started 2'!$E10,1)*CH14+IF(AND(CH4<>1,CH54*IF($C17=TRUE,1-'Get Started 2'!$E10,1)<>0,SUM($G54:CH54)*IF($C17=TRUE,1-'Get Started 2'!$E10,1)<>CF54*IF($C17=TRUE,1-'Get Started 2'!$E10,1)),CH54*IF($C17=TRUE,1-'Get Started 2'!$E10,1)*(CH4-1)*CH14,0),IF(CH15="called",CH14*(CH60+CG60)/2*IF($C17=TRUE,1-'Get Started 2'!$E10,1),CH14*(CH85+CG85)/2*IF($C17=TRUE,1-'Get Started 2'!$E10,1))),0) -> 0
B42: Recycled Capital | D42: sum | E42: =IF(D42="sum",SUM(G42:CH42),IF(D42="final",CH42,IF(D42="initial",G42,IF(D42="average",AVERAGE(G42:CH42),0)))) -> 1042708.3 | G42: =G208 -> 0 | H42: =H208 -> 0 | I42: =I208 -> 0 | J42: =J208 -> 0 | K42: =K208 -> 0 | L42: =L208 -> 0 | M42: =M208 -> 0 | N42: =N208 -> 0 | ... CH42: =CH208 -> 0
B43: Proceeds | D43: sum | E43: =IF(D43="sum",SUM(G43:CH43),IF(D43="final",CH43,IF(D43="initial",G43,IF(D43="average",AVERAGE(G43:CH43),0)))) -> 95669973 | G43: =IF(G4<'Get Started 2'!$H112,0,OFFSET(G37,0,-1*'Get Started 2'!$H112)*'Get Started 2'!$H42*'Get Started 2'!$G112)+IF(G4<'Get Started 2'!$H111,0,OFFSET(G37,0,-1*'Get Started 2'!$H111)*'Get Started 2'!$G42*'Get Started 2'!$G111)+IF(G4<'Get Started 2'!$H110,0,OFFSET(G37,0,-1*'Get Started 2'!$H110)*'Get Started 2'!$F42*'Get Started 2'!$G110)+IF(G4<'Get Started 2'!$H109,0,OFFSET(G37,0,-1*'Get Started 2'!$H109)*'Get Started 2'!$E42*'Get Started 2'!$G109) -> 0 | H43: =IF(H4<'Get Started 2'!$H112,0,OFFSET(H37,0,-1*'Get Started 2'!$H112)*'Get Started 2'!$H42*'Get Started 2'!$G112)+IF(H4<'Get Started 2'!$H111,0,OFFSET(H37,0,-1*'Get Started 2'!$H111)*'Get Started 2'!$G42*'Get Started 2'!$G111)+IF(H4<'Get Started 2'!$H110,0,OFFSET(H37,0,-1*'Get Started 2'!$H110)*'Get Started 2'!$F42*'Get Started 2'!$G110)+IF(H4<'Get Started 2'!$H109,0,OFFSET(H37,0,-1*'Get Started 2'!$H109)*'Get Started 2'!$E42*'Get Started 2'!$G109) -> 0 | I43: =IF(I4<'Get Started 2'!$H112,0,OFFSET(I37,0,-1*'Get Started 2'!$H112)*'Get Started 2'!$H42*'Get Started 2'!$G112)+IF(I4<'Get Started 2'!$H111,0,OFFSET(I37,0,-1*'Get Started 2'!$H111)*'Get Started 2'!$G42*'Get Started 2'!$G111)+IF(I4<'Get Started 2'!$H110,0,OFFSET(I37,0,-1*'Get Started 2'!$H110)*'Get Started 2'!$F42*'Get Started 2'!$G110)+IF(I4<'Get Started 2'!$H109,0,OFFSET(I37,0,-1*'Get Started 2'!$H109)*'Get Started 2'!$E42*'Get Started 2'!$G109) -> 0 | J43: =IF(J4<'Get Started 2'!$H112,0,OFFSET(J37,0,-1*'Get Started 2'!$H112)*'Get Started 2'!$H42*'Get Started 2'!$G112)+IF(J4<'Get Started 2'!$H111,0,OFFSET(J37,0,-1*'Get Started 2'!$H111)*'Get Started 2'!$G42*'Get Started 2'!$G111)+IF(J4<'Get Started 2'!$H110,0,OFFSET(J37,0,-1*'Get Started 2'!$H110)*'Get Started 2'!$F42*'Get Started 2'!$G110)+IF(J4<'Get Started 2'!$H109,0,OFFSET(J37,0,-1*'Get Started 2'!$H109)*'Get Started 2'!$E42*'Get Started 2'!$G109) -> 0 | K43: =IF(K4<'Get Started 2'!$H112,0,OFFSET(K37,0,-1*'Get Started 2'!$H112)*'Get Started 2'!$H42*'Get Started 2'!$G112)+IF(K4<'Get Started 2'!$H111,0,OFFSET(K37,0,-1*'Get Started 2'!$H111)*'Get Started 2'!$G42*'Get Started 2'!$G111)+IF(K4<'Get Started 2'!$H110,0,OFFSET(K37,0,-1*'Get Started 2'!$H110)*'Get Started 2'!$F42*'Get Started 2'!$G110)+IF(K4<'Get Started 2'!$H109,0,OFFSET(K37,0,-1*'Get Started 2'!$H109)*'Get Started 2'!$E42*'Get Started 2'!$G109) -> 0 | L43: =IF(L4<'Get Started 2'!$H112,0,OFFSET(L37,0,-1*'Get Started 2'!$H112)*'Get Started 2'!$H42*'Get Started 2'!$G112)+IF(L4<'Get Started 2'!$H111,0,OFFSET(L37,0,-1*'Get Started 2'!$H111)*'Get Started 2'!$G42*'Get Started 2'!$G111)+IF(L4<'Get Started 2'!$H110,0,OFFSET(L37,0,-1*'Get Started 2'!$H110)*'Get Started 2'!$F42*'Get Started 2'!$G110)+IF(L4<'Get Started 2'!$H109,0,OFFSET(L37,0,-1*'Get Started 2'!$H109)*'Get Started 2'!$E42*'Get Started 2'!$G109) -> 0 | M43: =IF(M4<'Get Started 2'!$H112,0,OFFSET(M37,0,-1*'Get Started 2'!$H112)*'Get Started 2'!$H42*'Get Started 2'!$G112)+IF(M4<'Get Started 2'!$H111,0,OFFSET(M37,0,-1*'Get Started 2'!$H111)*'Get Started 2'!$G42*'Get Started 2'!$G111)+IF(M4<'Get Started 2'!$H110,0,OFFSET(M37,0,-1*'Get Started 2'!$H110)*'Get Started 2'!$F42*'Get Started 2'!$G110)+IF(M4<'Get Started 2'!$H109,0,OFFSET(M37,0,-1*'Get Started 2'!$H109)*'Get Started 2'!$E42*'Get Started 2'!$G109) -> 0 | N43: =IF(N4<'Get Started 2'!$H112,0,OFFSET(N37,0,-1*'Get Started 2'!$H112)*'Get Started 2'!$H42*'Get Started 2'!$G112)+IF(N4<'Get Started 2'!$H111,0,OFFSET(N37,0,-1*'Get Started 2'!$H111)*'Get Started 2'!$G42*'Get Started 2'!$G111)+IF(N4<'Get Started 2'!$H110,0,OFFSET(N37,0,-1*'Get Started 2'!$H110)*'Get Started 2'!$F42*'Get Started 2'!$G110)+IF(N4<'Get Started 2'!$H109,0,OFFSET(N37,0,-1*'Get Started 2'!$H109)*'Get Started 2'!$E42*'Get Started 2'!$G109) -> 0 | ... CH43: =IF(CH4<'Get Started 2'!$H112,0,OFFSET(CH37,0,-1*'Get Started 2'!$H112)*'Get Started 2'!$H42*'Get Started 2'!$G112)+IF(CH4<'Get Started 2'!$H111,0,OFFSET(CH37,0,-1*'Get Started 2'!$H111)*'Get Started 2'!$G42*'Get Started 2'!$G111)+IF(CH4<'Get Started 2'!$H110,0,OFFSET(CH37,0,-1*'Get Started 2'!$H110)*'Get Started 2'!$F42*'Get Started 2'!$G110)+IF(CH4<'Get Started 2'!$H109,0,OFFSET(CH37,0,-1*'Get Started 2'!$H109)*'Get Started 2'!$E42*'Get Started 2'!$G109) -> 0
B44: Preferred Return | D44: sum | E44: =IF(D44="sum",SUM(G44:CH44),IF(D44="final",CH44,IF(D44="initial",G44,IF(D44="average",AVERAGE(G44:CH44),0)))) -> 0 | G44: 0 | H44: 0 | I44: 0 | J44: 0 | K44: 0 | L44: 0 | M44: 0 | N44: 0 | O44: 0 | P44: 0 | Q44: 0 | R44: 0 | S44: 0 | T44: 0 | U44: 0 | V44: 0 | W44: 0 | X44: 0 | Y44: 0 | Z44: 0 | AA44: 0 | AB44: 0 | AC44: 0 | AD44: 0 | AE44: 0 | AF44: 0 | AG44: 0 | AH44: 0 | AI44: 0 | AJ44: 0 | AK44: 0 | AL44: 0 | AM44: 0 | AN44: 0 | AO44: 0 | AP44: 0 | AQ44: 0 | AR44: 0 | AS44: 0 | AT44: 0 | AU44: 0 | AV44: 0 | AW44: 0 | AX44: 0 | AY44: 0 | AZ44: 0 | BA44: 0 | BB44: 0 | BC44: 0 | BD44: 0 | BE44: 0 | BF44: 0 | BG44: 0 | BH44: 0 | BI44: 0 | BJ44: 0 | BK44: 0 | BL44: 0 | BM44: 0 | BN44: 0 | BO44: 0 | BP44: 0 | BQ44: 0 | BR44: 0 | BS44: 0 | BT44: 0 | BU44: 0 | BV44: 0 | BW44: 0 | BX44: 0 | BY44: 0 | BZ44: 0 | CA44: 0 | CB44: 0 | CC44: 0 | CD44: 0 | CE44: 0 | CF44: 0 | CG44: 0 | CH44: 0
B45: GP Catchup | D45: sum | E45: =IF(D45="sum",SUM(G45:CH45),IF(D45="final",CH45,IF(D45="initial",G45,IF(D45="average",AVERAGE(G45:CH45),0)))) -> 0 | G45: 0 | H45: 0 | I45: 0 | J45: 0 | K45: 0 | L45: 0 | M45: 0 | N45: 0 | O45: 0 | P45: 0 | Q45: 0 | R45: 0 | S45: 0 | T45: 0 | U45: 0 | V45: 0 | W45: 0 | X45: 0 | Y45: 0 | Z45: 0 | AA45: 0 | AB45: 0 | AC45: 0 | AD45: 0 | AE45: 0 | AF45: 0 | AG45: 0 | AH45: 0 | AI45: 0 | AJ45: 0 | AK45: 0 | AL45: 0 | AM45: 0 | AN45: 0 | AO45: 0 | AP45: 0 | AQ45: 0 | AR45: 0 | AS45: 0 | AT45: 0 | AU45: 0 | AV45: 0 | AW45: 0 | AX45: 0 | AY45: 0 | AZ45: 0 | BA45: 0 | BB45: 0 | BC45: 0 | BD45: 0 | BE45: 0 | BF45: 0 | BG45: 0 | BH45: 0 | BI45: 0 | BJ45: 0 | BK45: 0 | BL45: 0 | BM45: 0 | BN45: 0 | BO45: 0 | BP45: 0 | BQ45: 0 | BR45: 0 | BS45: 0 | BT45: 0 | BU45: 0 | BV45: 0 | BW45: 0 | BX45: 0 | BY45: 0 | BZ45: 0 | CA45: 0 | CB45: 0 | CC45: 0 | CD45: 0 | CE45: 0 | CF45: 0 | CG45: 0 | CH45: 0
B46: Carried Interest | D46: sum | E46: =IF(D46="sum",SUM(G46:CH46),IF(D46="final",CH46,IF(D46="initial",G46,IF(D46="average",AVERAGE(G46:CH46),0)))) -> 13925453 | G46: =G194 -> 0 | H46: =H194 -> 0 | I46: =I194 -> 0 | J46: =J194 -> 0 | K46: =K194 -> 0 | L46: =L194 -> 0 | M46: =M194 -> 0 | N46: =N194 -> 0 | ... CH46: =CH194 -> 0
...

Sheet Get Started  3
B2: Get Started
B3: Key model assumptions and performance metrics
B5: Capital and Fund Assumptions
B6: Capital, Management Fees, base Fund-level assumptions
B8: Detail | C8: Unit | E8: Assumption | F8: Forecast | K8: Notes
B9: Total Commited Capital (Fund Size) | C9: ='Get Started'!C9 -> $ | E9: ='Get Started'!E9 -> 25000000 | F9: =E9 -> 25000000 | K9: Fund size. By default, assumes all committed capital is closed at the start. Can adjust that by modifying the committed capital on Forecast sheet.
B10: GP Commit, as % of committed capital | C10: % | E10: ='Get Started'!E10 -> 0.02 | F10: =E10*F$9 -> 500000 | K10: GP commit is treated as an LP interest for purposes of calculating mangement fees and carried interest. see glossary for additional details
B11: Organizational Expenses (one time) | C11: =C$9 -> $ | E11: ='Get Started'!E11 -> 100000 | F11: ='Forecast 3'!E39 -> 100000 | K11: paid by fund, in addition to management fees. one time costs associated with forming the fund, primarily legal fees
B12: Operational Expenses (annual) | C12: =C$9 -> $ | E12: ='Get Started'!E12 -> 75000 | F12: ='Forecast 3'!E40 -> 750000 | K12: paid by fund, in addition to management fees. see https://foresight.is/docs/management-company/ for more context. calculated based on the fund operations period for operating expenses
B13: Management Fees, per year, as % of committed capital | C13: % | E13: ='Get Started'!E13 -> 0.02 | F13: ='Forecast 3'!E41 -> 4900000 | K13: model works for management fees based on called and committed capital (can be edited for fee structures based on assets under management). if you have a management fee structure that steps down over time, you can edit the management fees directly on the Forecast sheet.
B14: Carry | C14: % | E14: ='Get Started'!E14 -> 0.2 | F14: =E124 -> 41159896 | K14: carry is the % of gains that are paid to the managers of the fund. part of the commonly cited "2 and 20" fees structure for funds
B15: Active Investment time period (quarters) | C15: # | E15: ='Get Started'!E15 -> 16 | K15: time period for new investments (follow ons by default assumed to come over time)
B16: Fund Duration (Management Fees time period) (quarters) | C16: # | E16: ='Get Started'!E16 -> 40 | K16: time period used for assuming management fees, tied to the fund duration and not including the fund extension period, if applicable
B17: Fund Operations time period (quarters) | C17: # | E17: ='Get Started'!E17 -> 40 | K17: time period used for assuming operational expenses, which is calculated from the new invesetment and exit timeframes, to cover the periods the fund incurrs operational expenses. you can override the calculated period if desired.
B18: Fund Duration Extension Period (quarters) | C18: # | E18: =MAX(0,E17-E16) -> 0 | K18: extra time period calculated from your deployment and holding period assumptions. purely for informational purposes, the model uses the fund duration for calculating management fees, this just shows how long of an extension you will need based on your assumptions
B21: Recycling
B22: Details on recycling provisions for closed end and evergreen funds | K22: more at https://foresight.is/docs/management-fee-recycling/
B24: Detail | C24: Unit | E24: Assumption | F24: Forecast | K24: Notes
B25: ="Target recycling %, and max achievable" -> Target recycling %, and max achievable | C25: % | E25: ='Get Started'!E25 -> 0.25 | F25: =IFERROR(F29/F26,0) -> 0.032083333 | K25: input is for the target % to recycle, and the forecast shows the % that is achievable given the parameters in the assumptions below. It is very common for the max acheivable to be less than the target. Note that LPAs may set the number differently; for example, some LPAs may note that recycling is 125% of committed capital (meaning that the total can be 25% higher than the amount of committed capital), or it may say that recycling is 25% of committed capital. They mean the same thing, but the number may be expressed differently. The model uses an assumption of 25% of recycling + 100% of committed capital = 125% of total committed capital plus recycling
B26: ="... based on "&E26 -> ... based on committed capital | C26: - | E26: ='Get Started'!E26 -> committed capital | F26: =IF(E26="management fees",F13,F9) -> 25000000 | K26: can be set to management fees or committed capital, and the forecast outputs the amount of it forecasted in the model
