Workbook
Name AnnExp: 'Annual Expense'!$A$1:$L$57
Name Basis: Basis!$A$1:$W$31
Name CostAllocation: 'Cost Allocation Basis'!$A$1:$O$53
Name CreditCalculation: 'CR Calculation'!$A$1:$I$33
Name EstimateCost: 'Cost Estimate'!$A$1:$G$66
Name LoanConstruction: 'Construction Loan'!$A$1:$J$53
Name Mortgage1: #REF!
Name Mortgage2: 'Interest Calculation'!$A$1:$G$30
Name Parish: '[1]2)Summary'!$H$8
Name Proforma15: 'Proforma (Reality) '!$A$1:$S$39
Name Proforma15: 'Proforma (Application)'!$A$1:$S$39
Name Rent: Rent!$A$1:$K$47
Name ReplacementReserve: 'Repl.-Reserve'!$A$1:$J$29
Name ScatteredSite: 'Cost by Building'!$A$1:$W$101
Name source: 'Sources & Uses'!$A$1:$I$83
Name SqFtg: 'Sq Footage'!$A$1:$O$114
Name TDCPERUNIT: 'Cost by Building'!$A$1:$U$19
Name TotalOperating: Expenses!$C$51
Name Units: '[1]2)Summary'!$D$11
Name utility: 'Utility Allowance'!$A$1:$K$21

Sheet 0000

Sheet Recovered_Sheet1

Sheet Source Use  OS
A1: Hollywood Acres | E1: =+B81 -> 72 | F1: New Construction
A2: Sources And Uses Statement | F2: =+Rent!C3 -> Augusta GA | T2: Workspace and Notes
A4: Sources: | AI4: Source of Funds
T5: Other Sources of Funds | AI5: Bond Funds (Interim) | AJ5: 4000000
A6: First Mortgage - HOPE | F6: =+#REF! -> #REF! | T6: GP Capital | V6: 100 | AI6: =+A6 -> First Mortgage - HOPE | AJ6: =+F6 -> #REF!
A7: Second Mortgage - CDBG | F7: =+'Interest Calculation'!C4 -> 18500000 | T7: SLP Capital | V7: 239 | AI7: =+A7 -> Second Mortgage - CDBG | AJ7: =+F7 -> 18500000
A8: Other Sources of Funds | C8: SLP-GP | F8: =+AJ8+AJ9 -> 339 | V8: 0 | AI8: Other - SLP | AJ8: 239
A9: Total Sources From Debt | I9: =SUM(F6:F8) -> #REF! | V9: =SUM(V6:V8) -> 339 | AI9: Other - GP | AJ9: 100
A10: Deferred Development Fee | H10: Cash Shortfall | I10: =+'Sources & Uses'!#REF! -> #REF! | AI10: =+A10 -> Deferred Development Fee | AJ10: =+I10 -> #REF!
A11: Sub Total - Sources for Gap Calculation | I11: =SUM(I9:I10) -> #REF! | K11: =SUM(I11) -> #REF! | T11: Land Acquisition Price | V11: 500000
M12: Must Be Zero
A13: Tax Credit - LP Equity Contribution | I13: =+'Sources & Uses'!I10-F8 -> 24499661 | K13: =+'CR Calculation'!F30 -> 3825871.7 | M13: =SUM(I13-K13) -> 20673789 | T13: Construction Breakdown: | AI13: =+A13 -> Tax Credit - LP Equity Contribution | AJ13: =+I13 -> 24499661
A14: TOTAL SOURCES | I14: =SUM(I11:I13) -> #REF! | K14: =SUM(I14) -> #REF! | T14: Total Land Improvements | V14: 204405
T15: Construction Hard Cost | V15: 4245865 | AJ15: =SUM(AJ5:AJ13) -> #REF!
F16: Uses included in | H16: Uses excluded from | T16: Total Hard Cost | V16: =SUM(V14:V15) -> 4450270
A17: Uses: | F17: Total Dev. Fee Cal. | H17: Total Dev. Fee Cal. | T17: Per Unit Hard Costs | V17: =+V16/E1 -> 61809.306
A19: Land | B19: Acres/Price | D19: 0 | E19: =+'Sources & Uses'!E16 -> 0 | H19: =+E19 -> 0 | T19: Pojected Hard Cost Contingency | V19: 255000 | X19: 5344695 | Y19: =+E27 -> 5349669.1 | AI19: =+A19 -> Land | AJ19: =+'Sources & Uses'!V11 -> 0 | AK19: Per D Stromburg 11.25.19
A20: Building Acquistion | H20: =+E19-H19 -> 0
A21: Land Improvements
A22: Unusual Land Improvements | V22: =SUM(V19:V21) -> 255000
A23: Other Land Improvements | F23: 0
A24: Sub-Total Land Improvements | F24: =SUM(F22:F23) -> 0 | T24: Deferred Developer Fee Analysis
T25: Max Deferred Fee (50% 15 Year Cash Flow) | V25: =+'Proforma (Application)'!S33 -> 0 | AI25: Construction Hard Cost
A26: Buildings | T26: Projected Deferred Fee | V26: =+I10+M13 -> #REF!
A27: Construction Hard Costs | C27: Ttl Constr Contract | E27: =SUM(F24+F27+F28+F29+F33+F34)+F35 -> 5349669.1 | F27: =+E1*H88 -> 4450270 | T27: Cash Flow For Soft Debt | V27: =+V25-V26 -> #REF! | AI27: =+A27 -> Construction Hard Costs | AJ27: =+F27 -> 4450270
A28: (Contingency) Hard Costs | E28: =+F28/SUM(E27-V22) -> 0.050052318 | F28: =+V22 -> 255000 | T28: Deferred Fee Feasibility | V28: =IF(V25>V26,"TEST MET","TEST NOT MET") -> #REF! | AI28: =+A28 -> (Contingency) Hard Costs | AJ28: =+F28 -> 255000
A29: General Requirements | E29: 0.06 | F29: =SUM(F27*E29) -> 267016.2 | AI29: =+A29 -> General Requirements | AJ29: =+F29 -> 267016.2
A30: Sub-Total Buildings | F30: =SUM(F27:F29) -> 4972286.2 | AI30: =+A33 -> Builders Profit | AJ30: =+F33 -> 283037.17
AI31: =+A34 -> Builders O/H (2%) | AJ31: =+F34 -> 94345.724
A32: Fees | AI32: Total Const. Costs | AJ32: =SUM(AJ27:AJ31) -> 5349669.1
A33: Builders Profit | E33: 0.06 | F33: =SUM(F27+F29)*E33 -> 283037.17
A34: Builders O/H (2%) | E34: 0.02 | F34: =SUM(F27+F29)*E34 -> 94345.724 | T34: Architect Worksheet: | AI34: Const. Soft Costs
A35: Bond Premium/Impact Fees | F35: 0 | T35: Architect Contract: | U35: 0.8 | V35: =SUM(V38*U35) -> 61600 | AI35: =+A36 -> Architects Fee-Design | AJ35: =+F36 -> 61600
A36: Architects Fee-Design | D36: =+U35 -> 0.8 | E36: 0.04 | F36: =+V35 -> 61600 | U36: 0.2 | V36: =SUM(V38*U36) -> 15400 | AI36: =+A37 -> Architects Fee-Supervision | AJ36: =+F37 -> 15400
A37: Architects Fee-Supervision | D37: =+U36 -> 0.2 | F37: =+V36 -> 15400 | G37: =SUM(F37) -> 15400 | H37: =SUM(F36:F37) -> 77000 | U37: =+V37/E27 -> 0.014393414 | V37: =+V35+V36 -> 77000 | AI37: =+A38 -> Other- Engineering | AJ37: =+F38 -> 41900
A38: Other- Engineering | F38: =35000+6900 -> 41900 | T38: Total Fees | U38: Fixed Fee | V38: 77000 | AI38: =+A46 -> Taxes | AJ38: =+F46 -> 5000
A39: Sub-Total Fees | F39: =SUM(F33:F38) -> 496282.9 | T39: Legal Fees Breakdown | AI39: =+A47 -> Insurance | AJ39: =+F47 -> 25000
U40: Basis Elig. | AI40: =+A53 -> CPA Fees | AJ40: =+F53 -> 10000
A41: Charges and Financing | T41: Real Estate Legal | U41: x | V41: 35000 | W41: =IF(U41="x",V41/V$46,0) -> 0.2991453 | Y41: Regions | AE41: 41000 | AI41: =+A55 -> Cost Certification | AJ41: =+F55 -> 15000
A42: Interest | F42: =+'Construction Loan'!E34 -> #REF! | T42: Lender Legal Const | U42: x | V42: =15000+10000 -> 25000 | W42: =IF(U42="x",V42/V$46,0) -> 0.21367521 | Y42: CR | AE42: 55000 | AI42: =+A62 -> Other Third Party Costs | AJ42: =+F62 -> 146419
...

Sheet Modeling Assp Wkst
O3: PH I | P3: PH II | Q3: PH III | R3: Total
M4: Total Units Original Submission | O4: 213 | P4: 213 | Q4: 174 | R4: =SUM(O4:Q4) -> 600
M5: Total Units - Proposed Submission | R5: =+'Sources & Uses'!E1 -> 72
N6: All Phases
B7: Phase I | D7: Phase II | F7: Phase III | I7: Total | N7: Per Unit
A8: ITEM | B8: COST | C8: % TOTAL | D8: COST | E8: % TOTAL | F8: COST | G8: % TOTAL | I8: All Phases
A9: ACQUISITION
A10: Build Acquisition | C10: =IF($B$70>0,B10/$B$70,B10/1) -> 0 | E10: =IF($D$70>0,D10/$D$70,D10/1) -> 0 | G10: =IF($F$70>0,F10/$F$70,F10/1) -> 0 | I10: =SUM(B10+D10+F10) -> 0
A11: Land Acquisition | B11: 250000 | C11: =IF($B$70>0,B11/$B$70,B11/1) -> 0.0054224872 | D11: 0 | E11: =IF($D$70>0,D11/$D$70,D11/1) -> 0 | F11: 0 | G11: =IF($F$70>0,F11/$F$70,F11/1) -> 0 | I11: =SUM(B11+D11+F11) -> 250000 | K11: =+I11 -> 250000
A12: SITE IMPROVEMENTS
A13: Demolition | B13: 0 | C13: =IF($B$70>0,B13/$B$70,B13/1) -> 0 | D13: 0 | E13: =IF($D$70>0,D13/$D$70,D13/1) -> 0 | F13: 0 | G13: =IF($F$70>0,F13/$F$70,F13/1) -> 0 | I13: =SUM(B13+D13+F13) -> 0
A14: On-Site Imp. | B14: 1217200 | C14: =IF($B$70>0,B14/$B$70,B14/1) -> 0.026401006 | D14: 1278060 | E14: =IF($D$70>0,D14/$D$70,D14/1) -> 0.02711791 | F14: =(1217200*1.1)*0.82 -> 1097914.4 | G14: =IF($F$70>0,F14/$F$70,F14/1) -> 0.027055514 | I14: =SUM(B14+D14+F14) -> 3593174.4 | M14: Construction Costs were provided by client
A15: Off-Site Imp. | C15: =IF($B$70>0,B15/$B$70,B15/1) -> 0 | E15: =IF($D$70>0,D15/$D$70,D15/1) -> 0 | G15: =IF($F$70>0,F15/$F$70,F15/1) -> 0 | I15: =SUM(B15+D15+F15) -> 0 | M15: Construction Costs were provided by client
A16: CONSTRUCTION | M16: Construction Costs were provided by client
A17: Rehabilitation | C17: =IF($B$70>0,B17/$B$70,B17/1) -> 0 | E17: =IF($D$70>0,D17/$D$70,D17/1) -> 0 | G17: =IF($F$70>0,F17/$F$70,F17/1) -> 0 | I17: =SUM(B17+D17+F17) -> 0 | M17: Construction Costs were provided by client
A18: New Construction | B18: 29010676 | C18: =IF($B$70>0,B18/$B$70,B18/1) -> 0.62924008 | D18: 30461210 | E18: =IF($D$70>0,D18/$D$70,D18/1) -> 0.64632673 | F18: =(29010676*1.1)*0.82 -> 26167630 | G18: =IF($F$70>0,F18/$F$70,F18/1) -> 0.64483959 | I18: =SUM(B18+D18+F18) -> 85639516 | M18: Construction Costs were provided by client
A19: General Requirements | B19: 2531830 | C19: =IF($B$70>0,B19/$B$70,B19/1) -> 0.054915263 | D19: 1827673 | E19: =IF($D$70>0,D19/$D$70,D19/1) -> 0.038779613 | F19: =F18*0.06 -> 1570057.8 | G19: =IF($F$70>0,F19/$F$70,F19/1) -> 0.038690375 | I19: =SUM(B19+D19+F19) -> 5929560.8 | M19: Construction Costs were provided by client
A20: Contractor Overhead | B20: 596000 | C20: =IF($B$70>0,B20/$B$70,B20/1) -> 0.012927209 | D20: 609224 | E20: =IF($D$70>0,D20/$D$70,D20/1) -> 0.01292653 | F20: =F18*0.02 -> 523352.6 | G20: =IF($F$70>0,F20/$F$70,F20/1) -> 0.012896792 | I20: =SUM(B20+D20+F20) -> 1728576.6 | M20: Construction Costs were provided by client
A21: Contractor Profit | B21: 1450534 | C21: =IF($B$70>0,B21/$B$70,B21/1) -> 0.031462008 | D21: 1523060 | E21: =IF($D$70>0,D21/$D$70,D21/1) -> 0.032316326 | F21: =F18*0.05 -> 1308381.5 | G21: =IF($F$70>0,F21/$F$70,F21/1) -> 0.03224198 | I21: =SUM(B21+D21+F21) -> 4281975.5 | M21: Construction Costs were provided by client
A22: P & P Bond or LOC | B22: 179050 | C22: =IF($B$70>0,B22/$B$70,B22/1) -> 0.0038835853 | D22: 179050 | E22: =IF($D$70>0,D22/$D$70,D22/1) -> 0.0037990875 | F22: 150000 | G22: =IF($F$70>0,F22/$F$70,F22/1) -> 0.0036963966 | I22: =SUM(B22+D22+F22) -> 508100 | M22: Construction Costs were provided by client
A23: Contingency | B23: 2610961 | C23: =IF($B$70>0,B23/$B$70,B23/1) -> 0.05663161 | D23: 2741509 | E23: =IF($D$70>0,D23/$D$70,D23/1) -> 0.058169408 | F23: =F18*0.09 -> 2355086.7 | G23: =IF($F$70>0,F23/$F$70,F23/1) -> 0.058035563 | I23: =SUM(B23+D23+F23) -> 7707556.7 | M23: Construction Costs were provided by client
A24: Permits & Impact Fees | B24: 180120 | C24: =IF($B$70>0,B24/$B$70,B24/1) -> 0.0039067936 | D24: 180120 | E24: =IF($D$70>0,D24/$D$70,D24/1) -> 0.0038217908 | F24: 150000 | G24: =IF($F$70>0,F24/$F$70,F24/1) -> 0.0036963966 | I24: =SUM(B24+D24+F24) -> 510240 | M24: Construction Costs were provided by client
A25: Furnishings | B25: 956000 | C25: =IF($B$70>0,B25/$B$70,B25/1) -> 0.020735591 | D25: 1003800 | E25: =IF($D$70>0,D25/$D$70,D25/1) -> 0.021298654 | F25: =((478000*2)*1.1)*0.82 -> 862312 | G25: =IF($F$70>0,F25/$F$70,F25/1) -> 0.021249648 | I25: =SUM(B25+D25+F25) -> 2822112 | M25: Construction Costs were provided by client
A26: Relocation | C26: =IF($B$70>0,B26/$B$70,B26/1) -> 0 | E26: =IF($D$70>0,D26/$D$70,D26/1) -> 0 | G26: =IF($F$70>0,F26/$F$70,F26/1) -> 0 | I26: =SUM(B26+D26+F26) -> 0
A27: Other | C27: =IF($B$70>0,B27/$B$70,B27/1) -> 0 | E27: =IF($D$70>0,D27/$D$70,D27/1) -> 0 | G27: =IF($F$70>0,F27/$F$70,F27/1) -> 0 | I27: =SUM(B27+D27+F27) -> 0
A28: PROFESSIONAL FEES
A29: Architect & Engineer | B29: =B18*0.06 -> 1740640.6 | C29: =IF($B$70>0,B29/$B$70,B29/1) -> 0.037754405 | D29: =D18*0.06 -> 1827672.6 | E29: =IF($D$70>0,D29/$D$70,D29/1) -> 0.038779604 | F29: =F18*0.06 -> 1570057.8 | G29: =IF($F$70>0,F29/$F$70,F29/1) -> 0.038690375 | I29: =SUM(B29+D29+F29) -> 5138370.9 | K29: =SUM('Sources & Uses'!F24*L29) -> 554921.44 | L29: =IF($I$70>0,I29/$I$70,I29/1) -> 0.038399323 | M29: Calculated by average % of all phases X construction costs provided by client
A30: Real Estate Legal | B30: 200000 | C30: =IF($B$70>0,B30/$B$70,B30/1) -> 0.0043379898 | D30: 200000 | E30: =IF($D$70>0,D30/$D$70,D30/1) -> 0.0042436051 | F30: 200000 | G30: =IF($F$70>0,F30/$F$70,F30/1) -> 0.0049285289 | I30: =SUM(B30+D30+F30) -> 600000 | K30: =SUM(R$5*N30) -> 72000 | L30: =IF($I$70>0,I30/$I$70,I30/1) -> 0.0044838323 | M30: Calculated on Per Unit Basis | N30: =SUM(I30/R$4) -> 1000
A31: Consultants | B31: 132000 | C31: =IF($B$70>0,B31/$B$70,B31/1) -> 0.0028630732 | D31: 132000 | E31: =IF($D$70>0,D31/$D$70,D31/1) -> 0.0028007794 | F31: 132000 | G31: =IF($F$70>0,F31/$F$70,F31/1) -> 0.003252829 | I31: =SUM(B31+D31+F31) -> 396000 | K31: =SUM(R$5*N31) -> 47520 | L31: =IF($I$70>0,I31/$I$70,I31/1) -> 0.0029593293 | M31: Calculated on Per Unit Basis | N31: =SUM(I31/R$4) -> 660
A32: Developer Fee | B32: =(B18*0.09) -> 2610960.8 | C32: =IF($B$70>0,B32/$B$70,B32/1) -> 0.056631607 | D32: =(D18*0.09) -> 2741508.9 | E32: =IF($D$70>0,D32/$D$70,D32/1) -> 0.058169406 | F32: =(F18*0.09) -> 2355086.7 | G32: =IF($F$70>0,F32/$F$70,F32/1) -> 0.058035563 | I32: =SUM(B32+D32+F32) -> 7707556.4 | L32: =IF($I$70>0,I32/$I$70,I32/1) -> 0.057598984 | M32: Calculated per LHC Formula
A33: Environmental | B33: 50000 | C33: =IF($B$70>0,B33/$B$70,B33/1) -> 0.0010844974 | D33: 0 | E33: =IF($D$70>0,D33/$D$70,D33/1) -> 0 | F33: 0 | G33: =IF($F$70>0,F33/$F$70,F33/1) -> 0 | I33: =SUM(B33+D33+F33) -> 50000 | K33: =SUM(R$5*N33) -> 6000 | L33: =IF($I$70>0,I33/$I$70,I33/1) -> 0.00037365269 | N33: =SUM(I33/R$4) -> 83.333333
A34: Cost Certification | B34: 5000 | C34: =IF($B$70>0,B34/$B$70,B34/1) -> 0.00010844974 | D34: 5000 | E34: =IF($D$70>0,D34/$D$70,D34/1) -> 0.00010609013 | F34: 5000 | G34: =IF($F$70>0,F34/$F$70,F34/1) -> 0.00012321322 | I34: =SUM(B34+D34+F34) -> 15000 | K34: 25000 | L34: =IF($I$70>0,I34/$I$70,I34/1) -> 0.00011209581 | M34: Re-allocated per LHC average for similar development
A35: Accounting | B35: 25000 | C35: =IF($B$70>0,B35/$B$70,B35/1) -> 0.00054224872 | D35: 25000 | E35: =IF($D$70>0,D35/$D$70,D35/1) -> 0.00053045064 | F35: 25000 | G35: =IF($F$70>0,F35/$F$70,F35/1) -> 0.00061606611 | I35: =SUM(B35+D35+F35) -> 75000 | K35: =SUM(R$5*N35) -> 9000 | L35: =IF($I$70>0,I35/$I$70,I35/1) -> 0.00056047904 | M35: Calculated on Per Unit Basis | N35: =SUM(I35/R$4) -> 125
A36: Survey | B36: 12000 | C36: =IF($B$70>0,B36/$B$70,B36/1) -> 0.00026027939 | D36: 12000 | E36: =IF($D$70>0,D36/$D$70,D36/1) -> 0.00025461631 | F36: 12000 | G36: =IF($F$70>0,F36/$F$70,F36/1) -> 0.00029571173 | I36: =SUM(B36+D36+F36) -> 36000 | K36: =SUM(R$5*N36) -> 4320 | L36: =IF($I$70>0,I36/$I$70,I36/1) -> 0.00026902994 | M36: Calculated on Per Unit Basis | N36: =SUM(I36/R$4) -> 60
A37: GeoTech | B37: 20000 | C37: =IF($B$70>0,B37/$B$70,B37/1) -> 0.00043379898 | D37: 20000 | E37: =IF($D$70>0,D37/$D$70,D37/1) -> 0.00042436051 | F37: 20000 | G37: =IF($F$70>0,F37/$F$70,F37/1) -> 0.00049285289 | I37: =SUM(B37+D37+F37) -> 60000 | K37: =SUM(R$5*N37) -> 7200 | L37: =IF($I$70>0,I37/$I$70,I37/1) -> 0.00044838323 | M37: Calculated on Per Unit Basis | N37: =SUM(I37/R$4) -> 100
A38: CONSTRUCTION FINANCE | C38: =IF($B$70>0,B38/$B$70,B38/1) -> 0
A39: Title and Recording | B39: =500*200 -> 100000 | C39: =IF($B$70>0,B39/$B$70,B39/1) -> 0.0021689949 | D39: =500*200 -> 100000 | E39: =IF($D$70>0,D39/$D$70,D39/1) -> 0.0021218026 | F39: =500*200 -> 100000 | G39: =IF($F$70>0,F39/$F$70,F39/1) -> 0.0024642644 | I39: =SUM(B39+D39+F39) -> 300000 | K39: =SUM(R$5*N39) -> 36000 | L39: =IF($I$70>0,I39/$I$70,I39/1) -> 0.0022419162 | M39: Calculated on Per Unit Basis | N39: =SUM(I39/R$4) -> 500
A40: Constr. Interest | B40: 185000 | C40: =IF($B$70>0,B40/$B$70,B40/1) -> 0.0040126405 | D40: 185000 | E40: =IF($D$70>0,D40/$D$70,D40/1) -> 0.0039253347 | F40: 185000 | G40: =IF($F$70>0,F40/$F$70,F40/1) -> 0.0045588892 | I40: =SUM(B40+D40+F40) -> 555000 | L40: =IF($I$70>0,I40/$I$70,I40/1) -> 0.0041475449 | M40: calculated in L&A model
A41: Constr. Loan Fees | B41: 40000 | C41: =IF($B$70>0,B41/$B$70,B41/1) -> 0.00086759795 | D41: 40000 | E41: =IF($D$70>0,D41/$D$70,D41/1) -> 0.00084872103 | F41: 40000 | G41: =IF($F$70>0,F41/$F$70,F41/1) -> 0.00098570577 | I41: =SUM(B41+D41+F41) -> 120000 | L41: =IF($I$70>0,I41/$I$70,I41/1) -> 0.00089676646 | M41: Calculated 1% Loan Amount L&A Model
A42: Appraisal | B42: =200*300 -> 60000 | C42: =IF($B$70>0,B42/$B$70,B42/1) -> 0.0013013969 | D42: =200*300 -> 60000 | E42: =IF($D$70>0,D42/$D$70,D42/1) -> 0.0012730815 | F42: =200*300 -> 60000 | G42: =IF($F$70>0,F42/$F$70,F42/1) -> 0.0014785587 | I42: =SUM(B42+D42+F42) -> 180000 | K42: =SUM(R$5*N42) -> 21600 | L42: =IF($I$70>0,I42/$I$70,I42/1) -> 0.0013451497 | M42: Calculated on Per Unit Basis | N42: =SUM(I42/R$4) -> 300
...

Sheet Construction Breakdown (PBC)
A2: Calliope Senior Village | F2: Per
A3: Original Assumptions | C3: 355 | D3: units | F3: Unit
A4: Original Assumptions | C4: 328000 | D4: SF | F4: Cost
A5: Updated on Per unit Basis - 2/5/19 | F5: 355 Units
A6: SITE IMPROVEMENTS
A7: Demolition
A8: On-Site Improvements | C8: 1566510 | F8: =SUM(C8/C$3) -> 4412.7042
A9: Off-Site Improvements
A11: CONSTRUCTION | E11: Fees to S/U
A12: Rehabilitation | C12: 2640000 | F12: 0
A13: New Construction | C13: 50361930 | F13: =SUM(C13/C$3) -> 141864.59
A14: Gen Requirements | C14: 3548750 | D14: =-C14+'Sources & Uses'!F26 -> -3259723.3 | E14: =SUM(C14:D14) -> 289026.68 | F14: =SUM(C14/C$3) -> 9996.4789
A15: Contractor Overhead | C15: 1073724 | E15: =+C15 -> 1073724 | F15: =SUM(C15/C$3) -> 3024.5746
A16: Contractor Profit | C16: 2135784 | D16: =-D14 -> 3259723.3 | E16: =SUM(C16:D16) -> 5395507.3 | F16: =SUM(C16/C$3) -> 6016.293
A17: P & P Bond | C17: 319152 | F17: =SUM(C17/C$3) -> 899.01972
A18: Contingency | C18: 4300000 | F18: =SUM(C18/C$3) -> 12112.676
A19: Permits & Impact Fees | C19: 321059 | F19: =SUM(C19/C$3) -> 904.39155
A20: Furnishings | C20: 223735 | F20: =SUM(C20/C$3) -> 630.23944
A22: TOTAL | C22: =SUM(C8:C20) -> 66490644
A23: Variance to S/U | C23: =+C22-'Sources & Uses'!E24 -> 52039310
C24: =C22/C3 -> 187297.59 | D24: cost/unit
C25: =C22/C4 -> 202.71538 | D25: cost/sf
A29: Total Hard Costs | C29: =SUM(C8:C13)+C20 -> 54792175 | D29: =+C29/C3 -> 154344.15
A30: Gen. Requirement | C30: =SUM(C14) -> 3548750 | D30: =+C30/C29 -> 0.06476746
A33: LHC Calculated Fee Limits:
A35: General Requirement | B35: 0.06 | C35: =SUM(C29*B35) -> 3287530.5 | D35: =+E14 -> 289026.68 | E35: =IF(D35+C35,"TEST MET","TEST NOT MET") -> TEST MET
A36: Overhead | B36: 0.02 | C36: =SUM(C29+C35)*B36 -> 1161594.1 | D36: =+E15 -> 1073724 | E36: =IF(D36+C36,"TEST MET","TEST NOT MET") -> TEST MET
A37: Builder Profit | B37: 0.06 | C37: =SUM(C29+C35)*B37 -> 3484782.3 | D37: =+E16 -> 5395507.3 | E37: =IF(D37+C37,"TEST MET","TEST NOT MET") -> TEST MET

Sheet Intermediary Cost
A1: =+'Sources & Uses'!A1 -> Lamar Building
A2: Intermediary Cost Worksheet
A5: Total Development Costs | F5: =+'Sources & Uses'!I75 -> 24500000
A8: Intermediary Costs:
A10: General Overhead | F10: =+'Sources & Uses'!F30 -> 722566.7
A11: Builder's Profit | F11: =+'Sources & Uses'!F31 -> 221105.41
A12: Developer Fee | F12: =+'Sources & Uses'!#REF! -> #REF!
A13: Syndication Costs | F13: =+'Sources & Uses'!F73 -> 0
A14: Architect's Fees | F14: =+'Sources & Uses'!F33+'Sources & Uses'!F34 -> 400000
A15: Legal Fees | F15: =+'Sources & Uses'!F48 -> 50000
A16: Organization Costs | F16: =+'Sources & Uses'!F50 -> 0
A17: Other Fees | F17: 0
A19: Total Intermediary Costs | F19: =SUM(F10:F18) -> #REF!
A22: Percentage of Total Development Costs | F22: =SUM(F19/F5) -> #REF!

Sheet TDC Per Unit
A1: =+'Sources & Uses'!A1 -> Lamar Building
A2: Calculation of TDC per Unit (Per QAP)
A6: Total Development Costs | H6: =+'Sources & Uses'!I75 -> 24500000
A8: Less Non-Basis Allowable Deletions:
B10: Permanent Financing Fee (2% of Loan Max.) | G10: 0
B11: Organization Costs ( 25,000 Max.) | G11: 0
B12: Non Eligible Legal | G12: =+'[2]Cost Allocation Basis'!I34 -> 0
B13: Community Facility | G13: 55000
B14: Reserves | G14: =+'Sources & Uses'!H65 -> 0
B15: Total Allowable Deletions | H15: =SUM(G10:G14) -> 55000
B17: Total Development Costs | H17: =SUM(H6-H15) -> 24445000
B19: Total Development Costs Per Unit | H19: =SUM(H17/'Sources & Uses'!B77) -> 339513.89
B21: Total Square Footage: | D21: Gross | H21: =+'Sq Footage'!L103 -> 155913
D22: Net | H22: =+H21 -> 155913
B23: TDC Per Square Footage - Gross | H23: =SUM(H17/H21) -> 156.78616 | I23: 105 | J23: =SUM(H23-I23) -> 51.786156 | K23: Variance Sq. Ftg.
J24: =SUM(H21*J23) -> 8074135 | K24: Cost Variance

Sheet Sources & Uses
A1: Lamar Building | E1: =+Rent!C44 -> 72 | F1: Acquisition/Rehabilitation
A2: Sources And Uses Statement | F2: Augusta GA | T2: Workspace and Notes
A4: Sources:
T5: Other Sources of Funds
A6: Construction Loan | F6: 18500000 | T6: =+'Interest Calculation'!G1 -> 0 | U6: Soft | V6: 0
T7: Other Sources of Funds | U7: Seller Note | V7: 0
A8: Equity | F8: 6000000 | V8: 0
A9: Total Sources From Debt and Equity | F9: =+F6+F7+F8 -> 24500000 | V9: =SUM(V6:V8) -> 0
A10: TOTAL SOURCES | I10: =+F9 -> 24500000
T11: Land Acquisition Price | U11: 127000 | V11: 0
T12: Buildng Acquisition | U12: 5000000 | V12: =+U12 -> 5000000
M13: =+I10 -> 24500000 | T13: Construction Breakdown:
A14: Uses: | T14: Total Land Improvements | V14: 201000
T15: Construction Hard Cost | V15: =+E1*190000 -> 13680000
A16: Land | B16: Acres/Price | D16: 0 | E16: =+V11 -> 0 | F16: 5000000 | G16: x | T16: Total Hard Cost | V16: =+V15+V14 -> 13881000
A17: Building Acquistion | G17: x | T17: Per Unit Hard Costs | V17: =+V16/E1 -> 192791.67
A18: Land Improvements
A19: Unusual Land Improvements | T19: Projected Hard Cost Contingency | V19: =+V16*0.1 -> 1388100
A20: Other Land Improvements | F20: 0 | T20: Excess OH; GR; BP | V20: 0
A21: Sub-Total Land Improvements | F21: =SUM(F19:F20) -> 0
T22: Total Contingency (Including Excess Bldr Fees. | V22: =SUM(V19:V21) -> 1388100
A23: Buildings
A24: Construction Hard Costs | C24: Ttl Constr Contract | E24: 14451334 | F24: 14451334 | G24: x
A25: (Contingency) Hard Costs | E25: 0.07 | F25: =+F24*E25 -> 1011593.4 | G25: x
A26: General Requirements | E26: 0.02 | F26: =SUM(F24*E26) -> 289026.68 | G26: x
A27: Sub-Total Buildings | F27: =SUM(F24:F26) -> 15751954
A29: Fees
A30: Builders Profit | E30: 0.05 | F30: =SUM(F24)*E30 -> 722566.7 | G30: x
A31: Builders O/H (2%) | E31: 0.015 | F31: =SUM(F24+F26)*E31 -> 221105.41 | G31: x
A32: Bond Premium/Impact Fees | F32: 0 | G32: x
A33: Architects Fee-Design | D33: =+U35 -> 0.8 | E33: =+U37 -> 0.027679106 | F33: =+V35 -> 400000 | G33: x
A34: Architects Fee-Supervision | D34: =+U36 -> 0.2 | F34: =+V36 -> 0 | G34: x | H34: =SUM(F33:F34) -> 400000 | T34: Architect Worksheet:
A35: Other- CM | F35: =+F24*0.05 -> 722566.7 | T35: Architect Contract: | U35: 0.8 | V35: 400000
A36: Sub-Total Fees | F36: =SUM(F30:F35) -> 2066238.8 | U36: 0.2 | V36: 0
U37: =+V37/E24 -> 0.027679106 | V37: =+V35+V36 -> 400000
A38: Charges and Financing | T38: Total Fees | U38: Fixed Fee | V38: =+V16*0.06 -> 832860
A39: Interest | F39: =+'Interest Calculation'!D50 -> 859375 | T39: Legal Fees Breakdown
A40: Financing Fee - Construction | F40: =17500000*0.003 -> 52500 | H40: 0.0125 | U40: Basis Elig.
A41: Bond Cost of Issuance | F41: 20000 | H41: Bond Structure Needed for Tax Abatement | T41: Lender Legal Const | U41: x | V41: 100000 | W41: =IF(U41="x",V41/V$45,0) -> 0.57142857 | AB41: CR | AH41: 55000
A42: Taxes | F42: 0 | T42: Lender Legal Perm | U42: x | V42: 75000 | W42: =IF(U42="x",V42/V$45,0) -> 0.42857143 | AB42: Perm | AH42: 21000
...

Sheet Sheet3
B4: Amount | C4: Percentage
A5: Total Construction Cost | B5: =+'Sources & Uses'!F75 -> 24569810 | C5: N/A
A6: Loan from SRP | B6: =+'Sources & Uses'!F6 -> 18500000 | C6: =+B6/B5 -> 0.75295658
A7: Total Equity from HTC’s | B7: 6900000 | C7: =+B7/B5 -> 0.28083245
A8: Total Equity from Partners | B8: 3500000 | C8: =+B8/B5 -> 0.14245124
A9: Total Debt & Equity | B9: =+B8+B7+B6 -> 28900000 | C9: 1
A11: NOTE: | B11: Equity from HTC's enter the project as follows:
B13: =6900000*0.25 -> 1725000 | C13: At closing
B14: =+B13*2 -> 3450000 | C14: At construction completion
B15: =+B13 -> 1725000 | C15: At occupancy
A17: The balance of HTC funds from project projections held as contingency until loan paid in full

Sheet 3rd Mortgage
A1: =+'Sources & Uses'!A1 -> Lamar Building | E1: 3rd Mortgage Loan | G1: Grant Funds - Loaned In (CAP;CNO;LHC)
A4: PRINCIPLE: | D4: =+C4 -> 0
A5: YEARLY INT RATE: | C5: 0 | E5: PMT AMT: | G5: =-PMT(C5/C7,C6,C4)*0 -> 0
A6: TOTAL # PMTS: | C6: 40 | E6: Ann. Debt Serv. | G6: =G5*C7 -> 0
A7: # PMTS PER YEAR: | C7: 1 | E7: D.S.C. | G7: =+'Proforma (Application)'!D79 -> 9359 | I7: =+'Sources & Uses'!#REF! -> #REF!
G8: =SUM('Proforma (Application)'!D82:R82)/15 -> 0
B10: PMT # | C10: PMT AMT | D10: INTEREST | E10: PRINCIPAL | F10: REM BAL | G10: ACC INT
B11: 1 | C11: =$G$5 -> 0 | D11: =C4*$C$5/12 -> 0 | E11: =C11-D11 -> 0 | F11: =C4-E11 -> 0 | G11: =D11 -> 0
B12: 2 | C12: =$G$5 -> 0 | D12: =F11*$C$5/12 -> 0 | E12: =C12-D12 -> 0 | F12: =F11-E12 -> 0 | G12: =D12+G11 -> 0
B13: 3 | C13: =$G$5 -> 0 | D13: =F12*$C$5/12 -> 0 | E13: =C13-D13 -> 0 | F13: =F12-E13 -> 0 | G13: =D13+G12 -> 0
B14: 4 | C14: =+'Residual Calculation'!H55 -> #REF! | D14: =F13*$C$5/12 -> 0 | E14: =C14-D14 -> #REF! | F14: =F13-E14 -> #REF! | G14: =D14+G13 -> 0
B15: 5 | C15: =+'Residual Calculation'!I55 -> #REF! | D15: =F14*$C$5/12 -> #REF! | E15: =C15-D15 -> #REF! | F15: =F14-E15 -> #REF! | G15: =D15+G14 -> #REF!
B16: 6 | C16: =+'Residual Calculation'!J55 -> #REF! | D16: =F15*$C$5/12 -> #REF! | E16: =C16-D16 -> #REF! | F16: =F15-E16 -> #REF! | G16: =D16+G15 -> #REF!
B17: 7 | C17: =+'Residual Calculation'!K55 -> #REF! | D17: =F16*$C$5/12 -> #REF! | E17: =C17-D17 -> #REF! | F17: =F16-E17 -> #REF! | G17: =D17+G16 -> #REF!
B18: 8 | C18: =+'Residual Calculation'!L55 -> #REF! | D18: =F17*$C$5/12 -> #REF! | E18: =C18-D18 -> #REF! | F18: =F17-E18 -> #REF! | G18: =D18+G17 -> #REF!
B19: 9 | C19: =+'Residual Calculation'!M55 -> #REF! | D19: =F18*$C$5/12 -> #REF! | E19: =C19-D19 -> #REF! | F19: =F18-E19 -> #REF! | G19: =D19+G18 -> #REF!
B20: 10 | C20: =+'Residual Calculation'!N55 -> #REF! | D20: =F19*$C$5/12 -> #REF! | E20: =C20-D20 -> #REF! | F20: =F19-E20 -> #REF! | G20: =D20+G19 -> #REF!
B21: 11 | C21: =+'Residual Calculation'!O55 -> #REF! | D21: =F20*$C$5/12 -> #REF! | E21: =C21-D21 -> #REF! | F21: =F20-E21 -> #REF! | G21: =D21+G20 -> #REF!
B22: 12 | C22: =+'Residual Calculation'!P55 -> #REF! | D22: =F21*$C$5/12 -> #REF! | E22: =C22-D22 -> #REF! | F22: =F21-E22 -> #REF! | G22: =D22+G21 -> #REF!
B23: 13 | C23: =+'Residual Calculation'!Q55 -> #REF! | D23: =F22*$C$5/12 -> #REF! | E23: =C23-D23 -> #REF! | F23: =F22-E23 -> #REF! | G23: =D23+G22 -> #REF!
B24: 14 | C24: =+'Residual Calculation'!R55 -> #REF! | D24: =F23*$C$5/12 -> #REF! | E24: =C24-D24 -> #REF! | F24: =F23-E24 -> #REF! | G24: =D24+G23 -> #REF!
B25: 15 | C25: =+'Residual Calculation'!S55 -> #REF! | D25: =F24*$C$5/12 -> #REF! | E25: =C25-D25 -> #REF! | F25: =F24-E25 -> #REF! | G25: =D25+G24 -> #REF!
B26: 16 | C26: =+'Residual Calculation'!T55 -> #REF! | D26: =F25*$C$5/12 -> #REF! | E26: =C26-D26 -> #REF! | F26: =F25-E26 -> #REF! | G26: =D26+G25 -> #REF!
B27: 17 | C27: =+'Residual Calculation'!U55 -> #REF! | D27: =F26*$C$5/12 -> #REF! | E27: =C27-D27 -> #REF! | F27: =F26-E27 -> #REF! | G27: =D27+G26 -> #REF!
B28: 18 | C28: =+'Residual Calculation'!V55 -> #REF! | D28: =F27*$C$5/12 -> #REF! | E28: =C28-D28 -> #REF! | F28: =F27-E28 -> #REF! | G28: =D28+G27 -> #REF!
B29: 19 | C29: =+'Residual Calculation'!W55 -> #REF! | D29: =F28*$C$5/12 -> #REF! | E29: =C29-D29 -> #REF! | F29: =F28-E29 -> #REF! | G29: =D29+G28 -> #REF!
B30: 20 | C30: =+'Residual Calculation'!X55 -> #REF! | D30: =F29*$C$5/12 -> #REF! | E30: =C30-D30 -> #REF! | F30: =F29-E30 -> #REF! | G30: =D30+G29 -> #REF!
B31: 21 | C31: =$G$5 -> 0 | D31: =F30*$C$5/12 -> #REF! | E31: =C31-D31 -> #REF! | F31: =F30-E31 -> #REF! | G31: =D31+G30 -> #REF!
B32: 22 | C32: =$G$5 -> 0 | D32: =F31*$C$5/12 -> #REF! | E32: =C32-D32 -> #REF! | F32: =F31-E32 -> #REF! | G32: =D32+G31 -> #REF!
B33: 23 | C33: =$G$5 -> 0 | D33: =F32*$C$5/12 -> #REF! | E33: =C33-D33 -> #REF! | F33: =F32-E33 -> #REF! | G33: =D33+G32 -> #REF!
B34: 24 | C34: =$G$5 -> 0 | D34: =F33*$C$5/12 -> #REF! | E34: =C34-D34 -> #REF! | F34: =F33-E34 -> #REF! | G34: =D34+G33 -> #REF!
B35: 25 | C35: =$G$5 -> 0 | D35: =F34*$C$5/12 -> #REF! | E35: =C35-D35 -> #REF! | F35: =F34-E35 -> #REF! | G35: =D35+G34 -> #REF!
B36: 26 | C36: =$G$5 -> 0 | D36: =F35*$C$5/12 -> #REF! | E36: =C36-D36 -> #REF! | F36: =F35-E36 -> #REF! | G36: =D36+G35 -> #REF!
B37: 27 | C37: =$G$5 -> 0 | D37: =F36*$C$5/12 -> #REF! | E37: =C37-D37 -> #REF! | F37: =F36-E37 -> #REF! | G37: =D37+G36 -> #REF!
B38: 28 | C38: =$G$5 -> 0 | D38: =F37*$C$5/12 -> #REF! | E38: =C38-D38 -> #REF! | F38: =F37-E38 -> #REF! | G38: =D38+G37 -> #REF!
B39: 29 | C39: =$G$5 -> 0 | D39: =F38*$C$5/12 -> #REF! | E39: =C39-D39 -> #REF! | F39: =F38-E39 -> #REF! | G39: =D39+G38 -> #REF!
B40: 30 | C40: =$G$5 -> 0 | D40: =F39*$C$5/12 -> #REF! | E40: =C40-D40 -> #REF! | F40: =F39-E40 -> #REF! | G40: =D40+G39 -> #REF!
B41: 31 | C41: =$G$5 -> 0 | D41: =F40*$C$5/12 -> #REF! | E41: =C41-D41 -> #REF! | F41: =F40-E41 -> #REF! | G41: =D41+G40 -> #REF!
B42: 32 | C42: =$G$5 -> 0 | D42: =F41*$C$5/12 -> #REF! | E42: =C42-D42 -> #REF! | F42: =F41-E42 -> #REF! | G42: =D42+G41 -> #REF!
... B50: 40 | C50: =$G$5 -> 0 | D50: =F49*$C$5/12 -> #REF! | E50: =C50-D50 -> #REF! | F50: =F49-E50 -> #REF! | G50: =D50+G49 -> #REF!

Sheet Cost Allocation Basis
A1: =+'Sources & Uses'!A1 -> Lamar Building
A2: Cost Allocation
A4: Sources:
A6: First Mortgage - Conventional | F6: =+'Sources & Uses'!F6 -> 18500000
A7: Second Mortgage - Non - Profit | F7: =+'Sources & Uses'!F7 -> 0
A8: =+'Sources & Uses'!A8 -> Equity | F8: =+'Sources & Uses'!F8 -> 6000000
A9: Owner Contribution | F9: =+'Sources & Uses'!#REF! -> #REF!
A10: Tax Credit - Equity Contribution | F10: =+'Sources & Uses'!#REF! -> #REF!
A11: TOTAL SOURCES | F11: =SUM(F6:F10) -> #REF!
F13: Total | I13: Amortizable | K13: Non- Amortizable | M13: Eligible Basis | O13: Historic
A14: Uses: | F14: Development Cost | I14: Costs | K14: Non - Depreciable | M14: Costs | O14: Basis
A16: Land | F16: =+'Sources & Uses'!H16 -> 0 | I16: =SUM(H16*$F16) -> 0 | J16: 1 | K16: =SUM(J16*$F16) -> 0 | M16: =SUM(L16*$F16) -> 0 | O16: =SUM(N16*$F16) -> 0 | P16: =SUM(H16+J16+L16) -> 1 | Q16: 1000000
A17: Building Acquisition | F17: =+'Sources & Uses'!H17 -> 0 | L17: 1 | M17: =SUM(L17*$F17) -> 0 | P17: =SUM(H17+J17+L17) -> 1
A18: Unusual Land Improvements | F18: =+'Sources & Uses'!F19 -> 0 | I18: =SUM(H18*$F18) -> 0 | J18: 1 | K18: =SUM(J18*$F18) -> 0 | M18: =SUM(L18*$F18) -> 0 | O18: =SUM(N18*$F18) -> 0 | P18: =SUM(H18+J18+L18) -> 1
A19: Other Land Improvements | F19: =+'Sources & Uses'!F20 -> 0 | I19: =SUM(H19*$F19) -> 0 | J19: 0 | K19: =SUM(J19*$F19) -> 0 | L19: 1 | M19: =SUM(L19*$F19) -> 0 | O19: =SUM(N19*$F19) -> 0 | P19: =SUM(H19+J19+L19) -> 1
A20: Construction Hard Costs | F20: =+'Sources & Uses'!F24 -> 14451334 | I20: =SUM(H20*$F20) -> 0 | J20: 0 | K20: =SUM(J20*$F20) -> 0 | L20: 1 | M20: =SUM(L20*$F20) -> 14451334 | O20: =+F20 -> 14451334 | P20: =SUM(H20+J20+L20) -> 1 | Q20: 104296
A21: =+'Sources & Uses'!A25 -> (Contingency) Hard Costs | F21: =+'Sources & Uses'!F25 -> 1011593.4 | I21: =SUM(H21*$F21) -> 0 | K21: =SUM(J21*$F21) -> 0 | L21: 1 | M21: =SUM(L21*$F21) -> 1011593.4 | O21: =+F21 -> 1011593.4 | P21: =SUM(H21+J21+L21) -> 1
A22: General Requirements | F22: =+'Sources & Uses'!F26 -> 289026.68 | I22: =SUM(H22*$F22) -> 0 | K22: =SUM(J22*$F22) -> 0 | L22: 1 | M22: =SUM(L22*$F22) -> 289026.68 | O22: =+F22 -> 289026.68 | P22: =SUM(H22+J22+L22) -> 1
A23: Builders Profit | F23: =+'Sources & Uses'!F30 -> 722566.7 | I23: =SUM(H23*$F23) -> 0 | K23: =SUM(J23*$F23) -> 0 | L23: 1 | M23: =SUM(L23*$F23) -> 722566.7 | O23: =+F23 -> 722566.7 | P23: =SUM(H23+J23+L23) -> 1
A24: Builders O/H (2%) | F24: =+'Sources & Uses'!F31 -> 221105.41 | I24: =SUM(H24*$F24) -> 0 | K24: =SUM(J24*$F24) -> 0 | L24: 1 | M24: =SUM(L24*$F24) -> 221105.41 | O24: =+F24 -> 221105.41 | P24: =SUM(H24+J24+L24) -> 1
A25: Bond Premium | F25: =+'Sources & Uses'!F32 -> 0 | I25: =SUM(H25*$F25) -> 0 | K25: =SUM(J25*$F25) -> 0 | L25: 1 | M25: =SUM(L25*$F25) -> 0 | O25: =+F25 -> 0 | P25: =SUM(H25+J25+L25) -> 1
A26: Architects Fee-Design | F26: =+'Sources & Uses'!F33 -> 400000 | I26: =SUM(H26*$F26) -> 0 | K26: =SUM(J26*$F26) -> 0 | L26: 1 | M26: =SUM(L26*$F26) -> 400000 | O26: =+F26 -> 400000 | P26: =SUM(H26+J26+L26) -> 1 | Q26: 68000 | R26: x
A27: Architects Fee-Supervision | F27: =+'Sources & Uses'!F34 -> 0 | I27: =SUM(H27*$F27) -> 0 | K27: =SUM(J27*$F27) -> 0 | L27: 1 | M27: =SUM(L27*$F27) -> 0 | O27: =+F27 -> 0 | P27: =SUM(H27+J27+L27) -> 1
A28: =+'Sources & Uses'!A35 -> Other- CM | F28: =+'Sources & Uses'!F35 -> 722566.7 | I28: =SUM(H28*$F28) -> 0 | K28: =SUM(J28*$F28) -> 0 | L28: 1 | M28: =SUM(L28*$F28) -> 722566.7 | O28: =+F28 -> 722566.7 | P28: =SUM(H28+J28+L28) -> 1
A29: Interest | F29: =+'Sources & Uses'!F39 -> 859375 | I29: =SUM(H29*$F29) -> 0 | J29: =+L28-L29 -> 0 | K29: =+F29*J29 -> 0 | L29: 1 | M29: 0 | O29: =+F29 -> 859375 | P29: =SUM(H29+J29+L29) -> 1
A30: =+'Sources & Uses'!A40 -> Financing Fee - Construction | F30: =+'Sources & Uses'!F40 -> 52500 | H30: 1 | I30: =SUM(H30*$F30) -> 52500 | K30: =SUM(J30*$F30) -> 0 | M30: =SUM(L30*$F30) -> 0 | O30: 0 | P30: =SUM(H30+J30+L30) -> 1
A31: =+'Sources & Uses'!#REF! -> #REF! | F31: =+'Sources & Uses'!#REF! -> #REF! | I31: =SUM(H31*$F31) -> #REF! | J31: 0 | K31: =SUM(J31*$F31) -> #REF! | L31: 1 | M31: =SUM(L31*$F31) -> #REF! | O31: 0 | P31: =SUM(H31+J31+L31) -> 1
A32: =+'Sources & Uses'!A41 -> Bond Cost of Issuance | F32: =+'Sources & Uses'!F41 -> 20000 | J32: 1 | K32: =SUM(J32*$F32) -> 20000 | L32: 0 | M32: =SUM(L32*$F32) -> 0 | O32: 0 | P32: =SUM(H32+J32+L32) -> 1
A33: Taxes | F33: =+'Sources & Uses'!F42 -> 0 | I33: =SUM(H33*$F33) -> 0 | K33: =SUM(J33*$F33) -> 0 | L33: 1 | M33: =SUM(L33*$F33) -> 0 | O33: =+F33 -> 0 | P33: =SUM(H33+J33+L33) -> 1
A34: Insurance | F34: =+'Sources & Uses'!F43 -> 120000 | I34: =SUM(H34*$F34) -> 0 | K34: =SUM(J34*$F34) -> 0 | L34: 1 | M34: =SUM(L34*$F34) -> 120000 | O34: =+F34 -> 120000 | P34: =SUM(H34+J34+L34) -> 1
A35: Title/Recording | F35: =+'Sources & Uses'!F44 -> 7000 | I35: =SUM(H35*$F35) -> 0 | J35: 0 | K35: =SUM(J35*$F35) -> 0 | L35: 0 | M35: =SUM(L35*$F35) -> 0 | O35: 0 | P35: =SUM(H35+J35+L35) -> 0
A36: Legal | F36: =+'Sources & Uses'!F48 -> 50000 | I36: =SUM(H36*$F36) -> 0 | J36: =+'Sources & Uses'!W46 -> 0 | K36: =SUM(J36*$F36) -> 0 | L36: =+'Sources & Uses'!W45 -> 1 | M36: =SUM(L36*$F36) -> 50000 | O36: =+F36 -> 50000 | P36: =SUM(H36+J36+L36) -> 1
A37: CPA Fees | F37: =+'Sources & Uses'!F49 -> 25000 | I37: =SUM(H37*$F37) -> 0 | K37: =SUM(J37*$F37) -> 0 | L37: 1 | M37: =SUM(L37*$F37) -> 25000 | O37: 0 | P37: =SUM(H37+J37+L37) -> 1
A38: Organizational | F38: =+'Sources & Uses'!F50 -> 0 | H38: 1 | I38: =SUM(H38*$F38) -> 0 | K38: =SUM(J38*$F38) -> 0 | M38: =SUM(L38*$F38) -> 0 | O38: =+F38 -> 0 | P38: =SUM(H38+J38+L38) -> 1
A39: Cost Certification | F39: =+'Sources & Uses'!F51 -> 0 | I39: =SUM(H39*$F39) -> 0 | J39: 1 | K39: =SUM(J39*$F39) -> 0 | L39: 0 | M39: =SUM(L39*$F39) -> 0 | O39: 0 | P39: =SUM(H39+J39+L39) -> 1
A40: =+'Sources & Uses'!A55 -> Operational Fees | F40: =+'Sources & Uses'!F55 -> 400000 | I40: =SUM(H40*$F40) -> 0 | K40: =SUM(J40*$F40) -> 0 | L40: 1 | M40: =SUM(L40*$F40) -> 400000 | O40: =+F40 -> 400000 | P40: =SUM(H40+J40+L40) -> 1
A41: LIHTC Application Fee | F41: =+'Sources & Uses'!F56 -> 0 | I41: =SUM(H41*$F41) -> 0 | J41: 1 | K41: =SUM(J41*$F41) -> 0 | L41: 0 | M41: =SUM(L41*$F41) -> 0 | O41: =+K41 -> 0 | P41: =SUM(H41+J41+L41) -> 1
A42: Tax Credit Commitment Fees | F42: =+'Sources & Uses'!F57 -> 0 | I42: =SUM(H42*$F42) -> 0 | J42: 1 | K42: =SUM(J42*$F42) -> 0 | L42: 0 | O42: =+F42 -> 0 | P42: =SUM(H42+J42+L42) -> 1
A43: =+'Sources & Uses'!A58 -> Other Third Party Costs | F43: =+'Sources & Uses'!F58 -> 217742 | I43: =SUM(H43*$F43) -> 0 | J43: =+K43/F43 -> 0 | K43: =+'Sources & Uses'!Y68 -> 0 | L43: =+M43/F43 -> 0 | M43: =+'Sources & Uses'!X68 -> 0 | O43: =+F43 -> 217742 | P43: =SUM(H43+J43+L43) -> 0 | Q43: =1500+2140+6255+1965+3500 -> 15360
A44: =+'Sources & Uses'!A59 -> 0 | F44: =+'Sources & Uses'!F25 -> 1011593.4 | I44: =SUM(H44*$F44) -> 0 | J44: 0.15 | K44: =SUM(J44*$F44) -> 151739.01 | L44: 0.85 | M44: =SUM(L44*$F44) -> 859854.37 | O44: =+F44 -> 1011593.4 | P44: =SUM(H44+J44+L44) -> 1
...

Sheet carryover calc
A1: St Landry Place
A2: Calculation of Reasonably Expected Basis
A3: FYE 2006 Carryover
A5: Total Eligible Basis per Allocation Schedule: | G5: =+'Cost Allocation Basis'!M52 -> #REF!
A7: Add Land | G7: =+'Cost Allocation Basis'!K16 -> 0
A9: Total Reasonably Expected Basis | G9: =SUM(G5:G8) -> #REF!
A11: 10% Requirement | F11: 0.1 | G11: =SUM(G9*F11) -> #REF!
A13: Costs incurred/ Accrued to meet test:
A15: Carryover Fees/Accounting Costs | G15: =9500+3500 -> 13000
A16: Developer Fee Accrual | E16: 0.2 | G16: =SUM(E16*'Cost Allocation Basis'!F47) -> 0
A17: Land Costs | G17: =+'Cost Allocation Basis'!F16 -> 0
A18: Market Study Costs | G18: 4800
A19: Neighborhood Review | G19: 750
A20: Phase I | G20: 0
A21: Architect Design Phase | G21: =+'Cost Allocation Basis'!F26 -> 400000
A22: Soils Report | G22: 1700
A23: Engineering | G23: 31500
A26: Total Costs | G26: =SUM(G15:G23) -> 451750
A28: Remaining Needed to meet 10% | G28: =SUM(G11-G26) -> #REF!
A31: Estimated Materials to Store: | G31: 100000
A34: Total Costs if Materials Used | G34: =SUM(G26+G31) -> 551750
A36: Percentage of REB | G36: =SUM(G34/G9) -> #REF!

Sheet Interest Calculation
A1: =+'Sources & Uses'!A1 -> Lamar Building | E1: Construction Loan
A4: PRINCIPAL: | C4: 18500000
A5: YEARLY INT RATE: | C5: 0.075
A6: TOTAL # PMTS: | C6: i.o
A7: # PMTS PER YEAR: | C7: 12
B10: PMT # | C10: Draw | D10: INTEREST | E10: Paydowns | F10: Balance
B11: 1 | C11: =$G$5 -> 0 | D11: =C$4*$C$5/1 -> 1387500 | E11: =C11-D11 -> -1387500 | F11: =C4-E11 -> 19887500 | G11: =D11 -> 1387500
B12: 2 | C12: =$G$5 -> 0 | D12: =C$4*$C$5/1 -> 1387500 | E12: =C12-D12 -> -1387500 | F12: =F11-E12 -> 21275000 | G12: =D12+G11 -> 2775000
B13: 3 | C13: =$G$5 -> 0 | D13: =C$4*$C$5/1 -> 1387500 | E13: =C13-D13 -> -1387500 | F13: =F12-E13 -> 22662500 | G13: =D13+G12 -> 4162500
B14: 4 | C14: =+'Residual Calculation'!H53 -> #REF! | D14: 0 | E14: =SUM(E13-D14) -> -1387500 | F14: =F13-E14 -> 24050000 | G14: =D14+G13 -> 4162500
B15: 5 | C15: =+'Residual Calculation'!I53 -> #REF! | D15: 0 | E15: =+C15+D15 -> #REF! | F15: =F14-E15 -> #REF! | G15: =D15+G14 -> 4162500
B16: 6 | C16: =+'Residual Calculation'!J53 -> #REF! | D16: 0 | E16: =+C16+D16 -> #REF! | F16: =F15-E16 -> #REF! | G16: =D16+G15 -> 4162500
B17: 7 | C17: =+'Residual Calculation'!K53 -> #REF! | D17: 0 | E17: =+C17+D17 -> #REF! | F17: =F16-E17 -> #REF! | G17: 0
B18: 8 | C18: =+'Residual Calculation'!L53 -> #REF! | D18: =C$4*$C$5/1*-1 -> -1387500 | E18: =+C18+D18 -> #REF! | F18: =F17-E18 -> #REF! | G18: 0
B19: 9 | C19: =+'Residual Calculation'!M53 -> #REF! | D19: =C$4*$C$5/1*-1 -> -1387500 | E19: =+C19+D19 -> #REF! | F19: =F18-E19 -> #REF! | G19: 0
B20: 10 | C20: =+'Residual Calculation'!N53 -> #REF! | D20: =C$4*$C$5/1*-1 -> -1387500 | E20: =+C20+D20 -> #REF! | F20: =F19-E20 -> #REF! | G20: 0
B21: 11 | C21: =+'Residual Calculation'!O53 -> #REF! | D21: =C$4*$C$5/1*-1 -> -1387500 | E21: =+C21+D21 -> #REF! | F21: =F20-E21 -> #REF! | G21: 0
B22: 12 | C22: =+'Residual Calculation'!P53 -> #REF! | D22: =C$4*$C$5/1*-1 -> -1387500 | E22: =+C22+D22 -> #REF! | F22: =F21-E22 -> #REF! | G22: 0
B23: 13 | C23: =+'Residual Calculation'!Q53 -> #REF! | D23: =C$4*$C$5/1*-1 -> -1387500 | E23: =+C23+D23 -> #REF! | F23: =F22-E23 -> #REF! | G23: 0
B24: 14 | C24: =+'Residual Calculation'!R53 -> #REF! | D24: =C$4*$C$5/1*-1 -> -1387500 | E24: =+C24+D24 -> #REF! | F24: =F23-E24 -> #REF! | G24: 0
B25: 15 | C25: =+'Residual Calculation'!S53 -> #REF! | D25: =C$4*$C$5/1*-1 -> -1387500 | E25: =+C25+D25 -> #REF! | F25: =F24-E25 -> #REF! | G25: 0
B26: 16 | C26: =+'Residual Calculation'!T53 -> #REF! | D26: =C$4*$C$5/1*-1 -> -1387500 | E26: =+C26+D26 -> #REF! | F26: =F25-E26 -> #REF! | G26: 0
B27: 17 | C27: =+'Residual Calculation'!U53 -> #REF! | D27: =C$4*$C$5/1*-1 -> -1387500 | E27: =+C27+D27 -> #REF! | F27: =F26-E27 -> #REF! | G27: 0
B28: 18 | C28: =+'Residual Calculation'!V53 -> #REF! | D28: =C$4*$C$5/1*-1 -> -1387500 | E28: =+C28+D28 -> #REF! | F28: =F27-E28 -> #REF! | G28: 0
B29: 19 | C29: =+'Residual Calculation'!W53 -> #REF! | D29: =C$4*$C$5/1*-1 -> -1387500 | E29: =+C29+D29 -> #REF! | F29: =F28-E29 -> #REF! | G29: 0
B30: 20 | C30: =+'Residual Calculation'!X53 -> #REF! | D30: =C$4*$C$5/1*-1 -> -1387500 | E30: =+C30+D30 -> #REF! | F30: =F29-E30 -> #REF! | G30: 0
C31: 1000000 | D31: 0 | F31: =+C31+D31-E31 -> 1000000
C32: 500000 | D32: =+(C32*$C$5/$C$7)+D31 -> 3125 | F32: =+C32+D32+F31 -> 1503125
C33: 1000000 | D33: =+(C33*$C$5/$C$7)+D32 -> 9375 | E33: 0 | F33: =+F32+C33+D33-E33 -> 2512500
C34: 1000000 | D34: =+(C34*$C$5/$C$7)+D33 -> 15625 | F34: =+C34+D34+F33 -> 3528125
C35: 1000000 | D35: =+(C35*$C$5/$C$7)+D34 -> 21875 | F35: =+C35+D35+F34 -> 4550000
C36: 1500000 | D36: =+(C36*$C$5/$C$7)+D35 -> 31250 | F36: =+C36+D36+F35 -> 6081250
C37: 1500000 | D37: =+(C37*$C$5/$C$7)+D36 -> 40625 | F37: =+C37+D37+F36 -> 7621875
C38: 1500000 | D38: =+(C38*$C$5/$C$7)+D37 -> 50000 | F38: =+C38+D38+F37 -> 9171875
C39: 1500000 | D39: =+(C39*$C$5/$C$7)+D38 -> 59375 | F39: =+C39+D39+F38 -> 10731250
C40: 1500000 | D40: =+(C40*$C$5/$C$7)+D39 -> 68750 | F40: =+C40+D40+F39 -> 12300000
C41: 1000000 | D41: =+(C41*$C$5/$C$7)+D40 -> 75000 | F41: =+C41+D41+F40 -> 13375000
C42: 1500000 | D42: =+(C42*$C$5/$C$7)+D41 -> 84375 | F42: =+C42+D42+F41 -> 14959375
C43: 1000000 | D43: =+(C43*$C$5/$C$7)+D42 -> 90625 | F43: =+C43+D43+F42 -> 16050000
C44: 1000000 | D44: =+(C44*$C$5/$C$7)+D43 -> 96875 | F44: =+C44+D44+F43 -> 17146875
...

Sheet CR Calculation
A1: =+'Sources & Uses'!A1 -> Lamar Building
A2: Credit Calculation Worksheet
A4: Total Eligible Basis | F4: =+'Sources & Uses'!F27+'Sources & Uses'!F30+'Sources & Uses'!F31+'Sources & Uses'!F33+'Sources & Uses'!F58+'Sources & Uses'!F67 -> 17313368 | H4: Tax Credit Basis only, based on Sources and Uses
A5: Less: Acquisition Costs
A6: Total Eligible Basis New Construciton /Rehab. | F6: =SUM(F4-F5) -> 17313368
A8: Calculation of Credits: | D8: % | H8: New Const./
F9: Total | H9: Rehabilition | I9: Acquisition
A10: Total Eligible Basis | F10: =SUM(H10:I10) -> 17313368 | H10: =+F6 -> 17313368 | I10: 0
I11: =-H11 -> 0
A12: Eligible Historic Credit | D12: 0
A14: Adjusted Eligible Basis | F14: =SUM(F10-F12) -> 17313368 | H14: =SUM(H10+H11) -> 17313368 | I14: =SUM(I10+I11) -> 0
K15: =+H20*0.15 -> 1688053.4
A16: Elibible Basis Adjusted for QCT/DDA | D16: 1.3 | F16: =SUM(H16:I16) -> 22507379 | H16: =SUM(H14*D16) -> 22507379 | I16: =SUM(I14) -> 0 | K16: =+I20*0.05 -> 0
A18: Low Income Percentage | D18: 0.5
A20: Total Qualified Basis | F20: =SUM(H20:I20) -> 11253689 | H20: =SUM(H16*D18) -> 11253689 | I20: =SUM(I16*D18) -> 0
A22: LIHTC Percentage | H22: 0.04 | I22: 0.04
A24: Total Annual Credits Calculated | F24: =SUM(H24:I24) -> 450147.57 | H24: =SUM(H20*H22) -> 450147.57 | I24: =SUM(I20*I22) -> 0
A26: Total Annual Credits Reserved | C26: (Lessor of Reserved/Calculated) | F26: =SUM(H26:I26) -> 450147.57 | H26: =+IF(H24>H38,H38,H24) -> 450147.57 | I26: =+I24 -> 0
A28: Equity Investment Percentage | H28: 0.9999 | I28: 0.9999
A30: Equity Raised | D30: 0.85 | F30: =SUM(F26*D33*D34)*D30/100 -> 3825871.7 | H30: =SUM(H26*H28*D30*10) -> 3825871.7 | I30: =SUM(I26*I28*D30*10) -> 0
A33: Total Tax Credit Period | D33: 10
A34: Investment Percentage | D34: 99.99
H35: =SUM(H26/H22) -> 11253689
H36: =+H20-H35 -> 0
C38: Maximum Credits Allowed | H38: =+F24 -> 450147.57
C39: Excess Basis Utilizing 9% | H39: =SUM(H24-H38)/H22 -> 0
C40: Excess Cash | E40: =+'Sources & Uses'!#REF!+'Sources & Uses'!#REF! -> #REF!
E43: 70
A44: Maximum Per Developer Credit | C44: 1500000
A45: Amt per Winnsboro | C45: 823000
C46: =+C44-C45 -> 677000
F48: 5062647
C51: Maximum Request | F51: 750000
A53: Historic Credit
A55: Eligible Historic Credit | F55: =+F6 -> 17313368
A57: Credits Calculated | E57: 0.2 | F57: =+F55*0.2 -> 3462673.6
A59: Equity Raised | D59: 0.8 | F59: =+F57*D59 -> 2770138.9
A62: State Credit
A64: Eligible Historic Credit | F64: =+F55 -> 17313368
A66: Credits Calculated | E66: 0.25 | F66: =+F64*0.25 -> 4328342
...

Sheet  Draw Schedule
B1: =+'Sources & Uses'!A1 -> Lamar Building
B2: CONSTRUCTION INTEREST CALCULATION:
B4: Total Construction Contract Amount | F4: =+'Sources & Uses'!E24 -> 14451334
G6: =+'Sources & Uses'!F34 -> 0 | H6: =+'Sources & Uses'!F59 -> 0 | I6: =SUM('Sources & Uses'!H67-'Sources & Uses'!#REF!-'Sources & Uses'!#REF!)*0 -> #REF!
E7: 0.05 | F7: Amount of | G7: Architect | H7: Payment of | I7: Developer fee | J7: Monthly | K7: Total
B8: Draw No: | D8: Draw Amt. | E8: Retainage | F8: Payment | G8: Inspection | H8: Contingency | I8: Pd. (Const. Term) | J8: Interest Pmt | K8: Payment Due
B9: Closing | K9: =+'Application of Funds'!G26 -> #REF!
A10: =+C10 -> 0.03 | B10: 1 | C10: 0.03 | D10: =SUM(C10*F$4) -> 433540.02 | E10: =SUM(D10*E$7)*-1 -> -21677.001 | F10: =SUM(D10:E10) -> 411863.02 | G10: =SUM(G$6/D$57) -> 0 | H10: =SUM(H$6/D$57) -> 0 | I10: =SUM(I$6/D$57) -> #REF! | J10: =+'Construction Loan'!E10 -> #REF! | K10: =SUM(F10:J10) -> #REF! | L10: =+'Application of Funds'!E30 -> 43770
A11: =+A10+C11 -> 0.06 | B11: =+B10+1 -> 2 | C11: 0.03 | D11: =SUM(C11*F$4) -> 433540.02 | E11: =SUM(D11*E$7)*-1 -> -21677.001 | F11: =SUM(D11:E11) -> 411863.02 | G11: =SUM(G$6/D$57) -> 0 | H11: =SUM(H$6/D$57) -> 0 | I11: =SUM(I$6/D$57) -> #REF! | J11: =+'Construction Loan'!E11 -> #REF! | K11: =SUM(F11:J11) -> #REF! | L11: =+'Application of Funds'!E31 -> 43800
A12: =+A11+C12 -> 0.09 | B12: =+B11+1 -> 3 | C12: 0.03 | D12: =SUM(C12*F$4) -> 433540.02 | E12: =SUM(D12*E$7)*-1 -> -21677.001 | F12: =SUM(D12:E12) -> 411863.02 | G12: =SUM(G$6/D$57) -> 0 | H12: =SUM(H$6/D$57) -> 0 | I12: =SUM(I$6/D$57) -> #REF! | J12: =+'Construction Loan'!E12 -> #REF! | K12: =SUM(F12:J12) -> #REF! | L12: =+'Application of Funds'!E32 -> 43831
A13: =+A12+C13 -> 0.12 | B13: =+B12+1 -> 4 | C13: 0.03 | D13: =SUM(C13*F$4) -> 433540.02 | E13: =SUM(D13*E$7)*-1 -> -21677.001 | F13: =SUM(D13:E13) -> 411863.02 | G13: =SUM(G$6/D$57) -> 0 | H13: =SUM(H$6/D$57) -> 0 | I13: =SUM(I$6/D$57) -> #REF! | J13: =+'Construction Loan'!E13 -> #REF! | K13: =SUM(F13:J13) -> #REF! | L13: =+'Application of Funds'!E34 -> 43862
A14: =+A13+C14 -> 0.17 | B14: =+B13+1 -> 5 | C14: 0.05 | D14: =SUM(C14*F$4) -> 722566.7 | E14: =SUM(D14*E$7)*-1 -> -36128.335 | F14: =SUM(D14:E14) -> 686438.37 | G14: =SUM(G$6/D$57) -> 0 | H14: =SUM(H$6/D$57) -> 0 | I14: =SUM(I$6/D$57) -> #REF! | J14: =+'Construction Loan'!E14 -> #REF! | K14: =SUM(F14:J14) -> #REF! | L14: =+'Application of Funds'!E35 -> 43892
A15: =+A14+C15 -> 0.24 | B15: =+B14+1 -> 6 | C15: 0.07 | D15: =SUM(C15*F$4) -> 1011593.4 | E15: =SUM(D15*E$7)*-1 -> -50579.669 | F15: =SUM(D15:E15) -> 961013.71 | G15: =SUM(G$6/D$57) -> 0 | H15: =SUM(H$6/D$57) -> 0 | I15: =SUM(I$6/D$57) -> #REF! | J15: =+'Construction Loan'!E15 -> #REF! | K15: =SUM(F15:J15) -> #REF! | L15: =+'Application of Funds'!E37 -> 43922
A16: =+A15+C16 -> 0.32 | B16: =+B15+1 -> 7 | C16: 0.08 | D16: =SUM(C16*F$4) -> 1156106.7 | E16: =SUM(D16*E$7)*-1 -> -57805.336 | F16: =SUM(D16:E16) -> 1098301.4 | G16: =SUM(G$6/D$57) -> 0 | H16: =SUM(H$6/D$57) -> 0 | I16: =SUM(I$6/D$57) -> #REF! | J16: =+'Construction Loan'!E16 -> #REF! | K16: =SUM(F16:J16) -> #REF! | L16: =+'Application of Funds'!E38 -> 43953
A17: =+A16+C17 -> 0.41 | B17: =+B16+1 -> 8 | C17: 0.09 | D17: =SUM(C17*F$4) -> 1300620.1 | E17: =SUM(D17*E$7)*-1 -> -65031.003 | F17: =SUM(D17:E17) -> 1235589.1 | G17: =SUM(G$6/D$57) -> 0 | H17: =SUM(H$6/D$57) -> 0 | I17: =SUM(I$6/D$57) -> #REF! | J17: =+'Construction Loan'!E17 -> #REF! | K17: =SUM(F17:J17) -> #REF! | L17: =+'Application of Funds'!E39 -> 43983
A18: =+A17+C18 -> 0.5 | B18: =+B17+1 -> 9 | C18: 0.09 | D18: =SUM(C18*F$4) -> 1300620.1 | E18: =SUM(D18*E$7)*-1 -> -65031.003 | F18: =SUM(D18:E18) -> 1235589.1 | G18: =SUM(G$6/D$57) -> 0 | H18: =SUM(H$6/D$57) -> 0 | I18: =SUM(I$6/D$57) -> #REF! | J18: =+'Construction Loan'!E18 -> #REF! | K18: =SUM(F18:J18) -> #REF! | L18: =+'Application of Funds'!E42 -> 44013
A19: =+A18+C19 -> 0.58 | B19: =+B18+1 -> 10 | C19: 0.08 | D19: =SUM(C19*F$4) -> 1156106.7 | E19: =SUM(D19*E$7)*-1 -> -57805.336 | F19: =SUM(D19:E19) -> 1098301.4 | G19: =SUM(G$6/D$57) -> 0 | H19: =SUM(H$6/D$57) -> 0 | I19: =SUM(I$6/D$57) -> #REF! | J19: =+'Construction Loan'!E19 -> #REF! | K19: =SUM(F19:J19) -> #REF! | L19: =+'Application of Funds'!E45 -> 44044
A20: =+A19+C20 -> 0.66 | B20: =+B19+1 -> 11 | C20: 0.08 | D20: =SUM(C20*F$4) -> 1156106.7 | E20: =SUM(D20*E$7)*-1 -> -57805.336 | F20: =SUM(D20:E20) -> 1098301.4 | G20: =SUM(G$6/D$57) -> 0 | H20: =SUM(H$6/D$57) -> 0 | I20: =SUM(I$6/D$57) -> #REF! | J20: =+'Construction Loan'!E20 -> #REF! | K20: =SUM(F20:J20) -> #REF! | L20: =+'Application of Funds'!E46 -> 44075
A21: =+A20+C21 -> 0.73 | B21: =+B20+1 -> 12 | C21: 0.07 | D21: =SUM(C21*F$4) -> 1011593.4 | E21: =SUM(D21*E$7)*-1 -> -50579.669 | F21: =SUM(D21:E21) -> 961013.71 | G21: =SUM(G$6/D$57) -> 0 | H21: =SUM(H$6/D$57) -> 0 | I21: =SUM(I$6/D$57) -> #REF! | J21: =+'Construction Loan'!E21 -> #REF! | K21: =SUM(F21:J21) -> #REF! | L21: =+'Application of Funds'!E47 -> 44106
A22: =+A21+C22 -> 0.8 | B22: =+B21+1 -> 13 | C22: 0.07 | D22: =SUM(C22*$F$4) -> 1011593.4 | E22: =SUM(D22*E$7)*-1 -> -50579.669 | F22: =SUM(D22:E22) -> 961013.71 | G22: =SUM(G$6/D$57) -> 0 | H22: =SUM(H$6/D$57) -> 0 | I22: =SUM(I$6/D$57) -> #REF! | J22: =+'Construction Loan'!E22 -> #REF! | K22: =SUM(F22:J22) -> #REF! | L22: =+'Application of Funds'!E48 -> 44136
A23: =+A22+C23 -> 0.86 | B23: =+B22+1 -> 14 | C23: 0.06 | D23: =SUM(C23*$F$4) -> 867080.04 | E23: =SUM(D23*E$7)*-1 -> -43354.002 | F23: =SUM(D23:E23) -> 823726.04 | G23: =SUM(G$6/D$57) -> 0 | H23: =SUM(H$6/D$57) -> 0 | I23: =SUM(I$6/D$57) -> #REF! | J23: =+'Construction Loan'!E23 -> #REF! | K23: =SUM(F23:J23) -> #REF! | L23: =+'Application of Funds'!E49 -> 44166
A24: =+A23+C24 -> 0.93 | B24: 15 | C24: 0.07 | D24: =SUM(C24*$F$4) -> 1011593.4 | E24: =SUM(D24*E$7)*-1 -> -50579.669 | F24: =SUM(D24:E24) -> 961013.71 | G24: =SUM(G$6/D$57) -> 0 | H24: =SUM(H$6/D$57) -> 0 | J24: =+'Construction Loan'!E24 -> #REF! | K24: =SUM(F24:J24) -> #REF! | L24: =+'Application of Funds'!E51 -> 44197
A25: =+A24+C25 -> 0.96 | B25: 16 | C25: 0.03 | D25: =SUM(C25*$F$4) -> 433540.02 | E25: =SUM(D25*E$7)*-1 -> -21677.001 | F25: =SUM(D25:E25) -> 411863.02 | G25: =SUM(G$6/D$57) -> 0 | H25: =SUM(H$6/D$57) -> 0 | J25: =+'Construction Loan'!E25 -> #REF! | K25: =SUM(F25:J25) -> #REF! | L25: =+'Application of Funds'!E53 -> 44228
A26: =+A25+C26 -> 0.98 | B26: 17 | C26: 0.02 | D26: =SUM(C26*$F$4) -> 289026.68 | E26: =SUM(D26*E$7)*-1 -> -14451.334 | F26: =SUM(D26:E26) -> 274575.35 | G26: =SUM(G$6/D$57) -> 0 | H26: =SUM(H$6/D$57) -> 0 | J26: =+'Construction Loan'!E26 -> #REF! | K26: =SUM(F26:J26) -> #REF! | L26: =+'Application of Funds'!E55 -> 44258
A27: =+A26+C27 -> 1 | B27: 18 | C27: 0.02 | D27: =SUM(C27*$F$4) -> 289026.68 | E27: =SUM(D27*E$7)*-1 -> -14451.334 | F27: =SUM(D27:E27) -> 274575.35 | G27: =SUM(G$6/D$57) -> 0 | H27: =SUM(H$6/D$57) -> 0 | J27: =+'Construction Loan'!E27 -> #REF! | K27: =SUM(F27:J27) -> #REF! | L27: =+'Application of Funds'!E57 -> 44288
B28: 19 | D28: =SUM(C28*$F$4) -> 0 | E28: =SUM(D28*E$7)*-1 -> 0 | F28: =SUM(D28:E28) -> 0 | J28: =+'Construction Loan'!E28 -> #REF! | K28: =SUM(F28:J28) -> #REF! | L28: =+L27+31 -> 44319
B29: 20 | D29: =SUM(C29*$F$4) -> 0 | E29: =SUM(D29*E$7)*-1 -> 0 | F29: =SUM(D29:E29) -> 0 | J29: =+'Construction Loan'!E29 -> #REF! | K29: =SUM(F29:J29) -> #REF! | L29: =+L28+30 -> 44349
B30: 21 | J30: =+'Construction Loan'!E30 -> #REF! | K30: =SUM(F30:J30) -> #REF! | L30: =+L29+30 -> 44379
B31: 22 | J31: =+'Construction Loan'!E31 -> #REF! | K31: =SUM(F31:J31) -> #REF! | L31: =+'Application of Funds'!E67 -> 44409
B32: 23 | J32: =+'Construction Loan'!E32 -> #REF! | K32: =SUM(F32:J32) -> #REF! | L32: =+'Application of Funds'!E73 -> 44440
B33: 24
C36: =SUM(C10:C27) -> 1 | D36: =SUM(D10:D33) -> 14451334 | E36: =SUM(E10:E33) -> -722566.7 | F36: =SUM(F10:F33) -> 13728767 | G36: =SUM(G10:G33) -> 0 | H36: =SUM(H10:H33) -> 0 | I36: =SUM(I10:I33) -> #REF! | J36: =SUM(J10:J33) -> #REF! | K36: =SUM(K10:K23) -> #REF!
D38: Capitalizable Construction Interest
D39: Interest to Operating Deficit
B41: Days in Year | D41: 360
B42: Days In Month | D42: 30
B46: Construction Loan Calculation:
B48: Total Development Costs
B50: Less 1st Equity Installment
B51: Less Unpaid Developer Fee
...

Sheet Application of Funds
H1: Tax Credit Equity | J1: Construction/Bridge Loan | L1: Interim Bonds | N1: LHC CDBG | P1: Cash Collateral Fund | R1: Permanent Loan
A2: =+'Sources & Uses'!A1 -> Lamar Building | D2: Percentage | E2: Projected | G2: Total | I2: Remaining | K2: Const/Bridge | M2: Available | O2: Available | Q2: Available | S2: Available | W2: Pari-Passu Calculation | AB2: CDBG | AC2: CDBG | AD2: Const/Bridge
A3: Schedule of Draws and Application of Funds | D3: Paid | E3: Date Paid | G3: Costs Incurred | H3: Draws | I3: Balance | J3: Draws | K3: Loan Balance | L3: Draws | M3: Funds | O3: Funds | Q3: Funds | R3: Draws | S3: Funds | T3: Def. Dev. Fee | W3: 50% Draw | X3: Equity | Y3: Cont/Br. | Z3: BONDS | AA3: CDBG | AB3: Balance | AC3: CK | AD3: Collateral Daw
I4: 0 | M4: 0 | O4: =+'Sources & Uses'!V7 -> 0 | S4: =+#REF! -> #REF! | T4: =+'Sources & Uses'!#REF!+'Sources & Uses'!#REF!+'Sources & Uses'!V8 -> #REF!
I5: =+I4+H5 -> 0 | K5: 0 | M5: =+M4+L5 -> 0 | O5: =+O4+N5 -> 0 | Q5: 0 | S5: =+S4-R5 -> #REF! | U5: =SUM(+G5+H5+J5+L5+P5+T5+N5+R5) -> 0
A6: Equtiy Paid At Closing | D6: 0.1 | E6: 43739 | H6: =SUM('CR Calculation'!F30*'Application of Funds'!D6) -> 382587.17 | I6: =+I5+H6 -> 382587.17 | K6: =+K5+J6 -> 0 | M6: =+M5+L6 -> 0 | O6: =+O5+N6 -> 0 | Q6: =+Q5+P6 -> 0 | S6: =+S5+R6 -> #REF! | U6: =SUM(+G6+H6+J6+L6+P6+T6+N6+R6) -> 382587.17
I7: =+I6+H7 -> 382587.17 | K7: =+K6+J7 -> 0 | M7: =+M6+L7 -> 0 | O7: =+O6+N7 -> 0 | Q7: =+Q6+P7 -> 0 | S7: =+S6+R7 -> #REF! | U7: =SUM(+G7+H7+J7+L7+P7+T7+N7+R7) -> 0
A8: Items to Be paid/Reimbursed at Closing: | I8: =+I7+H8 -> 382587.17 | K8: =+K7+J8 -> 0 | M8: =+M7+L8 -> 0 | O8: =+O7+N8 -> 0 | Q8: =+Q7+P8 -> 0 | S8: =+S7+R8 -> #REF! | U8: =SUM(+G8+H8+J8+L8+P8+T8+N8+R8) -> 0
I9: =+I8+H9 -> 382587.17 | K9: =+K8+J9 -> 0 | M9: =+M8+L9 -> 0 | O9: =+O8+N9 -> 0 | Q9: =+Q8+P9 -> 0 | S9: =+S8+R9 -> #REF! | U9: =SUM(+G9+H9+J9+L9+P9+T9+N9+R9) -> 0
A10: Cls. Draw | B10: Land & Building Acquistion | E10: =+E6 -> 43739 | F10: =+'Sources & Uses'!H16+'Sources & Uses'!H17 -> 0 | I10: =+I9+H10 -> 382587.17 | K10: =+K9+J10 -> 0 | M10: =+M9+L10 -> 0 | O10: =+O9+N10 -> 0 | Q10: =+Q9+P10 -> 0 | S10: =+S9+R10 -> #REF! | U10: =SUM(+G10+H10+J10+L10+P10+T10+N10+R10) -> 0
B11: =+'Sources & Uses'!A33 -> Architects Fee-Design | E11: =+E10 -> 43739 | F11: =+'Sources & Uses'!F33 -> 400000 | I11: =+I10+H11 -> 382587.17 | K11: =+K10+J11 -> 0 | M11: =+M10+L11 -> 0 | O11: =+O10+N11 -> 0 | Q11: =+Q10+P11 -> 0 | S11: =+S10+R11 -> #REF! | U11: =SUM(+G11+H11+J11+L11+P11+T11+N11+R11) -> 0
B12: =+'Sources & Uses'!A35 -> Other- CM | E12: =+E11 -> 43739 | F12: =+'Sources & Uses'!F35 -> 722566.7 | I12: =+I11+H12 -> 382587.17 | K12: =+K11+J12 -> 0 | M12: =+M11+L12 -> 0 | O12: =+O11+N12 -> 0 | Q12: =+Q11+P12 -> 0 | S12: =+S11+R12 -> #REF! | U12: =SUM(+G12+H12+J12+L12+P12+T12+N12+R12) -> 0
B13: =+'Sources & Uses'!#REF! -> #REF! | E13: =+E12 -> 43739 | F13: =+'Sources & Uses'!#REF! -> #REF! | I13: =+I12+H13 -> 382587.17 | K13: =+K12+J13 -> 0 | M13: =+M12+L13 -> 0 | O13: =+O12+N13 -> 0 | Q13: =+Q12+P13 -> 0 | S13: =+S12+R13 -> #REF! | U13: =SUM(+G13+H13+J13+L13+P13+T13+N13+R13) -> 0
B14: =+'Sources & Uses'!A41 -> Bond Cost of Issuance | E14: =+E13 -> 43739 | F14: =+'Sources & Uses'!F41 -> 20000 | I14: =+I13+H14 -> 382587.17 | K14: =+K13+J14 -> 0 | M14: =+M13+L14 -> 0 | O14: =+O13+N14 -> 0 | Q14: =+Q13+P14 -> 0 | S14: =+S13+R14 -> #REF! | U14: =SUM(+G14+H14+J14+L14+P14+T14+N14+R14) -> 0
B15: =+'Sources & Uses'!A42 -> Taxes | E15: =+E13 -> 43739 | F15: =+'Sources & Uses'!F42 -> 0 | I15: =+I14+H15 -> 382587.17 | K15: =+K14+J15 -> 0 | M15: =+M14+L15 -> 0 | O15: =+O14+N15 -> 0 | Q15: =+Q14+P15 -> 0 | S15: =+S14+R15 -> #REF! | U15: =SUM(+G15+H15+J15+L15+P15+T15+N15+R15) -> 0
B16: =+'Sources & Uses'!A43 -> Insurance | E16: =+E15 -> 43739 | F16: =+'Sources & Uses'!F43 -> 120000 | I16: =+I15+H16 -> 382587.17 | K16: =+K15+J16 -> 0 | M16: =+M15+L16 -> 0 | O16: =+O15+N16 -> 0 | Q16: =+Q15+P16 -> 0 | S16: =+S15+R16 -> #REF! | U16: =SUM(+G16+H16+J16+L16+P16+T16+N16+R16) -> 0
B17: =+'Sources & Uses'!A44 -> Title/Recording | E17: =+E16 -> 43739 | F17: =+'Sources & Uses'!F44 -> 7000 | I17: =+I16+H17 -> 382587.17 | K17: =+K16+J17 -> 0 | M17: =+M16+L17 -> 0 | O17: =+O16+N17 -> 0 | Q17: =+Q16+P17 -> 0 | S17: =+S16+R17 -> #REF! | U17: =SUM(+G17+H17+J17+L17+P17+T17+N17+R17) -> 0
B18: =+'Sources & Uses'!A48 -> Legal | E18: =+E17 -> 43739 | F18: =+'Sources & Uses'!F48 -> 50000 | I18: =+I17+H18 -> 382587.17 | K18: =+K17+J18 -> 0 | M18: =+M17+L18 -> 0 | O18: =+O17+N18 -> 0 | Q18: =+Q17+P18 -> 0 | S18: =+S17+R18 -> #REF! | U18: =SUM(+G18+H18+J18+L18+P18+T18+N18+R18) -> 0
B19: =+'Sources & Uses'!A49 -> CPA Fees | E19: =+E18 -> 43739 | F19: =+'Sources & Uses'!F49 -> 25000 | I19: =+I18+H19 -> 382587.17 | K19: =+K18+J19 -> 0 | M19: =+M18+L19 -> 0 | O19: =+O18+N19 -> 0 | Q19: =+Q18+P19 -> 0 | S19: =+S18+R19 -> #REF! | U19: =SUM(+G19+H19+J19+L19+P19+T19+N19+R19) -> 0
B20: =+'Sources & Uses'!A56 -> LIHTC Application Fee | E20: =+E19 -> 43739 | F20: =+'Sources & Uses'!F56 -> 0 | I20: =+I19+H20 -> 382587.17 | K20: =+K19+J20 -> 0 | M20: =+M19+L20 -> 0 | O20: =+O19+N20 -> 0 | Q20: =+Q19+P20 -> 0 | S20: =+S19+R20 -> #REF! | U20: =SUM(+G20+H20+J20+L20+P20+T20+N20+R20) -> 0
B21: =+'Sources & Uses'!A57 -> Tax Credit Commitment Fees | E21: =+E20 -> 43739 | F21: =+'Sources & Uses'!F57 -> 0 | I21: =+I20+H21 -> 382587.17 | K21: =+K20+J21 -> 0 | M21: =+M20+L21 -> 0 | O21: =+O20+N21 -> 0 | Q21: =+Q20+P21 -> 0 | S21: =+S20+R21 -> #REF! | U21: =SUM(+G21+H21+J21+L21+P21+T21+N21+R21) -> 0
B22: =+'Sources & Uses'!A58 -> Other Third Party Costs | E22: =+E21 -> 43739 | F22: =+'Sources & Uses'!F58 -> 217742 | I22: =+I21+H22 -> 382587.17 | K22: =+K21+J22 -> 0 | M22: =+M21+L22 -> 0 | O22: =+O21+N22 -> 0 | Q22: =+Q21+P22 -> 0 | S22: =+S21+R22 -> #REF! | U22: =SUM(+G22+H22+J22+L22+P22+T22+N22+R22) -> 0
B23: Initial Deposit to Replacement Reserve | E23: =+E22 -> 43739 | F23: =+'Sources & Uses'!H64 -> 0 | I23: =+I22+H23 -> 382587.17 | K23: =+K22+J23 -> 0 | M23: =+M22+L23 -> 0 | O23: =+O22+N23 -> 0 | Q23: =+Q22+P23 -> 0 | S23: =+S22+R23 -> #REF! | U23: =SUM(+G23+H23+J23+L23+P23+T23+N23+R23) -> 0
B24: =+'Sources & Uses'!A70 -> Syndication/ Other Expenses | E24: =+E22 -> 43739 | F24: =+'Sources & Uses'!F73 -> 0 | I24: =+I23+H24 -> 382587.17 | K24: =+K23+J24 -> 0 | M24: =+M23+L24 -> 0 | O24: =+O23+N24 -> 0 | Q24: =+Q23+P24 -> 0 | S24: =+S23+R24 -> #REF! | U24: =SUM(+G24+H24+J24+L24+P24+T24+N24+R24) -> 0
B25: Payment of Developer Fees | C25: (See Draw Schedule) | D25: 0 | E25: =+E22 -> 43739 | F25: =+D25*'Sources & Uses'!H67 -> 0 | I25: =+I24+H25 -> 382587.17 | K25: =+K24+J25 -> 0 | M25: =+M24+L25 -> 0 | O25: =+O24+N25 -> 0 | Q25: =+Q24+P25 -> 0 | S25: =+S24+R25 -> #REF! | U25: =SUM(+G25+H25+J25+L25+P25+T25+N25+R25) -> 0
A26: Total Soft Costs Paid/Reimbursed at Closing | E26: =+E25 -> 43739 | G26: =SUM(F10:F25) -> #REF! | H26: =-I25 -> -382587.17 | I26: =+I25+H26 -> 0 | J26: =-Y26 -> #REF! | K26: =+K25+J26 -> #REF! | L26: =-Z26 -> #REF! | M26: =+M25+L26 -> #REF! | N26: =+L26 -> #REF! | O26: =+O25+N26 -> #REF! | P26: =-N26 -> #REF! | Q26: =+Q25+P26 -> #REF! | S26: =+S25+R26 -> #REF! | U26: =SUM(+G26+H26+J26+L26+P26+T26+N26+R26) -> #REF! | W26: =G26*0.5 -> #REF! | X26: =-H26 -> 382587.17 | Y26: =+W26-X26 -> #REF! | Z26: =+G26-X26-Y26+AD26 -> #REF! | AA26: =-N26 -> #REF! | AB26: =+AA26 -> #REF! | AC26: =IF(AB26<=D$97,"OK","ERROR") -> #REF!
A27: Total paid from HOME and Construction Loan Funds | G27: =SUM(H7:H25)+SUM(J5:J25)+SUM(N5:N25)+SUM(L5:L25)-P10 -> 0 | I27: =+I26+H27 -> 0 | K27: =+K26+J27 -> #REF! | M27: =+M26+L27 -> #REF! | N27: =+L27 -> 0 | O27: =+O26+N27 -> #REF! | P27: =-N27 -> 0 | Q27: =+Q26+P27 -> #REF! | S27: =+S26+R27 -> #REF! | U27: =SUM(+G27+H27+J27+L27+P27+T27+N27+R27) -> 0 | Z27: =+G27-X27-Y27+AD27 -> 0 | AA27: =-N27 -> 0 | AB27: =+AB26+AA27 -> #REF! | AC27: =IF(AB27<=D$97,"OK","ERROR") -> #REF!
