Workbook
Name ExternalData_1: 'Pension-Fund-Base-V1-Default-vi'!$B$3:$AC$78

Sheet Pension-Fund-Base-V1-Default-vi
B2: This Pension Fund "Giveaway" file contains 75 records. You can request access to our Premium Datasets by e-mailing launch@polarityiq.com or by going to www.polarityiq.com
B3: Pension Fund Name | C3: Data Completeness Score (Visual) | D3: Pension Fund Description / Investing The | E3: Investor Type | F3: Pension Fund Linkedin Profile | G3: Preferred Country of Investment | H3: Preferred Continent of Investment | I3: Typical Ticket Size | J3: Preferred Asset Class | K3: AUM in USD (millions) | L3: AUM in USD | M3: Investor Address | N3: Investor City | O3: Investor State | P3: Investor Country | Q3: First Name | R3: Last Name | S3: Full Name | T3: Job Title | U3: Location | V3: Pension Fund Domain | W3: LinkedIn Profile | X3: Primary Email | Y3: Primary Email Quality Assessment | Z3: Primary Phone Number | AA3: Secondary Phone Number | AB3: Secondary Email | AC3: Secondary Email Quality Assessment
B4: Walt Disney | C4: =COUNTA('Pension-Fund-Base-V1-Default-vi'!$D4:$AC4) -> 26 | D4: The Walt Disney Company is a leading diversified international family entertainment and media enterprise founded in 1923. Their mission is to entertain, inform, and inspire people around the globe through unparalleled storytelling. They focus on generating the best creative content, fostering innovation, and expanding into new markets globally. Currently led by CEO Robert A. Iger, the company is undergoing a significant transformation to enhance its creativity and position its streaming business for growth. Disney's goals include maximizing financial performance while emphasizing innovative growth, strategic investment, and a balanced approach to human resource development in their business models. | E4: Pension Fund (Top 1500 Institutional Investor) | F4: https://www.linkedin.com/company/the-walt-disney-company | G4: United States, Eurozone countries, Japan, United Kingdom, China, Canada | H4: North America, Europe, Asia | I4: $75M–$200M | J4: Public Equity, Fixed Income, Other Alternatives, Cash | K4: 25282 million | L4: 25282000000 | M4: 500 South Buena Vista Street | N4: Burbank | O4: California | P4: United States | Q4: Amy | R4: Chan | S4: Amy Chang | T4: Board of Directors | U4: Palo Alto, California, United States | V4: disneycareers.com | W4: https://www.linkedin.com/in/changamy/ | X4: amy.chang@ucsfmedctr.org | Y4: Highest Quality | Z4: 16507997988 | AA4: (415) 476-1000 | AB4: amcchang@gmail.com | AC4: Highest Quality
B5: Walmart | C5: =COUNTA('Pension-Fund-Base-V1-Default-vi'!$D5:$AC5) -> 24 | D5: Walmart is a global retail corporation operating more than 10,500 stores and eCommerce platforms in 19 countries. Its core mission is to help people save money so they can live better, emphasizing affordability and a commitment to customer service. Walmart's investment thesis is robust, focusing on stable growth, innovative omnichannel strategies, and expansion into higher-margin businesses, with a target price indicating substantial upside potential over the next few years. | E5: Pension Fund (Top 1500 Institutional Investor) | F5: https://www.linkedin.com/company/walmart | I5: $75M–$200M | J5: Public Equity, Cash, Fixed Income, Other Alternatives (Mutual Funds) | K5: 31349 million | L5: 31349000000 | M5: 702 SW 8th Street | N5: Bentonville | O5: Arkansas | P5: United States | Q5: Gene | R5: Kent | S5: Gene Kent | T5: Managing Partner | U5: Salt Lake City, Utah, United States | V5: bit.ly | W5: https://www.linkedin.com/in/gene-kent-00823575/ | X5: gene.kent@walmart.com | Y5: Medium Quality | Z5: 18016372944 | AA5: (800) 925-6278 | AB5: genekent1@aol.com | AC5: Highest Quality
B6: New York State Teachers Retirement System | C6: =COUNTA('Pension-Fund-Base-V1-Default-vi'!$D6:$AC6) -> 24 | D6: The New York State Teachers' Retirement System (NYSTRS) is one of the ten largest public pension funds in the United States, mainly serving eligible public school teachers and administrators in New York State. NYSTRS administers a defined benefit plan providing members with retirement, disability, and death benefits. Currently, it has 448,785 total members, including 268,058 active members and 180,727 retired members. It emphasizes strong ethical values, has a fiduciary responsibility to prudently manage its assets, and focuses on long-term investments across a diverse portfolio. The Retirement Board oversees the operations, ensuring that their investment approach is transparent and accountable, addressing risks such as climate change in their strategies. In 2022, they paid out $8.2 billion in annual benefits and continue to support their members with resources and guidance. | E6: Public Pension | F6: www.linkedin.com/company/nystrs | G6: United States primarily, with international equity covering multiple countries globally (implied by MSCI ACWI Ex-U.S. Index which includes developed and emerging markets globally excluding U.S.) | H6: North America, Europe, Asia, Global | I6: $200M–$500M+ | J6: Public Equity, Fixed Income, Private Equity, Private Credit, Real Estate Equity, Real Estate Debt, Cash | M6: 10 Corporate Woods Drive | N6: Albany | O6: New York | P6: United States | Q6: Emily | R6: Ekland | S6: Emily Ekland | T6: Senior Advisor to the Executive Director & Chief Investment Officer | U6: Albany, New York, United States | V6: nystrs.org | W6: https://www.linkedin.com/in/emily-ekland-1916b71a/ | X6: emily.ekland@nystrs.org | Y6: Highest Quality | Z6: 15187631999 | AA6: (800) 782-0289 | AB6: edekland@gmail.com | AC6: Highest Quality
B7: Southern Co. | C7: =COUNTA('Pension-Fund-Base-V1-Default-vi'!$D7:$AC7) -> 26 | D7: Southern Company is a leading producer of clean, safe, reliable, and affordable energy, committed to building a sustainable future through innovation and investment in new energy technologies. They are focused on achieving net-zero greenhouse gas emissions by 2050 and currently rank as the 4th largest owner of renewable energy in the U.S. Their philosophy emphasizes environmental stewardship, community support, and operational integrity. The company's core values and strategic goals include reliability, resilience, affordability, and diversity, underpinned by a strong commitment to corporate responsibility. Southern Company operates through various subsidiaries, and has been recognized for its sustainability efforts and innovation initiatives. | E7: Pension Fund (Top 1500 Institutional Investor) | F7: https://www.linkedin.com/company/southern-company | G7: United States | H7: North America | I7: $20M–$75M | J7: Public Equity, Fixed Income, Private Equity, Real Estate, Infrastructure, Private Credit, Cash, Other Alternatives | K7: 21774 million | L7: 21774000000 | M7: 30 Ivan Allen Jr Blvd NW | N7: Atlanta | O7: Georgia | P7: United States | Q7: Dekia | R7: Scott, CFA | S7: Dekia Scott, CFA | T7: Trust Finance Vice President & Chief Investment Officer | U7: Atlanta, Georgia, United States | V7: southerncompany.com | W7: https://www.linkedin.com/in/dekia-scott-cfa-ba48233/ | X7: dscott@southernco.com | Y7: Medium Quality | Z7: 14046444838 | AA7: (404) 506-5000 | AB7: dekia.scott@gmail.com | AC7: Highest Quality
B8: General Dynamics | C8: =COUNTA('Pension-Fund-Base-V1-Default-vi'!$D8:$AC8) -> 24 | D8: General Dynamics is a prominent American aerospace and defense company founded in 1893 and headquartered in Reston, Virginia. It operates globally and is known for being one of the largest defense contractors by arms sales. The company has several divisions including Aerospace, Marine Systems, Combat Systems, and Technologies, offering a diverse range of products and services such as Gulfstream business jets, combat vehicles, nuclear-powered submarines, and communication systems. General Dynamics emphasizes corporate citizenship, sustainable practices, and community support as part of its philosophy. In terms of investment thesis, their recent performance indicates strong revenue growth and improvements in earnings, making it a potential investment opportunity, although growth rates may vary due to market conditions and external factors. | E8: Pension Fund (Top 1500 Institutional Investor) | F8: https://www.linkedin.com/company/general-dynamics | I8: $20M–$75M | J8: Public Equity, Fixed Income, Cash, Other Alternatives | K8: 29467 million | L8: 29467000000 | M8: 11011 Sunset Hills Rd | N8: Reston | O8: VA | P8: United States | Q8: Jeff | R8: Sutton | S8: Jeff Sutton | T8: Asset Manager | U8: Homestead, Florida, United States | V8: generaldynamics.com | W8: https://www.linkedin.com/in/jeff-sutton-314b536/ | X8: jeff.sutton@gd.com | Y8: Medium Quality | Z8: 17864720336 | AA8: (786) 339-9897 | AB8: jswsupbra@yahoo.com | AC8: Lower Quality
B9: Illinois State Universities | C9: =COUNTA('Pension-Fund-Base-V1-Default-vi'!$D9:$AC9) -> 25 | D9: Illinois State University (ISU) is a public research university in Normal, Illinois, founded in 1857. Originally named Illinois State Normal University, it was established as the first state university in Illinois. The institution emphasizes teaching and is recognized as one of the largest producers of teachers in the U.S. The university's motto is "Gladly We Learn and Teach," reflecting its commitment to education and research. ISU has an endowment of $204 million (2023) and a budget of $509.3 million. As of 2023, it enrolls 20,989 students, including 18,450 undergraduates and 2,539 postgraduates, across its 1,180-acre urban campus. The university is classified as an R2: Doctoral University, indicating high research activity. While specific goals, philosophical statements, and investment thesis were not retrieved, ISU's educational focus and commitment to teacher training are central to its operations. | E9: Pension Fund (Top 1500 Institutional Investor) | F9: https://www.linkedin.com/company/surs | G9: United States, United Kingdom, Canada | H9: North America, Europe, Asia | I9: $75M–$200M | J9: Public Equity, Fixed Income, Private Equity, Real Estate, Infrastructure, Private Credit, Other Alternatives, Cash | K9: 25077 million | L9: 25077000000 | M9: 100 North University Street | N9: Normal | O9: Illinois | P9: United States | Q9: Michael | R9: Schlachter | S9: Michael Schlachter, CFA | T9: Chief Investment Officer designee | U9: Los Angeles, California, United States | V9: surs.org | W9: https://www.linkedin.com/in/michael-schlachter-cfa-a68b2467/ | X9: mschlachter@surs.org | Y9: Medium Quality | AA9: (217) 378-8800 | AB9: michael.c.schlachter@gmail.com | AC9: Highest Quality
B10: Johnson & Johnson | C10: =COUNTA('Pension-Fund-Base-V1-Default-vi'!$D10:$AC10) -> 24 | D10: Johnson & Johnson (J&J), founded in 1886, is an American multinational corporation headquartered in New Brunswick, New Jersey. The company specializes in researching, developing, manufacturing, and selling pharmaceuticals, medical devices, and consumer health products. J&J's mission is to improve health and wellness globally, underpinned by their Credo reflecting responsibility towards stakeholders - customers, employees, communities, and shareholders.### IntroductionJ&J operates in three main segments: consumer health, pharmaceuticals, and medical devices. Key products include immunology medications, surgical products, and consumer health goods such as baby care and beauty products.### Goals and PhilosophyTheir philosophy emphasizes good health as the foundation for thriving lives and progressive communities. They are committed to sustainability and innovation, aiming to enhance access to healthcare while maintaining high ethical standards in operations.### Investing ThesisJ&J presents a stable investment opportunity with strong fundamentals: $89.7B in revenue for 2024 and a market cap of approximately $384.2B. They maintain a notable dividend yield of 3.17%. The diversification in product offerings and recent acquisitions, like Yellow Jersey Therapeutics, support growth potential, despite facing competition from major pharmaceutical firms like Merck and Pfizer. J&J's commitment to innovation and sustainability positions it favorably for future growth.### Recent Financials- Revenue (2022): $85.2B- Market Cap (2023): $376B- Dividend per Share: $4.81The leadership team includes CEO Joaquin Duato, who steers J&J towards its strategic goals while addressing contemporary healthcare challenges. | E10: Pension Fund (Top 1500 Institutional Investor) | F10: https://www.linkedin.com/company/johnson-&-johnson | G10: United States, United Kingdom, Brazil | H10: North America, Europe, South America | I10: $75M-$200M, | J10: Public Equity, Fixed Income, Real Estate, Private Equity, Cash | K10: 44371 million | L10: 44371000000 | M10: One Johnson & Johnson Plaza | N10: New Brunswick | O10: New Jersey | P10: United States | Q10: John | R10: Strainic | S10: John Strainic | T10: Managing Partner | U10: Chagrin Falls, Ohio, United States | V10: jnj.com | W10: https://www.linkedin.com/in/john-strainic-b188479/ | X10: john.strainic@j-jconsulting.net | Y10: Medium Quality | Z10: 12163467030 | AA10: (301) 922-4938
B11: Federal Reserve Employees | C11: =COUNTA('Pension-Fund-Base-V1-Default-vi'!$D11:$AC11) -> 23 | D11: The Federal Reserve is the central bank of the U.S., established by the Federal Reserve Act of 1913. Its key functions include conducting monetary policy, stabilizing the financial system, supervising financial institutions, ensuring payment system safety, and promoting consumer protection. The Federal Reserve aims to promote maximum employment and stable prices. Its philosophy revolves around economic stability and public interest, engaging in thorough data collection and analysis. The members of the Board of Governors, who oversee these functions, include prominent figures like Jerome H. Powell and Philip N. Jefferson. The Federal Reserve does not have an investing thesis typical of corporations; rather, it focuses on regulatory and economic functions to influence the broader economy. | E11: Pension Fund (Top 1500 Institutional Investor) | F11: https://www.linkedin.com/company/federal-reserve-system | G11: United States, Japan, Korea, Canada | H11: North America, Asia | I11: $5M–$20M | K11: 34035 million | L11: 34035000000 | M11: 20th Street and Constitution Avenue N.W. | N11: Washington | O11: DC | P11: United States | Q11: Pat | R11: Mcclanahan | S11: Pat McClanahan | T11: Chief Operating Officer | U11: Washington DC-Baltimore Area | V11: federalreserve.gov | W11: https://www.linkedin.com/in/pat-mcclanahan-790a558/ | X11: patmcclanahan@federalreserve.gov | Y11: Medium Quality | Z11: 17039462914 | AA11: (202) 452-3000
B12: Los Angeles County Empl. | C12: =COUNTA('Pension-Fund-Base-V1-Default-vi'!$D12:$AC12) -> 26 | D12: Los Angeles County Department of Human Resources is committed to providing innovative and efficient talent solutions, aiming to recruit, develop, and retain diverse talent for public service. The department emphasizes creating opportunities for professional and personal growth, advocating diversity, and maintaining a professional work environment. They consider themselves an 'employer of choice' with a strong focus on employee welfare through various benefits. | E12: Pension Fund (Top 1500 Institutional Investor) | F12: www.linkedin.com/company/lacera | G12: United States, United Kingdom, Canada, Germany, Japan, China, Taiwan, India, South Korea, Brazil | H12: North America, Europe, Asia, South America | I12: $75M–$200M | J12: Public Equity, Fixed Income, Private Equity, Real Estate, Infrastructure, Hedge Funds, Private Credit, Cash | K12: 67616 million | L12: 67616000000 | M12: 300 N. Lake Ave. | N12: Pasadena | O12: CA | P12: United States | Q12: Herman | R12: Santos | S12: Herman Santos | T12: Chairman of the LACERA Board of Retirement. | U12: Chino Hills, California, United States | V12: lacera.com | W12: https://www.linkedin.com/in/herman-santos-a4098798/ | X12: hsantos@lacera.com | Y12: Highest Quality | Z12: 19097313701 | AA12: (626) 229-3500 | AB12: hbsantos1@verizon.net | AC12: Lower Quality
B13: Missouri Schools & Educ. | C13: =COUNTA('Pension-Fund-Base-V1-Default-vi'!$D13:$AC13) -> 26 | D13: Missouri Department of Elementary and Secondary Education is the official department responsible for education in Missouri. | E13: Pension Fund (Top 1500 Institutional Investor) | F13: https://www.linkedin.com/company/psrspeers | G13: United States, Russia (exposure until halted), China (exposure until divestment vote), other unspecified countries due to Non-US public equities and private investments | H13: North America, Europe, Asia, likely multiple other continents due to non-US public equities and private equity investments | I13: $75M–$200M | J13: Public Equity, Fixed Income, Private Equity, Real Estate, Private Credit, Cash, Hedge Funds | K13: 51163 million | L13: 51163000000 | M13: 3210 West Truman Boulevard | N13: Jefferson City | O13: MO | P13: United States | Q13: Brenna | R13: Noble, CFA | S13: Brenna Noble, CFA | T13: Portfolio Manager | U13: United States | V13: psrs-peers.org | W13: https://www.linkedin.com/in/brennanoble/ | X13: bnoble@psrs-peers.org | Y13: Highest Quality | Z13: 15737016733 | AA13: (219) 210-3564 | AB13: brenna.noble@gmail.com | AC13: Highest Quality
B14: Mass General Brigham | C14: =COUNTA('Pension-Fund-Base-V1-Default-vi'!$D14:$AC14) -> 25 | D14: **Mass General Brigham Overview**: Mass General Brigham is a not-for-profit integrated health care system based in Massachusetts, encompassing 16 hospitals and numerous community and specialty care resources. Notable components include Massachusetts General Hospital and Brigham and Women's Hospital. The system is focused on improving health and lives in the communities it serves, investing significantly in community initiatives and workforce development. **Goals and Philosophy**: The core mission of Mass General Brigham is to enhance patient care, invest in education and training for future healthcare leaders, and employ a coordinated care model emphasizing diversity, equity, and inclusion in health care practices. In 2021, for example, the organization channeled $225 million into community benefits. **Investing Thesis**: The Mass General Brigham Investment Office oversees institutional investments aimed at generating returns to fuel major health care advancements and projects, including capital developments and biotech research. They collaborate with leading global investment firms to create diverse and dynamic investment portfolios, ensuring long-term value preservation and operational support. | E14: Pension Fund (Top 1500 Institutional Investor) | F14: https://www.linkedin.com/company/mass-general-brigham | G14: United States, various developed countries in Europe, various emerging markets in Asia | H14: North America, Europe, Asia | I14: $20M -$75M | J14: Public Equity, Fixed Income, Private Equity, Real Estate, Other Alternatives | K14: 20014 million | L14: 20014000000 | M14: 399 Revolution Drive | N14: Somerville | O14: Massachusetts | P14: United States | Q14: Lisa | R14: Vazquez | S14: Lisa Vazquez | T14: Investment Portfolio Manager | U14: Boston, Massachusetts, United States | V14: danafarberbostonchildrens.org | W14: https://www.linkedin.com/in/lisa-vazquez-5455b25/ | X14: lvazquez@partnersinvest.org | Y14: Highest Quality | AA14: (617) 248-6000 | AB14: lisa.m.vazquez@gmail.com | AC14: Highest Quality
B15: Colorado Employees | C15: =COUNTA('Pension-Fund-Base-V1-Default-vi'!$D15:$AC15) -> 26 | D15: The Colorado Employee Ownership Office works to promote employee ownership as a sustainable business structure. The office focuses on establishing networks for training, support, and consulting for businesses interested in converting to employee ownership, thereby promoting higher wages, better job security, and lower turnover among employees.**Goals & Philosophy:**- Establish technical support networks for businesses transitioning to employee ownership.- Educate about the benefits of employee-owned businesses, including higher wages and reduced turnover.- Encourage cooperative law and diverse employee ownership options within the state.- Provide funding opportunities to assist transitions to employee ownership, such as tax credits and grants.**Investment Thesis:**- Emphasizes the advantages of employee ownership, such as improved employee retention, reduced broker costs for business sales, and long-term sustainability of jobs.- By increasing access to employee ownership, Colorado aims to foster economic stability and growth by ensuring that businesses remain locally owned and managed. - Notably, employee-owned companies like New Belgium Brewing Co. exemplify the success of this model, showcasing increased performance and stability. | E15: Pension Fund (Top 1500 Institutional Investor) | F15: https://www.linkedin.com/company/colorado-pera | G15: United States primarily, plus developed and emerging countries globally without specific country breakdown | H15: North America, Global (including developed and emerging markets in various continents) | I15: $75M–$200M | J15: Public Equity, Fixed Income, Private Equity, Real Estate, Infrastructure, Private Credit, Hedge Funds, Other Alternatives, Cash | K15: $68.6B | L15: 68600000000 | M15: 1301 Pennsylvania Street | N15: Denver | O15: Colorado | P15: United States | Q15: Marcus | R15: Pennell | S15: Marcus Pennell | T15: Member Board of Trustees | U15: Golden, Colorado, United States | V15: copera.org | W15: https://www.linkedin.com/in/marcus-pennell-a7439a47/ | X15: mpennell@copera.org | Y15: Medium Quality | Z15: 13036679035 | AA15: (303) 832-9550 | AB15: marcusapennell@gmail.com | AC15: Highest Quality
B16: Dow | C16: =COUNTA('Pension-Fund-Base-V1-Default-vi'!$D16:$AC16) -> 26 | D16: Dow Inc. is a materials science company founded in 1897, headquartered in Midland, Michigan. Its mission is to be the most innovative and sustainable materials science company worldwide. Dow emphasizes core values of integrity, respect, and community engagement and has a commitment to address social issues, including systemic racism. The company aims for a circular economy by elevating recycled materials and strives for net-zero emissions with innovative projects. Its investing thesis focuses on a diverse portfolio including plastics and chemicals, strong financial performance with 2022 revenue of $44.6 billion, and a commitment to sustainability and innovation in product offerings. Dow engages with stakeholders through transparency and aims to deliver long-term value while advancing its sustainability goals. | E16: Pension Fund (Top 1500 Institutional Investor) | F16: https://www.linkedin.com/company/dow-chemical | G16: United States, United Kingdom, Netherlands, Switzerland, Canada, Japan | H16: North America, Europe, Asia | I16: $200M–$500M+ | J16: Fixed Income, Public Equity, Private Equity, Real Estate, Infrastructure, Other Alternatives | K16: 26610 million | L16: 26610000000 | M16: 2211 H H Dow Way | N16: Midland | O16: Michigan | P16: United States | Q16: James | R16: R. Fitterling | S16: Jim Fitterling | T16: Chair, Board of Directors | U16: Midland, Michigan, United States | V16: dow.com | W16: https://www.linkedin.com/in/jim-fitterling/ | X16: jim.fitterling@dow.com | Y16: Highest Quality | Z16: 19899484988 | AA16: (800) 258-2436 | AB16: jrfitter@yahoo.com | AC16: Highest Quality
B17: California State Teachers Retirement System | C17: =COUNTA('Pension-Fund-Base-V1-Default-vi'!$D17:$AC17) -> 23 | D17: The California State Teachers Retirement System (CalSTRS) is the largest educator-only pension fund in the world, providing services such as retirement, disability, and survivor benefits to over 1 million public school educators and their families in California. CalSTRS aims to secure the financial future and sustain the trust of California’s educators through strong leadership and a commitment to accountability and customer service. Its investment philosophy prioritizes mitigating environmental, social, and governance risks, along with achieving long-term asset allocation targets diversified across various asset classes. Notable quotes include their focus on stewardship and risk assessment in investment decisions. | E17: Pension Fund | G17: United States, Canada, Japan, China, United Kingdom, Germany, France, Australia, Brazil, India, South Africa | H17: North America, Asia, Europe, Australia, South America, Africa | I17: $200M–$500M | J17: Public Equity, Fixed Income, Real Estate, Private Equity, Risk Mitigating Strategies (RMS), Inflation Sensitive, Cash/Liquidity, Collaborative Strategies, Strategic Overlay | M17: 100 Waterfront Place | N17: West Sacramento | O17: California | P17: United States | Q17: Michael | R17: McGowan, CRE | S17: Michael McGowan, CRE | T17: Portfolio Manager | U17: Sacramento, California, United States | V17: calstrs.com | W17: https://www.linkedin.com/in/michaelmmcgowan/ | X17: mmcgowan@calstrs.com | Y17: Highest Quality | Z17: 19252121823 | AA17: (800) 228-5453 | AB17: azurite1@icloud.com | AC17: Highest Quality
B18: PepsiCo | C18: =COUNTA('Pension-Fund-Base-V1-Default-vi'!$D18:$AC18) -> 24 | D18: PepsiCo, Inc. is an American multinational food, snack, and beverage corporation headquartered in Harrison, New York. Founded in 1898, the company has grown to be one of the world's largest food and beverage companies, known for brands such as Lays, Mountain Dew, Doritos, and Tropicana.### Introduction:PepsiCo operates in over 200 countries and territories and employs around 300,000 people worldwide. The company generates a significant portion of its revenue from non-carbonated drinks and snack foods, illustrating a diversified business model.### Goals and Philosophy:PepsiCo aims to achieve net zero greenhouse gas emissions by 2040. This goal reflects their commitment to sustainability. The company focuses on creating sustainable growth through innovation and commitment to environmental conservation. Additionally, PepsiCo emphasizes corporate responsibility and community engagement.### Investing Thesis:PepsiCo’s strategy includes divesting from low-margin business areas to focus more on high-growth snack and healthier food segments. This was evident when they sold a majority stake in Tropicana for $3.3 billion to invest in health-oriented products. Their recent investment in energy drink maker Celsius further illustrates a strategic approach to capturing growth in popular beverage categories. Consequently, PepsiCo is positioning itself as a leader not only in snacks and beverages but also in nutritious food solutions. For more detailed information, you can visit PepsiCo’s [Wikipedia page](https://en.wikipedia.org/wiki/PepsiCo). | E18: Pension Fund (Top 1500 Institutional Investor) | F18: https://www.linkedin.com/company/pepsico | G18: United States, United Kingdom, Canada, European countries excluding UK, Japan, Asian countries excluding Japan, emerging markets countries | H18: North America, Europe, Asia | I18: $20M–$75M | K18: 25699 million | L18: 25699000000 | M18: 700 Anderson Hill Road | N18: Purchase | O18: New York | P18: United States | Q18: Ramon | R18: Laguarta | S18: Ramon Laguarta | T18: Chairman of the Board of Directors | U18: Purchase, New York, United States | V18: pepsico.com | W18: https://www.linkedin.com/in/ramonlaguarta/ | X18: ramon.laguarta@pepsico.com | Y18: Medium Quality | AA18: (914) 253-2000 | AB18: tktennis12@gmail.com | AC18: Highest Quality
B19: Indiana Public Retirement | C19: =COUNTA('Pension-Fund-Base-V1-Default-vi'!$D19:$AC19) -> 24 | D19: The Indiana Public Retirement System (INPRS) is one of the largest pension systems in the United States, serving a total of 529,244 working members and retirees from over 1,318 employers, which include public universities, school corporations, and state agencies. INPRS has been recognized as one of the Best Places to Work in 2024 by the Indiana Chamber of Commerce.**Mission and Vision:** - **Vision:** Engaged members able to realize their retirement dreams.- **Mission:** As fiduciaries, INPRS is committed to educating stakeholders, collecting necessary contributions, and prudently managing member assets to deliver promised Defined Benefit (DB) and Defined Contribution (DC) benefits and services. As of June 30, 2021, INPRS had $47.961 billion in actuarial accrued liabilities and $34.479 billion in actuarial assets, managing a portfolio valued at $45.8 billion with an 89.0 percent funded actuarial value. In fiscal year 2021, the system paid out approximately $3.4 billion in benefits and received $3.2 billion in contributions. | E19: Pension Fund (Top 1500 Institutional Investor) | F19: www.linkedin.com/company/indiana-public-retirement-system | H19: North America, Europe, Asia, Africa, South America, Australia (developed, emerging, frontier markets globally) | I19: $75M-$200M | J19: Public Equity, Private Markets, Fixed Income (Ex Inflation-Linked), Fixed Income (Inflation-Linked), Commodities, Real Assets, Absolute Return, Risk Parity | K19: 42849 million | L19: 42849000000 | M19: 1 N Capitol Ave, Ste 001 | N19: Indianapolis | O19: IN | P19: United States | Q19: Beth | R19: Romer, PMP, A-CSM | S19: Beth Romer, PMP, A-CSM | T19: Information Technology Portfolio Manager | U19: Indianapolis, Indiana, United States | V19: in.gov | W19: https://www.linkedin.com/in/beth-romer-pmp-a-csm-a6235511/ | X19: bromer@in.gov | Y19: Medium Quality | AA19: (317) 232-4567 | AB19: beth.anne.reynolds@gmail.com | AC19: Highest Quality
B20: Texas Employees | C20: =COUNTA('Pension-Fund-Base-V1-Default-vi'!$D20:$AC20) -> 25 | D20: Texas Employees, formally known as the Employees Retirement System of Texas (ERS), administers retirement benefits, health and insurance plans, and flexible benefit programs such as TexFlex and the Texa$aver 401(k)/457 Program on behalf of Texas state employees and retirees. They manage and invest trust funds solely for the benefit of their members, aiming to enhance the lives of those they serve. **Introduction:** ERS serves employees and retirees of State of Texas agencies and higher education institutions and is dedicated to providing competitive benefits that enhance the lives of its members.**Goals and Philosophy:** The mission of ERS is to offer competitive benefits, ensuring a positive impact on the lives of its members. **Investing Thesis:** While a specific investing thesis wasn't detailed, the ERS's investment approach emphasizes prudent management and investments aimed at securing the benefits for its members.**Specialties:** Investments, Retirement benefits, Health and other insurance benefits. | E20: Pension Fund (Top 1500 Institutional Investor) | F20: https://www.linkedin.com/company/employees-retirement-system-of-texas | H20: North America primarily based on the nature of the fund and location of beneficiaries, but no specific country allocations were publicly disclosed. | I20: $75M-$200M | J20: Public Equity, Private Equity, Public Credit, Private Credit, Private Real Estate, Private Infrastructure, Hedge Funds, Cash, Rates | K20: 37200 million | L20: 37200000000 | M20: 1000 Red River Street | N20: Austin | O20: Texas | P20: United States | Q20: Anthony | R20: Curtiss | S20: Anthony Curtiss | T20: Deputy Chief Investment Officer | U20: Austin, Texas, United States | V20: texas.gov | W20: https://www.linkedin.com/in/anthony-curtiss-5135245/ | X20: anthony.curtiss@ers.texas.gov | Y20: Highest Quality | Z20: 18324893897 | AA20: (877) 275-4377 | AB20: anthony.curtiss@gmail.com | AC20: Highest Quality
B21: Hydro-Quebec | C21: =COUNTA('Pension-Fund-Base-V1-Default-vi'!$D21:$AC21) -> 24 | D21: Hydro-Québec is a major electricity producer, transmitter and distributor in Canada, focusing primarily on renewable energy, particularly hydroelectric power. It operates under the ownership of the Quebec government and is comprised of four critical divisions: Hydro-Québec Production, Hydro-Québec TransÉnergie, Hydro-Québec Distribution, and Hydro-Québec Équipement. The company's commitment includes research into energy efficiency and the development of related technologies. Its primary goals revolve around delivering reliable energy supply, effective resource utilization, and sustainable energy practices. | E21: Pension Fund (Top 1500 Institutional Investor) | G21: Canada, United States, multiple European countries | H21: North America, Europe | I21: $75M–$200M | J21: Public Equity, Private Equity, Real Estate, Infrastructure, Fixed Income, Private Credit, Hedge Funds, Other Alternatives | K21: 21426 million | L21: 21426000000 | M21: 75, boulevard René-Lévesque Ouest | N21: Montréal | O21: Quebec | P21: Canada | Q21: Jeanne | R21: Olivier | S21: Jeanne Olivier | T21: Directrice principale, cheffe de cabinet bureau du PDG / Chief of staff for the CEO | U21: Canada | V21: hydroquebec.com | W21: https://www.linkedin.com/in/jeanne-olivier-9003a1106/ | X21: olivier.jeanne@hydroquebec.com | Y21: Highest Quality | AA21: (514) 289-6244 | AB21: jeannemolivier@gmail.com | AC21: Highest Quality
B22: J.P. Morgan Chase | C22: =COUNTA('Pension-Fund-Base-V1-Default-vi'!$D22:$AC22) -> 26 | D22: J.P. Morgan Chase is one of the world's oldest and largest financial institutions, founded in 1799. The company offers extensive financial services across global markets, focusing on asset management, commercial banking, consumer banking, and investment banking. Its philosophy revolves around delivering value to shareholders, fostering community growth, and promoting integrity and operational excellence in all business practices. The investment thesis for J.P. Morgan Chase highlights its broad scale and strength, predicting strong earnings potential and a buy rating from analysts due to its strong market position. | E22: Pension Fund (Top 1500 Institutional Investor) | F22: www.linkedin.com/company/jpmorganchase | G22: United States, United Kingdom, Japan, Germany, France, China, India, Brazil, South Africa, Turkey, Mexico | H22: North America, Europe, Asia, South America, Africa | I22: $20M–$75M , | J22: Public Equity, Fixed Income, Private Equity, Real Estate, Hedge Funds, Private Credit, Cash, Other Alternatives | K22: $62.8B | L22: 62800000000 | M22: 270 Park Avenue | N22: New York | O22: New York | P22: United States | Q22: Fotini | R22: Minasidis | S22: Fotini Minasidis | T22: Senior Fund Administrator | U22: Dedham, Massachusetts, United States | V22: jpmorganchase.com | W22: https://www.linkedin.com/in/fotini-minasidis-594800149/ | X22: fotini.minasidis@jpmorgan.com | Y22: Medium Quality | Z22: 16173354085 | AA22: (212) 270-6000 | AB22: fotinim@aol.com | AC22: Highest Quality
B23: Millennium Inorganic Chemicals (UK) Pension Scheme | C23: =COUNTA('Pension-Fund-Base-V1-Default-vi'!$D23:$AC23) -> 24 | D23: Millennium Inorganic Chemicals (UK) Pension Scheme predominantly invests in pooled funds, specifically focusing on fixed income assets. The trustees of the scheme delegate the responsibility for voting and engagement activities to their investment managers. Key investment vehicles include the TwentyFour Absolute Return Credit Fund and the CVC Global Yield Fund. The trustees review voting information and engagement policies of their investment managers annually. Engagement activities primarily revolve around environmental, social, and governance (ESG) factors, with noteworthy interactions including discussions on carbon emissions reduction and gender diversity credentials with various companies. | E23: Pension Fund | F23: https://www.linkedin.com/company/millennium-inorganic-chemicals | G23: United Kingdom, India, Brazil, South Africa | H23: Europe, Asia, South America, Africa | I23: $5M–$20M | J23: Public Equity, Fixed Income, Cash, Other Alternatives | M23: Laporte Road | N23: Grimsby | O23: North East Lincolnshire | P23: England | Q23: Jean-FranAois | R23: Turgeon | S23: Jean-Francois Turgeon | T23: Co-Chief Executive Officer | U23: Stamford, Connecticut, United States | V23: tronox.com | W23: https://www.linkedin.com/in/jean-francois-turgeon-763b1a68/ | X23: jean-francois.turgeon@tronox.com | Y23: Medium Quality | Z23: 12037053768 | AA23: (203) 705-3800 | AB23: jfturgeon333@gmail.com | AC23: Highest Quality
B24: Virginia Retirement | C24: =COUNTA('Pension-Fund-Base-V1-Default-vi'!$D24:$AC24) -> 26 | D24: The Virginia Retirement System (VRS) is an independent state agency established in 1952, responsible for administering pension plans and other benefits for Virginia's public sector employees. It was renamed in 1990 and is governed by a detailed legislative and oversight framework. VRS's philosophy emphasizes sound financial stewardship and superior customer service, ensuring that investments are managed solely for the benefit of its members. The system is committed to maximizing returns while managing risk through diversification, aiming to fund benefit payments primarily through investment earnings. In FY2023, VRS reported a total fund market value of $113.0 billion and an investment return assumption of 6.75%. The average added value from investments over the past decade is approximately $956 million annually. The VRS pays about $5.7 billion annually to its retirees and beneficiaries. | E24: Pension Fund (Top 1500 Institutional Investor) | F24: https://www.linkedin.com/company/virginia-retirement-system | G24: United States, countries in Europe, countries in Asia Pacific, countries in Latin and South America | H24: North America, Europe, Asia, Latin America | I24: $200M–$500M | J24: Public Equity, Private Equity, Real Assets, Credit Strategies, Fixed Income, Diversifying Strategies, Private Investment Partnerships, Exposure Management Portfolio, Cash | K24: $110.0B | L24: 110000000000 | M24: 1200 East Main Street | N24: Richmond | O24: Virginia | P24: United States | Q24: Vu | R24: Le | S24: Vu Le | T24: Portfolio Manager | U24: Richmond, Virginia, United States | V24: varetire.org | W24: https://www.linkedin.com/in/vumanhle/ | X24: vle@varetire.org | Y24: Medium Quality | Z24: 18046158491 | AA24: (804) 649-8059 | AB24: lmvu00@yahoo.com | AC24: Highest Quality
B25: Oregon Public Employees | C25: =COUNTA('Pension-Fund-Base-V1-Default-vi'!$D25:$AC25) -> 23 | D25: The Oregon Public Employees Retirement System (PERS) administers public employee benefit trusts in Oregon and serves over 367,000 current and former employees. PERS is dedicated to integrity, professionalism, and respect in serving the public. Its investment philosophy focuses on maximizing returns while managing risks, aiming for net annualized returns. The asset allocation includes 55% in equities, with specific targets for fixed income, real estate, and alternatives. These values and policies guide their operations and investment decisions. | E25: Pension Fund | G25: United States (primary), Canada, European developed markets | H25: North America, Europe | I25: $200M–$500M+ | J25: Public Equity, Fixed Income, Cash, Real Estate, Private Equity, Opportunity, Real Assets, Diversifying Strategies | M25: 11410 SW 68th Parkway | N25: Tigard | O25: Oregon | P25: United States | Q25: Micha | R25: Sinclair | S25: Micha Sinclair, MBA | T25: Chairman, LCB Board Of Directors | U25: Portland, Oregon, United States | V25: oregon.gov | W25: https://www.linkedin.com/in/michasinclair/ | X25: micha.sinclair@oregon.gov | Y25: Highest Quality | Z25: 15034599541 | AA25: (503) 378-3111 | AB25: constantinesinclair@gmail.com | AC25: Highest Quality
B26: United Airlines Holdings | C26: =COUNTA('Pension-Fund-Base-V1-Default-vi'!$D26:$AC26) -> 25 | D26: United Airlines Holdings, Inc. is an airline holding company that offers air travel services for passengers and cargo across North America and internationally. Founded on April 6, 1926, the company is headquartered in Chicago, Illinois, and operates major hub airports including Newark Liberty International, Chicago O'Hare, and Denver International. United has a workforce of approximately 104,500 employees and generated a revenue of $53.7 billion in 2022. The company aims to connect people and unite the world with its vision and mission focused on safety, reliability, and sustainability in operations. United Airlines holds a strong position in the market with a competitive network among its main competitors like Delta and American Airlines. The company's investing philosophy emphasizes sustainability, aiming for net-zero greenhouse gas emissions by 2050. A commitment to ethical decision-making and community involvement is also central to their corporate philosophy. Their current strategy includes an emphasis on expanding their route network and improving customer experience through innovative services. | E26: Pension Fund (Top 1500 Institutional Investor) | F26: https://www.linkedin.com/company/united-airlines | G26: United States, Japan, Canada, Norway, Netherlands, Australia, South Korea, United Kingdom, Singapore, Sweden, Denmark, China, Switzerland, Malaysia, Germany, Brazil, Chile, Colombia, France, Finland, India, Italy, Kuwait, Luxembourg, Mexico, New Zealand, Philippines, Portugal, Russia, South Africa, Taiwan, Thailand, Vietnam | H26: North America, Asia, Europe, Oceania, South America | J26: Fixed Income, Cash, Public Equity, Other Alternatives | K26: 25200 million | L26: 25200000000 | M26: 233 South Wacker Drive | N26: Chicago | O26: Illinois | P26: United States | Q26: Mukul | R26: Hariharan | S26: Mukul Hariharan | T26: Managing Partner | U26: Houston, Texas, United States | V26: united.com | W26: https://www.linkedin.com/in/mukul-hariharan-49ba5912/ | X26: mukul.hariharan@aa.com | Y26: Medium Quality | Z26: 15122948639 | AA26: (800) 433-7300 | AB26: mukul.hariharan@gmail.com | AC26: Highest Quality
B27: Andersen Corporation Employees' Pension and Retirement Plan | C27: =COUNTA('Pension-Fund-Base-V1-Default-vi'!$D27:$AC27) -> 23 | D27: The Andersen Corporation Employees' Pension and Retirement Plan is a defined-benefit plan established in 1950, located in Bayport, Minnesota. It covers all eligible employees and is a non-contributory pension plan that provides predetermined monthly retirement benefits based on credited years of service and salary. The retirement benefits generally start when employees reach normal retirement age. The plan does not maintain individual accounts, and benefits are typically expressed as monthly payments rather than lump sums. | E27: Pension Fund | F27: https://www.linkedin.com/company/andersen | G27: United States, Germany | H27: North America, Europe | I27: $5M–$20M | J27: Public Equity, Fixed Income, Cash | M27: 100 4th Avenue North | N27: Bayport | O27: MN | P27: United States | Q27: Tom | R27: Andersen | S27: Tom Andersen | T27: Managing Partner | U27: Greenwich, Connecticut, United States | V27: andersenwindows.com | W27: https://www.linkedin.com/in/tom-andersen-8bb3ab56/ | X27: tom@andersenfinancialgroup.com | Y27: Highest Quality | AA27: (203) 422-0166 | AB27: ander7902@aol.com | AC27: Highest Quality
B28: Raytheon Technologies | C28: =COUNTA('Pension-Fund-Base-V1-Default-vi'!$D28:$AC28) -> 25 | D28: Raytheon Technologies, also known as RTX, is a prominent aerospace and defense company that aims to tackle significant challenges in aviation, space, and defense. They employ over 185,000 professionals across their primary businesses: Collins Aerospace, Pratt & Whitney, and Raytheon. The company enhances safety and efficiency with innovative technologies, impacting aviation, defense, and space sectors substantially. RTX emphasizes sustainability, aiming for net-zero emissions, while advancing technologies addressing complex issues.RTX's corporate philosophy revolves around integrity, accountability, ethical business practices, and a commitment to product safety and quality. Leadership encourages a culture that prioritizes human rights and compliance. They are focused on resilience in business operations and fostering an accountable culture by promoting strong ethical standards through extensive training and programs.The investment thesis for Raytheon Technologies indicates strong growth potential, particularly in their defense and aerospace sectors, buoyed by a solid strategy involving share buybacks and dividends. Notably, they plan to repurchase $6 billion worth of shares and distribute $3 billion in dividends within 2023, representing about 6.3% of their market cap. Key growth drivers include maintenance needs in the civil aftermarket, steady cash flows from the Defense Missile Segment, and increased GTF engine deliveries. Recent performance shows a 5% year-over-year revenue increase, highlighting the company’s robust market position and potential for future earnings growth. | E28: Pension Fund (Top 1500 Institutional Investor) | F28: https://www.linkedin.com/company/raytheon-technologies-co | G28: United States, Italy, Japan, Canada, United Kingdom, Spain | H28: North America, Europe, Asia | I28: $200M-$500M | J28: Public Equity, Fixed Income, Real Estate, Cash, Other Alternatives | K28: $108.9B | L28: 108900000000 | M28: 1000 Wilson Blvd | N28: Arlington | O28: Virginia | P28: United States | Q28: Neil | R28: Mitchill | S28: Neil Mitchill | T28: Chief Financial Officer | U28: Greater Hartford | V28: rtx.com | W28: https://www.linkedin.com/in/neil-mitchill-412b6213/ | X28: neil.mitchill@pw.utc.com | Y28: Highest Quality | AA28: (860) 403-5000 | AB28: advdance@aol.com | AC28: Highest Quality
B29: State Farm | C29: =COUNTA('Pension-Fund-Base-V1-Default-vi'!$D29:$AC29) -> 25 | D29: State Farm is a mutual insurance company founded in 1922, headquartered in Bloomington, Illinois. It is the largest property and casualty insurance provider and the largest auto insurance provider in the United States. The company's mission is to help people manage everyday risks, recover from the unexpected, and realize their dreams. Their goals include being the first and best choice for customers in insurance and financial services, and they emphasize values such as quality service, relationships, integrity, and financial strength. State Farm's financial services include banking and investing, with significant revenue and net income figures indicating a robust financial standing. In 2019, its revenue was approximately $79.4 billion, and it had a net income of about $5.6 billion. The company's operational strategy focuses on maintaining diverse services and a strong community presence through over 19,000 agents and numerous service centers. State Farm prioritizes mutual trust, fulfilling promises, and assisting in community strength as part of their overall philosophy. | E29: Pension Fund (Top 1500 Institutional Investor) | F29: https://www.linkedin.com/company/state_farm | G29: European countries, Australia, Israel, New Zealand, Hong Kong, Japan, Singapore | H29: Europe, Asia, Oceania | I29: $20M–$75M | J29: Public Equity, Fixed Income, Cash | K29: 45793 million | L29: 45793000000 | M29: One State Farm Plaza | N29: Bloomington | O29: Illinois | P29: United States | Q29: Steven | R29: Williams | S29: Steven Williams | T29: Member Board Of Directors | U29: Dallas-Fort Worth Metroplex | V29: statefarm.com | W29: https://www.linkedin.com/in/steven-williams-b4b8604/ | X29: steven.williams@pepsico.com | Y29: Medium Quality | AA29: (800) 226-0083 | AB29: stevewilliamscpa@aol.com | AC29: Highest Quality
B30: Duke Energy | C30: =COUNTA('Pension-Fund-Base-V1-Default-vi'!$D30:$AC30) -> 26 | D30: Duke Energy, a Fortune 150 company, provides electric and gas services to millions across several states, focusing on sustainable energy transitions, customer reliability, and emerging technologies. Its goals include achieving net-zero methane emissions by 2030 and net-zero carbon emissions from electricity generation by 2050, with a major emphasis on affordability, safety, and infrastructure investment. | E30: Pension Fund (Top 1500 Institutional Investor) | F30: https://www.linkedin.com/company/duke-energy-corporation | G30: United States | H30: North America, Global (including unspecified countries) | I30: $75M–$200M | J30: Public Equity, Fixed Income, Private Equity, Real Estate, Commodities, Cash, Other Alternatives | K30: 17145 million | L30: 17145000000 | M30: 525 South Tryon Street | N30: Charlotte | O30: North Carolina | P30: United States | Q30: Marie | R30: McKee | S30: Marie McKee | T30: Board of Directors | U30: Sarasota, Florida, United States | V30: duke-energy.com | W30: https://www.linkedin.com/in/marie-mckee-ba95178/ | X30: marie.mckee@duke-energy.com | Y30: Medium Quality | Z30: 16077658209 | AA30: (877) 372-8477 | AB30: kmckee-cole@hotmail.com | AC30: Lower Quality
B31: PSP Investments | C31: =COUNTA('Pension-Fund-Base-V1-Default-vi'!$D31:$AC31) -> 23 | D31: PSP Investments, or the Public Sector Pension Investment Board, is one of Canada's largest pension investment managers with CAD $264.9 billion in net assets under management. It was established in 1999 to manage pension funds for public service employees of the Canadian federal government, including the Canadian Armed Forces, the Royal Canadian Mounted Police, and the Reserve Force. The organization's primary mandate is to invest these funds with a view to achieving maximum returns while managing risks, in accordance with the Public Sector Pension Investment Act. The company's philosophy emphasizes long-term thinking, sustainability, and responsible investing, integrating environmental, social, and governance (ESG) factors into its investment processes. Unfortunately, detailed information about the specific investing thesis could not be extracted from available sources. | E31: Public Pension | F31: https://www.linkedin.com/company/psp-investments | G31: United States, Canada, United Kingdom, Australia | H31: North America, Europe, Asia, Oceania, Africa, Central and South America | I31: $200M–$500M+ | J31: Public Equity, Fixed Income, Private Equity, Real Estate, Infrastructure, Hedge Funds (Complementary Portfolio), Private Credit (Credit Investments), Cash, Other Alternatives (Natural Resources, Complementary Portfolio) | M31: 135 Laurier Avenue, West | N31: Ottawa | O31: Ontario | P31: Canada | Q31: Jonathon | R31: Hammond | S31: Jonathon Hammond | T31: Director - Credit Investments | U31: New York, New York, United States | V31: investpsp.com | W31: https://www.linkedin.com/in/jonathon-hammond-06014b23/ | X31: jhammond@investpsp.com | Y31: Highest Quality | AA31: (613) 782-3095 | AB31: jonathon.hammond@crescentcap.com | AC31: Highest Quality
B32: Utah State Retirement | C32: =COUNTA('Pension-Fund-Base-V1-Default-vi'!$D32:$AC32) -> 24 | D32: Utah Retirement Systems (URS) serves as the retirement fund for Utah's public employees, managing pension and defined contribution benefits for over 250,000 members across 493 employers including state, local governments, and educational institutions. The organization administers eight defined benefit pension systems and four IRS-qualified retirement savings plans, ensuring fiduciary management of these funds. URS emphasizes its mission of delivering value, innovation, and excellence in service, alongside its commitment to responsible investing and financial security for its members. The investing philosophy involves a commitment to sound financial practices and transparency, with a focus on long-term sustainability and the fiduciary duty to manage retirement assets effectively. The organization conducts regular actuarial reports and comprehensive financial assessments to maintain accountability and performance. | E32: Pension Fund (Top 1500 Institutional Investor) | F32: https://www.linkedin.com/company/utah-retirement-systems | H32: North America and Globally | I32: $75M–$200M | J32: Public Equity, Fixed Income, Private Equity, Real Estate, Infrastructure, Hedge Funds, Private Credit, Cash | K32: 48181 million | L32: 48181000000 | M32: 540 East 200 South | N32: Salt Lake City | O32: UT | P32: United States | Q32: Jason | R32: Morrow | S32: Jason Morrow | T32: Deputy Chief Investment Officer | U32: Salt Lake City, Utah, United States | V32: urs.org | W32: https://www.linkedin.com/in/jasonkmorrow/ | X32: jason.morrow@urs.org | Y32: Highest Quality | AA32: (801) 366-7700 | AB32: granjamo@gmail.com | AC32: Highest Quality
B33: California Public Employees | C33: =COUNTA('Pension-Fund-Base-V1-Default-vi'!$D33:$AC33) -> 26 | D33: California Public Employees' Retirement System (CalPERS) is a non-profit organization based in Sacramento, California. Established in 1932, CalPERS administers health and retirement benefits for over 3 million members including more than 1.6 million in their retirement system. The organization is dedicated to providing benefits to its members through careful investment and management of its funds. CalPERS has a total investment commitment exceeding $30 billion, focusing on areas such as venture capital and growth equity. The organization employs between 1,001 to 5,000 staff members, maintaining active operational status. Notably, CalPERS has invested in major technology stocks, including Intel and Nvidia. | E33: Pension Fund (Top 1500 Institutional Investor) | F33: https://www.linkedin.com/company/calpers | G33: United States, China, India, Japan, various countries in Europe (e.g., United Kingdom, Germany, France), Australia, Canada | H33: North America, Europe, Asia, Australia, South America, Africa | I33: $200M–$500M | J33: Public Equity, Fixed Income, Private Equity, Private Debt, Real Estate, Infrastructure, Opportunistic, Cash | K33: $496.8B | L33: 496800000000 | M33: 400 Q St | N33: Sacramento | O33: California | P33: United States | Q33: Tamara | R33: Alexander, CFA, CAIA | S33: Tamara Alexander, CFA, CAIA | T33: Associate Investment Manager, Portfolio Strategies | U33: Walnut Creek, California, United States | V33: calpers.ca.gov | W33: https://www.linkedin.com/in/tamara-alexander-cfa-caia-04563ba/ | X33: tamara.alexander@ca.gov | Y33: Lower Quality | Z33: 19165190012 | AA33: (916) 795-3000 | AB33: vorobtsova@yahoo.com | AC33: Highest Quality
B34: Chicago Teachers Pension Fund | C34: =COUNTA('Pension-Fund-Base-V1-Default-vi'!$D34:$AC34) -> 23 | D34: The Chicago Teachers' Pension Fund (CTPF) was established by the Illinois state legislature in 1895, making it the oldest public pension fund in Illinois. It manages assets for over 94,000 members, administering benefits that total more than $1.6 billion annually. CTPF is dedicated to the financial security of teachers, principals, and administrators serving or who have served the Chicago Public Schools, including charter and contract schools.**Goals and Philosophy:** CTPF's mission emphasizes the importance of securing retirement, survivor, and disability benefits for certified teachers and employees of the Chicago Public Schools. The organization is governed by a 12-member Board of Trustees, which includes members elected by active and retired teachers as well as appointed representatives. CTPF has a strategic plan in place for the years 2023-26 aimed at optimizing its resources for the benefit of its members.**Investing Thesis:** The CTPF Investment Department focuses on enhancing the total return of its investment portfolio through diversified long-term investments and meticulous risk management. Its Investment Policy outlines the framework for managing its defined benefit plan and establishes guidelines for investment objectives, policies, and responsibilities. The fund works closely with independent professional investment managers and consultants to achieve its investment goals and ensure strong governance practices.More details can be found on their official website: [CTPF](https://ctpf.org). | E34: Pension Fund | G34: United States, Canada, countries in Western Europe, countries in Asia Pacific region, African countries, countries in the Middle East | H34: North America, Europe, Asia, Africa, Middle East | I34: $20M-$75M | J34: Domestic Equity, Global ex-US Equity, Private Equity, U.S. Fixed Income, Real Estate, Private Credit, Infrastructure | M34: 425 S. Financial Place, Chicago | N34: Chicago | O34: IL | P34: United States | Q34: John | R34: Freihammer | S34: John Freihammer, CAIA | T34: Portfolio Manager | U34: Greater Chicago Area | V34: ctpf.org | W34: https://www.linkedin.com/in/john-freihammer-caia-9a3b089/ | X34: freihammerj@ctpf.org | Y34: Medium Quality | Z34: 13127051376 | AA34: (847) 566-4221 | AB34: timothy.silvers@yahoo.com | AC34: Lower Quality
B35: Estee Lauder Pension Plan (US) | C35: =COUNTA('Pension-Fund-Base-V1-Default-vi'!$D35:$AC35) -> 24 | D35: The Estee Lauder Pension Plan (US) is a domestic trust-based noncontributory qualified defined benefit pension plan located in New York, NY. It manages assets primarily for eligible employees of The Estée Lauder Companies, providing retirement benefits, as well as death and pension benefits. It is categorized as a private sector pension fund with investments across alternative asset classes including Private Equity, Venture Capital, Private Debt, Real Estate, Infrastructure, Natural Resources, and Hedge Funds. The executive team involved includes several high-profile executive positions focusing on various asset classes. | E35: Pension Fund | F35: https://www.linkedin.com/company/the-estee-lauder-companies-inc | G35: United States, China, Switzerland, South Korea, Canada | H35: North America, Asia, Europe | I35: $5M–$20M | J35: Public Equity, Fixed Income, Cash, Other Alternatives | M35: 18-01 Marilyn Monroe Blvd | N35: Melville | O35: New York | P35: United States | Q35: David | R35: Vaughn | S35: Jane Sebastian | T35: Chief Operating Officer | U35: New York, New York, United States | V35: bobbibrown.de | W35: https://www.linkedin.com/in/drvaughn/ | X35: fdavidvaughn@ecbm.com | Y35: Medium Quality | Z35: 17578314934 | AA35: (646) 837-0837 | AB35: vaughndr@gmail.com | AC35: Lower Quality
B36: World Bank | C36: =COUNTA('Pension-Fund-Base-V1-Default-vi'!$D36:$AC36) -> 24 | D36: The World Bank is a unique global partnership comprising 189 member countries that focuses on sustainable solutions to reduce poverty and build shared prosperity in developing countries. Its vision is to create a world free of poverty on a livable planet, with a mission to end extreme poverty and promote shared prosperity. The World Bank operates through core values of impact, integrity, respect, teamwork, and innovation. | E36: Pension Fund (Top 1500 Institutional Investor) | F36: https://www.linkedin.com/company/the-world-bank | H36: Africa, East Asia and Pacific, Europe and Central Asia, Latin America and Caribbean, Middle East and North Africa, South Asia | I36: $20M–$75M | J36: Fixed Income, Public Equity, Private Equity, Real Assets, Private Credit, Absolute Return Strategies | K36: 29597 million | L36: 29597000000 | M36: 1818 H Street NW | N36: Washington | O36: DC | P36: United States | Q36: Natan | R36: Goldberger | S36: Natan Goldberger | T36: Portfolio Manager | U36: Arlington, Virginia, United States | V36: worldbank.org | W36: https://www.linkedin.com/in/natangoldberger/ | X36: ngoldberger@worldbank.org | Y36: Medium Quality | AA36: (202) 473-1000 | AB36: natan.goldberger@gmail.com | AC36: Highest Quality
