Workbook

Sheet README
B2: SaaS Forecasting Tool, by Foresight
B3: A basic tool to help you model the revenues and costs of an SaaS business.
B5: Copyright & Contact | C5: This was created by Taylor Davidson (@tdavidson) of Foresight. © 2022, Unstructured Ventures, LLC. Questions, contact taylor@foresight.is or @tdavidson
B6: License | C6: tl:dr; You can modify, edit, use, and share within your company (and with third-parties as needed to operate your business). You may not redistribute, resell, give away to others. Full license.
B7: Goal | C7: Goal of this model is to create an easy way for anyone to model the basic revenue operations of an SaaS business. The model uses external market data where applicable and estimates when necessary. You should adjust all metrics and inputs to fit your business.
B8: Copy to Google Sheets or Download to Excel | C8: File > Make a Copy to copy it to your own Google Drive, or File > Download to download this to use in Excel or other spreadsheet programs. See License for warranties and liabilities.
B9: Support | C9: Questions, happy to assist, contact anytime. More details on how I provide support: https://foresight.is/learn/support
B10: Missing a feature you need? | C10: Check out Alternatives to Foresight for more modeling tools, and check out Foresight's Standard Financial Model for a more comprehensive model with extensive prebuilt options for different revenue models, MRR and ARR, historical financials, budget variances, and more.
B11: Quickstart | C11: 1) Any number in blue with grey shaded background is an input (i.e. an assumption or data point that can be changed), anything in black is the result of a formula. Change blue at will, change anything in black with caution. 2) All cells and formulas are unlocked - as in all Foresight models - so that you can make edits as needed and completely understand what is going on. 3) All assumptions are illustrative ONLY, do not assume they are market data or standard. 4) As with all templates, feel free to create your own model from scratch, using this as a guide. 5) The model is constructed to fit a wide variety of businesses, and therefore, some sections may or may not be relevant to yours. I have grouped together sections on all sheets so that you can review different sections and see all the possibilities, but also easily hide the sections not relevant for you. Simply click on the "+" button on the left-hand side to unhide a section, and click on the "-" button to hide it.
B13: Outline
B15: README | C15: Contact into, overview on model. Safe to delete or hide.
B16: Formatting and Colors Overview | C16: Details on what the colors and formatting in the model mean. https://foresight.is/learn/colors-and-formatting
B17: License | C17: Terms of use of the model. Safe to delete or hide. https://foresight.is/license
B18: Get Started | C18: Assumptions used in the model
B19: Forecast | C19: Calculations for the model, with a couple detailed optional assumptions.
B20: Key Reports | C20: Key charts, using data from the Forecast sheet
B21: Model Comparison | C21: Informational sheet with links to other models available to use. Safe to delete or hide.
B22: Glossary | C22: Informational sheet on common financial terms used in the model. Safe to delete or hide.
B23: Changelog | C23: List of what has been changed in model versions. Safe to delete or hide, although I'd advise to hide (instead of delete) so can always check to see what model version you are using to compare to future changes.

Sheet License
B1: License Agreement
B2: Available on website
B4: This License Agreement (“the Agreement”) between you, the licensee, and Unstructured Ventures, LLC (the “Company”) a limited liability corporation headquartered and registered in the Commonwealth of Pennsylvania and organized under the laws of the state of Delaware. The Company owns the financial model (the “Product”) and any edits, additions, or customizations (the "Service") delivered under this Agreement. This Agreement grants you a non-exclusive, non-transferable right to use and incorporate the Product and Service in personal and corporate projects for the organization that purchased the Product and/or Service.
B6: You agree as follows:
B8: 1. Scope of use
B9: * Use and incorporate the Product and/or Service in personal and commercial projects for your company including financial models, business plans, pitch decks, etc.
B10: * You may modify the Product and/or Service to better serve your project.
B11: * You are granted unlimited usage of the Product and/or Service purchased in your organization.
B12: * If an organization is the licensee, all employees of the organization may use the same license.
B14: 2. Limitations and non-use
B15: * You may not redistribute, sublicense or resell the Product and/or Service.
B16: * You may not distribute, license or sell derivative, recompiled, reverse engineered, or modified versions of the Product and/or Service.
... B29: This Agreement is governed by the laws of the Commonwealth of Pennsylvania and the applicable laws of the United States of America. Legal proceedings related to this Agreement may only be brought in the courts of Pennsylvania. You agree to service of process at the e-mail address on your original order. Notices may be sent to Unstructured Ventures, LLC by email to hello@unstructuredventures.com or by post to Unstructured Ventures, LLC, 6360 Broad St, #5226, Pittsburgh, PA, 15206, USA.

Sheet Disclaimer
B2: Disclaimer
B4: ="This Investor Presentation is provided for informational purposes only and does not constitute an offer to buy or a solicitation of an offer to invest, or to procure an investment in "&'Get Started'!D9&" (the “Company”)." -> This Investor Presentation is provided for informational purposes only and does not constitute an offer to buy or a solicitation of an offer to invest, or to procure an investment in 44561 (the “Company”).
B5: Investments in the Company, if offered, will only be offered to a selected number of accredited investors, and only on the basis of a private offering memorandum for the Company. There are significant risks that are not presented and disclosed in this Investor Presentation. These risks could have a significant negative impact on the performance of the Company.
B6: This Investor Presentation contains forward-looking statements regarding our business plans and prospects and financial conditions, all statements, other than statements of historical fact, in this Investor Presentation, and the attached exhibits, including, among other things, statements regarding our competitive strengths, business strategy, financial projections and plans and objectives of management are forward-looking statements. Although we believe that the expectations reflected in such forward-looking statements are reasonable, there can be no assurance that such expectations will prove to be correct. Forward-looking statements are inherently subject to risks and uncertainties, many of which cannot be predicted with accuracy and some of which might not even be anticipated. Future events and actual results, financial or otherwise, could differ materially from those set forth in, or contemplated by, the forward-looking statements in this Investor Presentation, and, as such, the forward-looking statements contained herein should not be relied upon when making your investment decision. We undertake no obligation to update or revise any forward-looking statements.
B7: The financial projections in this Investor Presentation present, to the best of management’s knowledge and belief, the Company’s expected financial position, results of operations, and cash flows for the forecast period. Accordingly, the financial projections reflect its judgment, as of the date of these financial projections, of the expected conditions and its expected course of action following the sale of securities by the Company. The assumptions disclosed herein are those that management believes are significant to the financial projections. There will usually be differences between the projected and actual results, because events and circumstances frequently do not occur as expected, and those differences may be material. Since the projections are based upon assumptions about circumstances and events that have not yet taken place regarding costs, income, expenses and federal tax matters, which are subject to variations and economic events as future operations actually occur, they do not necessarily reflect the results that will be achieved and should not be relied upon. In all cases, the targeted returns are not predictions or projections that the results in the pro forma financials will be achieved nor of the performance of any investment, and are expressly subject to all assumptions embedded in the pro forma financials and the risk factors disclosed herein. This investment has a high degree of risk, and there can be no assurances that all or any of the assumptions will be true or that an investment’s actual performance will bear any relation to these hypothetical illustrations.
B8: This information contained in this Investor Presentation includes proprietary information, is strictly confidential, and is not to be used or distributed to others without the express written consent of the Company.
B9: This document has been prepared solely for information purposes and is being furnished solely for use by prospective purchasers in considering their interest in obtaining additional information and making their own evaluation of the Company and does not contain all of the information that a prospective purchaser may desire. This information reflects various assumptions by the Company concerning anticipated results, which assumptions may or may not prove to be correct, and the Company has no obligation to update such information. The only information that will have any legal effect will be that specifically contained in definitive documentation. This Investor Presentation has been submitted confidentially to a limited number of investors so that they can consider their interest in obtaining additional information and making their own evaluation of the Company. No offers to purchase the securities of the Company will be accepted prior to (1) the receipt by recipient of a complete private offering memorandum and (2) determination by the Company that the recipient is an appropriate purchaser in light of standards contained in U.S. Securities laws after a full evaluation of recipient by the Company. The Company has not authorized its use for any other purpose. This Investor Presentation may not be copied or reproduced in whole or in part. By accepting a copy of this Investor Presentation, the recipient agrees that neither it nor any of its representatives, agents or employees shall use it for any other purpose or divulge to any party any confidential information about the Company.

Sheet Get Started
B2: Get Started
B3: Key model assumptions and summaries. Detailed inputs on Forecast sheet.
B5: Setup and Timescale
B6: What is the name of your company? | D6: Company | F6: This is used in the Legal Disclaimer sheet, which is purely optional, but something many people choose to include in their projections when they provide them to potential investors
B7: What is your currency? | D7: $ | F7: Model works for any currency, as there are no currency-specific calculations in the model. This label is used in some presentation areas.
B8: What is the first date you want to forecast? | D8: 44440 | F8: First month in the model; if this model is entirely a forecast of the future, input the first month you want to forecast from.
B9: What is the fiscal year end of the first year modeled? | D9: =DATE(YEAR(D8),12,31) -> 44561 | F9: Define the month that is the fiscal year end of the first year in the model. This allows you to set the fiscal years in the model, and thus the # of months in the first year forecasted in the model. The default setting uses a formula to return the year end (in December) from the first month in the forecast. Feel free to overwrite this to set a different fiscal year end, just overwrite the formula with a date.
B11: Revenue and Marketing Assumptions
B12: ="Average Revenue per "&PROPER(LEFT(B20,LEN(B20)-1))&", per month" -> Average Revenue per Subscriber, per month | C12: =D$7 -> $ | D12: 30 | F12: average revenue per month
B13: Gross Margin % | C13: % | D13: 0.875 | F13: as a % of revenues
B14: Customer Acquisition Cost (CAC) | C14: =D$7 -> $ | D14: 25 | F14: ="Customer acquisition cost, per new "&LOWER(LEFT(B20,LEN(B20)-1)) -> Customer acquisition cost, per new subscriber
B15: ="Retention Cost per renewed "&LOWER(LEFT(B20,LEN(B20)-1)) -> Retention Cost per renewed subscriber | C15: =D$7 -> $ | D15: 5 | F15: retention cost per subscriber, per renew cycle. Intention is to include cost to market to existing subscribers to increase retention
B16: Deferred Revenues, beginning of first month | C16: =D$7 -> $ | D16: 0 | F16: optional: deferred revenue at the beginning of the first month in model
B18: Growth and Churn Assumptions
B19: Date to start growth and revenues | D19: =D8 -> 44440 | F19: date to start growth of revenues, used on Forecast sheet in Growth section
B20: Subscribers | C20: # | D20: 25 | F20: use the input to change the label, the number input refers to the # new in the first month, as defined above
B21: =B20&", beginning of first month" -> Subscribers, beginning of first month | C21: # | D21: 0 | F21: at the beginning of the first period in model
B22: ="Baseline growth rate in New "&B20 -> Baseline growth rate in New Subscribers | C22: % | D22: 0.1 | F22: this assumes the growth rate in the first month after growth starts, as defined above
B23: ="… where the growth rate "&IF(D23<0,"declines %",IF(D23>0,"increases %","stays the same"))&" per month" -> … where the growth rate declines % per month | C23: % | D23: -0.05 | F23: this changes the growth rate over time: you can assume a growth rate that increases over time, stays the same, or decreases (most common)
B24: Churn rate, per period | C24: % | D24: 0.05 | F24: Churn per month, as a % at the beginning of the period
B25: Reactivation Rate, per period | C25: % | D25: 0 | F25: optional: for previously churned subscribers that reactive. calculated as % of churn in previous period.
B26: Contract Cycle | C26: # | D26: 12 | F26: Assume the length of the contract, in months, to calculate churn cycles. E.g. input 12 for an annual contract, 1 for a month-to-month contract
B27: Billing Cycle | C27: # | D27: 12 | F27: Assume the length of the billing cycle, in months. e.g. an annual contract billed all up front is 12, an annual contract billed month to month is 1, a month-to-month contract is 1

Sheet Key Reports

Sheet Forecast
B2: Forecast
B4: Date | C4: Unit | D4: Note | T4: =EOMONTH('Get Started'!D8,0) -> 44469 | U4: =EOMONTH(EDATE(T4,1),0) -> 44500 | V4: =EOMONTH(EDATE(U4,1),0) -> 44530 | W4: =EOMONTH(EDATE(V4,1),0) -> 44561 | X4: =EOMONTH(EDATE(W4,1),0) -> 44592 | Y4: =EOMONTH(EDATE(X4,1),0) -> 44620 | Z4: =EOMONTH(EDATE(Y4,1),0) -> 44651 | AA4: =EOMONTH(EDATE(Z4,1),0) -> 44681 | AB4: =EOMONTH(EDATE(AA4,1),0) -> 44712 | ... BO4: =EOMONTH(EDATE(BN4,1),0) -> 45900
B5: Timestep | C5: # | D5: where the first month in the period = 0 | T5: 0 | U5: =T5+1 -> 1 | V5: =U5+1 -> 2 | W5: =V5+1 -> 3 | X5: =W5+1 -> 4 | Y5: =X5+1 -> 5 | Z5: =Y5+1 -> 6 | AA5: =Z5+1 -> 7 | AB5: =AA5+1 -> 8 | ... BO5: =BN5+1 -> 47
B6: Month # in Model | C6: # | D6: ="the model structure runs for "&BO6&" months. Month 0 is a pre-structure month, meant to capture opening items that help calculate the first month" -> the model structure runs for 48 months. Month 0 is a pre-structure month, meant to capture opening items that help calculate the first month | T6: 1 | U6: =T6+1 -> 2 | V6: =U6+1 -> 3 | W6: =V6+1 -> 4 | X6: =W6+1 -> 5 | Y6: =X6+1 -> 6 | Z6: =Y6+1 -> 7 | AA6: =Z6+1 -> 8 | AB6: =AA6+1 -> 9 | ... BO6: =BN6+1 -> 48
B7: Fiscal Year | C7: # | D7: the fiscal year can vary from the calendar year, this is calculated based on the assumption for fiscal year end | T7: {=IF(EOMONTH(T4,0)<=EOMONTH('Get Started'!$D9,0),YEAR('Get Started'!$D9),IF(T6<=(MONTH('Get Started'!$D9)-MONTH('Get Started'!$D8)),YEAR('Get Started'!$D9),IF(T6<=12,YEAR('Get Started'!$D9)+1,IFERROR(INDEX(S7:$T7,0,MATCH(T5-12,S5:$T5,0)),0)+1)))} -> 2021 | U7: {=IF(EOMONTH(U4,0)<=EOMONTH('Get Started'!$D9,0),YEAR('Get Started'!$D9),IF(U6<=(MONTH('Get Started'!$D9)-MONTH('Get Started'!$D8)),YEAR('Get Started'!$D9),IF(U6<=12,YEAR('Get Started'!$D9)+1,IFERROR(INDEX(T7:$T7,0,MATCH(U5-12,T5:$T5,0)),0)+1)))} -> 2021 | V7: {=IF(EOMONTH(V4,0)<=EOMONTH('Get Started'!$D9,0),YEAR('Get Started'!$D9),IF(V6<=(MONTH('Get Started'!$D9)-MONTH('Get Started'!$D8)),YEAR('Get Started'!$D9),IF(V6<=12,YEAR('Get Started'!$D9)+1,IFERROR(INDEX($T7:U7,0,MATCH(V5-12,$T5:U5,0)),0)+1)))} -> 2021 | W7: {=IF(EOMONTH(W4,0)<=EOMONTH('Get Started'!$D9,0),YEAR('Get Started'!$D9),IF(W6<=(MONTH('Get Started'!$D9)-MONTH('Get Started'!$D8)),YEAR('Get Started'!$D9),IF(W6<=12,YEAR('Get Started'!$D9)+1,IFERROR(INDEX($T7:V7,0,MATCH(W5-12,$T5:V5,0)),0)+1)))} -> 2021 | X7: {=IF(EOMONTH(X4,0)<=EOMONTH('Get Started'!$D9,0),YEAR('Get Started'!$D9),IF(X6<=(MONTH('Get Started'!$D9)-MONTH('Get Started'!$D8)),YEAR('Get Started'!$D9),IF(X6<=12,YEAR('Get Started'!$D9)+1,IFERROR(INDEX($T7:W7,0,MATCH(X5-12,$T5:W5,0)),0)+1)))} -> 2022 | Y7: {=IF(EOMONTH(Y4,0)<=EOMONTH('Get Started'!$D9,0),YEAR('Get Started'!$D9),IF(Y6<=(MONTH('Get Started'!$D9)-MONTH('Get Started'!$D8)),YEAR('Get Started'!$D9),IF(Y6<=12,YEAR('Get Started'!$D9)+1,IFERROR(INDEX($T7:X7,0,MATCH(Y5-12,$T5:X5,0)),0)+1)))} -> 2022 | Z7: {=IF(EOMONTH(Z4,0)<=EOMONTH('Get Started'!$D9,0),YEAR('Get Started'!$D9),IF(Z6<=(MONTH('Get Started'!$D9)-MONTH('Get Started'!$D8)),YEAR('Get Started'!$D9),IF(Z6<=12,YEAR('Get Started'!$D9)+1,IFERROR(INDEX($T7:Y7,0,MATCH(Z5-12,$T5:Y5,0)),0)+1)))} -> 2022 | AA7: {=IF(EOMONTH(AA4,0)<=EOMONTH('Get Started'!$D9,0),YEAR('Get Started'!$D9),IF(AA6<=(MONTH('Get Started'!$D9)-MONTH('Get Started'!$D8)),YEAR('Get Started'!$D9),IF(AA6<=12,YEAR('Get Started'!$D9)+1,IFERROR(INDEX($T7:Z7,0,MATCH(AA5-12,$T5:Z5,0)),0)+1)))} -> 2022 | AB7: {=IF(EOMONTH(AB4,0)<=EOMONTH('Get Started'!$D9,0),YEAR('Get Started'!$D9),IF(AB6<=(MONTH('Get Started'!$D9)-MONTH('Get Started'!$D8)),YEAR('Get Started'!$D9),IF(AB6<=12,YEAR('Get Started'!$D9)+1,IFERROR(INDEX($T7:AA7,0,MATCH(AB5-12,$T5:AA5,0)),0)+1)))} -> 2022 | AC7: {=IF(EOMONTH(AC4,0)<=EOMONTH('Get Started'!$D9,0),YEAR('Get Started'!$D9),IF(AC6<=(MONTH('Get Started'!$D9)-MONTH('Get Started'!$D8)),YEAR('Get Started'!$D9),IF(AC6<=12,YEAR('Get Started'!$D9)+1,IFERROR(INDEX($T7:AB7,0,MATCH(AC5-12,$T5:AB5,0)),0)+1)))} -> 2022 | ... BO7: {=IF(EOMONTH(BO4,0)<=EOMONTH('Get Started'!$D9,0),YEAR('Get Started'!$D9),IF(BO6<=(MONTH('Get Started'!$D9)-MONTH('Get Started'!$D8)),YEAR('Get Started'!$D9),IF(BO6<=12,YEAR('Get Started'!$D9)+1,IFERROR(INDEX($T7:BN7,0,MATCH(BO5-12,$T5:BN5,0)),0)+1)))} -> 2025
B8: Quarter in Fiscal Year | C8: text | D8: the quarters of the year vary according by the fiscal year end | T8: =IF(OR(T11=3,T11=2,T11=1),"Q1",IF(OR(T11=6,T11=5,T11=4),"Q2",IF(OR(T11=9,T11=8,T11=7),"Q3","Q4"))) -> Q3 | U8: =IF(OR(U11=3,U11=2,U11=1),"Q1",IF(OR(U11=6,U11=5,U11=4),"Q2",IF(OR(U11=9,U11=8,U11=7),"Q3","Q4"))) -> Q4 | V8: =IF(OR(V11=3,V11=2,V11=1),"Q1",IF(OR(V11=6,V11=5,V11=4),"Q2",IF(OR(V11=9,V11=8,V11=7),"Q3","Q4"))) -> Q4 | W8: =IF(OR(W11=3,W11=2,W11=1),"Q1",IF(OR(W11=6,W11=5,W11=4),"Q2",IF(OR(W11=9,W11=8,W11=7),"Q3","Q4"))) -> Q4 | X8: =IF(OR(X11=3,X11=2,X11=1),"Q1",IF(OR(X11=6,X11=5,X11=4),"Q2",IF(OR(X11=9,X11=8,X11=7),"Q3","Q4"))) -> Q1 | Y8: =IF(OR(Y11=3,Y11=2,Y11=1),"Q1",IF(OR(Y11=6,Y11=5,Y11=4),"Q2",IF(OR(Y11=9,Y11=8,Y11=7),"Q3","Q4"))) -> Q1 | Z8: =IF(OR(Z11=3,Z11=2,Z11=1),"Q1",IF(OR(Z11=6,Z11=5,Z11=4),"Q2",IF(OR(Z11=9,Z11=8,Z11=7),"Q3","Q4"))) -> Q1 | AA8: =IF(OR(AA11=3,AA11=2,AA11=1),"Q1",IF(OR(AA11=6,AA11=5,AA11=4),"Q2",IF(OR(AA11=9,AA11=8,AA11=7),"Q3","Q4"))) -> Q2 | ... BO8: =IF(OR(BO11=3,BO11=2,BO11=1),"Q1",IF(OR(BO11=6,BO11=5,BO11=4),"Q2",IF(OR(BO11=9,BO11=8,BO11=7),"Q3","Q4"))) -> Q3
B9: Quarter / Year | C9: text | D9: quarters and year, reported in text form for some charts and graphs | T9: =T8&" "&T7 -> Q3 2021 | U9: =U8&" "&U7 -> Q4 2021 | V9: =V8&" "&V7 -> Q4 2021 | W9: =W8&" "&W7 -> Q4 2021 | X9: =X8&" "&X7 -> Q1 2022 | Y9: =Y8&" "&Y7 -> Q1 2022 | Z9: =Z8&" "&Z7 -> Q1 2022 | AA9: =AA8&" "&AA7 -> Q2 2022 | ... BO9: =BO8&" "&BO7 -> Q3 2025
B10: Month (Text) | C10: text | D10: the month of the calendar year, used for reporting and seasonality calculations | T10: =TEXT(T4,"mmmm") -> September | U10: =TEXT(U4,"mmmm") -> October | V10: =TEXT(V4,"mmmm") -> November | W10: =TEXT(W4,"mmmm") -> December | X10: =TEXT(X4,"mmmm") -> January | Y10: =TEXT(Y4,"mmmm") -> February | Z10: =TEXT(Z4,"mmmm") -> March | AA10: =TEXT(AA4,"mmmm") -> April | ... BO10: =TEXT(BO4,"mmmm") -> August
B11: Month # in Fiscal year | C11: # | D11: the month # in the fiscal year. This rolls over to 1 at the start of each fiscal year | T11: =IF(MOD(MONTH(T4)+12-MONTH('Get Started'!$D9),12)=0,12,MOD(MONTH(T4)+12-MONTH('Get Started'!$D9),12)) -> 9 | U11: =IF(MOD(MONTH(U4)+12-MONTH('Get Started'!$D9),12)=0,12,MOD(MONTH(U4)+12-MONTH('Get Started'!$D9),12)) -> 10 | V11: =IF(MOD(MONTH(V4)+12-MONTH('Get Started'!$D9),12)=0,12,MOD(MONTH(V4)+12-MONTH('Get Started'!$D9),12)) -> 11 | W11: =IF(MOD(MONTH(W4)+12-MONTH('Get Started'!$D9),12)=0,12,MOD(MONTH(W4)+12-MONTH('Get Started'!$D9),12)) -> 12 | X11: =IF(MOD(MONTH(X4)+12-MONTH('Get Started'!$D9),12)=0,12,MOD(MONTH(X4)+12-MONTH('Get Started'!$D9),12)) -> 1 | Y11: =IF(MOD(MONTH(Y4)+12-MONTH('Get Started'!$D9),12)=0,12,MOD(MONTH(Y4)+12-MONTH('Get Started'!$D9),12)) -> 2 | Z11: =IF(MOD(MONTH(Z4)+12-MONTH('Get Started'!$D9),12)=0,12,MOD(MONTH(Z4)+12-MONTH('Get Started'!$D9),12)) -> 3 | AA11: =IF(MOD(MONTH(AA4)+12-MONTH('Get Started'!$D9),12)=0,12,MOD(MONTH(AA4)+12-MONTH('Get Started'!$D9),12)) -> 4 | ... BO11: =IF(MOD(MONTH(BO4)+12-MONTH('Get Started'!$D9),12)=0,12,MOD(MONTH(BO4)+12-MONTH('Get Started'!$D9),12)) -> 8
B12: Year of Operations | C12: # | D12: the year of operations. Used for some reports based on time of operations, not calendar year | T12: 1 | U12: =T12 -> 1 | V12: =U12 -> 1 | W12: =V12 -> 1 | X12: =W12 -> 1 | Y12: =X12 -> 1 | Z12: =Y12 -> 1 | AA12: =Z12 -> 1 | AB12: =AA12 -> 1 | ... AE12: =AD12 -> 1 | AF12: =T12+1 -> 2 | AG12: =U12+1 -> 2 | AH12: =V12+1 -> 2 | AI12: =W12+1 -> 2 | AJ12: =X12+1 -> 2 | AK12: =Y12+1 -> 2 | AL12: =Z12+1 -> 2 | AM12: =AA12+1 -> 2 | ... BO12: =BC12+1 -> 4
B15: Revenue and Marketing Assumptions
B16: Average Revenue per Subscriber | C16: # | D16: ='Get Started'!F12 -> average revenue per month | H16: average | I16: =IF(H16=Forecast!$H$74,T16,IF(H16=Forecast!$H$75,BO16,IF(H16=Forecast!$H$76,SUM(T16:BO16),IF(H16=Forecast!$H$77,AVERAGE(T16:BO16),0)))) -> 30 | T16: ='Get Started'!$D12 -> 30 | U16: ='Get Started'!$D12 -> 30 | V16: ='Get Started'!$D12 -> 30 | W16: ='Get Started'!$D12 -> 30 | X16: ='Get Started'!$D12 -> 30 | Y16: ='Get Started'!$D12 -> 30 | Z16: ='Get Started'!$D12 -> 30 | AA16: ='Get Started'!$D12 -> 30 | ... BO16: ='Get Started'!$D12 -> 30
B17: Gross Margin % | C17: % | D17: ='Get Started'!F13 -> as a % of revenues | H17: average | I17: =IF(H17=Forecast!$H$74,T17,IF(H17=Forecast!$H$75,BO17,IF(H17=Forecast!$H$76,SUM(T17:BO17),IF(H17=Forecast!$H$77,AVERAGE(T17:BO17),0)))) -> 0.875 | T17: ='Get Started'!$D13 -> 0.875 | U17: ='Get Started'!$D13 -> 0.875 | V17: ='Get Started'!$D13 -> 0.875 | W17: ='Get Started'!$D13 -> 0.875 | X17: ='Get Started'!$D13 -> 0.875 | Y17: ='Get Started'!$D13 -> 0.875 | Z17: ='Get Started'!$D13 -> 0.875 | AA17: ='Get Started'!$D13 -> 0.875 | ... BO17: ='Get Started'!$D13 -> 0.875
B18: CAC | C18: # | D18: ='Get Started'!F14 -> Customer acquisition cost, per new subscriber | H18: average | I18: =IF(H18=Forecast!$H$74,T18,IF(H18=Forecast!$H$75,BO18,IF(H18=Forecast!$H$76,SUM(T18:BO18),IF(H18=Forecast!$H$77,AVERAGE(T18:BO18),0)))) -> 25 | T18: ='Get Started'!$D14 -> 25 | U18: ='Get Started'!$D14 -> 25 | V18: ='Get Started'!$D14 -> 25 | W18: ='Get Started'!$D14 -> 25 | X18: ='Get Started'!$D14 -> 25 | Y18: ='Get Started'!$D14 -> 25 | Z18: ='Get Started'!$D14 -> 25 | AA18: ='Get Started'!$D14 -> 25 | ... BO18: ='Get Started'!$D14 -> 25
B19: ='Get Started'!B15 -> Retention Cost per renewed subscriber | C19: # | D19: ='Get Started'!F15 -> retention cost per subscriber, per renew cycle. Intention is to include cost to market to existing subscribers to increase retention | H19: average | I19: =IF(H19=Forecast!$H$74,T19,IF(H19=Forecast!$H$75,BO19,IF(H19=Forecast!$H$76,SUM(T19:BO19),IF(H19=Forecast!$H$77,AVERAGE(T19:BO19),0)))) -> 5 | T19: ='Get Started'!$D15 -> 5 | U19: ='Get Started'!$D15 -> 5 | V19: ='Get Started'!$D15 -> 5 | W19: ='Get Started'!$D15 -> 5 | X19: ='Get Started'!$D15 -> 5 | Y19: ='Get Started'!$D15 -> 5 | Z19: ='Get Started'!$D15 -> 5 | AA19: ='Get Started'!$D15 -> 5 | ... BO19: ='Get Started'!$D15 -> 5
B20: Deferred Revenue, first month | C20: # | D20: ='Get Started'!F16 -> optional: deferred revenue at the beginning of the first month in model | H20: average | I20: =IF(H20=Forecast!$H$74,T20,IF(H20=Forecast!$H$75,BO20,IF(H20=Forecast!$H$76,SUM(T20:BO20),IF(H20=Forecast!$H$77,AVERAGE(T20:BO20),0)))) -> 0 | T20: ='Get Started'!$D16 -> 0 | U20: ='Get Started'!$D16 -> 0 | V20: ='Get Started'!$D16 -> 0 | W20: ='Get Started'!$D16 -> 0 | X20: ='Get Started'!$D16 -> 0 | Y20: ='Get Started'!$D16 -> 0 | Z20: ='Get Started'!$D16 -> 0 | AA20: ='Get Started'!$D16 -> 0 | ... BO20: ='Get Started'!$D16 -> 0
B22: Growth and Churn Assumptions
B23: Date to start growth and revenues | C23: # | D23: ='Get Started'!F19 -> date to start growth of revenues, used on Forecast sheet in Growth section | H23: initial | I23: =IF(H23=Forecast!$H$74,T23,IF(H23=Forecast!$H$75,BO23,IF(H23=Forecast!$H$76,SUM(T23:BO23),IF(H23=Forecast!$H$77,AVERAGE(T23:BO23),0)))) -> 44440 | T23: ='Get Started'!$D19 -> 44440 | U23: ='Get Started'!$D19 -> 44440 | V23: ='Get Started'!$D19 -> 44440 | W23: ='Get Started'!$D19 -> 44440 | X23: ='Get Started'!$D19 -> 44440 | Y23: ='Get Started'!$D19 -> 44440 | Z23: ='Get Started'!$D19 -> 44440 | AA23: ='Get Started'!$D19 -> 44440 | ... BO23: ='Get Started'!$D19 -> 44440
B24: New Subscribers, first month | C24: # | D24: ='Get Started'!F20 -> use the input to change the label, the number input refers to the # new in the first month, as defined above | H24: average | I24: =IF(H24=Forecast!$H$74,T24,IF(H24=Forecast!$H$75,BO24,IF(H24=Forecast!$H$76,SUM(T24:BO24),IF(H24=Forecast!$H$77,AVERAGE(T24:BO24),0)))) -> 25 | T24: ='Get Started'!$D20 -> 25 | U24: ='Get Started'!$D20 -> 25 | V24: ='Get Started'!$D20 -> 25 | W24: ='Get Started'!$D20 -> 25 | X24: ='Get Started'!$D20 -> 25 | Y24: ='Get Started'!$D20 -> 25 | Z24: ='Get Started'!$D20 -> 25 | AA24: ='Get Started'!$D20 -> 25 | ... BO24: ='Get Started'!$D20 -> 25
B25: Subscribers, first month | C25: # | D25: ='Get Started'!F21 -> at the beginning of the first period in model | H25: average | I25: =IF(H25=Forecast!$H$74,T25,IF(H25=Forecast!$H$75,BO25,IF(H25=Forecast!$H$76,SUM(T25:BO25),IF(H25=Forecast!$H$77,AVERAGE(T25:BO25),0)))) -> 0 | T25: ='Get Started'!$D21 -> 0 | U25: ='Get Started'!$D21 -> 0 | V25: ='Get Started'!$D21 -> 0 | W25: ='Get Started'!$D21 -> 0 | X25: ='Get Started'!$D21 -> 0 | Y25: ='Get Started'!$D21 -> 0 | Z25: ='Get Started'!$D21 -> 0 | AA25: ='Get Started'!$D21 -> 0 | ... BO25: ='Get Started'!$D21 -> 0
B26: Starting growth rate, new subscribers | C26: % | D26: ='Get Started'!F22 -> this assumes the growth rate in the first month after growth starts, as defined above | H26: average | I26: =IF(H26=Forecast!$H$74,T26,IF(H26=Forecast!$H$75,BO26,IF(H26=Forecast!$H$76,SUM(T26:BO26),IF(H26=Forecast!$H$77,AVERAGE(T26:BO26),0)))) -> 0.1 | T26: ='Get Started'!$D22 -> 0.1 | U26: ='Get Started'!$D22 -> 0.1 | V26: ='Get Started'!$D22 -> 0.1 | W26: ='Get Started'!$D22 -> 0.1 | X26: ='Get Started'!$D22 -> 0.1 | Y26: ='Get Started'!$D22 -> 0.1 | Z26: ='Get Started'!$D22 -> 0.1 | AA26: ='Get Started'!$D22 -> 0.1 | ... BO26: ='Get Started'!$D22 -> 0.1
B27: Change in Growth Rate in new subscribers | C27: % | D27: ='Get Started'!F23 -> this changes the growth rate over time: you can assume a growth rate that increases over time, stays the same, or decreases (most common) | H27: average | I27: =IF(H27=Forecast!$H$74,T27,IF(H27=Forecast!$H$75,BO27,IF(H27=Forecast!$H$76,SUM(T27:BO27),IF(H27=Forecast!$H$77,AVERAGE(T27:BO27),0)))) -> -0.05 | T27: ='Get Started'!$D23 -> -0.05 | U27: ='Get Started'!$D23 -> -0.05 | V27: ='Get Started'!$D23 -> -0.05 | W27: ='Get Started'!$D23 -> -0.05 | X27: ='Get Started'!$D23 -> -0.05 | Y27: ='Get Started'!$D23 -> -0.05 | Z27: ='Get Started'!$D23 -> -0.05 | AA27: ='Get Started'!$D23 -> -0.05 | ... BO27: ='Get Started'!$D23 -> -0.05
B28: Churn | C28: % | D28: ='Get Started'!F24 -> Churn per month, as a % at the beginning of the period | H28: average | I28: =IF(H28=Forecast!$H$74,T28,IF(H28=Forecast!$H$75,BO28,IF(H28=Forecast!$H$76,SUM(T28:BO28),IF(H28=Forecast!$H$77,AVERAGE(T28:BO28),0)))) -> 0.05 | T28: ='Get Started'!$D24 -> 0.05 | U28: ='Get Started'!$D24 -> 0.05 | V28: ='Get Started'!$D24 -> 0.05 | W28: ='Get Started'!$D24 -> 0.05 | X28: ='Get Started'!$D24 -> 0.05 | Y28: ='Get Started'!$D24 -> 0.05 | Z28: ='Get Started'!$D24 -> 0.05 | AA28: ='Get Started'!$D24 -> 0.05 | ... BO28: ='Get Started'!$D24 -> 0.05
B29: Reactivation Rate, per month | C29: % | D29: ='Get Started'!F25 -> optional: for previously churned subscribers that reactive. calculated as % of churn in previous period. | H29: average | I29: =IF(H29=Forecast!$H$74,T29,IF(H29=Forecast!$H$75,BO29,IF(H29=Forecast!$H$76,SUM(T29:BO29),IF(H29=Forecast!$H$77,AVERAGE(T29:BO29),0)))) -> 0 | T29: ='Get Started'!$D25 -> 0 | U29: ='Get Started'!$D25 -> 0 | V29: ='Get Started'!$D25 -> 0 | W29: ='Get Started'!$D25 -> 0 | X29: ='Get Started'!$D25 -> 0 | Y29: ='Get Started'!$D25 -> 0 | Z29: ='Get Started'!$D25 -> 0 | AA29: ='Get Started'!$D25 -> 0 | ... BO29: ='Get Started'!$D25 -> 0
B30: Contract Cycle | C30: # | D30: ='Get Started'!F26 -> Assume the length of the contract, in months, to calculate churn cycles. E.g. input 12 for an annual contract, 1 for a month-to-month contract | H30: average | I30: =IF(H30=Forecast!$H$74,T30,IF(H30=Forecast!$H$75,BO30,IF(H30=Forecast!$H$76,SUM(T30:BO30),IF(H30=Forecast!$H$77,AVERAGE(T30:BO30),0)))) -> 12 | T30: ='Get Started'!$D26 -> 12 | U30: ='Get Started'!$D26 -> 12 | V30: ='Get Started'!$D26 -> 12 | W30: ='Get Started'!$D26 -> 12 | X30: ='Get Started'!$D26 -> 12 | Y30: ='Get Started'!$D26 -> 12 | Z30: ='Get Started'!$D26 -> 12 | AA30: ='Get Started'!$D26 -> 12 | ... BO30: ='Get Started'!$D26 -> 12
B31: Billing Cycle | C31: # | D31: ='Get Started'!F27 -> Assume the length of the billing cycle, in months. e.g. an annual contract billed all up front is 12, an annual contract billed month to month is 1, a month-to-month contract is 1 | H31: average | I31: =IF(H31=Forecast!$H$74,T31,IF(H31=Forecast!$H$75,BO31,IF(H31=Forecast!$H$76,SUM(T31:BO31),IF(H31=Forecast!$H$77,AVERAGE(T31:BO31),0)))) -> 12 | T31: ='Get Started'!$D27 -> 12 | U31: ='Get Started'!$D27 -> 12 | V31: ='Get Started'!$D27 -> 12 | W31: ='Get Started'!$D27 -> 12 | X31: ='Get Started'!$D27 -> 12 | Y31: ='Get Started'!$D27 -> 12 | Z31: ='Get Started'!$D27 -> 12 | AA31: ='Get Started'!$D27 -> 12 | ... BO31: ='Get Started'!$D27 -> 12
B33: Subscribers
B34: Subscribers, beginning of month | C34: # | D34: at the beginning of the period | H34: initial | I34: =IF(H34=Forecast!$H$74,T34,IF(H34=Forecast!$H$75,BO34,IF(H34=Forecast!$H$76,SUM(T34:BO34),IF(H34=Forecast!$H$77,AVERAGE(T34:BO34),0)))) -> 0 | T34: =IF(T5=0,T25,S40) -> 0 | U34: =IF(U5=0,U25,T40) -> 25 | V34: =IF(V5=0,V25,U40) -> 52.375 | W34: =IF(W5=0,W25,V40) -> 82.220594 | X34: =IF(X5=0,X25,W40) -> 114.62507 | Y34: =IF(Y5=0,Y25,X40) -> 149.66892 | Z34: =IF(Z5=0,Z25,Y40) -> 187.42439 | AA34: =IF(AA5=0,AA25,Z40) -> 227.95524 | ... BO34: =IF(BO5=0,BO25,BN40) -> 3811.3315
B35: Subscribers, not up for renewal | C35: # | D35: subscribers not up for renewal each period | H35: sum | I35: =IF(H35=Forecast!$H$74,T35,IF(H35=Forecast!$H$75,BO35,IF(H35=Forecast!$H$76,SUM(T35:BO35),IF(H35=Forecast!$H$77,AVERAGE(T35:BO35),0)))) -> 68218.325 | T35: =T34-T37-T38 -> 0 | U35: =U34-U37-U38 -> 25 | V35: =V34-V37-V38 -> 52.375 | W35: =W34-W37-W38 -> 82.220594 | X35: =X34-X37-X38 -> 114.62507 | Y35: =Y34-Y37-Y38 -> 149.66892 | Z35: =Z34-Z37-Z38 -> 187.42439 | AA35: =AA34-AA37-AA38 -> 227.95524 | ... BO35: =BO34-BO37-BO38 -> 3559.7964
B36: New subscribers, during month | C36: # | D36: new during period | H36: sum | I36: =IF(H36=Forecast!$H$74,T36,IF(H36=Forecast!$H$75,BO36,IF(H36=Forecast!$H$76,SUM(T36:BO36),IF(H36=Forecast!$H$77,AVERAGE(T36:BO36),0)))) -> 4150.9294 | T36: =IF(EOMONTH(T23,0)=T4,T24,S36*(1+T42)) -> 25 | U36: =IF(EOMONTH(U23,0)=U4,U24,T36*(1+U42)) -> 27.375 | V36: =IF(EOMONTH(V23,0)=V4,V24,U36*(1+V42)) -> 29.845594 | W36: =IF(EOMONTH(W23,0)=W4,W24,V36*(1+W42)) -> 32.40448 | X36: =IF(EOMONTH(X23,0)=X4,X24,W36*(1+X42)) -> 35.043846 | Y36: =IF(EOMONTH(Y23,0)=Y4,Y24,X36*(1+Y42)) -> 37.755471 | Z36: =IF(EOMONTH(Z23,0)=Z4,Z24,Y36*(1+Z42)) -> 40.530846 | AA36: =IF(EOMONTH(AA23,0)=AA4,AA24,Z36*(1+AA42)) -> 43.361266 | ... BO36: =IF(EOMONTH(BO23,0)=BO4,BO24,BN36*(1+BO42)) -> 134.87526
B37: Renewed subscribers, during month | C37: # | D37: renewed during period | H37: sum | I37: =IF(H37=Forecast!$H$74,T37,IF(H37=Forecast!$H$75,BO37,IF(H37=Forecast!$H$76,SUM(T37:BO37),IF(H37=Forecast!$H$77,AVERAGE(T37:BO37),0)))) -> 4128.6896 | T37: {=IF(T5<T30,T25/T30*(1-T28),0)+(IF(T6<T30,0,IFERROR(INDEX(S37:$T37,0,MATCH(T5-T30,S5:$T5,0)),0))+IF(T6<T30,0,IFERROR(INDEX(S36:$T36,0,MATCH(T5-T30,S5:$T5,0)),0))+IF(T6<T30,0,IFERROR(INDEX(S39:$T39,0,MATCH(T5-T30,S5:$T5,0)),0))) * (1-T28)} -> 0 | U37: {=IF(U5<U30,U25/U30*(1-U28),0)+(IF(U6<U30,0,IFERROR(INDEX(T37:$T37,0,MATCH(U5-U30,T5:$T5,0)),0))+IF(U6<U30,0,IFERROR(INDEX(T36:$T36,0,MATCH(U5-U30,T5:$T5,0)),0))+IF(U6<U30,0,IFERROR(INDEX(T39:$T39,0,MATCH(U5-U30,T5:$T5,0)),0))) * (1-U28)} -> 0 | V37: {=IF(V5<V30,V25/V30*(1-V28),0)+(IF(V6<V30,0,IFERROR(INDEX($T37:U37,0,MATCH(V5-V30,$T5:U5,0)),0))+IF(V6<V30,0,IFERROR(INDEX($T36:U36,0,MATCH(V5-V30,$T5:U5,0)),0))+IF(V6<V30,0,IFERROR(INDEX($T39:U39,0,MATCH(V5-V30,$T5:U5,0)),0))) * (1-V28)} -> 0 | W37: {=IF(W5<W30,W25/W30*(1-W28),0)+(IF(W6<W30,0,IFERROR(INDEX($T37:V37,0,MATCH(W5-W30,$T5:V5,0)),0))+IF(W6<W30,0,IFERROR(INDEX($T36:V36,0,MATCH(W5-W30,$T5:V5,0)),0))+IF(W6<W30,0,IFERROR(INDEX($T39:V39,0,MATCH(W5-W30,$T5:V5,0)),0))) * (1-W28)} -> 0 | X37: {=IF(X5<X30,X25/X30*(1-X28),0)+(IF(X6<X30,0,IFERROR(INDEX($T37:W37,0,MATCH(X5-X30,$T5:W5,0)),0))+IF(X6<X30,0,IFERROR(INDEX($T36:W36,0,MATCH(X5-X30,$T5:W5,0)),0))+IF(X6<X30,0,IFERROR(INDEX($T39:W39,0,MATCH(X5-X30,$T5:W5,0)),0))) * (1-X28)} -> 0 | Y37: {=IF(Y5<Y30,Y25/Y30*(1-Y28),0)+(IF(Y6<Y30,0,IFERROR(INDEX($T37:X37,0,MATCH(Y5-Y30,$T5:X5,0)),0))+IF(Y6<Y30,0,IFERROR(INDEX($T36:X36,0,MATCH(Y5-Y30,$T5:X5,0)),0))+IF(Y6<Y30,0,IFERROR(INDEX($T39:X39,0,MATCH(Y5-Y30,$T5:X5,0)),0))) * (1-Y28)} -> 0 | Z37: {=IF(Z5<Z30,Z25/Z30*(1-Z28),0)+(IF(Z6<Z30,0,IFERROR(INDEX($T37:Y37,0,MATCH(Z5-Z30,$T5:Y5,0)),0))+IF(Z6<Z30,0,IFERROR(INDEX($T36:Y36,0,MATCH(Z5-Z30,$T5:Y5,0)),0))+IF(Z6<Z30,0,IFERROR(INDEX($T39:Y39,0,MATCH(Z5-Z30,$T5:Y5,0)),0))) * (1-Z28)} -> 0 | AA37: {=IF(AA5<AA30,AA25/AA30*(1-AA28),0)+(IF(AA6<AA30,0,IFERROR(INDEX($T37:Z37,0,MATCH(AA5-AA30,$T5:Z5,0)),0))+IF(AA6<AA30,0,IFERROR(INDEX($T36:Z36,0,MATCH(AA5-AA30,$T5:Z5,0)),0))+IF(AA6<AA30,0,IFERROR(INDEX($T39:Z39,0,MATCH(AA5-AA30,$T5:Z5,0)),0))) * (1-AA28)} -> 0 | AB37: {=IF(AB5<AB30,AB25/AB30*(1-AB28),0)+(IF(AB6<AB30,0,IFERROR(INDEX($T37:AA37,0,MATCH(AB5-AB30,$T5:AA5,0)),0))+IF(AB6<AB30,0,IFERROR(INDEX($T36:AA36,0,MATCH(AB5-AB30,$T5:AA5,0)),0))+IF(AB6<AB30,0,IFERROR(INDEX($T39:AA39,0,MATCH(AB5-AB30,$T5:AA5,0)),0))) * (1-AB28)} -> 0 | AC37: {=IF(AC5<AC30,AC25/AC30*(1-AC28),0)+(IF(AC6<AC30,0,IFERROR(INDEX($T37:AB37,0,MATCH(AC5-AC30,$T5:AB5,0)),0))+IF(AC6<AC30,0,IFERROR(INDEX($T36:AB36,0,MATCH(AC5-AC30,$T5:AB5,0)),0))+IF(AC6<AC30,0,IFERROR(INDEX($T39:AB39,0,MATCH(AC5-AC30,$T5:AB5,0)),0))) * (1-AC28)} -> 0 | ... BO37: {=IF(BO5<BO30,BO25/BO30*(1-BO28),0)+(IF(BO6<BO30,0,IFERROR(INDEX($T37:BN37,0,MATCH(BO5-BO30,$T5:BN5,0)),0))+IF(BO6<BO30,0,IFERROR(INDEX($T36:BN36,0,MATCH(BO5-BO30,$T5:BN5,0)),0))+IF(BO6<BO30,0,IFERROR(INDEX($T39:BN39,0,MATCH(BO5-BO30,$T5:BN5,0)),0))) * (1-BO28)} -> 238.9583
B38: Churned subscribers, during month | C38: # | D38: churned during period | H38: sum | I38: =IF(H38=Forecast!$H$74,T38,IF(H38=Forecast!$H$75,BO38,IF(H38=Forecast!$H$76,SUM(T38:BO38),IF(H38=Forecast!$H$77,AVERAGE(T38:BO38),0)))) -> 217.29945 | T38: {=IF(T5<T30,T25/T30 * T28,0)+(IF(T6<T30,0,IFERROR(INDEX(S37:$T37,0,MATCH(T5-T30,S5:$T5,0)),0))+IF(T6<T30,0,IFERROR(INDEX(S36:$T36,0,MATCH(T5-T30,S5:$T5,0)),0))+IF(T6<T30,0,IFERROR(INDEX(S39:$T39,0,MATCH(T5-T30,S5:$T5,0)),0))) * T28} -> 0 | U38: {=IF(U5<U30,U25/U30 * U28,0)+(IF(U6<U30,0,IFERROR(INDEX(T37:$T37,0,MATCH(U5-U30,T5:$T5,0)),0))+IF(U6<U30,0,IFERROR(INDEX(T36:$T36,0,MATCH(U5-U30,T5:$T5,0)),0))+IF(U6<U30,0,IFERROR(INDEX(T39:$T39,0,MATCH(U5-U30,T5:$T5,0)),0))) * U28} -> 0 | V38: {=IF(V5<V30,V25/V30 * V28,0)+(IF(V6<V30,0,IFERROR(INDEX($T37:U37,0,MATCH(V5-V30,$T5:U5,0)),0))+IF(V6<V30,0,IFERROR(INDEX($T36:U36,0,MATCH(V5-V30,$T5:U5,0)),0))+IF(V6<V30,0,IFERROR(INDEX($T39:U39,0,MATCH(V5-V30,$T5:U5,0)),0))) * V28} -> 0 | W38: {=IF(W5<W30,W25/W30 * W28,0)+(IF(W6<W30,0,IFERROR(INDEX($T37:V37,0,MATCH(W5-W30,$T5:V5,0)),0))+IF(W6<W30,0,IFERROR(INDEX($T36:V36,0,MATCH(W5-W30,$T5:V5,0)),0))+IF(W6<W30,0,IFERROR(INDEX($T39:V39,0,MATCH(W5-W30,$T5:V5,0)),0))) * W28} -> 0 | X38: {=IF(X5<X30,X25/X30 * X28,0)+(IF(X6<X30,0,IFERROR(INDEX($T37:W37,0,MATCH(X5-X30,$T5:W5,0)),0))+IF(X6<X30,0,IFERROR(INDEX($T36:W36,0,MATCH(X5-X30,$T5:W5,0)),0))+IF(X6<X30,0,IFERROR(INDEX($T39:W39,0,MATCH(X5-X30,$T5:W5,0)),0))) * X28} -> 0 | Y38: {=IF(Y5<Y30,Y25/Y30 * Y28,0)+(IF(Y6<Y30,0,IFERROR(INDEX($T37:X37,0,MATCH(Y5-Y30,$T5:X5,0)),0))+IF(Y6<Y30,0,IFERROR(INDEX($T36:X36,0,MATCH(Y5-Y30,$T5:X5,0)),0))+IF(Y6<Y30,0,IFERROR(INDEX($T39:X39,0,MATCH(Y5-Y30,$T5:X5,0)),0))) * Y28} -> 0 | Z38: {=IF(Z5<Z30,Z25/Z30 * Z28,0)+(IF(Z6<Z30,0,IFERROR(INDEX($T37:Y37,0,MATCH(Z5-Z30,$T5:Y5,0)),0))+IF(Z6<Z30,0,IFERROR(INDEX($T36:Y36,0,MATCH(Z5-Z30,$T5:Y5,0)),0))+IF(Z6<Z30,0,IFERROR(INDEX($T39:Y39,0,MATCH(Z5-Z30,$T5:Y5,0)),0))) * Z28} -> 0 | AA38: {=IF(AA5<AA30,AA25/AA30 * AA28,0)+(IF(AA6<AA30,0,IFERROR(INDEX($T37:Z37,0,MATCH(AA5-AA30,$T5:Z5,0)),0))+IF(AA6<AA30,0,IFERROR(INDEX($T36:Z36,0,MATCH(AA5-AA30,$T5:Z5,0)),0))+IF(AA6<AA30,0,IFERROR(INDEX($T39:Z39,0,MATCH(AA5-AA30,$T5:Z5,0)),0))) * AA28} -> 0 | AB38: {=IF(AB5<AB30,AB25/AB30 * AB28,0)+(IF(AB6<AB30,0,IFERROR(INDEX($T37:AA37,0,MATCH(AB5-AB30,$T5:AA5,0)),0))+IF(AB6<AB30,0,IFERROR(INDEX($T36:AA36,0,MATCH(AB5-AB30,$T5:AA5,0)),0))+IF(AB6<AB30,0,IFERROR(INDEX($T39:AA39,0,MATCH(AB5-AB30,$T5:AA5,0)),0))) * AB28} -> 0 | AC38: {=IF(AC5<AC30,AC25/AC30 * AC28,0)+(IF(AC6<AC30,0,IFERROR(INDEX($T37:AB37,0,MATCH(AC5-AC30,$T5:AB5,0)),0))+IF(AC6<AC30,0,IFERROR(INDEX($T36:AB36,0,MATCH(AC5-AC30,$T5:AB5,0)),0))+IF(AC6<AC30,0,IFERROR(INDEX($T39:AB39,0,MATCH(AC5-AC30,$T5:AB5,0)),0))) * AC28} -> 0 | ... BO38: {=IF(BO5<BO30,BO25/BO30 * BO28,0)+(IF(BO6<BO30,0,IFERROR(INDEX($T37:BN37,0,MATCH(BO5-BO30,$T5:BN5,0)),0))+IF(BO6<BO30,0,IFERROR(INDEX($T36:BN36,0,MATCH(BO5-BO30,$T5:BN5,0)),0))+IF(BO6<BO30,0,IFERROR(INDEX($T39:BN39,0,MATCH(BO5-BO30,$T5:BN5,0)),0))) * BO28} -> 12.576752
B39: Reactivated subscribers, during month | C39: # | D39: reactivatived during period | H39: sum | I39: =IF(H39=Forecast!$H$74,T39,IF(H39=Forecast!$H$75,BO39,IF(H39=Forecast!$H$76,SUM(T39:BO39),IF(H39=Forecast!$H$77,AVERAGE(T39:BO39),0)))) -> 0 | T39: =S38*T29 -> 0 | U39: =T38*U29 -> 0 | V39: =U38*V29 -> 0 | W39: =V38*W29 -> 0 | X39: =W38*X29 -> 0 | Y39: =X38*Y29 -> 0 | Z39: =Y38*Z29 -> 0 | AA39: =Z38*AA29 -> 0 | ... BO39: =BN38*BO29 -> 0
B40: Subscribers, end of month | C40: # | D40: at end of period | H40: final | I40: =IF(H40=Forecast!$H$74,T40,IF(H40=Forecast!$H$75,BO40,IF(H40=Forecast!$H$76,SUM(T40:BO40),IF(H40=Forecast!$H$77,AVERAGE(T40:BO40),0)))) -> 3933.63 | T40: =T34+T36+T39-T38 -> 25 | U40: =U34+U36+U39-U38 -> 52.375 | V40: =V34+V36+V39-V38 -> 82.220594 | W40: =W34+W36+W39-W38 -> 114.62507 | X40: =X34+X36+X39-X38 -> 149.66892 | Y40: =Y34+Y36+Y39-Y38 -> 187.42439 | Z40: =Z34+Z36+Z39-Z38 -> 227.95524 | AA40: =AA34+AA36+AA39-AA38 -> 271.3165 | ... BO40: =BO34+BO36+BO39-BO38 -> 3933.63
B41: Subscribers, up for billing | C41: # | D41: calculates billings for subscribers up for billing cycle but not churn cycle | H41: sum | I41: =IF(H41=Forecast!$H$74,T41,IF(H41=Forecast!$H$75,BO41,IF(H41=Forecast!$H$76,SUM(T41:BO41),IF(H41=Forecast!$H$77,AVERAGE(T41:BO41),0)))) -> 0 | T41: {=IF(T5<T31,T25/T31,0)+IF(T6<T31,0,IFERROR(INDEX(S37:$T37,0,MATCH(T5-T31,S5:$T5,0)),0))+IF(T6<T31,0,IFERROR(INDEX(S36:$T36,0,MATCH(T5-T31,S5:$T5,0)),0))+IF(T6<T31,0,IFERROR(INDEX(S39:$T39,0,MATCH(T5-T31,S5:$T5,0)),0))+IF(T6<T31,0,IFERROR(INDEX(S41:$T41,0,MATCH(T5-T31,S5:$T5,0)),0))-T38-T37} -> 0 | U41: {=IF(U5<U31,U25/U31,0)+IF(U6<U31,0,IFERROR(INDEX(T37:$T37,0,MATCH(U5-U31,T5:$T5,0)),0))+IF(U6<U31,0,IFERROR(INDEX(T36:$T36,0,MATCH(U5-U31,T5:$T5,0)),0))+IF(U6<U31,0,IFERROR(INDEX(T39:$T39,0,MATCH(U5-U31,T5:$T5,0)),0))+IF(U6<U31,0,IFERROR(INDEX(T41:$T41,0,MATCH(U5-U31,T5:$T5,0)),0))-U38-U37} -> 0 | V41: {=IF(V5<V31,V25/V31,0)+IF(V6<V31,0,IFERROR(INDEX($T37:U37,0,MATCH(V5-V31,$T5:U5,0)),0))+IF(V6<V31,0,IFERROR(INDEX($T36:U36,0,MATCH(V5-V31,$T5:U5,0)),0))+IF(V6<V31,0,IFERROR(INDEX($T39:U39,0,MATCH(V5-V31,$T5:U5,0)),0))+IF(V6<V31,0,IFERROR(INDEX($T41:U41,0,MATCH(V5-V31,$T5:U5,0)),0))-V38-V37} -> 0 | W41: {=IF(W5<W31,W25/W31,0)+IF(W6<W31,0,IFERROR(INDEX($T37:V37,0,MATCH(W5-W31,$T5:V5,0)),0))+IF(W6<W31,0,IFERROR(INDEX($T36:V36,0,MATCH(W5-W31,$T5:V5,0)),0))+IF(W6<W31,0,IFERROR(INDEX($T39:V39,0,MATCH(W5-W31,$T5:V5,0)),0))+IF(W6<W31,0,IFERROR(INDEX($T41:V41,0,MATCH(W5-W31,$T5:V5,0)),0))-W38-W37} -> 0 | X41: {=IF(X5<X31,X25/X31,0)+IF(X6<X31,0,IFERROR(INDEX($T37:W37,0,MATCH(X5-X31,$T5:W5,0)),0))+IF(X6<X31,0,IFERROR(INDEX($T36:W36,0,MATCH(X5-X31,$T5:W5,0)),0))+IF(X6<X31,0,IFERROR(INDEX($T39:W39,0,MATCH(X5-X31,$T5:W5,0)),0))+IF(X6<X31,0,IFERROR(INDEX($T41:W41,0,MATCH(X5-X31,$T5:W5,0)),0))-X38-X37} -> 0 | Y41: {=IF(Y5<Y31,Y25/Y31,0)+IF(Y6<Y31,0,IFERROR(INDEX($T37:X37,0,MATCH(Y5-Y31,$T5:X5,0)),0))+IF(Y6<Y31,0,IFERROR(INDEX($T36:X36,0,MATCH(Y5-Y31,$T5:X5,0)),0))+IF(Y6<Y31,0,IFERROR(INDEX($T39:X39,0,MATCH(Y5-Y31,$T5:X5,0)),0))+IF(Y6<Y31,0,IFERROR(INDEX($T41:X41,0,MATCH(Y5-Y31,$T5:X5,0)),0))-Y38-Y37} -> 0 | Z41: {=IF(Z5<Z31,Z25/Z31,0)+IF(Z6<Z31,0,IFERROR(INDEX($T37:Y37,0,MATCH(Z5-Z31,$T5:Y5,0)),0))+IF(Z6<Z31,0,IFERROR(INDEX($T36:Y36,0,MATCH(Z5-Z31,$T5:Y5,0)),0))+IF(Z6<Z31,0,IFERROR(INDEX($T39:Y39,0,MATCH(Z5-Z31,$T5:Y5,0)),0))+IF(Z6<Z31,0,IFERROR(INDEX($T41:Y41,0,MATCH(Z5-Z31,$T5:Y5,0)),0))-Z38-Z37} -> 0 | AA41: {=IF(AA5<AA31,AA25/AA31,0)+IF(AA6<AA31,0,IFERROR(INDEX($T37:Z37,0,MATCH(AA5-AA31,$T5:Z5,0)),0))+IF(AA6<AA31,0,IFERROR(INDEX($T36:Z36,0,MATCH(AA5-AA31,$T5:Z5,0)),0))+IF(AA6<AA31,0,IFERROR(INDEX($T39:Z39,0,MATCH(AA5-AA31,$T5:Z5,0)),0))+IF(AA6<AA31,0,IFERROR(INDEX($T41:Z41,0,MATCH(AA5-AA31,$T5:Z5,0)),0))-AA38-AA37} -> 0 | AB41: {=IF(AB5<AB31,AB25/AB31,0)+IF(AB6<AB31,0,IFERROR(INDEX($T37:AA37,0,MATCH(AB5-AB31,$T5:AA5,0)),0))+IF(AB6<AB31,0,IFERROR(INDEX($T36:AA36,0,MATCH(AB5-AB31,$T5:AA5,0)),0))+IF(AB6<AB31,0,IFERROR(INDEX($T39:AA39,0,MATCH(AB5-AB31,$T5:AA5,0)),0))+IF(AB6<AB31,0,IFERROR(INDEX($T41:AA41,0,MATCH(AB5-AB31,$T5:AA5,0)),0))-AB38-AB37} -> 0 | AC41: {=IF(AC5<AC31,AC25/AC31,0)+IF(AC6<AC31,0,IFERROR(INDEX($T37:AB37,0,MATCH(AC5-AC31,$T5:AB5,0)),0))+IF(AC6<AC31,0,IFERROR(INDEX($T36:AB36,0,MATCH(AC5-AC31,$T5:AB5,0)),0))+IF(AC6<AC31,0,IFERROR(INDEX($T39:AB39,0,MATCH(AC5-AC31,$T5:AB5,0)),0))+IF(AC6<AC31,0,IFERROR(INDEX($T41:AB41,0,MATCH(AC5-AC31,$T5:AB5,0)),0))-AC38-AC37} -> 0 | ... BO41: {=IF(BO5<BO31,BO25/BO31,0)+IF(BO6<BO31,0,IFERROR(INDEX($T37:BN37,0,MATCH(BO5-BO31,$T5:BN5,0)),0))+IF(BO6<BO31,0,IFERROR(INDEX($T36:BN36,0,MATCH(BO5-BO31,$T5:BN5,0)),0))+IF(BO6<BO31,0,IFERROR(INDEX($T39:BN39,0,MATCH(BO5-BO31,$T5:BN5,0)),0))+IF(BO6<BO31,0,IFERROR(INDEX($T41:BN41,0,MATCH(BO5-BO31,$T5:BN5,0)),0))-BO38-BO37} -> 0
B42: Growth Rate in New Subscribers | C42: % | D42: growth rate in new subscribers per period | H42: average | I42: =IF(H42=Forecast!$H$74,T42,IF(H42=Forecast!$H$75,BO42,IF(H42=Forecast!$H$76,SUM(T42:BO42),IF(H42=Forecast!$H$77,AVERAGE(T42:BO42),0)))) -> 0.038114267 | T42: =IF(EOMONTH(T23,0)=T4,T26,S42*(1+T27)) -> 0.1 | U42: =IF(EOMONTH(U23,0)=U4,U26,T42*(1+U27)) -> 0.095 | V42: =IF(EOMONTH(V23,0)=V4,V26,U42*(1+V27)) -> 0.09025 | W42: =IF(EOMONTH(W23,0)=W4,W26,V42*(1+W27)) -> 0.0857375 | X42: =IF(EOMONTH(X23,0)=X4,X26,W42*(1+X27)) -> 0.081450625 | Y42: =IF(EOMONTH(Y23,0)=Y4,Y26,X42*(1+Y27)) -> 0.077378094 | Z42: =IF(EOMONTH(Z23,0)=Z4,Z26,Y42*(1+Z27)) -> 0.073509189 | AA42: =IF(EOMONTH(AA23,0)=AA4,AA26,Z42*(1+AA27)) -> 0.06983373 | ... BO42: =IF(EOMONTH(BO23,0)=BO4,BO26,BN42*(1+BO27)) -> 0.0089744832
B43: Growth Rate in Total Subscribers | C43: % | D43: growth rate in total subscribers | H43: average | I43: =IF(H43=Forecast!$H$74,T43,IF(H43=Forecast!$H$75,BO43,IF(H43=Forecast!$H$76,SUM(T43:BO43),IF(H43=Forecast!$H$77,AVERAGE(T43:BO43),0)))) -> 0.12108135 | T43: =IFERROR(T40/S40-1,0) -> 0 | U43: =IFERROR(U40/T40-1,0) -> 1.095 | V43: =IFERROR(V40/U40-1,0) -> 0.56984427 | W43: =IFERROR(W40/V40-1,0) -> 0.39411635 | X43: =IFERROR(X40/W40-1,0) -> 0.30572583 | Y43: =IFERROR(Y40/X40-1,0) -> 0.25225993 | Z43: =IFERROR(Z40/Y40-1,0) -> 0.21625171 | AA43: =IFERROR(AA40/Z40-1,0) -> 0.19021834 | ... BO43: =IFERROR(BO40/BN40-1,0) -> 0.032088132
B45: Revenues, Billings, Expenses
B46: Revenues | C46: ='Get Started'!D$7 -> $ | D46: ="average revenue * ending "&LOWER('Get Started'!B20) -> average revenue * ending subscribers | H46: sum | I46: =IF(H46="initial",T46,IF(H46="final",BO46,IF(H46="sum",SUM(T46:BO46)))) -> 2294938.3 | T46: =T40*T16 -> 750 | U46: =U40*U16 -> 1571.25 | V46: =V40*V16 -> 2466.6178 | W46: =W40*W16 -> 3438.7522 | X46: =X40*X16 -> 4490.0676 | Y46: =Y40*Y16 -> 5622.7317 | Z46: =Z40*Z16 -> 6838.6571 | AA46: =AA40*AA16 -> 8139.4951 | ... BO46: =BO40*BO16 -> 118008.9
B47: Marketing Spend | C47: ='Get Started'!D$7 -> $ | D47: new * CAC + renewed * retention cost + reactivated * CAC | H47: sum | I47: =IF(H47="initial",T47,IF(H47="final",BO47,IF(H47="sum",SUM(T47:BO47)))) -> 124416.68 | T47: =T36*T18+T37*T19+T18*T39 -> 625 | U47: =U36*U18+U37*U19+U18*U39 -> 684.375 | V47: =V36*V18+V37*V19+V18*V39 -> 746.13984 | W47: =W36*W18+W37*W19+W18*W39 -> 810.11201 | X47: =X36*X18+X37*X19+X18*X39 -> 876.09614 | Y47: =Y36*Y18+Y37*Y19+Y18*Y39 -> 943.88679 | Z47: =Z36*Z18+Z37*Z19+Z18*Z39 -> 1013.2711 | AA47: =AA36*AA18+AA37*AA19+AA18*AA39 -> 1084.0316 | ... BO47: =BO36*BO18+BO37*BO19+BO18*BO39 -> 4566.673
...

Sheet Additional Tools
B2: Additional Tools
B3: Additional tools to check out, install, and use to help you utilize the model.
B5: Term | C5: How it helps | D5: Definition | E5: Link
B7: Genius Sheets | C7: Using financials from Quickbooks | D7: Built into the model is a robust way to use actual financials (financial reports from Quickbooks, Xero, and others) in the model to create rolling forecasts and budget variances, detailed at https://foresight.is/learn/actual-financials The hardest part to this is simply pulling the data from your accounting software. It's something that can be done manually on a regular basis, but I've also started using add-ins to automate this process. One tool I like is Genius Sheets - https://geniussheets.com - which also has add-ins for Excel and Google Sheets. Visit their website or click the image below to create an account, install the add-ins, and start pulling your financial data into your model. Here's me showing an example of how to use Genius Sheets in the model: https://www.loom.com/share/f067d790d1f245a28abf33eecaa02abc Here's a good explainer on how to use Genius Sheets: https://www.excel-university.com/retrieve-quickbooks-data-with-genius-sheets/ | E7: https://geniussheets.com
B8: Causal | C8: Scenario modeling | D8: For scenarios, I like to leverage Excel and Google Sheets Add-ins to built out scenarios and analyze outputs based on distributions of assumptions. One tool I like is Causal - https://causal.app - which also has add-ins for Excel and Google Sheets. They can be installed into your Excel or Google Sheets, just click on the images below. Here's how to use it (instructions are for Google Sheets, same applies to Excel): https://www.causal.app/blog/google-sheets-add-on | E8: https://causal.app
B9: Liveflow | C9: Using financials from Quickbooks | D9: LiveFlow connects QuickBooks to your Google Sheet and automatically updates your financials. Save time pulling manually pulling and updating data in your financial model. | E9: https://www.liveflow.io/

Sheet Model Comparison
B2: Foresight Template Comparison
B3: I offer a range of templates for venture funds and angels. Here's a breakdown of the models and how they compare.
B5: Template | C5: Link | D5: Software | E5: Usecase | F5: Price | G5: Time Scale | H5: Prebuilt Revenue Model | I5: Operating Expenses | J5: Hiring Plan | K5: Consolidated Financials | L5: Charts and Graphs | M5: Key Performance Metrics | N5: Historical Financials and Budget Variances | O5: Prebuilt Inventory Calcs | P5: Capital Structure (Equity, Debt, Grants, etc.) | Q5: Cap Table and Valuation
B7: Runway and Cash Forecasting Tool | C7: https://foresight.is/runway-cash-forecasting | D7: Google Sheets, download to Excel | E7: Seed-stage companies building first model | F7: Free | G7: 3 years | H7: FALSE | I7: TRUE | J7: FALSE | K7: TRUE | L7: TRUE | M7: TRUE | N7: FALSE | O7: FALSE | P7: TRUE | Q7: FALSE
B8: Starter Financial Model | C8: https://foresight.is/starter-financial-model | D8: Excel, upload to Google Sheets | E8: Seed - A stage companies building their own custom revenue model | F8: $74 USD | G8: 5 years | H8: FALSE | I8: TRUE | J8: TRUE | K8: TRUE | L8: TRUE | M8: TRUE | N8: FALSE | O8: TRUE | P8: TRUE | Q8: FALSE
B9: Standard Financial Model | C9: https://foresight.is/standard-financial-model | D9: Excel, upload to Google Sheets | E9: Seed - B stage companies leveraging the prebuilt revenue model or building their own | F9: $149 USD | G9: 5 years | H9: TRUE | I9: TRUE | J9: TRUE | K9: TRUE | L9: TRUE | M9: TRUE | N9: TRUE | O9: TRUE | P9: TRUE | Q9: TRUE
B10: Standard Financial Model for SaaS | C10: https://foresight.is/saas-financial-model | D10: Excel, upload to Google Sheets | E10: Companies with SaaS business models | F10: $149 USD | G10: 5 years | H10: TRUE | I10: TRUE | J10: TRUE | K10: TRUE | L10: TRUE | M10: TRUE | N10: TRUE | O10: TRUE | P10: TRUE | Q10: TRUE
B11: Standard Financial Model for Ecommerce | C11: https://foresight.is/ecommerce-financial-model | D11: Excel, upload to Google Sheets | E11: Companies with Ecommerce business models | F11: $149 USD | G11: 5 years | H11: TRUE | I11: TRUE | J11: TRUE | K11: TRUE | L11: TRUE | M11: TRUE | N11: TRUE | O11: TRUE | P11: TRUE | Q11: TRUE
B12: SaaS Forecasting Tool | C12: https://foresight.is/saas-forecasting-tool | D12: Excel, upload to Google Sheets | E12: Seed-stage entrepreneurs wanting to understand how to forecast SaaS businesses | F12: Free | G12: 3 years | H12: TRUE | I12: FALSE | J12: FALSE | K12: FALSE | L12: TRUE | M12: TRUE | N12: FALSE | O12: FALSE | P12: FALSE | Q12: FALSE
B13: Ecommerce ForecastingTool | C13: https://foresight.is/ecommerce-forecasting-tool | D13: Excel, upload to Google Sheets | E13: Seed-stage entrepreneurs wanting to understand how to forecast Ecommerce businesses | F13: Free | G13: 3 years | H13: TRUE | I13: FALSE | J13: FALSE | K13: FALSE | L13: TRUE | M13: TRUE | N13: FALSE | O13: FALSE | P13: FALSE | Q13: FALSE
B14: Unit Economics Tool | C14: https://foresight.is/unit-economics-template | D14: Excel, upload to Google Sheets | E14: Seed - B stage companies wanting to detail their unit economics, LTV, and cash flows on a per-user (subscriber, client, customer, etc.) basis. | F14: Free | G14: ~ | H14: TRUE | I14: FALSE | J14: FALSE | K14: FALSE | L14: FALSE | M14: FALSE | N14: FALSE | O14: FALSE | P14: FALSE | Q14: FALSE
B15: Enterprise SaaS Forecasting Tool | C15: https://foresight.is/enterprise-saas-template | D15: Excel, upload to Google Sheets | E15: Enterprise SaaS businesses wanting to use an enterprise pipeline and specific customer method to forecast their revenues | F15: Free | G15: 3 years | H15: TRUE | I15: FALSE | J15: FALSE | K15: FALSE | L15: TRUE | M15: TRUE | N15: FALSE | O15: FALSE | P15: FALSE | Q15: FALSE

Sheet Changelog
B2: Changelog
B3: Here's what has changed.
B5: v1.05 - September 23, 2022
B6: Small styling edits, to changes to core structure
B8: v1.04 - February 16, 2022
B9: Pulled the model into Google Sheets as the default structure, edited Key Reports. No change to core structure.
B11: v1.03 - September 6, 2021
B12: Forecast: Fixed an error on the renewal and churn calcs, line 37 and 38. The formulas previously mixed up the churn and retention rate for calculating churn and retention from any subscribers assumed at the beginning of period,leading to incorrect calcs if that assumption was used.
B14: v1.02 - July 30, 2021
B15: Forecast: Edited to remove all formulas that use OFFSET. Reduces reliance on a volatile formula, to help with model performance in larger implementations, this is a change I am making across all models and standardizing on.
B17: v1.01 - August 17, 2020
B18: Get Started, Forecast: Added retention costs. Not a vital change, but I am changing the base templates to prebuild in marketing costs for retention and expansion, and adding the same thinking here. Also included reactivated subscribers *CAC to account for some cost here, I could see that using CAC or retention cost per subscriber. Sums to Marketing Costs for simplicity.
... B23: Questions, ask hello@foresight.is anytime.
